2020-10-06 11:24:02,098 - 37576 DEBUG - ['Traceback (most recent call last):\n', '  File "C:/Users/balaji.a.arunachalam/PycharmProjects/Back_end(Python,SQL)/src/main/insertion.py", line 17, in __init__\n    temp = sys.argv[1]\n', 'IndexError: list index out of range\n', '\nDuring handling of the above exception, another exception occurred:\n\n', 'Traceback (most recent call last):\n', '  File "C:/Users/balaji.a.arunachalam/PycharmProjects/Back_end(Python,SQL)/src/main/insertion.py", line 42, in record_insertion\n    with open(file_path, \'r\') as read_file:\n', "FileNotFoundError: [Errno 2] No such file or directory: 'C:/Users/balaji.a.arunachalam/PycharmProjects/Back_end(Python,SQL)/src\\\\files\\\\records\\\\1_category_details.csv.sql'\n"]
2020-10-06 11:24:02,098 - 37576 DEBUG - ['Traceback (most recent call last):\n', '  File "C:/Users/balaji.a.arunachalam/PycharmProjects/Back_end(Python,SQL)/src/main/insertion.py", line 17, in __init__\n    temp = sys.argv[1]\n', 'IndexError: list index out of range\n', '\nDuring handling of the above exception, another exception occurred:\n\n', 'Traceback (most recent call last):\n', '  File "C:/Users/balaji.a.arunachalam/PycharmProjects/Back_end(Python,SQL)/src/main/insertion.py", line 42, in record_insertion\n    with open(file_path, \'r\') as read_file:\n', "FileNotFoundError: [Errno 2] No such file or directory: 'C:/Users/balaji.a.arunachalam/PycharmProjects/Back_end(Python,SQL)/src\\\\files\\\\records\\\\1_category_details.csv.sql'\n"]
2020-10-06 11:24:02,098 - 37576 DEBUG - ['Traceback (most recent call last):\n', '  File "C:/Users/balaji.a.arunachalam/PycharmProjects/Back_end(Python,SQL)/src/main/insertion.py", line 17, in __init__\n    temp = sys.argv[1]\n', 'IndexError: list index out of range\n', '\nDuring handling of the above exception, another exception occurred:\n\n', 'Traceback (most recent call last):\n', '  File "C:/Users/balaji.a.arunachalam/PycharmProjects/Back_end(Python,SQL)/src/main/insertion.py", line 42, in record_insertion\n    with open(file_path, \'r\') as read_file:\n', "FileNotFoundError: [Errno 2] No such file or directory: 'C:/Users/balaji.a.arunachalam/PycharmProjects/Back_end(Python,SQL)/src\\\\files\\\\records\\\\1_category_details.csv.sql'\n"]
2020-10-06 11:24:02,099 - 37576 DEBUG - ['Traceback (most recent call last):\n', '  File "C:/Users/balaji.a.arunachalam/PycharmProjects/Back_end(Python,SQL)/src/main/insertion.py", line 17, in __init__\n    temp = sys.argv[1]\n', 'IndexError: list index out of range\n', '\nDuring handling of the above exception, another exception occurred:\n\n', 'Traceback (most recent call last):\n', '  File "C:/Users/balaji.a.arunachalam/PycharmProjects/Back_end(Python,SQL)/src/main/insertion.py", line 42, in record_insertion\n    with open(file_path, \'r\') as read_file:\n', "FileNotFoundError: [Errno 2] No such file or directory: 'C:/Users/balaji.a.arunachalam/PycharmProjects/Back_end(Python,SQL)/src\\\\files\\\\records\\\\2_customer_details.csv.sql'\n"]
2020-10-06 11:24:02,099 - 37576 DEBUG - ['Traceback (most recent call last):\n', '  File "C:/Users/balaji.a.arunachalam/PycharmProjects/Back_end(Python,SQL)/src/main/insertion.py", line 17, in __init__\n    temp = sys.argv[1]\n', 'IndexError: list index out of range\n', '\nDuring handling of the above exception, another exception occurred:\n\n', 'Traceback (most recent call last):\n', '  File "C:/Users/balaji.a.arunachalam/PycharmProjects/Back_end(Python,SQL)/src/main/insertion.py", line 42, in record_insertion\n    with open(file_path, \'r\') as read_file:\n', "FileNotFoundError: [Errno 2] No such file or directory: 'C:/Users/balaji.a.arunachalam/PycharmProjects/Back_end(Python,SQL)/src\\\\files\\\\records\\\\2_customer_details.csv.sql'\n"]
2020-10-06 11:24:02,099 - 37576 DEBUG - ['Traceback (most recent call last):\n', '  File "C:/Users/balaji.a.arunachalam/PycharmProjects/Back_end(Python,SQL)/src/main/insertion.py", line 17, in __init__\n    temp = sys.argv[1]\n', 'IndexError: list index out of range\n', '\nDuring handling of the above exception, another exception occurred:\n\n', 'Traceback (most recent call last):\n', '  File "C:/Users/balaji.a.arunachalam/PycharmProjects/Back_end(Python,SQL)/src/main/insertion.py", line 42, in record_insertion\n    with open(file_path, \'r\') as read_file:\n', "FileNotFoundError: [Errno 2] No such file or directory: 'C:/Users/balaji.a.arunachalam/PycharmProjects/Back_end(Python,SQL)/src\\\\files\\\\records\\\\2_customer_details.csv.sql'\n"]
2020-10-06 11:24:02,099 - 37576 DEBUG - ['Traceback (most recent call last):\n', '  File "C:/Users/balaji.a.arunachalam/PycharmProjects/Back_end(Python,SQL)/src/main/insertion.py", line 17, in __init__\n    temp = sys.argv[1]\n', 'IndexError: list index out of range\n', '\nDuring handling of the above exception, another exception occurred:\n\n', 'Traceback (most recent call last):\n', '  File "C:/Users/balaji.a.arunachalam/PycharmProjects/Back_end(Python,SQL)/src/main/insertion.py", line 42, in record_insertion\n    with open(file_path, \'r\') as read_file:\n', "FileNotFoundError: [Errno 2] No such file or directory: 'C:/Users/balaji.a.arunachalam/PycharmProjects/Back_end(Python,SQL)/src\\\\files\\\\records\\\\3_order_status_details.csv.sql'\n"]
2020-10-06 11:24:02,099 - 37576 DEBUG - ['Traceback (most recent call last):\n', '  File "C:/Users/balaji.a.arunachalam/PycharmProjects/Back_end(Python,SQL)/src/main/insertion.py", line 17, in __init__\n    temp = sys.argv[1]\n', 'IndexError: list index out of range\n', '\nDuring handling of the above exception, another exception occurred:\n\n', 'Traceback (most recent call last):\n', '  File "C:/Users/balaji.a.arunachalam/PycharmProjects/Back_end(Python,SQL)/src/main/insertion.py", line 42, in record_insertion\n    with open(file_path, \'r\') as read_file:\n', "FileNotFoundError: [Errno 2] No such file or directory: 'C:/Users/balaji.a.arunachalam/PycharmProjects/Back_end(Python,SQL)/src\\\\files\\\\records\\\\3_order_status_details.csv.sql'\n"]
2020-10-06 11:24:02,099 - 37576 DEBUG - ['Traceback (most recent call last):\n', '  File "C:/Users/balaji.a.arunachalam/PycharmProjects/Back_end(Python,SQL)/src/main/insertion.py", line 17, in __init__\n    temp = sys.argv[1]\n', 'IndexError: list index out of range\n', '\nDuring handling of the above exception, another exception occurred:\n\n', 'Traceback (most recent call last):\n', '  File "C:/Users/balaji.a.arunachalam/PycharmProjects/Back_end(Python,SQL)/src/main/insertion.py", line 42, in record_insertion\n    with open(file_path, \'r\') as read_file:\n', "FileNotFoundError: [Errno 2] No such file or directory: 'C:/Users/balaji.a.arunachalam/PycharmProjects/Back_end(Python,SQL)/src\\\\files\\\\records\\\\3_order_status_details.csv.sql'\n"]
2020-10-06 11:24:02,100 - 37576 DEBUG - ['Traceback (most recent call last):\n', '  File "C:/Users/balaji.a.arunachalam/PycharmProjects/Back_end(Python,SQL)/src/main/insertion.py", line 17, in __init__\n    temp = sys.argv[1]\n', 'IndexError: list index out of range\n', '\nDuring handling of the above exception, another exception occurred:\n\n', 'Traceback (most recent call last):\n', '  File "C:/Users/balaji.a.arunachalam/PycharmProjects/Back_end(Python,SQL)/src/main/insertion.py", line 42, in record_insertion\n    with open(file_path, \'r\') as read_file:\n', "FileNotFoundError: [Errno 2] No such file or directory: 'C:/Users/balaji.a.arunachalam/PycharmProjects/Back_end(Python,SQL)/src\\\\files\\\\records\\\\4_seller_details.csv.sql'\n"]
2020-10-06 11:24:02,100 - 37576 DEBUG - ['Traceback (most recent call last):\n', '  File "C:/Users/balaji.a.arunachalam/PycharmProjects/Back_end(Python,SQL)/src/main/insertion.py", line 17, in __init__\n    temp = sys.argv[1]\n', 'IndexError: list index out of range\n', '\nDuring handling of the above exception, another exception occurred:\n\n', 'Traceback (most recent call last):\n', '  File "C:/Users/balaji.a.arunachalam/PycharmProjects/Back_end(Python,SQL)/src/main/insertion.py", line 42, in record_insertion\n    with open(file_path, \'r\') as read_file:\n', "FileNotFoundError: [Errno 2] No such file or directory: 'C:/Users/balaji.a.arunachalam/PycharmProjects/Back_end(Python,SQL)/src\\\\files\\\\records\\\\4_seller_details.csv.sql'\n"]
2020-10-06 11:24:02,100 - 37576 DEBUG - ['Traceback (most recent call last):\n', '  File "C:/Users/balaji.a.arunachalam/PycharmProjects/Back_end(Python,SQL)/src/main/insertion.py", line 17, in __init__\n    temp = sys.argv[1]\n', 'IndexError: list index out of range\n', '\nDuring handling of the above exception, another exception occurred:\n\n', 'Traceback (most recent call last):\n', '  File "C:/Users/balaji.a.arunachalam/PycharmProjects/Back_end(Python,SQL)/src/main/insertion.py", line 42, in record_insertion\n    with open(file_path, \'r\') as read_file:\n', "FileNotFoundError: [Errno 2] No such file or directory: 'C:/Users/balaji.a.arunachalam/PycharmProjects/Back_end(Python,SQL)/src\\\\files\\\\records\\\\4_seller_details.csv.sql'\n"]
2020-10-06 11:24:02,101 - 37576 DEBUG - ['Traceback (most recent call last):\n', '  File "C:/Users/balaji.a.arunachalam/PycharmProjects/Back_end(Python,SQL)/src/main/insertion.py", line 17, in __init__\n    temp = sys.argv[1]\n', 'IndexError: list index out of range\n', '\nDuring handling of the above exception, another exception occurred:\n\n', 'Traceback (most recent call last):\n', '  File "C:/Users/balaji.a.arunachalam/PycharmProjects/Back_end(Python,SQL)/src/main/insertion.py", line 42, in record_insertion\n    with open(file_path, \'r\') as read_file:\n', "FileNotFoundError: [Errno 2] No such file or directory: 'C:/Users/balaji.a.arunachalam/PycharmProjects/Back_end(Python,SQL)/src\\\\files\\\\records\\\\5_cart_details.csv.sql'\n"]
2020-10-06 11:24:02,101 - 37576 DEBUG - ['Traceback (most recent call last):\n', '  File "C:/Users/balaji.a.arunachalam/PycharmProjects/Back_end(Python,SQL)/src/main/insertion.py", line 17, in __init__\n    temp = sys.argv[1]\n', 'IndexError: list index out of range\n', '\nDuring handling of the above exception, another exception occurred:\n\n', 'Traceback (most recent call last):\n', '  File "C:/Users/balaji.a.arunachalam/PycharmProjects/Back_end(Python,SQL)/src/main/insertion.py", line 42, in record_insertion\n    with open(file_path, \'r\') as read_file:\n', "FileNotFoundError: [Errno 2] No such file or directory: 'C:/Users/balaji.a.arunachalam/PycharmProjects/Back_end(Python,SQL)/src\\\\files\\\\records\\\\5_cart_details.csv.sql'\n"]
2020-10-06 11:24:02,101 - 37576 DEBUG - ['Traceback (most recent call last):\n', '  File "C:/Users/balaji.a.arunachalam/PycharmProjects/Back_end(Python,SQL)/src/main/insertion.py", line 17, in __init__\n    temp = sys.argv[1]\n', 'IndexError: list index out of range\n', '\nDuring handling of the above exception, another exception occurred:\n\n', 'Traceback (most recent call last):\n', '  File "C:/Users/balaji.a.arunachalam/PycharmProjects/Back_end(Python,SQL)/src/main/insertion.py", line 42, in record_insertion\n    with open(file_path, \'r\') as read_file:\n', "FileNotFoundError: [Errno 2] No such file or directory: 'C:/Users/balaji.a.arunachalam/PycharmProjects/Back_end(Python,SQL)/src\\\\files\\\\records\\\\5_cart_details.csv.sql'\n"]
2020-10-06 11:24:02,102 - 37576 DEBUG - ['Traceback (most recent call last):\n', '  File "C:/Users/balaji.a.arunachalam/PycharmProjects/Back_end(Python,SQL)/src/main/insertion.py", line 17, in __init__\n    temp = sys.argv[1]\n', 'IndexError: list index out of range\n', '\nDuring handling of the above exception, another exception occurred:\n\n', 'Traceback (most recent call last):\n', '  File "C:/Users/balaji.a.arunachalam/PycharmProjects/Back_end(Python,SQL)/src/main/insertion.py", line 42, in record_insertion\n    with open(file_path, \'r\') as read_file:\n', "FileNotFoundError: [Errno 2] No such file or directory: 'C:/Users/balaji.a.arunachalam/PycharmProjects/Back_end(Python,SQL)/src\\\\files\\\\records\\\\6_customer_address_details.csv.sql'\n"]
2020-10-06 11:24:02,102 - 37576 DEBUG - ['Traceback (most recent call last):\n', '  File "C:/Users/balaji.a.arunachalam/PycharmProjects/Back_end(Python,SQL)/src/main/insertion.py", line 17, in __init__\n    temp = sys.argv[1]\n', 'IndexError: list index out of range\n', '\nDuring handling of the above exception, another exception occurred:\n\n', 'Traceback (most recent call last):\n', '  File "C:/Users/balaji.a.arunachalam/PycharmProjects/Back_end(Python,SQL)/src/main/insertion.py", line 42, in record_insertion\n    with open(file_path, \'r\') as read_file:\n', "FileNotFoundError: [Errno 2] No such file or directory: 'C:/Users/balaji.a.arunachalam/PycharmProjects/Back_end(Python,SQL)/src\\\\files\\\\records\\\\6_customer_address_details.csv.sql'\n"]
2020-10-06 11:24:02,102 - 37576 DEBUG - ['Traceback (most recent call last):\n', '  File "C:/Users/balaji.a.arunachalam/PycharmProjects/Back_end(Python,SQL)/src/main/insertion.py", line 17, in __init__\n    temp = sys.argv[1]\n', 'IndexError: list index out of range\n', '\nDuring handling of the above exception, another exception occurred:\n\n', 'Traceback (most recent call last):\n', '  File "C:/Users/balaji.a.arunachalam/PycharmProjects/Back_end(Python,SQL)/src/main/insertion.py", line 42, in record_insertion\n    with open(file_path, \'r\') as read_file:\n', "FileNotFoundError: [Errno 2] No such file or directory: 'C:/Users/balaji.a.arunachalam/PycharmProjects/Back_end(Python,SQL)/src\\\\files\\\\records\\\\6_customer_address_details.csv.sql'\n"]
2020-10-06 11:24:02,103 - 37576 DEBUG - ['Traceback (most recent call last):\n', '  File "C:/Users/balaji.a.arunachalam/PycharmProjects/Back_end(Python,SQL)/src/main/insertion.py", line 17, in __init__\n    temp = sys.argv[1]\n', 'IndexError: list index out of range\n', '\nDuring handling of the above exception, another exception occurred:\n\n', 'Traceback (most recent call last):\n', '  File "C:/Users/balaji.a.arunachalam/PycharmProjects/Back_end(Python,SQL)/src/main/insertion.py", line 42, in record_insertion\n    with open(file_path, \'r\') as read_file:\n', "FileNotFoundError: [Errno 2] No such file or directory: 'C:/Users/balaji.a.arunachalam/PycharmProjects/Back_end(Python,SQL)/src\\\\files\\\\records\\\\7_order_details.csv.sql'\n"]
2020-10-06 11:24:02,103 - 37576 DEBUG - ['Traceback (most recent call last):\n', '  File "C:/Users/balaji.a.arunachalam/PycharmProjects/Back_end(Python,SQL)/src/main/insertion.py", line 17, in __init__\n    temp = sys.argv[1]\n', 'IndexError: list index out of range\n', '\nDuring handling of the above exception, another exception occurred:\n\n', 'Traceback (most recent call last):\n', '  File "C:/Users/balaji.a.arunachalam/PycharmProjects/Back_end(Python,SQL)/src/main/insertion.py", line 42, in record_insertion\n    with open(file_path, \'r\') as read_file:\n', "FileNotFoundError: [Errno 2] No such file or directory: 'C:/Users/balaji.a.arunachalam/PycharmProjects/Back_end(Python,SQL)/src\\\\files\\\\records\\\\7_order_details.csv.sql'\n"]
2020-10-06 11:24:02,103 - 37576 DEBUG - ['Traceback (most recent call last):\n', '  File "C:/Users/balaji.a.arunachalam/PycharmProjects/Back_end(Python,SQL)/src/main/insertion.py", line 17, in __init__\n    temp = sys.argv[1]\n', 'IndexError: list index out of range\n', '\nDuring handling of the above exception, another exception occurred:\n\n', 'Traceback (most recent call last):\n', '  File "C:/Users/balaji.a.arunachalam/PycharmProjects/Back_end(Python,SQL)/src/main/insertion.py", line 42, in record_insertion\n    with open(file_path, \'r\') as read_file:\n', "FileNotFoundError: [Errno 2] No such file or directory: 'C:/Users/balaji.a.arunachalam/PycharmProjects/Back_end(Python,SQL)/src\\\\files\\\\records\\\\7_order_details.csv.sql'\n"]
2020-10-06 11:24:02,104 - 37576 DEBUG - ['Traceback (most recent call last):\n', '  File "C:/Users/balaji.a.arunachalam/PycharmProjects/Back_end(Python,SQL)/src/main/insertion.py", line 17, in __init__\n    temp = sys.argv[1]\n', 'IndexError: list index out of range\n', '\nDuring handling of the above exception, another exception occurred:\n\n', 'Traceback (most recent call last):\n', '  File "C:/Users/balaji.a.arunachalam/PycharmProjects/Back_end(Python,SQL)/src/main/insertion.py", line 42, in record_insertion\n    with open(file_path, \'r\') as read_file:\n', "FileNotFoundError: [Errno 2] No such file or directory: 'C:/Users/balaji.a.arunachalam/PycharmProjects/Back_end(Python,SQL)/src\\\\files\\\\records\\\\8_product_stock_details.csv.sql'\n"]
2020-10-06 11:24:02,104 - 37576 DEBUG - ['Traceback (most recent call last):\n', '  File "C:/Users/balaji.a.arunachalam/PycharmProjects/Back_end(Python,SQL)/src/main/insertion.py", line 17, in __init__\n    temp = sys.argv[1]\n', 'IndexError: list index out of range\n', '\nDuring handling of the above exception, another exception occurred:\n\n', 'Traceback (most recent call last):\n', '  File "C:/Users/balaji.a.arunachalam/PycharmProjects/Back_end(Python,SQL)/src/main/insertion.py", line 42, in record_insertion\n    with open(file_path, \'r\') as read_file:\n', "FileNotFoundError: [Errno 2] No such file or directory: 'C:/Users/balaji.a.arunachalam/PycharmProjects/Back_end(Python,SQL)/src\\\\files\\\\records\\\\8_product_stock_details.csv.sql'\n"]
2020-10-06 11:24:02,104 - 37576 DEBUG - ['Traceback (most recent call last):\n', '  File "C:/Users/balaji.a.arunachalam/PycharmProjects/Back_end(Python,SQL)/src/main/insertion.py", line 17, in __init__\n    temp = sys.argv[1]\n', 'IndexError: list index out of range\n', '\nDuring handling of the above exception, another exception occurred:\n\n', 'Traceback (most recent call last):\n', '  File "C:/Users/balaji.a.arunachalam/PycharmProjects/Back_end(Python,SQL)/src/main/insertion.py", line 42, in record_insertion\n    with open(file_path, \'r\') as read_file:\n', "FileNotFoundError: [Errno 2] No such file or directory: 'C:/Users/balaji.a.arunachalam/PycharmProjects/Back_end(Python,SQL)/src\\\\files\\\\records\\\\8_product_stock_details.csv.sql'\n"]
2020-10-06 11:24:02,105 - 37576 DEBUG - ['Traceback (most recent call last):\n', '  File "C:/Users/balaji.a.arunachalam/PycharmProjects/Back_end(Python,SQL)/src/main/insertion.py", line 17, in __init__\n    temp = sys.argv[1]\n', 'IndexError: list index out of range\n', '\nDuring handling of the above exception, another exception occurred:\n\n', 'Traceback (most recent call last):\n', '  File "C:/Users/balaji.a.arunachalam/PycharmProjects/Back_end(Python,SQL)/src/main/insertion.py", line 42, in record_insertion\n    with open(file_path, \'r\') as read_file:\n', "FileNotFoundError: [Errno 2] No such file or directory: 'C:/Users/balaji.a.arunachalam/PycharmProjects/Back_end(Python,SQL)/src\\\\files\\\\records\\\\9.0_product_details.csv.sql'\n"]
2020-10-06 11:24:02,105 - 37576 DEBUG - ['Traceback (most recent call last):\n', '  File "C:/Users/balaji.a.arunachalam/PycharmProjects/Back_end(Python,SQL)/src/main/insertion.py", line 17, in __init__\n    temp = sys.argv[1]\n', 'IndexError: list index out of range\n', '\nDuring handling of the above exception, another exception occurred:\n\n', 'Traceback (most recent call last):\n', '  File "C:/Users/balaji.a.arunachalam/PycharmProjects/Back_end(Python,SQL)/src/main/insertion.py", line 42, in record_insertion\n    with open(file_path, \'r\') as read_file:\n', "FileNotFoundError: [Errno 2] No such file or directory: 'C:/Users/balaji.a.arunachalam/PycharmProjects/Back_end(Python,SQL)/src\\\\files\\\\records\\\\9.0_product_details.csv.sql'\n"]
2020-10-06 11:24:02,105 - 37576 DEBUG - ['Traceback (most recent call last):\n', '  File "C:/Users/balaji.a.arunachalam/PycharmProjects/Back_end(Python,SQL)/src/main/insertion.py", line 17, in __init__\n    temp = sys.argv[1]\n', 'IndexError: list index out of range\n', '\nDuring handling of the above exception, another exception occurred:\n\n', 'Traceback (most recent call last):\n', '  File "C:/Users/balaji.a.arunachalam/PycharmProjects/Back_end(Python,SQL)/src/main/insertion.py", line 42, in record_insertion\n    with open(file_path, \'r\') as read_file:\n', "FileNotFoundError: [Errno 2] No such file or directory: 'C:/Users/balaji.a.arunachalam/PycharmProjects/Back_end(Python,SQL)/src\\\\files\\\\records\\\\9.0_product_details.csv.sql'\n"]
2020-10-06 11:24:02,105 - 37576 DEBUG - ['Traceback (most recent call last):\n', '  File "C:/Users/balaji.a.arunachalam/PycharmProjects/Back_end(Python,SQL)/src/main/insertion.py", line 17, in __init__\n    temp = sys.argv[1]\n', 'IndexError: list index out of range\n', '\nDuring handling of the above exception, another exception occurred:\n\n', 'Traceback (most recent call last):\n', '  File "C:/Users/balaji.a.arunachalam/PycharmProjects/Back_end(Python,SQL)/src/main/insertion.py", line 42, in record_insertion\n    with open(file_path, \'r\') as read_file:\n', "FileNotFoundError: [Errno 2] No such file or directory: 'C:/Users/balaji.a.arunachalam/PycharmProjects/Back_end(Python,SQL)/src\\\\files\\\\records\\\\9.1_cart_product_details.csv.sql'\n"]
2020-10-06 11:24:02,105 - 37576 DEBUG - ['Traceback (most recent call last):\n', '  File "C:/Users/balaji.a.arunachalam/PycharmProjects/Back_end(Python,SQL)/src/main/insertion.py", line 17, in __init__\n    temp = sys.argv[1]\n', 'IndexError: list index out of range\n', '\nDuring handling of the above exception, another exception occurred:\n\n', 'Traceback (most recent call last):\n', '  File "C:/Users/balaji.a.arunachalam/PycharmProjects/Back_end(Python,SQL)/src/main/insertion.py", line 42, in record_insertion\n    with open(file_path, \'r\') as read_file:\n', "FileNotFoundError: [Errno 2] No such file or directory: 'C:/Users/balaji.a.arunachalam/PycharmProjects/Back_end(Python,SQL)/src\\\\files\\\\records\\\\9.1_cart_product_details.csv.sql'\n"]
2020-10-06 11:24:02,105 - 37576 DEBUG - ['Traceback (most recent call last):\n', '  File "C:/Users/balaji.a.arunachalam/PycharmProjects/Back_end(Python,SQL)/src/main/insertion.py", line 17, in __init__\n    temp = sys.argv[1]\n', 'IndexError: list index out of range\n', '\nDuring handling of the above exception, another exception occurred:\n\n', 'Traceback (most recent call last):\n', '  File "C:/Users/balaji.a.arunachalam/PycharmProjects/Back_end(Python,SQL)/src/main/insertion.py", line 42, in record_insertion\n    with open(file_path, \'r\') as read_file:\n', "FileNotFoundError: [Errno 2] No such file or directory: 'C:/Users/balaji.a.arunachalam/PycharmProjects/Back_end(Python,SQL)/src\\\\files\\\\records\\\\9.1_cart_product_details.csv.sql'\n"]
2020-10-06 11:24:02,106 - 37576 DEBUG - ['Traceback (most recent call last):\n', '  File "C:/Users/balaji.a.arunachalam/PycharmProjects/Back_end(Python,SQL)/src/main/insertion.py", line 17, in __init__\n    temp = sys.argv[1]\n', 'IndexError: list index out of range\n', '\nDuring handling of the above exception, another exception occurred:\n\n', 'Traceback (most recent call last):\n', '  File "C:/Users/balaji.a.arunachalam/PycharmProjects/Back_end(Python,SQL)/src/main/insertion.py", line 42, in record_insertion\n    with open(file_path, \'r\') as read_file:\n', "FileNotFoundError: [Errno 2] No such file or directory: 'C:/Users/balaji.a.arunachalam/PycharmProjects/Back_end(Python,SQL)/src\\\\files\\\\records\\\\9.2_category_product_details.csv.sql'\n"]
2020-10-06 11:24:02,106 - 37576 DEBUG - ['Traceback (most recent call last):\n', '  File "C:/Users/balaji.a.arunachalam/PycharmProjects/Back_end(Python,SQL)/src/main/insertion.py", line 17, in __init__\n    temp = sys.argv[1]\n', 'IndexError: list index out of range\n', '\nDuring handling of the above exception, another exception occurred:\n\n', 'Traceback (most recent call last):\n', '  File "C:/Users/balaji.a.arunachalam/PycharmProjects/Back_end(Python,SQL)/src/main/insertion.py", line 42, in record_insertion\n    with open(file_path, \'r\') as read_file:\n', "FileNotFoundError: [Errno 2] No such file or directory: 'C:/Users/balaji.a.arunachalam/PycharmProjects/Back_end(Python,SQL)/src\\\\files\\\\records\\\\9.2_category_product_details.csv.sql'\n"]
2020-10-06 11:24:02,106 - 37576 DEBUG - ['Traceback (most recent call last):\n', '  File "C:/Users/balaji.a.arunachalam/PycharmProjects/Back_end(Python,SQL)/src/main/insertion.py", line 17, in __init__\n    temp = sys.argv[1]\n', 'IndexError: list index out of range\n', '\nDuring handling of the above exception, another exception occurred:\n\n', 'Traceback (most recent call last):\n', '  File "C:/Users/balaji.a.arunachalam/PycharmProjects/Back_end(Python,SQL)/src/main/insertion.py", line 42, in record_insertion\n    with open(file_path, \'r\') as read_file:\n', "FileNotFoundError: [Errno 2] No such file or directory: 'C:/Users/balaji.a.arunachalam/PycharmProjects/Back_end(Python,SQL)/src\\\\files\\\\records\\\\9.2_category_product_details.csv.sql'\n"]
2020-10-06 11:24:02,107 - 37576 DEBUG - ['Traceback (most recent call last):\n', '  File "C:/Users/balaji.a.arunachalam/PycharmProjects/Back_end(Python,SQL)/src/main/insertion.py", line 17, in __init__\n    temp = sys.argv[1]\n', 'IndexError: list index out of range\n', '\nDuring handling of the above exception, another exception occurred:\n\n', 'Traceback (most recent call last):\n', '  File "C:/Users/balaji.a.arunachalam/PycharmProjects/Back_end(Python,SQL)/src/main/insertion.py", line 42, in record_insertion\n    with open(file_path, \'r\') as read_file:\n', "FileNotFoundError: [Errno 2] No such file or directory: 'C:/Users/balaji.a.arunachalam/PycharmProjects/Back_end(Python,SQL)/src\\\\files\\\\records\\\\9.3_customer_rating_details.csv.sql'\n"]
2020-10-06 11:24:02,107 - 37576 DEBUG - ['Traceback (most recent call last):\n', '  File "C:/Users/balaji.a.arunachalam/PycharmProjects/Back_end(Python,SQL)/src/main/insertion.py", line 17, in __init__\n    temp = sys.argv[1]\n', 'IndexError: list index out of range\n', '\nDuring handling of the above exception, another exception occurred:\n\n', 'Traceback (most recent call last):\n', '  File "C:/Users/balaji.a.arunachalam/PycharmProjects/Back_end(Python,SQL)/src/main/insertion.py", line 42, in record_insertion\n    with open(file_path, \'r\') as read_file:\n', "FileNotFoundError: [Errno 2] No such file or directory: 'C:/Users/balaji.a.arunachalam/PycharmProjects/Back_end(Python,SQL)/src\\\\files\\\\records\\\\9.3_customer_rating_details.csv.sql'\n"]
2020-10-06 11:24:02,107 - 37576 DEBUG - ['Traceback (most recent call last):\n', '  File "C:/Users/balaji.a.arunachalam/PycharmProjects/Back_end(Python,SQL)/src/main/insertion.py", line 17, in __init__\n    temp = sys.argv[1]\n', 'IndexError: list index out of range\n', '\nDuring handling of the above exception, another exception occurred:\n\n', 'Traceback (most recent call last):\n', '  File "C:/Users/balaji.a.arunachalam/PycharmProjects/Back_end(Python,SQL)/src/main/insertion.py", line 42, in record_insertion\n    with open(file_path, \'r\') as read_file:\n', "FileNotFoundError: [Errno 2] No such file or directory: 'C:/Users/balaji.a.arunachalam/PycharmProjects/Back_end(Python,SQL)/src\\\\files\\\\records\\\\9.3_customer_rating_details.csv.sql'\n"]
2020-10-06 11:24:02,108 - 37576 DEBUG - ['Traceback (most recent call last):\n', '  File "C:/Users/balaji.a.arunachalam/PycharmProjects/Back_end(Python,SQL)/src/main/insertion.py", line 17, in __init__\n    temp = sys.argv[1]\n', 'IndexError: list index out of range\n', '\nDuring handling of the above exception, another exception occurred:\n\n', 'Traceback (most recent call last):\n', '  File "C:/Users/balaji.a.arunachalam/PycharmProjects/Back_end(Python,SQL)/src/main/insertion.py", line 42, in record_insertion\n    with open(file_path, \'r\') as read_file:\n', "FileNotFoundError: [Errno 2] No such file or directory: 'C:/Users/balaji.a.arunachalam/PycharmProjects/Back_end(Python,SQL)/src\\\\files\\\\records\\\\9.4_invoice_details.csv.sql'\n"]
2020-10-06 11:24:02,108 - 37576 DEBUG - ['Traceback (most recent call last):\n', '  File "C:/Users/balaji.a.arunachalam/PycharmProjects/Back_end(Python,SQL)/src/main/insertion.py", line 17, in __init__\n    temp = sys.argv[1]\n', 'IndexError: list index out of range\n', '\nDuring handling of the above exception, another exception occurred:\n\n', 'Traceback (most recent call last):\n', '  File "C:/Users/balaji.a.arunachalam/PycharmProjects/Back_end(Python,SQL)/src/main/insertion.py", line 42, in record_insertion\n    with open(file_path, \'r\') as read_file:\n', "FileNotFoundError: [Errno 2] No such file or directory: 'C:/Users/balaji.a.arunachalam/PycharmProjects/Back_end(Python,SQL)/src\\\\files\\\\records\\\\9.4_invoice_details.csv.sql'\n"]
2020-10-06 11:24:02,108 - 37576 DEBUG - ['Traceback (most recent call last):\n', '  File "C:/Users/balaji.a.arunachalam/PycharmProjects/Back_end(Python,SQL)/src/main/insertion.py", line 17, in __init__\n    temp = sys.argv[1]\n', 'IndexError: list index out of range\n', '\nDuring handling of the above exception, another exception occurred:\n\n', 'Traceback (most recent call last):\n', '  File "C:/Users/balaji.a.arunachalam/PycharmProjects/Back_end(Python,SQL)/src/main/insertion.py", line 42, in record_insertion\n    with open(file_path, \'r\') as read_file:\n', "FileNotFoundError: [Errno 2] No such file or directory: 'C:/Users/balaji.a.arunachalam/PycharmProjects/Back_end(Python,SQL)/src\\\\files\\\\records\\\\9.4_invoice_details.csv.sql'\n"]
2020-10-06 11:24:02,108 - 37576 DEBUG - ['Traceback (most recent call last):\n', '  File "C:/Users/balaji.a.arunachalam/PycharmProjects/Back_end(Python,SQL)/src/main/insertion.py", line 17, in __init__\n    temp = sys.argv[1]\n', 'IndexError: list index out of range\n', '\nDuring handling of the above exception, another exception occurred:\n\n', 'Traceback (most recent call last):\n', '  File "C:/Users/balaji.a.arunachalam/PycharmProjects/Back_end(Python,SQL)/src/main/insertion.py", line 42, in record_insertion\n    with open(file_path, \'r\') as read_file:\n', "FileNotFoundError: [Errno 2] No such file or directory: 'C:/Users/balaji.a.arunachalam/PycharmProjects/Back_end(Python,SQL)/src\\\\files\\\\records\\\\9.5_payment_details.csv.sql'\n"]
2020-10-06 11:24:02,108 - 37576 DEBUG - ['Traceback (most recent call last):\n', '  File "C:/Users/balaji.a.arunachalam/PycharmProjects/Back_end(Python,SQL)/src/main/insertion.py", line 17, in __init__\n    temp = sys.argv[1]\n', 'IndexError: list index out of range\n', '\nDuring handling of the above exception, another exception occurred:\n\n', 'Traceback (most recent call last):\n', '  File "C:/Users/balaji.a.arunachalam/PycharmProjects/Back_end(Python,SQL)/src/main/insertion.py", line 42, in record_insertion\n    with open(file_path, \'r\') as read_file:\n', "FileNotFoundError: [Errno 2] No such file or directory: 'C:/Users/balaji.a.arunachalam/PycharmProjects/Back_end(Python,SQL)/src\\\\files\\\\records\\\\9.5_payment_details.csv.sql'\n"]
2020-10-06 11:24:02,108 - 37576 DEBUG - ['Traceback (most recent call last):\n', '  File "C:/Users/balaji.a.arunachalam/PycharmProjects/Back_end(Python,SQL)/src/main/insertion.py", line 17, in __init__\n    temp = sys.argv[1]\n', 'IndexError: list index out of range\n', '\nDuring handling of the above exception, another exception occurred:\n\n', 'Traceback (most recent call last):\n', '  File "C:/Users/balaji.a.arunachalam/PycharmProjects/Back_end(Python,SQL)/src/main/insertion.py", line 42, in record_insertion\n    with open(file_path, \'r\') as read_file:\n', "FileNotFoundError: [Errno 2] No such file or directory: 'C:/Users/balaji.a.arunachalam/PycharmProjects/Back_end(Python,SQL)/src\\\\files\\\\records\\\\9.5_payment_details.csv.sql'\n"]
2020-10-06 11:24:02,109 - 37576 DEBUG - ['Traceback (most recent call last):\n', '  File "C:/Users/balaji.a.arunachalam/PycharmProjects/Back_end(Python,SQL)/src/main/insertion.py", line 17, in __init__\n    temp = sys.argv[1]\n', 'IndexError: list index out of range\n', '\nDuring handling of the above exception, another exception occurred:\n\n', 'Traceback (most recent call last):\n', '  File "C:/Users/balaji.a.arunachalam/PycharmProjects/Back_end(Python,SQL)/src/main/insertion.py", line 42, in record_insertion\n    with open(file_path, \'r\') as read_file:\n', "FileNotFoundError: [Errno 2] No such file or directory: 'C:/Users/balaji.a.arunachalam/PycharmProjects/Back_end(Python,SQL)/src\\\\files\\\\records\\\\9.6_product_ordered_details.csv.sql'\n"]
2020-10-06 11:24:02,109 - 37576 DEBUG - ['Traceback (most recent call last):\n', '  File "C:/Users/balaji.a.arunachalam/PycharmProjects/Back_end(Python,SQL)/src/main/insertion.py", line 17, in __init__\n    temp = sys.argv[1]\n', 'IndexError: list index out of range\n', '\nDuring handling of the above exception, another exception occurred:\n\n', 'Traceback (most recent call last):\n', '  File "C:/Users/balaji.a.arunachalam/PycharmProjects/Back_end(Python,SQL)/src/main/insertion.py", line 42, in record_insertion\n    with open(file_path, \'r\') as read_file:\n', "FileNotFoundError: [Errno 2] No such file or directory: 'C:/Users/balaji.a.arunachalam/PycharmProjects/Back_end(Python,SQL)/src\\\\files\\\\records\\\\9.6_product_ordered_details.csv.sql'\n"]
2020-10-06 11:24:02,109 - 37576 DEBUG - ['Traceback (most recent call last):\n', '  File "C:/Users/balaji.a.arunachalam/PycharmProjects/Back_end(Python,SQL)/src/main/insertion.py", line 17, in __init__\n    temp = sys.argv[1]\n', 'IndexError: list index out of range\n', '\nDuring handling of the above exception, another exception occurred:\n\n', 'Traceback (most recent call last):\n', '  File "C:/Users/balaji.a.arunachalam/PycharmProjects/Back_end(Python,SQL)/src/main/insertion.py", line 42, in record_insertion\n    with open(file_path, \'r\') as read_file:\n', "FileNotFoundError: [Errno 2] No such file or directory: 'C:/Users/balaji.a.arunachalam/PycharmProjects/Back_end(Python,SQL)/src\\\\files\\\\records\\\\9.6_product_ordered_details.csv.sql'\n"]
2020-10-06 11:24:02,110 - 37576 DEBUG - ['Traceback (most recent call last):\n', '  File "C:/Users/balaji.a.arunachalam/PycharmProjects/Back_end(Python,SQL)/src/main/insertion.py", line 17, in __init__\n    temp = sys.argv[1]\n', 'IndexError: list index out of range\n', '\nDuring handling of the above exception, another exception occurred:\n\n', 'Traceback (most recent call last):\n', '  File "C:/Users/balaji.a.arunachalam/PycharmProjects/Back_end(Python,SQL)/src/main/insertion.py", line 42, in record_insertion\n    with open(file_path, \'r\') as read_file:\n', "FileNotFoundError: [Errno 2] No such file or directory: 'C:/Users/balaji.a.arunachalam/PycharmProjects/Back_end(Python,SQL)/src\\\\files\\\\records\\\\9.7_shipping_status.csv.sql'\n"]
2020-10-06 11:24:02,110 - 37576 DEBUG - ['Traceback (most recent call last):\n', '  File "C:/Users/balaji.a.arunachalam/PycharmProjects/Back_end(Python,SQL)/src/main/insertion.py", line 17, in __init__\n    temp = sys.argv[1]\n', 'IndexError: list index out of range\n', '\nDuring handling of the above exception, another exception occurred:\n\n', 'Traceback (most recent call last):\n', '  File "C:/Users/balaji.a.arunachalam/PycharmProjects/Back_end(Python,SQL)/src/main/insertion.py", line 42, in record_insertion\n    with open(file_path, \'r\') as read_file:\n', "FileNotFoundError: [Errno 2] No such file or directory: 'C:/Users/balaji.a.arunachalam/PycharmProjects/Back_end(Python,SQL)/src\\\\files\\\\records\\\\9.7_shipping_status.csv.sql'\n"]
2020-10-06 11:24:02,110 - 37576 DEBUG - ['Traceback (most recent call last):\n', '  File "C:/Users/balaji.a.arunachalam/PycharmProjects/Back_end(Python,SQL)/src/main/insertion.py", line 17, in __init__\n    temp = sys.argv[1]\n', 'IndexError: list index out of range\n', '\nDuring handling of the above exception, another exception occurred:\n\n', 'Traceback (most recent call last):\n', '  File "C:/Users/balaji.a.arunachalam/PycharmProjects/Back_end(Python,SQL)/src/main/insertion.py", line 42, in record_insertion\n    with open(file_path, \'r\') as read_file:\n', "FileNotFoundError: [Errno 2] No such file or directory: 'C:/Users/balaji.a.arunachalam/PycharmProjects/Back_end(Python,SQL)/src\\\\files\\\\records\\\\9.7_shipping_status.csv.sql'\n"]
2020-10-06 11:24:02,110 - 37576 DEBUG - ['Traceback (most recent call last):\n', '  File "C:/Users/balaji.a.arunachalam/PycharmProjects/Back_end(Python,SQL)/src/main/insertion.py", line 17, in __init__\n    temp = sys.argv[1]\n', 'IndexError: list index out of range\n', '\nDuring handling of the above exception, another exception occurred:\n\n', 'Traceback (most recent call last):\n', '  File "C:/Users/balaji.a.arunachalam/PycharmProjects/Back_end(Python,SQL)/src/main/insertion.py", line 42, in record_insertion\n    with open(file_path, \'r\') as read_file:\n', "FileNotFoundError: [Errno 2] No such file or directory: 'C:/Users/balaji.a.arunachalam/PycharmProjects/Back_end(Python,SQL)/src\\\\files\\\\records\\\\sample.csv.sql'\n"]
2020-10-06 11:24:02,110 - 37576 DEBUG - ['Traceback (most recent call last):\n', '  File "C:/Users/balaji.a.arunachalam/PycharmProjects/Back_end(Python,SQL)/src/main/insertion.py", line 17, in __init__\n    temp = sys.argv[1]\n', 'IndexError: list index out of range\n', '\nDuring handling of the above exception, another exception occurred:\n\n', 'Traceback (most recent call last):\n', '  File "C:/Users/balaji.a.arunachalam/PycharmProjects/Back_end(Python,SQL)/src/main/insertion.py", line 42, in record_insertion\n    with open(file_path, \'r\') as read_file:\n', "FileNotFoundError: [Errno 2] No such file or directory: 'C:/Users/balaji.a.arunachalam/PycharmProjects/Back_end(Python,SQL)/src\\\\files\\\\records\\\\sample.csv.sql'\n"]
2020-10-06 11:24:02,110 - 37576 DEBUG - ['Traceback (most recent call last):\n', '  File "C:/Users/balaji.a.arunachalam/PycharmProjects/Back_end(Python,SQL)/src/main/insertion.py", line 17, in __init__\n    temp = sys.argv[1]\n', 'IndexError: list index out of range\n', '\nDuring handling of the above exception, another exception occurred:\n\n', 'Traceback (most recent call last):\n', '  File "C:/Users/balaji.a.arunachalam/PycharmProjects/Back_end(Python,SQL)/src/main/insertion.py", line 42, in record_insertion\n    with open(file_path, \'r\') as read_file:\n', "FileNotFoundError: [Errno 2] No such file or directory: 'C:/Users/balaji.a.arunachalam/PycharmProjects/Back_end(Python,SQL)/src\\\\files\\\\records\\\\sample.csv.sql'\n"]
2020-10-06 11:24:13,686 - 33360 DEBUG - ['Traceback (most recent call last):\n', '  File "C:/Users/balaji.a.arunachalam/PycharmProjects/Back_end(Python,SQL)/src/main/insertion.py", line 17, in __init__\n    temp = sys.argv[1]\n', 'IndexError: list index out of range\n', '\nDuring handling of the above exception, another exception occurred:\n\n', 'Traceback (most recent call last):\n', '  File "C:/Users/balaji.a.arunachalam/PycharmProjects/Back_end(Python,SQL)/src/main/insertion.py", line 42, in record_insertion\n    with open(file_path, \'r\') as read_file:\n', "FileNotFoundError: [Errno 2] No such file or directory: 'C:/Users/balaji.a.arunachalam/PycharmProjects/Back_end(Python,SQL)/src\\\\files\\\\records\\\\1_category_details.sql'\n"]
2020-10-06 11:24:13,686 - 33360 DEBUG - ['Traceback (most recent call last):\n', '  File "C:/Users/balaji.a.arunachalam/PycharmProjects/Back_end(Python,SQL)/src/main/insertion.py", line 17, in __init__\n    temp = sys.argv[1]\n', 'IndexError: list index out of range\n', '\nDuring handling of the above exception, another exception occurred:\n\n', 'Traceback (most recent call last):\n', '  File "C:/Users/balaji.a.arunachalam/PycharmProjects/Back_end(Python,SQL)/src/main/insertion.py", line 42, in record_insertion\n    with open(file_path, \'r\') as read_file:\n', "FileNotFoundError: [Errno 2] No such file or directory: 'C:/Users/balaji.a.arunachalam/PycharmProjects/Back_end(Python,SQL)/src\\\\files\\\\records\\\\1_category_details.sql'\n"]
2020-10-06 11:24:13,686 - 33360 DEBUG - ['Traceback (most recent call last):\n', '  File "C:/Users/balaji.a.arunachalam/PycharmProjects/Back_end(Python,SQL)/src/main/insertion.py", line 17, in __init__\n    temp = sys.argv[1]\n', 'IndexError: list index out of range\n', '\nDuring handling of the above exception, another exception occurred:\n\n', 'Traceback (most recent call last):\n', '  File "C:/Users/balaji.a.arunachalam/PycharmProjects/Back_end(Python,SQL)/src/main/insertion.py", line 42, in record_insertion\n    with open(file_path, \'r\') as read_file:\n', "FileNotFoundError: [Errno 2] No such file or directory: 'C:/Users/balaji.a.arunachalam/PycharmProjects/Back_end(Python,SQL)/src\\\\files\\\\records\\\\1_category_details.sql'\n"]
2020-10-06 11:24:13,687 - 33360 DEBUG - ['Traceback (most recent call last):\n', '  File "C:/Users/balaji.a.arunachalam/PycharmProjects/Back_end(Python,SQL)/src/main/insertion.py", line 17, in __init__\n    temp = sys.argv[1]\n', 'IndexError: list index out of range\n', '\nDuring handling of the above exception, another exception occurred:\n\n', 'Traceback (most recent call last):\n', '  File "C:/Users/balaji.a.arunachalam/PycharmProjects/Back_end(Python,SQL)/src/main/insertion.py", line 42, in record_insertion\n    with open(file_path, \'r\') as read_file:\n', "FileNotFoundError: [Errno 2] No such file or directory: 'C:/Users/balaji.a.arunachalam/PycharmProjects/Back_end(Python,SQL)/src\\\\files\\\\records\\\\2_customer_details.sql'\n"]
2020-10-06 11:24:13,687 - 33360 DEBUG - ['Traceback (most recent call last):\n', '  File "C:/Users/balaji.a.arunachalam/PycharmProjects/Back_end(Python,SQL)/src/main/insertion.py", line 17, in __init__\n    temp = sys.argv[1]\n', 'IndexError: list index out of range\n', '\nDuring handling of the above exception, another exception occurred:\n\n', 'Traceback (most recent call last):\n', '  File "C:/Users/balaji.a.arunachalam/PycharmProjects/Back_end(Python,SQL)/src/main/insertion.py", line 42, in record_insertion\n    with open(file_path, \'r\') as read_file:\n', "FileNotFoundError: [Errno 2] No such file or directory: 'C:/Users/balaji.a.arunachalam/PycharmProjects/Back_end(Python,SQL)/src\\\\files\\\\records\\\\2_customer_details.sql'\n"]
2020-10-06 11:24:13,687 - 33360 DEBUG - ['Traceback (most recent call last):\n', '  File "C:/Users/balaji.a.arunachalam/PycharmProjects/Back_end(Python,SQL)/src/main/insertion.py", line 17, in __init__\n    temp = sys.argv[1]\n', 'IndexError: list index out of range\n', '\nDuring handling of the above exception, another exception occurred:\n\n', 'Traceback (most recent call last):\n', '  File "C:/Users/balaji.a.arunachalam/PycharmProjects/Back_end(Python,SQL)/src/main/insertion.py", line 42, in record_insertion\n    with open(file_path, \'r\') as read_file:\n', "FileNotFoundError: [Errno 2] No such file or directory: 'C:/Users/balaji.a.arunachalam/PycharmProjects/Back_end(Python,SQL)/src\\\\files\\\\records\\\\2_customer_details.sql'\n"]
2020-10-06 11:24:13,688 - 33360 DEBUG - ['Traceback (most recent call last):\n', '  File "C:/Users/balaji.a.arunachalam/PycharmProjects/Back_end(Python,SQL)/src/main/insertion.py", line 17, in __init__\n    temp = sys.argv[1]\n', 'IndexError: list index out of range\n', '\nDuring handling of the above exception, another exception occurred:\n\n', 'Traceback (most recent call last):\n', '  File "C:/Users/balaji.a.arunachalam/PycharmProjects/Back_end(Python,SQL)/src/main/insertion.py", line 42, in record_insertion\n    with open(file_path, \'r\') as read_file:\n', "FileNotFoundError: [Errno 2] No such file or directory: 'C:/Users/balaji.a.arunachalam/PycharmProjects/Back_end(Python,SQL)/src\\\\files\\\\records\\\\3_order_status_details.sql'\n"]
2020-10-06 11:24:13,688 - 33360 DEBUG - ['Traceback (most recent call last):\n', '  File "C:/Users/balaji.a.arunachalam/PycharmProjects/Back_end(Python,SQL)/src/main/insertion.py", line 17, in __init__\n    temp = sys.argv[1]\n', 'IndexError: list index out of range\n', '\nDuring handling of the above exception, another exception occurred:\n\n', 'Traceback (most recent call last):\n', '  File "C:/Users/balaji.a.arunachalam/PycharmProjects/Back_end(Python,SQL)/src/main/insertion.py", line 42, in record_insertion\n    with open(file_path, \'r\') as read_file:\n', "FileNotFoundError: [Errno 2] No such file or directory: 'C:/Users/balaji.a.arunachalam/PycharmProjects/Back_end(Python,SQL)/src\\\\files\\\\records\\\\3_order_status_details.sql'\n"]
2020-10-06 11:24:13,688 - 33360 DEBUG - ['Traceback (most recent call last):\n', '  File "C:/Users/balaji.a.arunachalam/PycharmProjects/Back_end(Python,SQL)/src/main/insertion.py", line 17, in __init__\n    temp = sys.argv[1]\n', 'IndexError: list index out of range\n', '\nDuring handling of the above exception, another exception occurred:\n\n', 'Traceback (most recent call last):\n', '  File "C:/Users/balaji.a.arunachalam/PycharmProjects/Back_end(Python,SQL)/src/main/insertion.py", line 42, in record_insertion\n    with open(file_path, \'r\') as read_file:\n', "FileNotFoundError: [Errno 2] No such file or directory: 'C:/Users/balaji.a.arunachalam/PycharmProjects/Back_end(Python,SQL)/src\\\\files\\\\records\\\\3_order_status_details.sql'\n"]
2020-10-06 11:24:13,689 - 33360 DEBUG - ['Traceback (most recent call last):\n', '  File "C:/Users/balaji.a.arunachalam/PycharmProjects/Back_end(Python,SQL)/src/main/insertion.py", line 17, in __init__\n    temp = sys.argv[1]\n', 'IndexError: list index out of range\n', '\nDuring handling of the above exception, another exception occurred:\n\n', 'Traceback (most recent call last):\n', '  File "C:/Users/balaji.a.arunachalam/PycharmProjects/Back_end(Python,SQL)/src/main/insertion.py", line 42, in record_insertion\n    with open(file_path, \'r\') as read_file:\n', "FileNotFoundError: [Errno 2] No such file or directory: 'C:/Users/balaji.a.arunachalam/PycharmProjects/Back_end(Python,SQL)/src\\\\files\\\\records\\\\4_seller_details.sql'\n"]
2020-10-06 11:24:13,689 - 33360 DEBUG - ['Traceback (most recent call last):\n', '  File "C:/Users/balaji.a.arunachalam/PycharmProjects/Back_end(Python,SQL)/src/main/insertion.py", line 17, in __init__\n    temp = sys.argv[1]\n', 'IndexError: list index out of range\n', '\nDuring handling of the above exception, another exception occurred:\n\n', 'Traceback (most recent call last):\n', '  File "C:/Users/balaji.a.arunachalam/PycharmProjects/Back_end(Python,SQL)/src/main/insertion.py", line 42, in record_insertion\n    with open(file_path, \'r\') as read_file:\n', "FileNotFoundError: [Errno 2] No such file or directory: 'C:/Users/balaji.a.arunachalam/PycharmProjects/Back_end(Python,SQL)/src\\\\files\\\\records\\\\4_seller_details.sql'\n"]
2020-10-06 11:24:13,689 - 33360 DEBUG - ['Traceback (most recent call last):\n', '  File "C:/Users/balaji.a.arunachalam/PycharmProjects/Back_end(Python,SQL)/src/main/insertion.py", line 17, in __init__\n    temp = sys.argv[1]\n', 'IndexError: list index out of range\n', '\nDuring handling of the above exception, another exception occurred:\n\n', 'Traceback (most recent call last):\n', '  File "C:/Users/balaji.a.arunachalam/PycharmProjects/Back_end(Python,SQL)/src/main/insertion.py", line 42, in record_insertion\n    with open(file_path, \'r\') as read_file:\n', "FileNotFoundError: [Errno 2] No such file or directory: 'C:/Users/balaji.a.arunachalam/PycharmProjects/Back_end(Python,SQL)/src\\\\files\\\\records\\\\4_seller_details.sql'\n"]
2020-10-06 11:24:13,689 - 33360 DEBUG - ['Traceback (most recent call last):\n', '  File "C:/Users/balaji.a.arunachalam/PycharmProjects/Back_end(Python,SQL)/src/main/insertion.py", line 17, in __init__\n    temp = sys.argv[1]\n', 'IndexError: list index out of range\n', '\nDuring handling of the above exception, another exception occurred:\n\n', 'Traceback (most recent call last):\n', '  File "C:/Users/balaji.a.arunachalam/PycharmProjects/Back_end(Python,SQL)/src/main/insertion.py", line 42, in record_insertion\n    with open(file_path, \'r\') as read_file:\n', "FileNotFoundError: [Errno 2] No such file or directory: 'C:/Users/balaji.a.arunachalam/PycharmProjects/Back_end(Python,SQL)/src\\\\files\\\\records\\\\5_cart_details.sql'\n"]
2020-10-06 11:24:13,689 - 33360 DEBUG - ['Traceback (most recent call last):\n', '  File "C:/Users/balaji.a.arunachalam/PycharmProjects/Back_end(Python,SQL)/src/main/insertion.py", line 17, in __init__\n    temp = sys.argv[1]\n', 'IndexError: list index out of range\n', '\nDuring handling of the above exception, another exception occurred:\n\n', 'Traceback (most recent call last):\n', '  File "C:/Users/balaji.a.arunachalam/PycharmProjects/Back_end(Python,SQL)/src/main/insertion.py", line 42, in record_insertion\n    with open(file_path, \'r\') as read_file:\n', "FileNotFoundError: [Errno 2] No such file or directory: 'C:/Users/balaji.a.arunachalam/PycharmProjects/Back_end(Python,SQL)/src\\\\files\\\\records\\\\5_cart_details.sql'\n"]
2020-10-06 11:24:13,689 - 33360 DEBUG - ['Traceback (most recent call last):\n', '  File "C:/Users/balaji.a.arunachalam/PycharmProjects/Back_end(Python,SQL)/src/main/insertion.py", line 17, in __init__\n    temp = sys.argv[1]\n', 'IndexError: list index out of range\n', '\nDuring handling of the above exception, another exception occurred:\n\n', 'Traceback (most recent call last):\n', '  File "C:/Users/balaji.a.arunachalam/PycharmProjects/Back_end(Python,SQL)/src/main/insertion.py", line 42, in record_insertion\n    with open(file_path, \'r\') as read_file:\n', "FileNotFoundError: [Errno 2] No such file or directory: 'C:/Users/balaji.a.arunachalam/PycharmProjects/Back_end(Python,SQL)/src\\\\files\\\\records\\\\5_cart_details.sql'\n"]
2020-10-06 11:24:13,690 - 33360 DEBUG - ['Traceback (most recent call last):\n', '  File "C:/Users/balaji.a.arunachalam/PycharmProjects/Back_end(Python,SQL)/src/main/insertion.py", line 17, in __init__\n    temp = sys.argv[1]\n', 'IndexError: list index out of range\n', '\nDuring handling of the above exception, another exception occurred:\n\n', 'Traceback (most recent call last):\n', '  File "C:/Users/balaji.a.arunachalam/PycharmProjects/Back_end(Python,SQL)/src/main/insertion.py", line 42, in record_insertion\n    with open(file_path, \'r\') as read_file:\n', "FileNotFoundError: [Errno 2] No such file or directory: 'C:/Users/balaji.a.arunachalam/PycharmProjects/Back_end(Python,SQL)/src\\\\files\\\\records\\\\6_customer_address_details.sql'\n"]
2020-10-06 11:24:13,690 - 33360 DEBUG - ['Traceback (most recent call last):\n', '  File "C:/Users/balaji.a.arunachalam/PycharmProjects/Back_end(Python,SQL)/src/main/insertion.py", line 17, in __init__\n    temp = sys.argv[1]\n', 'IndexError: list index out of range\n', '\nDuring handling of the above exception, another exception occurred:\n\n', 'Traceback (most recent call last):\n', '  File "C:/Users/balaji.a.arunachalam/PycharmProjects/Back_end(Python,SQL)/src/main/insertion.py", line 42, in record_insertion\n    with open(file_path, \'r\') as read_file:\n', "FileNotFoundError: [Errno 2] No such file or directory: 'C:/Users/balaji.a.arunachalam/PycharmProjects/Back_end(Python,SQL)/src\\\\files\\\\records\\\\6_customer_address_details.sql'\n"]
2020-10-06 11:24:13,690 - 33360 DEBUG - ['Traceback (most recent call last):\n', '  File "C:/Users/balaji.a.arunachalam/PycharmProjects/Back_end(Python,SQL)/src/main/insertion.py", line 17, in __init__\n    temp = sys.argv[1]\n', 'IndexError: list index out of range\n', '\nDuring handling of the above exception, another exception occurred:\n\n', 'Traceback (most recent call last):\n', '  File "C:/Users/balaji.a.arunachalam/PycharmProjects/Back_end(Python,SQL)/src/main/insertion.py", line 42, in record_insertion\n    with open(file_path, \'r\') as read_file:\n', "FileNotFoundError: [Errno 2] No such file or directory: 'C:/Users/balaji.a.arunachalam/PycharmProjects/Back_end(Python,SQL)/src\\\\files\\\\records\\\\6_customer_address_details.sql'\n"]
2020-10-06 11:24:13,691 - 33360 DEBUG - ['Traceback (most recent call last):\n', '  File "C:/Users/balaji.a.arunachalam/PycharmProjects/Back_end(Python,SQL)/src/main/insertion.py", line 17, in __init__\n    temp = sys.argv[1]\n', 'IndexError: list index out of range\n', '\nDuring handling of the above exception, another exception occurred:\n\n', 'Traceback (most recent call last):\n', '  File "C:/Users/balaji.a.arunachalam/PycharmProjects/Back_end(Python,SQL)/src/main/insertion.py", line 42, in record_insertion\n    with open(file_path, \'r\') as read_file:\n', "FileNotFoundError: [Errno 2] No such file or directory: 'C:/Users/balaji.a.arunachalam/PycharmProjects/Back_end(Python,SQL)/src\\\\files\\\\records\\\\7_order_details.sql'\n"]
2020-10-06 11:24:13,691 - 33360 DEBUG - ['Traceback (most recent call last):\n', '  File "C:/Users/balaji.a.arunachalam/PycharmProjects/Back_end(Python,SQL)/src/main/insertion.py", line 17, in __init__\n    temp = sys.argv[1]\n', 'IndexError: list index out of range\n', '\nDuring handling of the above exception, another exception occurred:\n\n', 'Traceback (most recent call last):\n', '  File "C:/Users/balaji.a.arunachalam/PycharmProjects/Back_end(Python,SQL)/src/main/insertion.py", line 42, in record_insertion\n    with open(file_path, \'r\') as read_file:\n', "FileNotFoundError: [Errno 2] No such file or directory: 'C:/Users/balaji.a.arunachalam/PycharmProjects/Back_end(Python,SQL)/src\\\\files\\\\records\\\\7_order_details.sql'\n"]
2020-10-06 11:24:13,691 - 33360 DEBUG - ['Traceback (most recent call last):\n', '  File "C:/Users/balaji.a.arunachalam/PycharmProjects/Back_end(Python,SQL)/src/main/insertion.py", line 17, in __init__\n    temp = sys.argv[1]\n', 'IndexError: list index out of range\n', '\nDuring handling of the above exception, another exception occurred:\n\n', 'Traceback (most recent call last):\n', '  File "C:/Users/balaji.a.arunachalam/PycharmProjects/Back_end(Python,SQL)/src/main/insertion.py", line 42, in record_insertion\n    with open(file_path, \'r\') as read_file:\n', "FileNotFoundError: [Errno 2] No such file or directory: 'C:/Users/balaji.a.arunachalam/PycharmProjects/Back_end(Python,SQL)/src\\\\files\\\\records\\\\7_order_details.sql'\n"]
2020-10-06 11:24:13,692 - 33360 DEBUG - ['Traceback (most recent call last):\n', '  File "C:/Users/balaji.a.arunachalam/PycharmProjects/Back_end(Python,SQL)/src/main/insertion.py", line 17, in __init__\n    temp = sys.argv[1]\n', 'IndexError: list index out of range\n', '\nDuring handling of the above exception, another exception occurred:\n\n', 'Traceback (most recent call last):\n', '  File "C:/Users/balaji.a.arunachalam/PycharmProjects/Back_end(Python,SQL)/src/main/insertion.py", line 42, in record_insertion\n    with open(file_path, \'r\') as read_file:\n', "FileNotFoundError: [Errno 2] No such file or directory: 'C:/Users/balaji.a.arunachalam/PycharmProjects/Back_end(Python,SQL)/src\\\\files\\\\records\\\\8_product_stock_details.sql'\n"]
2020-10-06 11:24:13,692 - 33360 DEBUG - ['Traceback (most recent call last):\n', '  File "C:/Users/balaji.a.arunachalam/PycharmProjects/Back_end(Python,SQL)/src/main/insertion.py", line 17, in __init__\n    temp = sys.argv[1]\n', 'IndexError: list index out of range\n', '\nDuring handling of the above exception, another exception occurred:\n\n', 'Traceback (most recent call last):\n', '  File "C:/Users/balaji.a.arunachalam/PycharmProjects/Back_end(Python,SQL)/src/main/insertion.py", line 42, in record_insertion\n    with open(file_path, \'r\') as read_file:\n', "FileNotFoundError: [Errno 2] No such file or directory: 'C:/Users/balaji.a.arunachalam/PycharmProjects/Back_end(Python,SQL)/src\\\\files\\\\records\\\\8_product_stock_details.sql'\n"]
2020-10-06 11:24:13,692 - 33360 DEBUG - ['Traceback (most recent call last):\n', '  File "C:/Users/balaji.a.arunachalam/PycharmProjects/Back_end(Python,SQL)/src/main/insertion.py", line 17, in __init__\n    temp = sys.argv[1]\n', 'IndexError: list index out of range\n', '\nDuring handling of the above exception, another exception occurred:\n\n', 'Traceback (most recent call last):\n', '  File "C:/Users/balaji.a.arunachalam/PycharmProjects/Back_end(Python,SQL)/src/main/insertion.py", line 42, in record_insertion\n    with open(file_path, \'r\') as read_file:\n', "FileNotFoundError: [Errno 2] No such file or directory: 'C:/Users/balaji.a.arunachalam/PycharmProjects/Back_end(Python,SQL)/src\\\\files\\\\records\\\\8_product_stock_details.sql'\n"]
2020-10-06 11:24:13,692 - 33360 DEBUG - ['Traceback (most recent call last):\n', '  File "C:/Users/balaji.a.arunachalam/PycharmProjects/Back_end(Python,SQL)/src/main/insertion.py", line 17, in __init__\n    temp = sys.argv[1]\n', 'IndexError: list index out of range\n', '\nDuring handling of the above exception, another exception occurred:\n\n', 'Traceback (most recent call last):\n', '  File "C:/Users/balaji.a.arunachalam/PycharmProjects/Back_end(Python,SQL)/src/main/insertion.py", line 42, in record_insertion\n    with open(file_path, \'r\') as read_file:\n', "FileNotFoundError: [Errno 2] No such file or directory: 'C:/Users/balaji.a.arunachalam/PycharmProjects/Back_end(Python,SQL)/src\\\\files\\\\records\\\\9.sql'\n"]
2020-10-06 11:24:13,692 - 33360 DEBUG - ['Traceback (most recent call last):\n', '  File "C:/Users/balaji.a.arunachalam/PycharmProjects/Back_end(Python,SQL)/src/main/insertion.py", line 17, in __init__\n    temp = sys.argv[1]\n', 'IndexError: list index out of range\n', '\nDuring handling of the above exception, another exception occurred:\n\n', 'Traceback (most recent call last):\n', '  File "C:/Users/balaji.a.arunachalam/PycharmProjects/Back_end(Python,SQL)/src/main/insertion.py", line 42, in record_insertion\n    with open(file_path, \'r\') as read_file:\n', "FileNotFoundError: [Errno 2] No such file or directory: 'C:/Users/balaji.a.arunachalam/PycharmProjects/Back_end(Python,SQL)/src\\\\files\\\\records\\\\9.sql'\n"]
2020-10-06 11:24:13,692 - 33360 DEBUG - ['Traceback (most recent call last):\n', '  File "C:/Users/balaji.a.arunachalam/PycharmProjects/Back_end(Python,SQL)/src/main/insertion.py", line 17, in __init__\n    temp = sys.argv[1]\n', 'IndexError: list index out of range\n', '\nDuring handling of the above exception, another exception occurred:\n\n', 'Traceback (most recent call last):\n', '  File "C:/Users/balaji.a.arunachalam/PycharmProjects/Back_end(Python,SQL)/src/main/insertion.py", line 42, in record_insertion\n    with open(file_path, \'r\') as read_file:\n', "FileNotFoundError: [Errno 2] No such file or directory: 'C:/Users/balaji.a.arunachalam/PycharmProjects/Back_end(Python,SQL)/src\\\\files\\\\records\\\\9.sql'\n"]
2020-10-06 11:24:13,693 - 33360 DEBUG - ['Traceback (most recent call last):\n', '  File "C:/Users/balaji.a.arunachalam/PycharmProjects/Back_end(Python,SQL)/src/main/insertion.py", line 17, in __init__\n    temp = sys.argv[1]\n', 'IndexError: list index out of range\n', '\nDuring handling of the above exception, another exception occurred:\n\n', 'Traceback (most recent call last):\n', '  File "C:/Users/balaji.a.arunachalam/PycharmProjects/Back_end(Python,SQL)/src/main/insertion.py", line 42, in record_insertion\n    with open(file_path, \'r\') as read_file:\n', "FileNotFoundError: [Errno 2] No such file or directory: 'C:/Users/balaji.a.arunachalam/PycharmProjects/Back_end(Python,SQL)/src\\\\files\\\\records\\\\9.sql'\n"]
2020-10-06 11:24:13,693 - 33360 DEBUG - ['Traceback (most recent call last):\n', '  File "C:/Users/balaji.a.arunachalam/PycharmProjects/Back_end(Python,SQL)/src/main/insertion.py", line 17, in __init__\n    temp = sys.argv[1]\n', 'IndexError: list index out of range\n', '\nDuring handling of the above exception, another exception occurred:\n\n', 'Traceback (most recent call last):\n', '  File "C:/Users/balaji.a.arunachalam/PycharmProjects/Back_end(Python,SQL)/src/main/insertion.py", line 42, in record_insertion\n    with open(file_path, \'r\') as read_file:\n', "FileNotFoundError: [Errno 2] No such file or directory: 'C:/Users/balaji.a.arunachalam/PycharmProjects/Back_end(Python,SQL)/src\\\\files\\\\records\\\\9.sql'\n"]
2020-10-06 11:24:13,693 - 33360 DEBUG - ['Traceback (most recent call last):\n', '  File "C:/Users/balaji.a.arunachalam/PycharmProjects/Back_end(Python,SQL)/src/main/insertion.py", line 17, in __init__\n    temp = sys.argv[1]\n', 'IndexError: list index out of range\n', '\nDuring handling of the above exception, another exception occurred:\n\n', 'Traceback (most recent call last):\n', '  File "C:/Users/balaji.a.arunachalam/PycharmProjects/Back_end(Python,SQL)/src/main/insertion.py", line 42, in record_insertion\n    with open(file_path, \'r\') as read_file:\n', "FileNotFoundError: [Errno 2] No such file or directory: 'C:/Users/balaji.a.arunachalam/PycharmProjects/Back_end(Python,SQL)/src\\\\files\\\\records\\\\9.sql'\n"]
2020-10-06 11:24:13,694 - 33360 DEBUG - ['Traceback (most recent call last):\n', '  File "C:/Users/balaji.a.arunachalam/PycharmProjects/Back_end(Python,SQL)/src/main/insertion.py", line 17, in __init__\n    temp = sys.argv[1]\n', 'IndexError: list index out of range\n', '\nDuring handling of the above exception, another exception occurred:\n\n', 'Traceback (most recent call last):\n', '  File "C:/Users/balaji.a.arunachalam/PycharmProjects/Back_end(Python,SQL)/src/main/insertion.py", line 42, in record_insertion\n    with open(file_path, \'r\') as read_file:\n', "FileNotFoundError: [Errno 2] No such file or directory: 'C:/Users/balaji.a.arunachalam/PycharmProjects/Back_end(Python,SQL)/src\\\\files\\\\records\\\\9.sql'\n"]
2020-10-06 11:24:13,694 - 33360 DEBUG - ['Traceback (most recent call last):\n', '  File "C:/Users/balaji.a.arunachalam/PycharmProjects/Back_end(Python,SQL)/src/main/insertion.py", line 17, in __init__\n    temp = sys.argv[1]\n', 'IndexError: list index out of range\n', '\nDuring handling of the above exception, another exception occurred:\n\n', 'Traceback (most recent call last):\n', '  File "C:/Users/balaji.a.arunachalam/PycharmProjects/Back_end(Python,SQL)/src/main/insertion.py", line 42, in record_insertion\n    with open(file_path, \'r\') as read_file:\n', "FileNotFoundError: [Errno 2] No such file or directory: 'C:/Users/balaji.a.arunachalam/PycharmProjects/Back_end(Python,SQL)/src\\\\files\\\\records\\\\9.sql'\n"]
2020-10-06 11:24:13,694 - 33360 DEBUG - ['Traceback (most recent call last):\n', '  File "C:/Users/balaji.a.arunachalam/PycharmProjects/Back_end(Python,SQL)/src/main/insertion.py", line 17, in __init__\n    temp = sys.argv[1]\n', 'IndexError: list index out of range\n', '\nDuring handling of the above exception, another exception occurred:\n\n', 'Traceback (most recent call last):\n', '  File "C:/Users/balaji.a.arunachalam/PycharmProjects/Back_end(Python,SQL)/src/main/insertion.py", line 42, in record_insertion\n    with open(file_path, \'r\') as read_file:\n', "FileNotFoundError: [Errno 2] No such file or directory: 'C:/Users/balaji.a.arunachalam/PycharmProjects/Back_end(Python,SQL)/src\\\\files\\\\records\\\\9.sql'\n"]
2020-10-06 11:24:13,695 - 33360 DEBUG - ['Traceback (most recent call last):\n', '  File "C:/Users/balaji.a.arunachalam/PycharmProjects/Back_end(Python,SQL)/src/main/insertion.py", line 17, in __init__\n    temp = sys.argv[1]\n', 'IndexError: list index out of range\n', '\nDuring handling of the above exception, another exception occurred:\n\n', 'Traceback (most recent call last):\n', '  File "C:/Users/balaji.a.arunachalam/PycharmProjects/Back_end(Python,SQL)/src/main/insertion.py", line 42, in record_insertion\n    with open(file_path, \'r\') as read_file:\n', "FileNotFoundError: [Errno 2] No such file or directory: 'C:/Users/balaji.a.arunachalam/PycharmProjects/Back_end(Python,SQL)/src\\\\files\\\\records\\\\9.sql'\n"]
2020-10-06 11:24:13,695 - 33360 DEBUG - ['Traceback (most recent call last):\n', '  File "C:/Users/balaji.a.arunachalam/PycharmProjects/Back_end(Python,SQL)/src/main/insertion.py", line 17, in __init__\n    temp = sys.argv[1]\n', 'IndexError: list index out of range\n', '\nDuring handling of the above exception, another exception occurred:\n\n', 'Traceback (most recent call last):\n', '  File "C:/Users/balaji.a.arunachalam/PycharmProjects/Back_end(Python,SQL)/src/main/insertion.py", line 42, in record_insertion\n    with open(file_path, \'r\') as read_file:\n', "FileNotFoundError: [Errno 2] No such file or directory: 'C:/Users/balaji.a.arunachalam/PycharmProjects/Back_end(Python,SQL)/src\\\\files\\\\records\\\\9.sql'\n"]
2020-10-06 11:24:13,695 - 33360 DEBUG - ['Traceback (most recent call last):\n', '  File "C:/Users/balaji.a.arunachalam/PycharmProjects/Back_end(Python,SQL)/src/main/insertion.py", line 17, in __init__\n    temp = sys.argv[1]\n', 'IndexError: list index out of range\n', '\nDuring handling of the above exception, another exception occurred:\n\n', 'Traceback (most recent call last):\n', '  File "C:/Users/balaji.a.arunachalam/PycharmProjects/Back_end(Python,SQL)/src/main/insertion.py", line 42, in record_insertion\n    with open(file_path, \'r\') as read_file:\n', "FileNotFoundError: [Errno 2] No such file or directory: 'C:/Users/balaji.a.arunachalam/PycharmProjects/Back_end(Python,SQL)/src\\\\files\\\\records\\\\9.sql'\n"]
2020-10-06 11:24:13,696 - 33360 DEBUG - ['Traceback (most recent call last):\n', '  File "C:/Users/balaji.a.arunachalam/PycharmProjects/Back_end(Python,SQL)/src/main/insertion.py", line 17, in __init__\n    temp = sys.argv[1]\n', 'IndexError: list index out of range\n', '\nDuring handling of the above exception, another exception occurred:\n\n', 'Traceback (most recent call last):\n', '  File "C:/Users/balaji.a.arunachalam/PycharmProjects/Back_end(Python,SQL)/src/main/insertion.py", line 42, in record_insertion\n    with open(file_path, \'r\') as read_file:\n', "FileNotFoundError: [Errno 2] No such file or directory: 'C:/Users/balaji.a.arunachalam/PycharmProjects/Back_end(Python,SQL)/src\\\\files\\\\records\\\\9.sql'\n"]
2020-10-06 11:24:13,696 - 33360 DEBUG - ['Traceback (most recent call last):\n', '  File "C:/Users/balaji.a.arunachalam/PycharmProjects/Back_end(Python,SQL)/src/main/insertion.py", line 17, in __init__\n    temp = sys.argv[1]\n', 'IndexError: list index out of range\n', '\nDuring handling of the above exception, another exception occurred:\n\n', 'Traceback (most recent call last):\n', '  File "C:/Users/balaji.a.arunachalam/PycharmProjects/Back_end(Python,SQL)/src/main/insertion.py", line 42, in record_insertion\n    with open(file_path, \'r\') as read_file:\n', "FileNotFoundError: [Errno 2] No such file or directory: 'C:/Users/balaji.a.arunachalam/PycharmProjects/Back_end(Python,SQL)/src\\\\files\\\\records\\\\9.sql'\n"]
2020-10-06 11:24:13,696 - 33360 DEBUG - ['Traceback (most recent call last):\n', '  File "C:/Users/balaji.a.arunachalam/PycharmProjects/Back_end(Python,SQL)/src/main/insertion.py", line 17, in __init__\n    temp = sys.argv[1]\n', 'IndexError: list index out of range\n', '\nDuring handling of the above exception, another exception occurred:\n\n', 'Traceback (most recent call last):\n', '  File "C:/Users/balaji.a.arunachalam/PycharmProjects/Back_end(Python,SQL)/src/main/insertion.py", line 42, in record_insertion\n    with open(file_path, \'r\') as read_file:\n', "FileNotFoundError: [Errno 2] No such file or directory: 'C:/Users/balaji.a.arunachalam/PycharmProjects/Back_end(Python,SQL)/src\\\\files\\\\records\\\\9.sql'\n"]
2020-10-06 11:24:13,697 - 33360 DEBUG - ['Traceback (most recent call last):\n', '  File "C:/Users/balaji.a.arunachalam/PycharmProjects/Back_end(Python,SQL)/src/main/insertion.py", line 17, in __init__\n    temp = sys.argv[1]\n', 'IndexError: list index out of range\n', '\nDuring handling of the above exception, another exception occurred:\n\n', 'Traceback (most recent call last):\n', '  File "C:/Users/balaji.a.arunachalam/PycharmProjects/Back_end(Python,SQL)/src/main/insertion.py", line 42, in record_insertion\n    with open(file_path, \'r\') as read_file:\n', "FileNotFoundError: [Errno 2] No such file or directory: 'C:/Users/balaji.a.arunachalam/PycharmProjects/Back_end(Python,SQL)/src\\\\files\\\\records\\\\9.sql'\n"]
2020-10-06 11:24:13,697 - 33360 DEBUG - ['Traceback (most recent call last):\n', '  File "C:/Users/balaji.a.arunachalam/PycharmProjects/Back_end(Python,SQL)/src/main/insertion.py", line 17, in __init__\n    temp = sys.argv[1]\n', 'IndexError: list index out of range\n', '\nDuring handling of the above exception, another exception occurred:\n\n', 'Traceback (most recent call last):\n', '  File "C:/Users/balaji.a.arunachalam/PycharmProjects/Back_end(Python,SQL)/src/main/insertion.py", line 42, in record_insertion\n    with open(file_path, \'r\') as read_file:\n', "FileNotFoundError: [Errno 2] No such file or directory: 'C:/Users/balaji.a.arunachalam/PycharmProjects/Back_end(Python,SQL)/src\\\\files\\\\records\\\\9.sql'\n"]
2020-10-06 11:24:13,697 - 33360 DEBUG - ['Traceback (most recent call last):\n', '  File "C:/Users/balaji.a.arunachalam/PycharmProjects/Back_end(Python,SQL)/src/main/insertion.py", line 17, in __init__\n    temp = sys.argv[1]\n', 'IndexError: list index out of range\n', '\nDuring handling of the above exception, another exception occurred:\n\n', 'Traceback (most recent call last):\n', '  File "C:/Users/balaji.a.arunachalam/PycharmProjects/Back_end(Python,SQL)/src/main/insertion.py", line 42, in record_insertion\n    with open(file_path, \'r\') as read_file:\n', "FileNotFoundError: [Errno 2] No such file or directory: 'C:/Users/balaji.a.arunachalam/PycharmProjects/Back_end(Python,SQL)/src\\\\files\\\\records\\\\9.sql'\n"]
2020-10-06 11:24:13,697 - 33360 DEBUG - ['Traceback (most recent call last):\n', '  File "C:/Users/balaji.a.arunachalam/PycharmProjects/Back_end(Python,SQL)/src/main/insertion.py", line 17, in __init__\n    temp = sys.argv[1]\n', 'IndexError: list index out of range\n', '\nDuring handling of the above exception, another exception occurred:\n\n', 'Traceback (most recent call last):\n', '  File "C:/Users/balaji.a.arunachalam/PycharmProjects/Back_end(Python,SQL)/src/main/insertion.py", line 42, in record_insertion\n    with open(file_path, \'r\') as read_file:\n', "FileNotFoundError: [Errno 2] No such file or directory: 'C:/Users/balaji.a.arunachalam/PycharmProjects/Back_end(Python,SQL)/src\\\\files\\\\records\\\\9.sql'\n"]
2020-10-06 11:24:13,697 - 33360 DEBUG - ['Traceback (most recent call last):\n', '  File "C:/Users/balaji.a.arunachalam/PycharmProjects/Back_end(Python,SQL)/src/main/insertion.py", line 17, in __init__\n    temp = sys.argv[1]\n', 'IndexError: list index out of range\n', '\nDuring handling of the above exception, another exception occurred:\n\n', 'Traceback (most recent call last):\n', '  File "C:/Users/balaji.a.arunachalam/PycharmProjects/Back_end(Python,SQL)/src/main/insertion.py", line 42, in record_insertion\n    with open(file_path, \'r\') as read_file:\n', "FileNotFoundError: [Errno 2] No such file or directory: 'C:/Users/balaji.a.arunachalam/PycharmProjects/Back_end(Python,SQL)/src\\\\files\\\\records\\\\9.sql'\n"]
2020-10-06 11:24:13,697 - 33360 DEBUG - ['Traceback (most recent call last):\n', '  File "C:/Users/balaji.a.arunachalam/PycharmProjects/Back_end(Python,SQL)/src/main/insertion.py", line 17, in __init__\n    temp = sys.argv[1]\n', 'IndexError: list index out of range\n', '\nDuring handling of the above exception, another exception occurred:\n\n', 'Traceback (most recent call last):\n', '  File "C:/Users/balaji.a.arunachalam/PycharmProjects/Back_end(Python,SQL)/src/main/insertion.py", line 42, in record_insertion\n    with open(file_path, \'r\') as read_file:\n', "FileNotFoundError: [Errno 2] No such file or directory: 'C:/Users/balaji.a.arunachalam/PycharmProjects/Back_end(Python,SQL)/src\\\\files\\\\records\\\\9.sql'\n"]
2020-10-06 11:24:13,698 - 33360 DEBUG - ['Traceback (most recent call last):\n', '  File "C:/Users/balaji.a.arunachalam/PycharmProjects/Back_end(Python,SQL)/src/main/insertion.py", line 17, in __init__\n    temp = sys.argv[1]\n', 'IndexError: list index out of range\n', '\nDuring handling of the above exception, another exception occurred:\n\n', 'Traceback (most recent call last):\n', '  File "C:/Users/balaji.a.arunachalam/PycharmProjects/Back_end(Python,SQL)/src/main/insertion.py", line 42, in record_insertion\n    with open(file_path, \'r\') as read_file:\n', "FileNotFoundError: [Errno 2] No such file or directory: 'C:/Users/balaji.a.arunachalam/PycharmProjects/Back_end(Python,SQL)/src\\\\files\\\\records\\\\9.sql'\n"]
2020-10-06 11:24:13,698 - 33360 DEBUG - ['Traceback (most recent call last):\n', '  File "C:/Users/balaji.a.arunachalam/PycharmProjects/Back_end(Python,SQL)/src/main/insertion.py", line 17, in __init__\n    temp = sys.argv[1]\n', 'IndexError: list index out of range\n', '\nDuring handling of the above exception, another exception occurred:\n\n', 'Traceback (most recent call last):\n', '  File "C:/Users/balaji.a.arunachalam/PycharmProjects/Back_end(Python,SQL)/src/main/insertion.py", line 42, in record_insertion\n    with open(file_path, \'r\') as read_file:\n', "FileNotFoundError: [Errno 2] No such file or directory: 'C:/Users/balaji.a.arunachalam/PycharmProjects/Back_end(Python,SQL)/src\\\\files\\\\records\\\\9.sql'\n"]
2020-10-06 11:24:13,698 - 33360 DEBUG - ['Traceback (most recent call last):\n', '  File "C:/Users/balaji.a.arunachalam/PycharmProjects/Back_end(Python,SQL)/src/main/insertion.py", line 17, in __init__\n    temp = sys.argv[1]\n', 'IndexError: list index out of range\n', '\nDuring handling of the above exception, another exception occurred:\n\n', 'Traceback (most recent call last):\n', '  File "C:/Users/balaji.a.arunachalam/PycharmProjects/Back_end(Python,SQL)/src/main/insertion.py", line 42, in record_insertion\n    with open(file_path, \'r\') as read_file:\n', "FileNotFoundError: [Errno 2] No such file or directory: 'C:/Users/balaji.a.arunachalam/PycharmProjects/Back_end(Python,SQL)/src\\\\files\\\\records\\\\9.sql'\n"]
2020-10-06 11:24:13,699 - 33360 DEBUG - ['Traceback (most recent call last):\n', '  File "C:/Users/balaji.a.arunachalam/PycharmProjects/Back_end(Python,SQL)/src/main/insertion.py", line 17, in __init__\n    temp = sys.argv[1]\n', 'IndexError: list index out of range\n', '\nDuring handling of the above exception, another exception occurred:\n\n', 'Traceback (most recent call last):\n', '  File "C:/Users/balaji.a.arunachalam/PycharmProjects/Back_end(Python,SQL)/src/main/insertion.py", line 42, in record_insertion\n    with open(file_path, \'r\') as read_file:\n', "FileNotFoundError: [Errno 2] No such file or directory: 'C:/Users/balaji.a.arunachalam/PycharmProjects/Back_end(Python,SQL)/src\\\\files\\\\records\\\\sample.sql'\n"]
2020-10-06 11:24:13,699 - 33360 DEBUG - ['Traceback (most recent call last):\n', '  File "C:/Users/balaji.a.arunachalam/PycharmProjects/Back_end(Python,SQL)/src/main/insertion.py", line 17, in __init__\n    temp = sys.argv[1]\n', 'IndexError: list index out of range\n', '\nDuring handling of the above exception, another exception occurred:\n\n', 'Traceback (most recent call last):\n', '  File "C:/Users/balaji.a.arunachalam/PycharmProjects/Back_end(Python,SQL)/src/main/insertion.py", line 42, in record_insertion\n    with open(file_path, \'r\') as read_file:\n', "FileNotFoundError: [Errno 2] No such file or directory: 'C:/Users/balaji.a.arunachalam/PycharmProjects/Back_end(Python,SQL)/src\\\\files\\\\records\\\\sample.sql'\n"]
2020-10-06 11:24:13,699 - 33360 DEBUG - ['Traceback (most recent call last):\n', '  File "C:/Users/balaji.a.arunachalam/PycharmProjects/Back_end(Python,SQL)/src/main/insertion.py", line 17, in __init__\n    temp = sys.argv[1]\n', 'IndexError: list index out of range\n', '\nDuring handling of the above exception, another exception occurred:\n\n', 'Traceback (most recent call last):\n', '  File "C:/Users/balaji.a.arunachalam/PycharmProjects/Back_end(Python,SQL)/src/main/insertion.py", line 42, in record_insertion\n    with open(file_path, \'r\') as read_file:\n', "FileNotFoundError: [Errno 2] No such file or directory: 'C:/Users/balaji.a.arunachalam/PycharmProjects/Back_end(Python,SQL)/src\\\\files\\\\records\\\\sample.sql'\n"]
2020-10-06 11:24:28,718 - 30776 DEBUG - ['Traceback (most recent call last):\n', '  File "C:/Users/balaji.a.arunachalam/PycharmProjects/Back_end(Python,SQL)/src/main/insertion.py", line 17, in __init__\n    temp = sys.argv[1]\n', 'IndexError: list index out of range\n', '\nDuring handling of the above exception, another exception occurred:\n\n', 'Traceback (most recent call last):\n', '  File "C:/Users/balaji.a.arunachalam/PycharmProjects/Back_end(Python,SQL)/src/main/insertion.py", line 42, in record_insertion\n    with open(file_path, \'r\') as read_file:\n', "FileNotFoundError: [Errno 2] No such file or directory: 'C:/Users/balaji.a.arunachalam/PycharmProjects/Back_end(Python,SQL)/src\\\\files\\\\records\\\\csv.sql'\n"]
2020-10-06 11:24:28,718 - 30776 DEBUG - ['Traceback (most recent call last):\n', '  File "C:/Users/balaji.a.arunachalam/PycharmProjects/Back_end(Python,SQL)/src/main/insertion.py", line 17, in __init__\n    temp = sys.argv[1]\n', 'IndexError: list index out of range\n', '\nDuring handling of the above exception, another exception occurred:\n\n', 'Traceback (most recent call last):\n', '  File "C:/Users/balaji.a.arunachalam/PycharmProjects/Back_end(Python,SQL)/src/main/insertion.py", line 42, in record_insertion\n    with open(file_path, \'r\') as read_file:\n', "FileNotFoundError: [Errno 2] No such file or directory: 'C:/Users/balaji.a.arunachalam/PycharmProjects/Back_end(Python,SQL)/src\\\\files\\\\records\\\\csv.sql'\n"]
2020-10-06 11:24:28,718 - 30776 DEBUG - ['Traceback (most recent call last):\n', '  File "C:/Users/balaji.a.arunachalam/PycharmProjects/Back_end(Python,SQL)/src/main/insertion.py", line 17, in __init__\n    temp = sys.argv[1]\n', 'IndexError: list index out of range\n', '\nDuring handling of the above exception, another exception occurred:\n\n', 'Traceback (most recent call last):\n', '  File "C:/Users/balaji.a.arunachalam/PycharmProjects/Back_end(Python,SQL)/src/main/insertion.py", line 42, in record_insertion\n    with open(file_path, \'r\') as read_file:\n', "FileNotFoundError: [Errno 2] No such file or directory: 'C:/Users/balaji.a.arunachalam/PycharmProjects/Back_end(Python,SQL)/src\\\\files\\\\records\\\\csv.sql'\n"]
2020-10-06 11:24:28,719 - 30776 DEBUG - ['Traceback (most recent call last):\n', '  File "C:/Users/balaji.a.arunachalam/PycharmProjects/Back_end(Python,SQL)/src/main/insertion.py", line 17, in __init__\n    temp = sys.argv[1]\n', 'IndexError: list index out of range\n', '\nDuring handling of the above exception, another exception occurred:\n\n', 'Traceback (most recent call last):\n', '  File "C:/Users/balaji.a.arunachalam/PycharmProjects/Back_end(Python,SQL)/src/main/insertion.py", line 42, in record_insertion\n    with open(file_path, \'r\') as read_file:\n', "FileNotFoundError: [Errno 2] No such file or directory: 'C:/Users/balaji.a.arunachalam/PycharmProjects/Back_end(Python,SQL)/src\\\\files\\\\records\\\\csv.sql'\n"]
2020-10-06 11:24:28,719 - 30776 DEBUG - ['Traceback (most recent call last):\n', '  File "C:/Users/balaji.a.arunachalam/PycharmProjects/Back_end(Python,SQL)/src/main/insertion.py", line 17, in __init__\n    temp = sys.argv[1]\n', 'IndexError: list index out of range\n', '\nDuring handling of the above exception, another exception occurred:\n\n', 'Traceback (most recent call last):\n', '  File "C:/Users/balaji.a.arunachalam/PycharmProjects/Back_end(Python,SQL)/src/main/insertion.py", line 42, in record_insertion\n    with open(file_path, \'r\') as read_file:\n', "FileNotFoundError: [Errno 2] No such file or directory: 'C:/Users/balaji.a.arunachalam/PycharmProjects/Back_end(Python,SQL)/src\\\\files\\\\records\\\\csv.sql'\n"]
2020-10-06 11:24:28,719 - 30776 DEBUG - ['Traceback (most recent call last):\n', '  File "C:/Users/balaji.a.arunachalam/PycharmProjects/Back_end(Python,SQL)/src/main/insertion.py", line 17, in __init__\n    temp = sys.argv[1]\n', 'IndexError: list index out of range\n', '\nDuring handling of the above exception, another exception occurred:\n\n', 'Traceback (most recent call last):\n', '  File "C:/Users/balaji.a.arunachalam/PycharmProjects/Back_end(Python,SQL)/src/main/insertion.py", line 42, in record_insertion\n    with open(file_path, \'r\') as read_file:\n', "FileNotFoundError: [Errno 2] No such file or directory: 'C:/Users/balaji.a.arunachalam/PycharmProjects/Back_end(Python,SQL)/src\\\\files\\\\records\\\\csv.sql'\n"]
2020-10-06 11:24:28,720 - 30776 DEBUG - ['Traceback (most recent call last):\n', '  File "C:/Users/balaji.a.arunachalam/PycharmProjects/Back_end(Python,SQL)/src/main/insertion.py", line 17, in __init__\n    temp = sys.argv[1]\n', 'IndexError: list index out of range\n', '\nDuring handling of the above exception, another exception occurred:\n\n', 'Traceback (most recent call last):\n', '  File "C:/Users/balaji.a.arunachalam/PycharmProjects/Back_end(Python,SQL)/src/main/insertion.py", line 42, in record_insertion\n    with open(file_path, \'r\') as read_file:\n', "FileNotFoundError: [Errno 2] No such file or directory: 'C:/Users/balaji.a.arunachalam/PycharmProjects/Back_end(Python,SQL)/src\\\\files\\\\records\\\\csv.sql'\n"]
2020-10-06 11:24:28,720 - 30776 DEBUG - ['Traceback (most recent call last):\n', '  File "C:/Users/balaji.a.arunachalam/PycharmProjects/Back_end(Python,SQL)/src/main/insertion.py", line 17, in __init__\n    temp = sys.argv[1]\n', 'IndexError: list index out of range\n', '\nDuring handling of the above exception, another exception occurred:\n\n', 'Traceback (most recent call last):\n', '  File "C:/Users/balaji.a.arunachalam/PycharmProjects/Back_end(Python,SQL)/src/main/insertion.py", line 42, in record_insertion\n    with open(file_path, \'r\') as read_file:\n', "FileNotFoundError: [Errno 2] No such file or directory: 'C:/Users/balaji.a.arunachalam/PycharmProjects/Back_end(Python,SQL)/src\\\\files\\\\records\\\\csv.sql'\n"]
2020-10-06 11:24:28,720 - 30776 DEBUG - ['Traceback (most recent call last):\n', '  File "C:/Users/balaji.a.arunachalam/PycharmProjects/Back_end(Python,SQL)/src/main/insertion.py", line 17, in __init__\n    temp = sys.argv[1]\n', 'IndexError: list index out of range\n', '\nDuring handling of the above exception, another exception occurred:\n\n', 'Traceback (most recent call last):\n', '  File "C:/Users/balaji.a.arunachalam/PycharmProjects/Back_end(Python,SQL)/src/main/insertion.py", line 42, in record_insertion\n    with open(file_path, \'r\') as read_file:\n', "FileNotFoundError: [Errno 2] No such file or directory: 'C:/Users/balaji.a.arunachalam/PycharmProjects/Back_end(Python,SQL)/src\\\\files\\\\records\\\\csv.sql'\n"]
2020-10-06 11:24:28,720 - 30776 DEBUG - ['Traceback (most recent call last):\n', '  File "C:/Users/balaji.a.arunachalam/PycharmProjects/Back_end(Python,SQL)/src/main/insertion.py", line 17, in __init__\n    temp = sys.argv[1]\n', 'IndexError: list index out of range\n', '\nDuring handling of the above exception, another exception occurred:\n\n', 'Traceback (most recent call last):\n', '  File "C:/Users/balaji.a.arunachalam/PycharmProjects/Back_end(Python,SQL)/src/main/insertion.py", line 42, in record_insertion\n    with open(file_path, \'r\') as read_file:\n', "FileNotFoundError: [Errno 2] No such file or directory: 'C:/Users/balaji.a.arunachalam/PycharmProjects/Back_end(Python,SQL)/src\\\\files\\\\records\\\\csv.sql'\n"]
2020-10-06 11:24:28,720 - 30776 DEBUG - ['Traceback (most recent call last):\n', '  File "C:/Users/balaji.a.arunachalam/PycharmProjects/Back_end(Python,SQL)/src/main/insertion.py", line 17, in __init__\n    temp = sys.argv[1]\n', 'IndexError: list index out of range\n', '\nDuring handling of the above exception, another exception occurred:\n\n', 'Traceback (most recent call last):\n', '  File "C:/Users/balaji.a.arunachalam/PycharmProjects/Back_end(Python,SQL)/src/main/insertion.py", line 42, in record_insertion\n    with open(file_path, \'r\') as read_file:\n', "FileNotFoundError: [Errno 2] No such file or directory: 'C:/Users/balaji.a.arunachalam/PycharmProjects/Back_end(Python,SQL)/src\\\\files\\\\records\\\\csv.sql'\n"]
2020-10-06 11:24:28,720 - 30776 DEBUG - ['Traceback (most recent call last):\n', '  File "C:/Users/balaji.a.arunachalam/PycharmProjects/Back_end(Python,SQL)/src/main/insertion.py", line 17, in __init__\n    temp = sys.argv[1]\n', 'IndexError: list index out of range\n', '\nDuring handling of the above exception, another exception occurred:\n\n', 'Traceback (most recent call last):\n', '  File "C:/Users/balaji.a.arunachalam/PycharmProjects/Back_end(Python,SQL)/src/main/insertion.py", line 42, in record_insertion\n    with open(file_path, \'r\') as read_file:\n', "FileNotFoundError: [Errno 2] No such file or directory: 'C:/Users/balaji.a.arunachalam/PycharmProjects/Back_end(Python,SQL)/src\\\\files\\\\records\\\\csv.sql'\n"]
2020-10-06 11:24:28,721 - 30776 DEBUG - ['Traceback (most recent call last):\n', '  File "C:/Users/balaji.a.arunachalam/PycharmProjects/Back_end(Python,SQL)/src/main/insertion.py", line 17, in __init__\n    temp = sys.argv[1]\n', 'IndexError: list index out of range\n', '\nDuring handling of the above exception, another exception occurred:\n\n', 'Traceback (most recent call last):\n', '  File "C:/Users/balaji.a.arunachalam/PycharmProjects/Back_end(Python,SQL)/src/main/insertion.py", line 42, in record_insertion\n    with open(file_path, \'r\') as read_file:\n', "FileNotFoundError: [Errno 2] No such file or directory: 'C:/Users/balaji.a.arunachalam/PycharmProjects/Back_end(Python,SQL)/src\\\\files\\\\records\\\\csv.sql'\n"]
2020-10-06 11:24:28,721 - 30776 DEBUG - ['Traceback (most recent call last):\n', '  File "C:/Users/balaji.a.arunachalam/PycharmProjects/Back_end(Python,SQL)/src/main/insertion.py", line 17, in __init__\n    temp = sys.argv[1]\n', 'IndexError: list index out of range\n', '\nDuring handling of the above exception, another exception occurred:\n\n', 'Traceback (most recent call last):\n', '  File "C:/Users/balaji.a.arunachalam/PycharmProjects/Back_end(Python,SQL)/src/main/insertion.py", line 42, in record_insertion\n    with open(file_path, \'r\') as read_file:\n', "FileNotFoundError: [Errno 2] No such file or directory: 'C:/Users/balaji.a.arunachalam/PycharmProjects/Back_end(Python,SQL)/src\\\\files\\\\records\\\\csv.sql'\n"]
2020-10-06 11:24:28,721 - 30776 DEBUG - ['Traceback (most recent call last):\n', '  File "C:/Users/balaji.a.arunachalam/PycharmProjects/Back_end(Python,SQL)/src/main/insertion.py", line 17, in __init__\n    temp = sys.argv[1]\n', 'IndexError: list index out of range\n', '\nDuring handling of the above exception, another exception occurred:\n\n', 'Traceback (most recent call last):\n', '  File "C:/Users/balaji.a.arunachalam/PycharmProjects/Back_end(Python,SQL)/src/main/insertion.py", line 42, in record_insertion\n    with open(file_path, \'r\') as read_file:\n', "FileNotFoundError: [Errno 2] No such file or directory: 'C:/Users/balaji.a.arunachalam/PycharmProjects/Back_end(Python,SQL)/src\\\\files\\\\records\\\\csv.sql'\n"]
2020-10-06 11:24:28,722 - 30776 DEBUG - ['Traceback (most recent call last):\n', '  File "C:/Users/balaji.a.arunachalam/PycharmProjects/Back_end(Python,SQL)/src/main/insertion.py", line 17, in __init__\n    temp = sys.argv[1]\n', 'IndexError: list index out of range\n', '\nDuring handling of the above exception, another exception occurred:\n\n', 'Traceback (most recent call last):\n', '  File "C:/Users/balaji.a.arunachalam/PycharmProjects/Back_end(Python,SQL)/src/main/insertion.py", line 42, in record_insertion\n    with open(file_path, \'r\') as read_file:\n', "FileNotFoundError: [Errno 2] No such file or directory: 'C:/Users/balaji.a.arunachalam/PycharmProjects/Back_end(Python,SQL)/src\\\\files\\\\records\\\\csv.sql'\n"]
2020-10-06 11:24:28,722 - 30776 DEBUG - ['Traceback (most recent call last):\n', '  File "C:/Users/balaji.a.arunachalam/PycharmProjects/Back_end(Python,SQL)/src/main/insertion.py", line 17, in __init__\n    temp = sys.argv[1]\n', 'IndexError: list index out of range\n', '\nDuring handling of the above exception, another exception occurred:\n\n', 'Traceback (most recent call last):\n', '  File "C:/Users/balaji.a.arunachalam/PycharmProjects/Back_end(Python,SQL)/src/main/insertion.py", line 42, in record_insertion\n    with open(file_path, \'r\') as read_file:\n', "FileNotFoundError: [Errno 2] No such file or directory: 'C:/Users/balaji.a.arunachalam/PycharmProjects/Back_end(Python,SQL)/src\\\\files\\\\records\\\\csv.sql'\n"]
2020-10-06 11:24:28,722 - 30776 DEBUG - ['Traceback (most recent call last):\n', '  File "C:/Users/balaji.a.arunachalam/PycharmProjects/Back_end(Python,SQL)/src/main/insertion.py", line 17, in __init__\n    temp = sys.argv[1]\n', 'IndexError: list index out of range\n', '\nDuring handling of the above exception, another exception occurred:\n\n', 'Traceback (most recent call last):\n', '  File "C:/Users/balaji.a.arunachalam/PycharmProjects/Back_end(Python,SQL)/src/main/insertion.py", line 42, in record_insertion\n    with open(file_path, \'r\') as read_file:\n', "FileNotFoundError: [Errno 2] No such file or directory: 'C:/Users/balaji.a.arunachalam/PycharmProjects/Back_end(Python,SQL)/src\\\\files\\\\records\\\\csv.sql'\n"]
2020-10-06 11:24:28,723 - 30776 DEBUG - ['Traceback (most recent call last):\n', '  File "C:/Users/balaji.a.arunachalam/PycharmProjects/Back_end(Python,SQL)/src/main/insertion.py", line 17, in __init__\n    temp = sys.argv[1]\n', 'IndexError: list index out of range\n', '\nDuring handling of the above exception, another exception occurred:\n\n', 'Traceback (most recent call last):\n', '  File "C:/Users/balaji.a.arunachalam/PycharmProjects/Back_end(Python,SQL)/src/main/insertion.py", line 42, in record_insertion\n    with open(file_path, \'r\') as read_file:\n', "FileNotFoundError: [Errno 2] No such file or directory: 'C:/Users/balaji.a.arunachalam/PycharmProjects/Back_end(Python,SQL)/src\\\\files\\\\records\\\\csv.sql'\n"]
2020-10-06 11:24:28,723 - 30776 DEBUG - ['Traceback (most recent call last):\n', '  File "C:/Users/balaji.a.arunachalam/PycharmProjects/Back_end(Python,SQL)/src/main/insertion.py", line 17, in __init__\n    temp = sys.argv[1]\n', 'IndexError: list index out of range\n', '\nDuring handling of the above exception, another exception occurred:\n\n', 'Traceback (most recent call last):\n', '  File "C:/Users/balaji.a.arunachalam/PycharmProjects/Back_end(Python,SQL)/src/main/insertion.py", line 42, in record_insertion\n    with open(file_path, \'r\') as read_file:\n', "FileNotFoundError: [Errno 2] No such file or directory: 'C:/Users/balaji.a.arunachalam/PycharmProjects/Back_end(Python,SQL)/src\\\\files\\\\records\\\\csv.sql'\n"]
2020-10-06 11:24:28,723 - 30776 DEBUG - ['Traceback (most recent call last):\n', '  File "C:/Users/balaji.a.arunachalam/PycharmProjects/Back_end(Python,SQL)/src/main/insertion.py", line 17, in __init__\n    temp = sys.argv[1]\n', 'IndexError: list index out of range\n', '\nDuring handling of the above exception, another exception occurred:\n\n', 'Traceback (most recent call last):\n', '  File "C:/Users/balaji.a.arunachalam/PycharmProjects/Back_end(Python,SQL)/src/main/insertion.py", line 42, in record_insertion\n    with open(file_path, \'r\') as read_file:\n', "FileNotFoundError: [Errno 2] No such file or directory: 'C:/Users/balaji.a.arunachalam/PycharmProjects/Back_end(Python,SQL)/src\\\\files\\\\records\\\\csv.sql'\n"]
2020-10-06 11:24:28,723 - 30776 DEBUG - ['Traceback (most recent call last):\n', '  File "C:/Users/balaji.a.arunachalam/PycharmProjects/Back_end(Python,SQL)/src/main/insertion.py", line 17, in __init__\n    temp = sys.argv[1]\n', 'IndexError: list index out of range\n', '\nDuring handling of the above exception, another exception occurred:\n\n', 'Traceback (most recent call last):\n', '  File "C:/Users/balaji.a.arunachalam/PycharmProjects/Back_end(Python,SQL)/src/main/insertion.py", line 42, in record_insertion\n    with open(file_path, \'r\') as read_file:\n', "FileNotFoundError: [Errno 2] No such file or directory: 'C:/Users/balaji.a.arunachalam/PycharmProjects/Back_end(Python,SQL)/src\\\\files\\\\records\\\\csv.sql'\n"]
2020-10-06 11:24:28,723 - 30776 DEBUG - ['Traceback (most recent call last):\n', '  File "C:/Users/balaji.a.arunachalam/PycharmProjects/Back_end(Python,SQL)/src/main/insertion.py", line 17, in __init__\n    temp = sys.argv[1]\n', 'IndexError: list index out of range\n', '\nDuring handling of the above exception, another exception occurred:\n\n', 'Traceback (most recent call last):\n', '  File "C:/Users/balaji.a.arunachalam/PycharmProjects/Back_end(Python,SQL)/src/main/insertion.py", line 42, in record_insertion\n    with open(file_path, \'r\') as read_file:\n', "FileNotFoundError: [Errno 2] No such file or directory: 'C:/Users/balaji.a.arunachalam/PycharmProjects/Back_end(Python,SQL)/src\\\\files\\\\records\\\\csv.sql'\n"]
2020-10-06 11:24:28,723 - 30776 DEBUG - ['Traceback (most recent call last):\n', '  File "C:/Users/balaji.a.arunachalam/PycharmProjects/Back_end(Python,SQL)/src/main/insertion.py", line 17, in __init__\n    temp = sys.argv[1]\n', 'IndexError: list index out of range\n', '\nDuring handling of the above exception, another exception occurred:\n\n', 'Traceback (most recent call last):\n', '  File "C:/Users/balaji.a.arunachalam/PycharmProjects/Back_end(Python,SQL)/src/main/insertion.py", line 42, in record_insertion\n    with open(file_path, \'r\') as read_file:\n', "FileNotFoundError: [Errno 2] No such file or directory: 'C:/Users/balaji.a.arunachalam/PycharmProjects/Back_end(Python,SQL)/src\\\\files\\\\records\\\\csv.sql'\n"]
2020-10-06 11:24:28,724 - 30776 DEBUG - ['Traceback (most recent call last):\n', '  File "C:/Users/balaji.a.arunachalam/PycharmProjects/Back_end(Python,SQL)/src/main/insertion.py", line 17, in __init__\n    temp = sys.argv[1]\n', 'IndexError: list index out of range\n', '\nDuring handling of the above exception, another exception occurred:\n\n', 'Traceback (most recent call last):\n', '  File "C:/Users/balaji.a.arunachalam/PycharmProjects/Back_end(Python,SQL)/src/main/insertion.py", line 42, in record_insertion\n    with open(file_path, \'r\') as read_file:\n', "FileNotFoundError: [Errno 2] No such file or directory: 'C:/Users/balaji.a.arunachalam/PycharmProjects/Back_end(Python,SQL)/src\\\\files\\\\records\\\\0_product_details.sql'\n"]
2020-10-06 11:24:28,724 - 30776 DEBUG - ['Traceback (most recent call last):\n', '  File "C:/Users/balaji.a.arunachalam/PycharmProjects/Back_end(Python,SQL)/src/main/insertion.py", line 17, in __init__\n    temp = sys.argv[1]\n', 'IndexError: list index out of range\n', '\nDuring handling of the above exception, another exception occurred:\n\n', 'Traceback (most recent call last):\n', '  File "C:/Users/balaji.a.arunachalam/PycharmProjects/Back_end(Python,SQL)/src/main/insertion.py", line 42, in record_insertion\n    with open(file_path, \'r\') as read_file:\n', "FileNotFoundError: [Errno 2] No such file or directory: 'C:/Users/balaji.a.arunachalam/PycharmProjects/Back_end(Python,SQL)/src\\\\files\\\\records\\\\0_product_details.sql'\n"]
2020-10-06 11:24:28,724 - 30776 DEBUG - ['Traceback (most recent call last):\n', '  File "C:/Users/balaji.a.arunachalam/PycharmProjects/Back_end(Python,SQL)/src/main/insertion.py", line 17, in __init__\n    temp = sys.argv[1]\n', 'IndexError: list index out of range\n', '\nDuring handling of the above exception, another exception occurred:\n\n', 'Traceback (most recent call last):\n', '  File "C:/Users/balaji.a.arunachalam/PycharmProjects/Back_end(Python,SQL)/src/main/insertion.py", line 42, in record_insertion\n    with open(file_path, \'r\') as read_file:\n', "FileNotFoundError: [Errno 2] No such file or directory: 'C:/Users/balaji.a.arunachalam/PycharmProjects/Back_end(Python,SQL)/src\\\\files\\\\records\\\\0_product_details.sql'\n"]
2020-10-06 11:24:28,725 - 30776 DEBUG - ['Traceback (most recent call last):\n', '  File "C:/Users/balaji.a.arunachalam/PycharmProjects/Back_end(Python,SQL)/src/main/insertion.py", line 17, in __init__\n    temp = sys.argv[1]\n', 'IndexError: list index out of range\n', '\nDuring handling of the above exception, another exception occurred:\n\n', 'Traceback (most recent call last):\n', '  File "C:/Users/balaji.a.arunachalam/PycharmProjects/Back_end(Python,SQL)/src/main/insertion.py", line 42, in record_insertion\n    with open(file_path, \'r\') as read_file:\n', "FileNotFoundError: [Errno 2] No such file or directory: 'C:/Users/balaji.a.arunachalam/PycharmProjects/Back_end(Python,SQL)/src\\\\files\\\\records\\\\1_cart_product_details.sql'\n"]
2020-10-06 11:24:28,725 - 30776 DEBUG - ['Traceback (most recent call last):\n', '  File "C:/Users/balaji.a.arunachalam/PycharmProjects/Back_end(Python,SQL)/src/main/insertion.py", line 17, in __init__\n    temp = sys.argv[1]\n', 'IndexError: list index out of range\n', '\nDuring handling of the above exception, another exception occurred:\n\n', 'Traceback (most recent call last):\n', '  File "C:/Users/balaji.a.arunachalam/PycharmProjects/Back_end(Python,SQL)/src/main/insertion.py", line 42, in record_insertion\n    with open(file_path, \'r\') as read_file:\n', "FileNotFoundError: [Errno 2] No such file or directory: 'C:/Users/balaji.a.arunachalam/PycharmProjects/Back_end(Python,SQL)/src\\\\files\\\\records\\\\1_cart_product_details.sql'\n"]
2020-10-06 11:24:28,725 - 30776 DEBUG - ['Traceback (most recent call last):\n', '  File "C:/Users/balaji.a.arunachalam/PycharmProjects/Back_end(Python,SQL)/src/main/insertion.py", line 17, in __init__\n    temp = sys.argv[1]\n', 'IndexError: list index out of range\n', '\nDuring handling of the above exception, another exception occurred:\n\n', 'Traceback (most recent call last):\n', '  File "C:/Users/balaji.a.arunachalam/PycharmProjects/Back_end(Python,SQL)/src/main/insertion.py", line 42, in record_insertion\n    with open(file_path, \'r\') as read_file:\n', "FileNotFoundError: [Errno 2] No such file or directory: 'C:/Users/balaji.a.arunachalam/PycharmProjects/Back_end(Python,SQL)/src\\\\files\\\\records\\\\1_cart_product_details.sql'\n"]
2020-10-06 11:24:28,726 - 30776 DEBUG - ['Traceback (most recent call last):\n', '  File "C:/Users/balaji.a.arunachalam/PycharmProjects/Back_end(Python,SQL)/src/main/insertion.py", line 17, in __init__\n    temp = sys.argv[1]\n', 'IndexError: list index out of range\n', '\nDuring handling of the above exception, another exception occurred:\n\n', 'Traceback (most recent call last):\n', '  File "C:/Users/balaji.a.arunachalam/PycharmProjects/Back_end(Python,SQL)/src/main/insertion.py", line 42, in record_insertion\n    with open(file_path, \'r\') as read_file:\n', "FileNotFoundError: [Errno 2] No such file or directory: 'C:/Users/balaji.a.arunachalam/PycharmProjects/Back_end(Python,SQL)/src\\\\files\\\\records\\\\2_category_product_details.sql'\n"]
2020-10-06 11:24:28,726 - 30776 DEBUG - ['Traceback (most recent call last):\n', '  File "C:/Users/balaji.a.arunachalam/PycharmProjects/Back_end(Python,SQL)/src/main/insertion.py", line 17, in __init__\n    temp = sys.argv[1]\n', 'IndexError: list index out of range\n', '\nDuring handling of the above exception, another exception occurred:\n\n', 'Traceback (most recent call last):\n', '  File "C:/Users/balaji.a.arunachalam/PycharmProjects/Back_end(Python,SQL)/src/main/insertion.py", line 42, in record_insertion\n    with open(file_path, \'r\') as read_file:\n', "FileNotFoundError: [Errno 2] No such file or directory: 'C:/Users/balaji.a.arunachalam/PycharmProjects/Back_end(Python,SQL)/src\\\\files\\\\records\\\\2_category_product_details.sql'\n"]
2020-10-06 11:24:28,726 - 30776 DEBUG - ['Traceback (most recent call last):\n', '  File "C:/Users/balaji.a.arunachalam/PycharmProjects/Back_end(Python,SQL)/src/main/insertion.py", line 17, in __init__\n    temp = sys.argv[1]\n', 'IndexError: list index out of range\n', '\nDuring handling of the above exception, another exception occurred:\n\n', 'Traceback (most recent call last):\n', '  File "C:/Users/balaji.a.arunachalam/PycharmProjects/Back_end(Python,SQL)/src/main/insertion.py", line 42, in record_insertion\n    with open(file_path, \'r\') as read_file:\n', "FileNotFoundError: [Errno 2] No such file or directory: 'C:/Users/balaji.a.arunachalam/PycharmProjects/Back_end(Python,SQL)/src\\\\files\\\\records\\\\2_category_product_details.sql'\n"]
2020-10-06 11:24:28,726 - 30776 DEBUG - ['Traceback (most recent call last):\n', '  File "C:/Users/balaji.a.arunachalam/PycharmProjects/Back_end(Python,SQL)/src/main/insertion.py", line 17, in __init__\n    temp = sys.argv[1]\n', 'IndexError: list index out of range\n', '\nDuring handling of the above exception, another exception occurred:\n\n', 'Traceback (most recent call last):\n', '  File "C:/Users/balaji.a.arunachalam/PycharmProjects/Back_end(Python,SQL)/src/main/insertion.py", line 42, in record_insertion\n    with open(file_path, \'r\') as read_file:\n', "FileNotFoundError: [Errno 2] No such file or directory: 'C:/Users/balaji.a.arunachalam/PycharmProjects/Back_end(Python,SQL)/src\\\\files\\\\records\\\\3_customer_rating_details.sql'\n"]
2020-10-06 11:24:28,726 - 30776 DEBUG - ['Traceback (most recent call last):\n', '  File "C:/Users/balaji.a.arunachalam/PycharmProjects/Back_end(Python,SQL)/src/main/insertion.py", line 17, in __init__\n    temp = sys.argv[1]\n', 'IndexError: list index out of range\n', '\nDuring handling of the above exception, another exception occurred:\n\n', 'Traceback (most recent call last):\n', '  File "C:/Users/balaji.a.arunachalam/PycharmProjects/Back_end(Python,SQL)/src/main/insertion.py", line 42, in record_insertion\n    with open(file_path, \'r\') as read_file:\n', "FileNotFoundError: [Errno 2] No such file or directory: 'C:/Users/balaji.a.arunachalam/PycharmProjects/Back_end(Python,SQL)/src\\\\files\\\\records\\\\3_customer_rating_details.sql'\n"]
2020-10-06 11:24:28,726 - 30776 DEBUG - ['Traceback (most recent call last):\n', '  File "C:/Users/balaji.a.arunachalam/PycharmProjects/Back_end(Python,SQL)/src/main/insertion.py", line 17, in __init__\n    temp = sys.argv[1]\n', 'IndexError: list index out of range\n', '\nDuring handling of the above exception, another exception occurred:\n\n', 'Traceback (most recent call last):\n', '  File "C:/Users/balaji.a.arunachalam/PycharmProjects/Back_end(Python,SQL)/src/main/insertion.py", line 42, in record_insertion\n    with open(file_path, \'r\') as read_file:\n', "FileNotFoundError: [Errno 2] No such file or directory: 'C:/Users/balaji.a.arunachalam/PycharmProjects/Back_end(Python,SQL)/src\\\\files\\\\records\\\\3_customer_rating_details.sql'\n"]
2020-10-06 11:24:28,727 - 30776 DEBUG - ['Traceback (most recent call last):\n', '  File "C:/Users/balaji.a.arunachalam/PycharmProjects/Back_end(Python,SQL)/src/main/insertion.py", line 17, in __init__\n    temp = sys.argv[1]\n', 'IndexError: list index out of range\n', '\nDuring handling of the above exception, another exception occurred:\n\n', 'Traceback (most recent call last):\n', '  File "C:/Users/balaji.a.arunachalam/PycharmProjects/Back_end(Python,SQL)/src/main/insertion.py", line 42, in record_insertion\n    with open(file_path, \'r\') as read_file:\n', "FileNotFoundError: [Errno 2] No such file or directory: 'C:/Users/balaji.a.arunachalam/PycharmProjects/Back_end(Python,SQL)/src\\\\files\\\\records\\\\4_invoice_details.sql'\n"]
2020-10-06 11:24:28,727 - 30776 DEBUG - ['Traceback (most recent call last):\n', '  File "C:/Users/balaji.a.arunachalam/PycharmProjects/Back_end(Python,SQL)/src/main/insertion.py", line 17, in __init__\n    temp = sys.argv[1]\n', 'IndexError: list index out of range\n', '\nDuring handling of the above exception, another exception occurred:\n\n', 'Traceback (most recent call last):\n', '  File "C:/Users/balaji.a.arunachalam/PycharmProjects/Back_end(Python,SQL)/src/main/insertion.py", line 42, in record_insertion\n    with open(file_path, \'r\') as read_file:\n', "FileNotFoundError: [Errno 2] No such file or directory: 'C:/Users/balaji.a.arunachalam/PycharmProjects/Back_end(Python,SQL)/src\\\\files\\\\records\\\\4_invoice_details.sql'\n"]
2020-10-06 11:24:28,727 - 30776 DEBUG - ['Traceback (most recent call last):\n', '  File "C:/Users/balaji.a.arunachalam/PycharmProjects/Back_end(Python,SQL)/src/main/insertion.py", line 17, in __init__\n    temp = sys.argv[1]\n', 'IndexError: list index out of range\n', '\nDuring handling of the above exception, another exception occurred:\n\n', 'Traceback (most recent call last):\n', '  File "C:/Users/balaji.a.arunachalam/PycharmProjects/Back_end(Python,SQL)/src/main/insertion.py", line 42, in record_insertion\n    with open(file_path, \'r\') as read_file:\n', "FileNotFoundError: [Errno 2] No such file or directory: 'C:/Users/balaji.a.arunachalam/PycharmProjects/Back_end(Python,SQL)/src\\\\files\\\\records\\\\4_invoice_details.sql'\n"]
2020-10-06 11:24:28,728 - 30776 DEBUG - ['Traceback (most recent call last):\n', '  File "C:/Users/balaji.a.arunachalam/PycharmProjects/Back_end(Python,SQL)/src/main/insertion.py", line 17, in __init__\n    temp = sys.argv[1]\n', 'IndexError: list index out of range\n', '\nDuring handling of the above exception, another exception occurred:\n\n', 'Traceback (most recent call last):\n', '  File "C:/Users/balaji.a.arunachalam/PycharmProjects/Back_end(Python,SQL)/src/main/insertion.py", line 42, in record_insertion\n    with open(file_path, \'r\') as read_file:\n', "FileNotFoundError: [Errno 2] No such file or directory: 'C:/Users/balaji.a.arunachalam/PycharmProjects/Back_end(Python,SQL)/src\\\\files\\\\records\\\\5_payment_details.sql'\n"]
2020-10-06 11:24:28,728 - 30776 DEBUG - ['Traceback (most recent call last):\n', '  File "C:/Users/balaji.a.arunachalam/PycharmProjects/Back_end(Python,SQL)/src/main/insertion.py", line 17, in __init__\n    temp = sys.argv[1]\n', 'IndexError: list index out of range\n', '\nDuring handling of the above exception, another exception occurred:\n\n', 'Traceback (most recent call last):\n', '  File "C:/Users/balaji.a.arunachalam/PycharmProjects/Back_end(Python,SQL)/src/main/insertion.py", line 42, in record_insertion\n    with open(file_path, \'r\') as read_file:\n', "FileNotFoundError: [Errno 2] No such file or directory: 'C:/Users/balaji.a.arunachalam/PycharmProjects/Back_end(Python,SQL)/src\\\\files\\\\records\\\\5_payment_details.sql'\n"]
2020-10-06 11:24:28,728 - 30776 DEBUG - ['Traceback (most recent call last):\n', '  File "C:/Users/balaji.a.arunachalam/PycharmProjects/Back_end(Python,SQL)/src/main/insertion.py", line 17, in __init__\n    temp = sys.argv[1]\n', 'IndexError: list index out of range\n', '\nDuring handling of the above exception, another exception occurred:\n\n', 'Traceback (most recent call last):\n', '  File "C:/Users/balaji.a.arunachalam/PycharmProjects/Back_end(Python,SQL)/src/main/insertion.py", line 42, in record_insertion\n    with open(file_path, \'r\') as read_file:\n', "FileNotFoundError: [Errno 2] No such file or directory: 'C:/Users/balaji.a.arunachalam/PycharmProjects/Back_end(Python,SQL)/src\\\\files\\\\records\\\\5_payment_details.sql'\n"]
2020-10-06 11:24:28,729 - 30776 DEBUG - ['Traceback (most recent call last):\n', '  File "C:/Users/balaji.a.arunachalam/PycharmProjects/Back_end(Python,SQL)/src/main/insertion.py", line 17, in __init__\n    temp = sys.argv[1]\n', 'IndexError: list index out of range\n', '\nDuring handling of the above exception, another exception occurred:\n\n', 'Traceback (most recent call last):\n', '  File "C:/Users/balaji.a.arunachalam/PycharmProjects/Back_end(Python,SQL)/src/main/insertion.py", line 42, in record_insertion\n    with open(file_path, \'r\') as read_file:\n', "FileNotFoundError: [Errno 2] No such file or directory: 'C:/Users/balaji.a.arunachalam/PycharmProjects/Back_end(Python,SQL)/src\\\\files\\\\records\\\\6_product_ordered_details.sql'\n"]
2020-10-06 11:24:28,729 - 30776 DEBUG - ['Traceback (most recent call last):\n', '  File "C:/Users/balaji.a.arunachalam/PycharmProjects/Back_end(Python,SQL)/src/main/insertion.py", line 17, in __init__\n    temp = sys.argv[1]\n', 'IndexError: list index out of range\n', '\nDuring handling of the above exception, another exception occurred:\n\n', 'Traceback (most recent call last):\n', '  File "C:/Users/balaji.a.arunachalam/PycharmProjects/Back_end(Python,SQL)/src/main/insertion.py", line 42, in record_insertion\n    with open(file_path, \'r\') as read_file:\n', "FileNotFoundError: [Errno 2] No such file or directory: 'C:/Users/balaji.a.arunachalam/PycharmProjects/Back_end(Python,SQL)/src\\\\files\\\\records\\\\6_product_ordered_details.sql'\n"]
2020-10-06 11:24:28,729 - 30776 DEBUG - ['Traceback (most recent call last):\n', '  File "C:/Users/balaji.a.arunachalam/PycharmProjects/Back_end(Python,SQL)/src/main/insertion.py", line 17, in __init__\n    temp = sys.argv[1]\n', 'IndexError: list index out of range\n', '\nDuring handling of the above exception, another exception occurred:\n\n', 'Traceback (most recent call last):\n', '  File "C:/Users/balaji.a.arunachalam/PycharmProjects/Back_end(Python,SQL)/src/main/insertion.py", line 42, in record_insertion\n    with open(file_path, \'r\') as read_file:\n', "FileNotFoundError: [Errno 2] No such file or directory: 'C:/Users/balaji.a.arunachalam/PycharmProjects/Back_end(Python,SQL)/src\\\\files\\\\records\\\\6_product_ordered_details.sql'\n"]
2020-10-06 11:24:28,729 - 30776 DEBUG - ['Traceback (most recent call last):\n', '  File "C:/Users/balaji.a.arunachalam/PycharmProjects/Back_end(Python,SQL)/src/main/insertion.py", line 17, in __init__\n    temp = sys.argv[1]\n', 'IndexError: list index out of range\n', '\nDuring handling of the above exception, another exception occurred:\n\n', 'Traceback (most recent call last):\n', '  File "C:/Users/balaji.a.arunachalam/PycharmProjects/Back_end(Python,SQL)/src/main/insertion.py", line 42, in record_insertion\n    with open(file_path, \'r\') as read_file:\n', "FileNotFoundError: [Errno 2] No such file or directory: 'C:/Users/balaji.a.arunachalam/PycharmProjects/Back_end(Python,SQL)/src\\\\files\\\\records\\\\7_shipping_status.sql'\n"]
2020-10-06 11:24:28,729 - 30776 DEBUG - ['Traceback (most recent call last):\n', '  File "C:/Users/balaji.a.arunachalam/PycharmProjects/Back_end(Python,SQL)/src/main/insertion.py", line 17, in __init__\n    temp = sys.argv[1]\n', 'IndexError: list index out of range\n', '\nDuring handling of the above exception, another exception occurred:\n\n', 'Traceback (most recent call last):\n', '  File "C:/Users/balaji.a.arunachalam/PycharmProjects/Back_end(Python,SQL)/src/main/insertion.py", line 42, in record_insertion\n    with open(file_path, \'r\') as read_file:\n', "FileNotFoundError: [Errno 2] No such file or directory: 'C:/Users/balaji.a.arunachalam/PycharmProjects/Back_end(Python,SQL)/src\\\\files\\\\records\\\\7_shipping_status.sql'\n"]
2020-10-06 11:24:28,729 - 30776 DEBUG - ['Traceback (most recent call last):\n', '  File "C:/Users/balaji.a.arunachalam/PycharmProjects/Back_end(Python,SQL)/src/main/insertion.py", line 17, in __init__\n    temp = sys.argv[1]\n', 'IndexError: list index out of range\n', '\nDuring handling of the above exception, another exception occurred:\n\n', 'Traceback (most recent call last):\n', '  File "C:/Users/balaji.a.arunachalam/PycharmProjects/Back_end(Python,SQL)/src/main/insertion.py", line 42, in record_insertion\n    with open(file_path, \'r\') as read_file:\n', "FileNotFoundError: [Errno 2] No such file or directory: 'C:/Users/balaji.a.arunachalam/PycharmProjects/Back_end(Python,SQL)/src\\\\files\\\\records\\\\7_shipping_status.sql'\n"]
2020-10-06 11:24:28,730 - 30776 DEBUG - ['Traceback (most recent call last):\n', '  File "C:/Users/balaji.a.arunachalam/PycharmProjects/Back_end(Python,SQL)/src/main/insertion.py", line 17, in __init__\n    temp = sys.argv[1]\n', 'IndexError: list index out of range\n', '\nDuring handling of the above exception, another exception occurred:\n\n', 'Traceback (most recent call last):\n', '  File "C:/Users/balaji.a.arunachalam/PycharmProjects/Back_end(Python,SQL)/src/main/insertion.py", line 42, in record_insertion\n    with open(file_path, \'r\') as read_file:\n', "FileNotFoundError: [Errno 2] No such file or directory: 'C:/Users/balaji.a.arunachalam/PycharmProjects/Back_end(Python,SQL)/src\\\\files\\\\records\\\\csv.sql'\n"]
2020-10-06 11:24:28,730 - 30776 DEBUG - ['Traceback (most recent call last):\n', '  File "C:/Users/balaji.a.arunachalam/PycharmProjects/Back_end(Python,SQL)/src/main/insertion.py", line 17, in __init__\n    temp = sys.argv[1]\n', 'IndexError: list index out of range\n', '\nDuring handling of the above exception, another exception occurred:\n\n', 'Traceback (most recent call last):\n', '  File "C:/Users/balaji.a.arunachalam/PycharmProjects/Back_end(Python,SQL)/src/main/insertion.py", line 42, in record_insertion\n    with open(file_path, \'r\') as read_file:\n', "FileNotFoundError: [Errno 2] No such file or directory: 'C:/Users/balaji.a.arunachalam/PycharmProjects/Back_end(Python,SQL)/src\\\\files\\\\records\\\\csv.sql'\n"]
2020-10-06 11:24:28,730 - 30776 DEBUG - ['Traceback (most recent call last):\n', '  File "C:/Users/balaji.a.arunachalam/PycharmProjects/Back_end(Python,SQL)/src/main/insertion.py", line 17, in __init__\n    temp = sys.argv[1]\n', 'IndexError: list index out of range\n', '\nDuring handling of the above exception, another exception occurred:\n\n', 'Traceback (most recent call last):\n', '  File "C:/Users/balaji.a.arunachalam/PycharmProjects/Back_end(Python,SQL)/src/main/insertion.py", line 42, in record_insertion\n    with open(file_path, \'r\') as read_file:\n', "FileNotFoundError: [Errno 2] No such file or directory: 'C:/Users/balaji.a.arunachalam/PycharmProjects/Back_end(Python,SQL)/src\\\\files\\\\records\\\\csv.sql'\n"]
2020-10-06 11:24:46,668 - 7304 DEBUG - ['Traceback (most recent call last):\n', '  File "C:/Users/balaji.a.arunachalam/PycharmProjects/Back_end(Python,SQL)/src/main/insertion.py", line 17, in __init__\n    temp = sys.argv[1]\n', 'IndexError: list index out of range\n', '\nDuring handling of the above exception, another exception occurred:\n\n', 'Traceback (most recent call last):\n', '  File "C:/Users/balaji.a.arunachalam/PycharmProjects/Back_end(Python,SQL)/src/main/insertion.py", line 42, in record_insertion\n    with open(file_path, \'r\') as read_file:\n', "FileNotFoundError: [Errno 2] No such file or directory: 'C:/Users/balaji.a.arunachalam/PycharmProjects/Back_end(Python,SQL)/src\\\\files\\\\records\\\\1_category_details.sql'\n"]
2020-10-06 11:24:46,668 - 7304 DEBUG - ['Traceback (most recent call last):\n', '  File "C:/Users/balaji.a.arunachalam/PycharmProjects/Back_end(Python,SQL)/src/main/insertion.py", line 17, in __init__\n    temp = sys.argv[1]\n', 'IndexError: list index out of range\n', '\nDuring handling of the above exception, another exception occurred:\n\n', 'Traceback (most recent call last):\n', '  File "C:/Users/balaji.a.arunachalam/PycharmProjects/Back_end(Python,SQL)/src/main/insertion.py", line 42, in record_insertion\n    with open(file_path, \'r\') as read_file:\n', "FileNotFoundError: [Errno 2] No such file or directory: 'C:/Users/balaji.a.arunachalam/PycharmProjects/Back_end(Python,SQL)/src\\\\files\\\\records\\\\1_category_details.sql'\n"]
2020-10-06 11:24:46,668 - 7304 DEBUG - ['Traceback (most recent call last):\n', '  File "C:/Users/balaji.a.arunachalam/PycharmProjects/Back_end(Python,SQL)/src/main/insertion.py", line 17, in __init__\n    temp = sys.argv[1]\n', 'IndexError: list index out of range\n', '\nDuring handling of the above exception, another exception occurred:\n\n', 'Traceback (most recent call last):\n', '  File "C:/Users/balaji.a.arunachalam/PycharmProjects/Back_end(Python,SQL)/src/main/insertion.py", line 42, in record_insertion\n    with open(file_path, \'r\') as read_file:\n', "FileNotFoundError: [Errno 2] No such file or directory: 'C:/Users/balaji.a.arunachalam/PycharmProjects/Back_end(Python,SQL)/src\\\\files\\\\records\\\\1_category_details.sql'\n"]
2020-10-06 11:24:46,669 - 7304 DEBUG - ['Traceback (most recent call last):\n', '  File "C:/Users/balaji.a.arunachalam/PycharmProjects/Back_end(Python,SQL)/src/main/insertion.py", line 17, in __init__\n    temp = sys.argv[1]\n', 'IndexError: list index out of range\n', '\nDuring handling of the above exception, another exception occurred:\n\n', 'Traceback (most recent call last):\n', '  File "C:/Users/balaji.a.arunachalam/PycharmProjects/Back_end(Python,SQL)/src/main/insertion.py", line 42, in record_insertion\n    with open(file_path, \'r\') as read_file:\n', "FileNotFoundError: [Errno 2] No such file or directory: 'C:/Users/balaji.a.arunachalam/PycharmProjects/Back_end(Python,SQL)/src\\\\files\\\\records\\\\2_customer_details.sql'\n"]
2020-10-06 11:24:46,669 - 7304 DEBUG - ['Traceback (most recent call last):\n', '  File "C:/Users/balaji.a.arunachalam/PycharmProjects/Back_end(Python,SQL)/src/main/insertion.py", line 17, in __init__\n    temp = sys.argv[1]\n', 'IndexError: list index out of range\n', '\nDuring handling of the above exception, another exception occurred:\n\n', 'Traceback (most recent call last):\n', '  File "C:/Users/balaji.a.arunachalam/PycharmProjects/Back_end(Python,SQL)/src/main/insertion.py", line 42, in record_insertion\n    with open(file_path, \'r\') as read_file:\n', "FileNotFoundError: [Errno 2] No such file or directory: 'C:/Users/balaji.a.arunachalam/PycharmProjects/Back_end(Python,SQL)/src\\\\files\\\\records\\\\2_customer_details.sql'\n"]
2020-10-06 11:24:46,669 - 7304 DEBUG - ['Traceback (most recent call last):\n', '  File "C:/Users/balaji.a.arunachalam/PycharmProjects/Back_end(Python,SQL)/src/main/insertion.py", line 17, in __init__\n    temp = sys.argv[1]\n', 'IndexError: list index out of range\n', '\nDuring handling of the above exception, another exception occurred:\n\n', 'Traceback (most recent call last):\n', '  File "C:/Users/balaji.a.arunachalam/PycharmProjects/Back_end(Python,SQL)/src/main/insertion.py", line 42, in record_insertion\n    with open(file_path, \'r\') as read_file:\n', "FileNotFoundError: [Errno 2] No such file or directory: 'C:/Users/balaji.a.arunachalam/PycharmProjects/Back_end(Python,SQL)/src\\\\files\\\\records\\\\2_customer_details.sql'\n"]
2020-10-06 11:24:46,669 - 7304 DEBUG - ['Traceback (most recent call last):\n', '  File "C:/Users/balaji.a.arunachalam/PycharmProjects/Back_end(Python,SQL)/src/main/insertion.py", line 17, in __init__\n    temp = sys.argv[1]\n', 'IndexError: list index out of range\n', '\nDuring handling of the above exception, another exception occurred:\n\n', 'Traceback (most recent call last):\n', '  File "C:/Users/balaji.a.arunachalam/PycharmProjects/Back_end(Python,SQL)/src/main/insertion.py", line 42, in record_insertion\n    with open(file_path, \'r\') as read_file:\n', "FileNotFoundError: [Errno 2] No such file or directory: 'C:/Users/balaji.a.arunachalam/PycharmProjects/Back_end(Python,SQL)/src\\\\files\\\\records\\\\3_order_status_details.sql'\n"]
2020-10-06 11:24:46,669 - 7304 DEBUG - ['Traceback (most recent call last):\n', '  File "C:/Users/balaji.a.arunachalam/PycharmProjects/Back_end(Python,SQL)/src/main/insertion.py", line 17, in __init__\n    temp = sys.argv[1]\n', 'IndexError: list index out of range\n', '\nDuring handling of the above exception, another exception occurred:\n\n', 'Traceback (most recent call last):\n', '  File "C:/Users/balaji.a.arunachalam/PycharmProjects/Back_end(Python,SQL)/src/main/insertion.py", line 42, in record_insertion\n    with open(file_path, \'r\') as read_file:\n', "FileNotFoundError: [Errno 2] No such file or directory: 'C:/Users/balaji.a.arunachalam/PycharmProjects/Back_end(Python,SQL)/src\\\\files\\\\records\\\\3_order_status_details.sql'\n"]
2020-10-06 11:24:46,669 - 7304 DEBUG - ['Traceback (most recent call last):\n', '  File "C:/Users/balaji.a.arunachalam/PycharmProjects/Back_end(Python,SQL)/src/main/insertion.py", line 17, in __init__\n    temp = sys.argv[1]\n', 'IndexError: list index out of range\n', '\nDuring handling of the above exception, another exception occurred:\n\n', 'Traceback (most recent call last):\n', '  File "C:/Users/balaji.a.arunachalam/PycharmProjects/Back_end(Python,SQL)/src/main/insertion.py", line 42, in record_insertion\n    with open(file_path, \'r\') as read_file:\n', "FileNotFoundError: [Errno 2] No such file or directory: 'C:/Users/balaji.a.arunachalam/PycharmProjects/Back_end(Python,SQL)/src\\\\files\\\\records\\\\3_order_status_details.sql'\n"]
2020-10-06 11:24:46,670 - 7304 DEBUG - ['Traceback (most recent call last):\n', '  File "C:/Users/balaji.a.arunachalam/PycharmProjects/Back_end(Python,SQL)/src/main/insertion.py", line 17, in __init__\n    temp = sys.argv[1]\n', 'IndexError: list index out of range\n', '\nDuring handling of the above exception, another exception occurred:\n\n', 'Traceback (most recent call last):\n', '  File "C:/Users/balaji.a.arunachalam/PycharmProjects/Back_end(Python,SQL)/src/main/insertion.py", line 42, in record_insertion\n    with open(file_path, \'r\') as read_file:\n', "FileNotFoundError: [Errno 2] No such file or directory: 'C:/Users/balaji.a.arunachalam/PycharmProjects/Back_end(Python,SQL)/src\\\\files\\\\records\\\\4_seller_details.sql'\n"]
2020-10-06 11:24:46,670 - 7304 DEBUG - ['Traceback (most recent call last):\n', '  File "C:/Users/balaji.a.arunachalam/PycharmProjects/Back_end(Python,SQL)/src/main/insertion.py", line 17, in __init__\n    temp = sys.argv[1]\n', 'IndexError: list index out of range\n', '\nDuring handling of the above exception, another exception occurred:\n\n', 'Traceback (most recent call last):\n', '  File "C:/Users/balaji.a.arunachalam/PycharmProjects/Back_end(Python,SQL)/src/main/insertion.py", line 42, in record_insertion\n    with open(file_path, \'r\') as read_file:\n', "FileNotFoundError: [Errno 2] No such file or directory: 'C:/Users/balaji.a.arunachalam/PycharmProjects/Back_end(Python,SQL)/src\\\\files\\\\records\\\\4_seller_details.sql'\n"]
2020-10-06 11:24:46,670 - 7304 DEBUG - ['Traceback (most recent call last):\n', '  File "C:/Users/balaji.a.arunachalam/PycharmProjects/Back_end(Python,SQL)/src/main/insertion.py", line 17, in __init__\n    temp = sys.argv[1]\n', 'IndexError: list index out of range\n', '\nDuring handling of the above exception, another exception occurred:\n\n', 'Traceback (most recent call last):\n', '  File "C:/Users/balaji.a.arunachalam/PycharmProjects/Back_end(Python,SQL)/src/main/insertion.py", line 42, in record_insertion\n    with open(file_path, \'r\') as read_file:\n', "FileNotFoundError: [Errno 2] No such file or directory: 'C:/Users/balaji.a.arunachalam/PycharmProjects/Back_end(Python,SQL)/src\\\\files\\\\records\\\\4_seller_details.sql'\n"]
2020-10-06 11:24:46,671 - 7304 DEBUG - ['Traceback (most recent call last):\n', '  File "C:/Users/balaji.a.arunachalam/PycharmProjects/Back_end(Python,SQL)/src/main/insertion.py", line 17, in __init__\n    temp = sys.argv[1]\n', 'IndexError: list index out of range\n', '\nDuring handling of the above exception, another exception occurred:\n\n', 'Traceback (most recent call last):\n', '  File "C:/Users/balaji.a.arunachalam/PycharmProjects/Back_end(Python,SQL)/src/main/insertion.py", line 42, in record_insertion\n    with open(file_path, \'r\') as read_file:\n', "FileNotFoundError: [Errno 2] No such file or directory: 'C:/Users/balaji.a.arunachalam/PycharmProjects/Back_end(Python,SQL)/src\\\\files\\\\records\\\\5_cart_details.sql'\n"]
2020-10-06 11:24:46,671 - 7304 DEBUG - ['Traceback (most recent call last):\n', '  File "C:/Users/balaji.a.arunachalam/PycharmProjects/Back_end(Python,SQL)/src/main/insertion.py", line 17, in __init__\n    temp = sys.argv[1]\n', 'IndexError: list index out of range\n', '\nDuring handling of the above exception, another exception occurred:\n\n', 'Traceback (most recent call last):\n', '  File "C:/Users/balaji.a.arunachalam/PycharmProjects/Back_end(Python,SQL)/src/main/insertion.py", line 42, in record_insertion\n    with open(file_path, \'r\') as read_file:\n', "FileNotFoundError: [Errno 2] No such file or directory: 'C:/Users/balaji.a.arunachalam/PycharmProjects/Back_end(Python,SQL)/src\\\\files\\\\records\\\\5_cart_details.sql'\n"]
2020-10-06 11:24:46,671 - 7304 DEBUG - ['Traceback (most recent call last):\n', '  File "C:/Users/balaji.a.arunachalam/PycharmProjects/Back_end(Python,SQL)/src/main/insertion.py", line 17, in __init__\n    temp = sys.argv[1]\n', 'IndexError: list index out of range\n', '\nDuring handling of the above exception, another exception occurred:\n\n', 'Traceback (most recent call last):\n', '  File "C:/Users/balaji.a.arunachalam/PycharmProjects/Back_end(Python,SQL)/src/main/insertion.py", line 42, in record_insertion\n    with open(file_path, \'r\') as read_file:\n', "FileNotFoundError: [Errno 2] No such file or directory: 'C:/Users/balaji.a.arunachalam/PycharmProjects/Back_end(Python,SQL)/src\\\\files\\\\records\\\\5_cart_details.sql'\n"]
2020-10-06 11:24:46,672 - 7304 DEBUG - ['Traceback (most recent call last):\n', '  File "C:/Users/balaji.a.arunachalam/PycharmProjects/Back_end(Python,SQL)/src/main/insertion.py", line 17, in __init__\n    temp = sys.argv[1]\n', 'IndexError: list index out of range\n', '\nDuring handling of the above exception, another exception occurred:\n\n', 'Traceback (most recent call last):\n', '  File "C:/Users/balaji.a.arunachalam/PycharmProjects/Back_end(Python,SQL)/src/main/insertion.py", line 42, in record_insertion\n    with open(file_path, \'r\') as read_file:\n', "FileNotFoundError: [Errno 2] No such file or directory: 'C:/Users/balaji.a.arunachalam/PycharmProjects/Back_end(Python,SQL)/src\\\\files\\\\records\\\\6_customer_address_details.sql'\n"]
2020-10-06 11:24:46,672 - 7304 DEBUG - ['Traceback (most recent call last):\n', '  File "C:/Users/balaji.a.arunachalam/PycharmProjects/Back_end(Python,SQL)/src/main/insertion.py", line 17, in __init__\n    temp = sys.argv[1]\n', 'IndexError: list index out of range\n', '\nDuring handling of the above exception, another exception occurred:\n\n', 'Traceback (most recent call last):\n', '  File "C:/Users/balaji.a.arunachalam/PycharmProjects/Back_end(Python,SQL)/src/main/insertion.py", line 42, in record_insertion\n    with open(file_path, \'r\') as read_file:\n', "FileNotFoundError: [Errno 2] No such file or directory: 'C:/Users/balaji.a.arunachalam/PycharmProjects/Back_end(Python,SQL)/src\\\\files\\\\records\\\\6_customer_address_details.sql'\n"]
2020-10-06 11:24:46,672 - 7304 DEBUG - ['Traceback (most recent call last):\n', '  File "C:/Users/balaji.a.arunachalam/PycharmProjects/Back_end(Python,SQL)/src/main/insertion.py", line 17, in __init__\n    temp = sys.argv[1]\n', 'IndexError: list index out of range\n', '\nDuring handling of the above exception, another exception occurred:\n\n', 'Traceback (most recent call last):\n', '  File "C:/Users/balaji.a.arunachalam/PycharmProjects/Back_end(Python,SQL)/src/main/insertion.py", line 42, in record_insertion\n    with open(file_path, \'r\') as read_file:\n', "FileNotFoundError: [Errno 2] No such file or directory: 'C:/Users/balaji.a.arunachalam/PycharmProjects/Back_end(Python,SQL)/src\\\\files\\\\records\\\\6_customer_address_details.sql'\n"]
2020-10-06 11:24:46,672 - 7304 DEBUG - ['Traceback (most recent call last):\n', '  File "C:/Users/balaji.a.arunachalam/PycharmProjects/Back_end(Python,SQL)/src/main/insertion.py", line 17, in __init__\n    temp = sys.argv[1]\n', 'IndexError: list index out of range\n', '\nDuring handling of the above exception, another exception occurred:\n\n', 'Traceback (most recent call last):\n', '  File "C:/Users/balaji.a.arunachalam/PycharmProjects/Back_end(Python,SQL)/src/main/insertion.py", line 42, in record_insertion\n    with open(file_path, \'r\') as read_file:\n', "FileNotFoundError: [Errno 2] No such file or directory: 'C:/Users/balaji.a.arunachalam/PycharmProjects/Back_end(Python,SQL)/src\\\\files\\\\records\\\\7_order_details.sql'\n"]
2020-10-06 11:24:46,672 - 7304 DEBUG - ['Traceback (most recent call last):\n', '  File "C:/Users/balaji.a.arunachalam/PycharmProjects/Back_end(Python,SQL)/src/main/insertion.py", line 17, in __init__\n    temp = sys.argv[1]\n', 'IndexError: list index out of range\n', '\nDuring handling of the above exception, another exception occurred:\n\n', 'Traceback (most recent call last):\n', '  File "C:/Users/balaji.a.arunachalam/PycharmProjects/Back_end(Python,SQL)/src/main/insertion.py", line 42, in record_insertion\n    with open(file_path, \'r\') as read_file:\n', "FileNotFoundError: [Errno 2] No such file or directory: 'C:/Users/balaji.a.arunachalam/PycharmProjects/Back_end(Python,SQL)/src\\\\files\\\\records\\\\7_order_details.sql'\n"]
2020-10-06 11:24:46,672 - 7304 DEBUG - ['Traceback (most recent call last):\n', '  File "C:/Users/balaji.a.arunachalam/PycharmProjects/Back_end(Python,SQL)/src/main/insertion.py", line 17, in __init__\n    temp = sys.argv[1]\n', 'IndexError: list index out of range\n', '\nDuring handling of the above exception, another exception occurred:\n\n', 'Traceback (most recent call last):\n', '  File "C:/Users/balaji.a.arunachalam/PycharmProjects/Back_end(Python,SQL)/src/main/insertion.py", line 42, in record_insertion\n    with open(file_path, \'r\') as read_file:\n', "FileNotFoundError: [Errno 2] No such file or directory: 'C:/Users/balaji.a.arunachalam/PycharmProjects/Back_end(Python,SQL)/src\\\\files\\\\records\\\\7_order_details.sql'\n"]
2020-10-06 11:24:46,673 - 7304 DEBUG - ['Traceback (most recent call last):\n', '  File "C:/Users/balaji.a.arunachalam/PycharmProjects/Back_end(Python,SQL)/src/main/insertion.py", line 17, in __init__\n    temp = sys.argv[1]\n', 'IndexError: list index out of range\n', '\nDuring handling of the above exception, another exception occurred:\n\n', 'Traceback (most recent call last):\n', '  File "C:/Users/balaji.a.arunachalam/PycharmProjects/Back_end(Python,SQL)/src/main/insertion.py", line 42, in record_insertion\n    with open(file_path, \'r\') as read_file:\n', "FileNotFoundError: [Errno 2] No such file or directory: 'C:/Users/balaji.a.arunachalam/PycharmProjects/Back_end(Python,SQL)/src\\\\files\\\\records\\\\8_product_stock_details.sql'\n"]
2020-10-06 11:24:46,673 - 7304 DEBUG - ['Traceback (most recent call last):\n', '  File "C:/Users/balaji.a.arunachalam/PycharmProjects/Back_end(Python,SQL)/src/main/insertion.py", line 17, in __init__\n    temp = sys.argv[1]\n', 'IndexError: list index out of range\n', '\nDuring handling of the above exception, another exception occurred:\n\n', 'Traceback (most recent call last):\n', '  File "C:/Users/balaji.a.arunachalam/PycharmProjects/Back_end(Python,SQL)/src/main/insertion.py", line 42, in record_insertion\n    with open(file_path, \'r\') as read_file:\n', "FileNotFoundError: [Errno 2] No such file or directory: 'C:/Users/balaji.a.arunachalam/PycharmProjects/Back_end(Python,SQL)/src\\\\files\\\\records\\\\8_product_stock_details.sql'\n"]
2020-10-06 11:24:46,673 - 7304 DEBUG - ['Traceback (most recent call last):\n', '  File "C:/Users/balaji.a.arunachalam/PycharmProjects/Back_end(Python,SQL)/src/main/insertion.py", line 17, in __init__\n    temp = sys.argv[1]\n', 'IndexError: list index out of range\n', '\nDuring handling of the above exception, another exception occurred:\n\n', 'Traceback (most recent call last):\n', '  File "C:/Users/balaji.a.arunachalam/PycharmProjects/Back_end(Python,SQL)/src/main/insertion.py", line 42, in record_insertion\n    with open(file_path, \'r\') as read_file:\n', "FileNotFoundError: [Errno 2] No such file or directory: 'C:/Users/balaji.a.arunachalam/PycharmProjects/Back_end(Python,SQL)/src\\\\files\\\\records\\\\8_product_stock_details.sql'\n"]
2020-10-06 11:24:46,674 - 7304 DEBUG - ['Traceback (most recent call last):\n', '  File "C:/Users/balaji.a.arunachalam/PycharmProjects/Back_end(Python,SQL)/src/main/insertion.py", line 17, in __init__\n    temp = sys.argv[1]\n', 'IndexError: list index out of range\n', '\nDuring handling of the above exception, another exception occurred:\n\n', 'Traceback (most recent call last):\n', '  File "C:/Users/balaji.a.arunachalam/PycharmProjects/Back_end(Python,SQL)/src/main/insertion.py", line 42, in record_insertion\n    with open(file_path, \'r\') as read_file:\n', "FileNotFoundError: [Errno 2] No such file or directory: 'C:/Users/balaji.a.arunachalam/PycharmProjects/Back_end(Python,SQL)/src\\\\files\\\\records\\\\9.sql'\n"]
2020-10-06 11:24:46,674 - 7304 DEBUG - ['Traceback (most recent call last):\n', '  File "C:/Users/balaji.a.arunachalam/PycharmProjects/Back_end(Python,SQL)/src/main/insertion.py", line 17, in __init__\n    temp = sys.argv[1]\n', 'IndexError: list index out of range\n', '\nDuring handling of the above exception, another exception occurred:\n\n', 'Traceback (most recent call last):\n', '  File "C:/Users/balaji.a.arunachalam/PycharmProjects/Back_end(Python,SQL)/src/main/insertion.py", line 42, in record_insertion\n    with open(file_path, \'r\') as read_file:\n', "FileNotFoundError: [Errno 2] No such file or directory: 'C:/Users/balaji.a.arunachalam/PycharmProjects/Back_end(Python,SQL)/src\\\\files\\\\records\\\\9.sql'\n"]
2020-10-06 11:24:46,674 - 7304 DEBUG - ['Traceback (most recent call last):\n', '  File "C:/Users/balaji.a.arunachalam/PycharmProjects/Back_end(Python,SQL)/src/main/insertion.py", line 17, in __init__\n    temp = sys.argv[1]\n', 'IndexError: list index out of range\n', '\nDuring handling of the above exception, another exception occurred:\n\n', 'Traceback (most recent call last):\n', '  File "C:/Users/balaji.a.arunachalam/PycharmProjects/Back_end(Python,SQL)/src/main/insertion.py", line 42, in record_insertion\n    with open(file_path, \'r\') as read_file:\n', "FileNotFoundError: [Errno 2] No such file or directory: 'C:/Users/balaji.a.arunachalam/PycharmProjects/Back_end(Python,SQL)/src\\\\files\\\\records\\\\9.sql'\n"]
2020-10-06 11:24:46,675 - 7304 DEBUG - ['Traceback (most recent call last):\n', '  File "C:/Users/balaji.a.arunachalam/PycharmProjects/Back_end(Python,SQL)/src/main/insertion.py", line 17, in __init__\n    temp = sys.argv[1]\n', 'IndexError: list index out of range\n', '\nDuring handling of the above exception, another exception occurred:\n\n', 'Traceback (most recent call last):\n', '  File "C:/Users/balaji.a.arunachalam/PycharmProjects/Back_end(Python,SQL)/src/main/insertion.py", line 42, in record_insertion\n    with open(file_path, \'r\') as read_file:\n', "FileNotFoundError: [Errno 2] No such file or directory: 'C:/Users/balaji.a.arunachalam/PycharmProjects/Back_end(Python,SQL)/src\\\\files\\\\records\\\\9.sql'\n"]
2020-10-06 11:24:46,675 - 7304 DEBUG - ['Traceback (most recent call last):\n', '  File "C:/Users/balaji.a.arunachalam/PycharmProjects/Back_end(Python,SQL)/src/main/insertion.py", line 17, in __init__\n    temp = sys.argv[1]\n', 'IndexError: list index out of range\n', '\nDuring handling of the above exception, another exception occurred:\n\n', 'Traceback (most recent call last):\n', '  File "C:/Users/balaji.a.arunachalam/PycharmProjects/Back_end(Python,SQL)/src/main/insertion.py", line 42, in record_insertion\n    with open(file_path, \'r\') as read_file:\n', "FileNotFoundError: [Errno 2] No such file or directory: 'C:/Users/balaji.a.arunachalam/PycharmProjects/Back_end(Python,SQL)/src\\\\files\\\\records\\\\9.sql'\n"]
2020-10-06 11:24:46,675 - 7304 DEBUG - ['Traceback (most recent call last):\n', '  File "C:/Users/balaji.a.arunachalam/PycharmProjects/Back_end(Python,SQL)/src/main/insertion.py", line 17, in __init__\n    temp = sys.argv[1]\n', 'IndexError: list index out of range\n', '\nDuring handling of the above exception, another exception occurred:\n\n', 'Traceback (most recent call last):\n', '  File "C:/Users/balaji.a.arunachalam/PycharmProjects/Back_end(Python,SQL)/src/main/insertion.py", line 42, in record_insertion\n    with open(file_path, \'r\') as read_file:\n', "FileNotFoundError: [Errno 2] No such file or directory: 'C:/Users/balaji.a.arunachalam/PycharmProjects/Back_end(Python,SQL)/src\\\\files\\\\records\\\\9.sql'\n"]
2020-10-06 11:24:46,676 - 7304 DEBUG - ['Traceback (most recent call last):\n', '  File "C:/Users/balaji.a.arunachalam/PycharmProjects/Back_end(Python,SQL)/src/main/insertion.py", line 17, in __init__\n    temp = sys.argv[1]\n', 'IndexError: list index out of range\n', '\nDuring handling of the above exception, another exception occurred:\n\n', 'Traceback (most recent call last):\n', '  File "C:/Users/balaji.a.arunachalam/PycharmProjects/Back_end(Python,SQL)/src/main/insertion.py", line 42, in record_insertion\n    with open(file_path, \'r\') as read_file:\n', "FileNotFoundError: [Errno 2] No such file or directory: 'C:/Users/balaji.a.arunachalam/PycharmProjects/Back_end(Python,SQL)/src\\\\files\\\\records\\\\9.sql'\n"]
2020-10-06 11:24:46,676 - 7304 DEBUG - ['Traceback (most recent call last):\n', '  File "C:/Users/balaji.a.arunachalam/PycharmProjects/Back_end(Python,SQL)/src/main/insertion.py", line 17, in __init__\n    temp = sys.argv[1]\n', 'IndexError: list index out of range\n', '\nDuring handling of the above exception, another exception occurred:\n\n', 'Traceback (most recent call last):\n', '  File "C:/Users/balaji.a.arunachalam/PycharmProjects/Back_end(Python,SQL)/src/main/insertion.py", line 42, in record_insertion\n    with open(file_path, \'r\') as read_file:\n', "FileNotFoundError: [Errno 2] No such file or directory: 'C:/Users/balaji.a.arunachalam/PycharmProjects/Back_end(Python,SQL)/src\\\\files\\\\records\\\\9.sql'\n"]
2020-10-06 11:24:46,676 - 7304 DEBUG - ['Traceback (most recent call last):\n', '  File "C:/Users/balaji.a.arunachalam/PycharmProjects/Back_end(Python,SQL)/src/main/insertion.py", line 17, in __init__\n    temp = sys.argv[1]\n', 'IndexError: list index out of range\n', '\nDuring handling of the above exception, another exception occurred:\n\n', 'Traceback (most recent call last):\n', '  File "C:/Users/balaji.a.arunachalam/PycharmProjects/Back_end(Python,SQL)/src/main/insertion.py", line 42, in record_insertion\n    with open(file_path, \'r\') as read_file:\n', "FileNotFoundError: [Errno 2] No such file or directory: 'C:/Users/balaji.a.arunachalam/PycharmProjects/Back_end(Python,SQL)/src\\\\files\\\\records\\\\9.sql'\n"]
2020-10-06 11:24:46,676 - 7304 DEBUG - ['Traceback (most recent call last):\n', '  File "C:/Users/balaji.a.arunachalam/PycharmProjects/Back_end(Python,SQL)/src/main/insertion.py", line 17, in __init__\n    temp = sys.argv[1]\n', 'IndexError: list index out of range\n', '\nDuring handling of the above exception, another exception occurred:\n\n', 'Traceback (most recent call last):\n', '  File "C:/Users/balaji.a.arunachalam/PycharmProjects/Back_end(Python,SQL)/src/main/insertion.py", line 42, in record_insertion\n    with open(file_path, \'r\') as read_file:\n', "FileNotFoundError: [Errno 2] No such file or directory: 'C:/Users/balaji.a.arunachalam/PycharmProjects/Back_end(Python,SQL)/src\\\\files\\\\records\\\\9.sql'\n"]
2020-10-06 11:24:46,676 - 7304 DEBUG - ['Traceback (most recent call last):\n', '  File "C:/Users/balaji.a.arunachalam/PycharmProjects/Back_end(Python,SQL)/src/main/insertion.py", line 17, in __init__\n    temp = sys.argv[1]\n', 'IndexError: list index out of range\n', '\nDuring handling of the above exception, another exception occurred:\n\n', 'Traceback (most recent call last):\n', '  File "C:/Users/balaji.a.arunachalam/PycharmProjects/Back_end(Python,SQL)/src/main/insertion.py", line 42, in record_insertion\n    with open(file_path, \'r\') as read_file:\n', "FileNotFoundError: [Errno 2] No such file or directory: 'C:/Users/balaji.a.arunachalam/PycharmProjects/Back_end(Python,SQL)/src\\\\files\\\\records\\\\9.sql'\n"]
2020-10-06 11:24:46,676 - 7304 DEBUG - ['Traceback (most recent call last):\n', '  File "C:/Users/balaji.a.arunachalam/PycharmProjects/Back_end(Python,SQL)/src/main/insertion.py", line 17, in __init__\n    temp = sys.argv[1]\n', 'IndexError: list index out of range\n', '\nDuring handling of the above exception, another exception occurred:\n\n', 'Traceback (most recent call last):\n', '  File "C:/Users/balaji.a.arunachalam/PycharmProjects/Back_end(Python,SQL)/src/main/insertion.py", line 42, in record_insertion\n    with open(file_path, \'r\') as read_file:\n', "FileNotFoundError: [Errno 2] No such file or directory: 'C:/Users/balaji.a.arunachalam/PycharmProjects/Back_end(Python,SQL)/src\\\\files\\\\records\\\\9.sql'\n"]
2020-10-06 11:24:46,677 - 7304 DEBUG - ['Traceback (most recent call last):\n', '  File "C:/Users/balaji.a.arunachalam/PycharmProjects/Back_end(Python,SQL)/src/main/insertion.py", line 17, in __init__\n    temp = sys.argv[1]\n', 'IndexError: list index out of range\n', '\nDuring handling of the above exception, another exception occurred:\n\n', 'Traceback (most recent call last):\n', '  File "C:/Users/balaji.a.arunachalam/PycharmProjects/Back_end(Python,SQL)/src/main/insertion.py", line 42, in record_insertion\n    with open(file_path, \'r\') as read_file:\n', "FileNotFoundError: [Errno 2] No such file or directory: 'C:/Users/balaji.a.arunachalam/PycharmProjects/Back_end(Python,SQL)/src\\\\files\\\\records\\\\9.sql'\n"]
2020-10-06 11:24:46,677 - 7304 DEBUG - ['Traceback (most recent call last):\n', '  File "C:/Users/balaji.a.arunachalam/PycharmProjects/Back_end(Python,SQL)/src/main/insertion.py", line 17, in __init__\n    temp = sys.argv[1]\n', 'IndexError: list index out of range\n', '\nDuring handling of the above exception, another exception occurred:\n\n', 'Traceback (most recent call last):\n', '  File "C:/Users/balaji.a.arunachalam/PycharmProjects/Back_end(Python,SQL)/src/main/insertion.py", line 42, in record_insertion\n    with open(file_path, \'r\') as read_file:\n', "FileNotFoundError: [Errno 2] No such file or directory: 'C:/Users/balaji.a.arunachalam/PycharmProjects/Back_end(Python,SQL)/src\\\\files\\\\records\\\\9.sql'\n"]
2020-10-06 11:24:46,677 - 7304 DEBUG - ['Traceback (most recent call last):\n', '  File "C:/Users/balaji.a.arunachalam/PycharmProjects/Back_end(Python,SQL)/src/main/insertion.py", line 17, in __init__\n    temp = sys.argv[1]\n', 'IndexError: list index out of range\n', '\nDuring handling of the above exception, another exception occurred:\n\n', 'Traceback (most recent call last):\n', '  File "C:/Users/balaji.a.arunachalam/PycharmProjects/Back_end(Python,SQL)/src/main/insertion.py", line 42, in record_insertion\n    with open(file_path, \'r\') as read_file:\n', "FileNotFoundError: [Errno 2] No such file or directory: 'C:/Users/balaji.a.arunachalam/PycharmProjects/Back_end(Python,SQL)/src\\\\files\\\\records\\\\9.sql'\n"]
2020-10-06 11:24:46,678 - 7304 DEBUG - ['Traceback (most recent call last):\n', '  File "C:/Users/balaji.a.arunachalam/PycharmProjects/Back_end(Python,SQL)/src/main/insertion.py", line 17, in __init__\n    temp = sys.argv[1]\n', 'IndexError: list index out of range\n', '\nDuring handling of the above exception, another exception occurred:\n\n', 'Traceback (most recent call last):\n', '  File "C:/Users/balaji.a.arunachalam/PycharmProjects/Back_end(Python,SQL)/src/main/insertion.py", line 42, in record_insertion\n    with open(file_path, \'r\') as read_file:\n', "FileNotFoundError: [Errno 2] No such file or directory: 'C:/Users/balaji.a.arunachalam/PycharmProjects/Back_end(Python,SQL)/src\\\\files\\\\records\\\\9.sql'\n"]
2020-10-06 11:24:46,678 - 7304 DEBUG - ['Traceback (most recent call last):\n', '  File "C:/Users/balaji.a.arunachalam/PycharmProjects/Back_end(Python,SQL)/src/main/insertion.py", line 17, in __init__\n    temp = sys.argv[1]\n', 'IndexError: list index out of range\n', '\nDuring handling of the above exception, another exception occurred:\n\n', 'Traceback (most recent call last):\n', '  File "C:/Users/balaji.a.arunachalam/PycharmProjects/Back_end(Python,SQL)/src/main/insertion.py", line 42, in record_insertion\n    with open(file_path, \'r\') as read_file:\n', "FileNotFoundError: [Errno 2] No such file or directory: 'C:/Users/balaji.a.arunachalam/PycharmProjects/Back_end(Python,SQL)/src\\\\files\\\\records\\\\9.sql'\n"]
2020-10-06 11:24:46,678 - 7304 DEBUG - ['Traceback (most recent call last):\n', '  File "C:/Users/balaji.a.arunachalam/PycharmProjects/Back_end(Python,SQL)/src/main/insertion.py", line 17, in __init__\n    temp = sys.argv[1]\n', 'IndexError: list index out of range\n', '\nDuring handling of the above exception, another exception occurred:\n\n', 'Traceback (most recent call last):\n', '  File "C:/Users/balaji.a.arunachalam/PycharmProjects/Back_end(Python,SQL)/src/main/insertion.py", line 42, in record_insertion\n    with open(file_path, \'r\') as read_file:\n', "FileNotFoundError: [Errno 2] No such file or directory: 'C:/Users/balaji.a.arunachalam/PycharmProjects/Back_end(Python,SQL)/src\\\\files\\\\records\\\\9.sql'\n"]
2020-10-06 11:24:46,679 - 7304 DEBUG - ['Traceback (most recent call last):\n', '  File "C:/Users/balaji.a.arunachalam/PycharmProjects/Back_end(Python,SQL)/src/main/insertion.py", line 17, in __init__\n    temp = sys.argv[1]\n', 'IndexError: list index out of range\n', '\nDuring handling of the above exception, another exception occurred:\n\n', 'Traceback (most recent call last):\n', '  File "C:/Users/balaji.a.arunachalam/PycharmProjects/Back_end(Python,SQL)/src/main/insertion.py", line 42, in record_insertion\n    with open(file_path, \'r\') as read_file:\n', "FileNotFoundError: [Errno 2] No such file or directory: 'C:/Users/balaji.a.arunachalam/PycharmProjects/Back_end(Python,SQL)/src\\\\files\\\\records\\\\9.sql'\n"]
2020-10-06 11:24:46,679 - 7304 DEBUG - ['Traceback (most recent call last):\n', '  File "C:/Users/balaji.a.arunachalam/PycharmProjects/Back_end(Python,SQL)/src/main/insertion.py", line 17, in __init__\n    temp = sys.argv[1]\n', 'IndexError: list index out of range\n', '\nDuring handling of the above exception, another exception occurred:\n\n', 'Traceback (most recent call last):\n', '  File "C:/Users/balaji.a.arunachalam/PycharmProjects/Back_end(Python,SQL)/src/main/insertion.py", line 42, in record_insertion\n    with open(file_path, \'r\') as read_file:\n', "FileNotFoundError: [Errno 2] No such file or directory: 'C:/Users/balaji.a.arunachalam/PycharmProjects/Back_end(Python,SQL)/src\\\\files\\\\records\\\\9.sql'\n"]
2020-10-06 11:24:46,679 - 7304 DEBUG - ['Traceback (most recent call last):\n', '  File "C:/Users/balaji.a.arunachalam/PycharmProjects/Back_end(Python,SQL)/src/main/insertion.py", line 17, in __init__\n    temp = sys.argv[1]\n', 'IndexError: list index out of range\n', '\nDuring handling of the above exception, another exception occurred:\n\n', 'Traceback (most recent call last):\n', '  File "C:/Users/balaji.a.arunachalam/PycharmProjects/Back_end(Python,SQL)/src/main/insertion.py", line 42, in record_insertion\n    with open(file_path, \'r\') as read_file:\n', "FileNotFoundError: [Errno 2] No such file or directory: 'C:/Users/balaji.a.arunachalam/PycharmProjects/Back_end(Python,SQL)/src\\\\files\\\\records\\\\9.sql'\n"]
2020-10-06 11:24:46,680 - 7304 DEBUG - ['Traceback (most recent call last):\n', '  File "C:/Users/balaji.a.arunachalam/PycharmProjects/Back_end(Python,SQL)/src/main/insertion.py", line 17, in __init__\n    temp = sys.argv[1]\n', 'IndexError: list index out of range\n', '\nDuring handling of the above exception, another exception occurred:\n\n', 'Traceback (most recent call last):\n', '  File "C:/Users/balaji.a.arunachalam/PycharmProjects/Back_end(Python,SQL)/src/main/insertion.py", line 42, in record_insertion\n    with open(file_path, \'r\') as read_file:\n', "FileNotFoundError: [Errno 2] No such file or directory: 'C:/Users/balaji.a.arunachalam/PycharmProjects/Back_end(Python,SQL)/src\\\\files\\\\records\\\\9.sql'\n"]
2020-10-06 11:24:46,680 - 7304 DEBUG - ['Traceback (most recent call last):\n', '  File "C:/Users/balaji.a.arunachalam/PycharmProjects/Back_end(Python,SQL)/src/main/insertion.py", line 17, in __init__\n    temp = sys.argv[1]\n', 'IndexError: list index out of range\n', '\nDuring handling of the above exception, another exception occurred:\n\n', 'Traceback (most recent call last):\n', '  File "C:/Users/balaji.a.arunachalam/PycharmProjects/Back_end(Python,SQL)/src/main/insertion.py", line 42, in record_insertion\n    with open(file_path, \'r\') as read_file:\n', "FileNotFoundError: [Errno 2] No such file or directory: 'C:/Users/balaji.a.arunachalam/PycharmProjects/Back_end(Python,SQL)/src\\\\files\\\\records\\\\9.sql'\n"]
2020-10-06 11:24:46,680 - 7304 DEBUG - ['Traceback (most recent call last):\n', '  File "C:/Users/balaji.a.arunachalam/PycharmProjects/Back_end(Python,SQL)/src/main/insertion.py", line 17, in __init__\n    temp = sys.argv[1]\n', 'IndexError: list index out of range\n', '\nDuring handling of the above exception, another exception occurred:\n\n', 'Traceback (most recent call last):\n', '  File "C:/Users/balaji.a.arunachalam/PycharmProjects/Back_end(Python,SQL)/src/main/insertion.py", line 42, in record_insertion\n    with open(file_path, \'r\') as read_file:\n', "FileNotFoundError: [Errno 2] No such file or directory: 'C:/Users/balaji.a.arunachalam/PycharmProjects/Back_end(Python,SQL)/src\\\\files\\\\records\\\\9.sql'\n"]
2020-10-06 11:24:46,680 - 7304 DEBUG - ['Traceback (most recent call last):\n', '  File "C:/Users/balaji.a.arunachalam/PycharmProjects/Back_end(Python,SQL)/src/main/insertion.py", line 17, in __init__\n    temp = sys.argv[1]\n', 'IndexError: list index out of range\n', '\nDuring handling of the above exception, another exception occurred:\n\n', 'Traceback (most recent call last):\n', '  File "C:/Users/balaji.a.arunachalam/PycharmProjects/Back_end(Python,SQL)/src/main/insertion.py", line 42, in record_insertion\n    with open(file_path, \'r\') as read_file:\n', "FileNotFoundError: [Errno 2] No such file or directory: 'C:/Users/balaji.a.arunachalam/PycharmProjects/Back_end(Python,SQL)/src\\\\files\\\\records\\\\sample.sql'\n"]
2020-10-06 11:24:46,680 - 7304 DEBUG - ['Traceback (most recent call last):\n', '  File "C:/Users/balaji.a.arunachalam/PycharmProjects/Back_end(Python,SQL)/src/main/insertion.py", line 17, in __init__\n    temp = sys.argv[1]\n', 'IndexError: list index out of range\n', '\nDuring handling of the above exception, another exception occurred:\n\n', 'Traceback (most recent call last):\n', '  File "C:/Users/balaji.a.arunachalam/PycharmProjects/Back_end(Python,SQL)/src/main/insertion.py", line 42, in record_insertion\n    with open(file_path, \'r\') as read_file:\n', "FileNotFoundError: [Errno 2] No such file or directory: 'C:/Users/balaji.a.arunachalam/PycharmProjects/Back_end(Python,SQL)/src\\\\files\\\\records\\\\sample.sql'\n"]
2020-10-06 11:24:46,680 - 7304 DEBUG - ['Traceback (most recent call last):\n', '  File "C:/Users/balaji.a.arunachalam/PycharmProjects/Back_end(Python,SQL)/src/main/insertion.py", line 17, in __init__\n    temp = sys.argv[1]\n', 'IndexError: list index out of range\n', '\nDuring handling of the above exception, another exception occurred:\n\n', 'Traceback (most recent call last):\n', '  File "C:/Users/balaji.a.arunachalam/PycharmProjects/Back_end(Python,SQL)/src/main/insertion.py", line 42, in record_insertion\n    with open(file_path, \'r\') as read_file:\n', "FileNotFoundError: [Errno 2] No such file or directory: 'C:/Users/balaji.a.arunachalam/PycharmProjects/Back_end(Python,SQL)/src\\\\files\\\\records\\\\sample.sql'\n"]
