2020-10-06 11:22:50,779 - 36772 DEBUG - ['Traceback (most recent call last):\n', '  File "C:/Users/balaji.a.arunachalam/PycharmProjects/Back_end(Python,SQL)/src/main/insertion.py", line 17, in __init__\n    temp = sys.argv[1]\n', 'IndexError: list index out of range\n', '\nDuring handling of the above exception, another exception occurred:\n\n', 'Traceback (most recent call last):\n', '  File "C:/Users/balaji.a.arunachalam/PycharmProjects/Back_end(Python,SQL)/src/main/insertion.py", line 42, in record_insertion\n    with open(file_path, \'r\') as read_file:\n', "FileNotFoundError: [Errno 2] No such file or directory: 'C:/Users/balaji.a.arunachalam/PycharmProjects/Back_end(Python,SQL)/src\\\\files\\\\records\\\\category_details.csv.sql'\n"]
2020-10-06 11:22:50,779 - 36772 DEBUG - ['Traceback (most recent call last):\n', '  File "C:/Users/balaji.a.arunachalam/PycharmProjects/Back_end(Python,SQL)/src/main/insertion.py", line 17, in __init__\n    temp = sys.argv[1]\n', 'IndexError: list index out of range\n', '\nDuring handling of the above exception, another exception occurred:\n\n', 'Traceback (most recent call last):\n', '  File "C:/Users/balaji.a.arunachalam/PycharmProjects/Back_end(Python,SQL)/src/main/insertion.py", line 42, in record_insertion\n    with open(file_path, \'r\') as read_file:\n', "FileNotFoundError: [Errno 2] No such file or directory: 'C:/Users/balaji.a.arunachalam/PycharmProjects/Back_end(Python,SQL)/src\\\\files\\\\records\\\\category_details.csv.sql'\n"]
2020-10-06 11:22:50,779 - 36772 DEBUG - ['Traceback (most recent call last):\n', '  File "C:/Users/balaji.a.arunachalam/PycharmProjects/Back_end(Python,SQL)/src/main/insertion.py", line 17, in __init__\n    temp = sys.argv[1]\n', 'IndexError: list index out of range\n', '\nDuring handling of the above exception, another exception occurred:\n\n', 'Traceback (most recent call last):\n', '  File "C:/Users/balaji.a.arunachalam/PycharmProjects/Back_end(Python,SQL)/src/main/insertion.py", line 42, in record_insertion\n    with open(file_path, \'r\') as read_file:\n', "FileNotFoundError: [Errno 2] No such file or directory: 'C:/Users/balaji.a.arunachalam/PycharmProjects/Back_end(Python,SQL)/src\\\\files\\\\records\\\\category_details.csv.sql'\n"]
2020-10-06 11:22:50,780 - 36772 DEBUG - ['Traceback (most recent call last):\n', '  File "C:/Users/balaji.a.arunachalam/PycharmProjects/Back_end(Python,SQL)/src/main/insertion.py", line 17, in __init__\n    temp = sys.argv[1]\n', 'IndexError: list index out of range\n', '\nDuring handling of the above exception, another exception occurred:\n\n', 'Traceback (most recent call last):\n', '  File "C:/Users/balaji.a.arunachalam/PycharmProjects/Back_end(Python,SQL)/src/main/insertion.py", line 42, in record_insertion\n    with open(file_path, \'r\') as read_file:\n', "FileNotFoundError: [Errno 2] No such file or directory: 'C:/Users/balaji.a.arunachalam/PycharmProjects/Back_end(Python,SQL)/src\\\\files\\\\records\\\\customer_details.csv.sql'\n"]
2020-10-06 11:22:50,780 - 36772 DEBUG - ['Traceback (most recent call last):\n', '  File "C:/Users/balaji.a.arunachalam/PycharmProjects/Back_end(Python,SQL)/src/main/insertion.py", line 17, in __init__\n    temp = sys.argv[1]\n', 'IndexError: list index out of range\n', '\nDuring handling of the above exception, another exception occurred:\n\n', 'Traceback (most recent call last):\n', '  File "C:/Users/balaji.a.arunachalam/PycharmProjects/Back_end(Python,SQL)/src/main/insertion.py", line 42, in record_insertion\n    with open(file_path, \'r\') as read_file:\n', "FileNotFoundError: [Errno 2] No such file or directory: 'C:/Users/balaji.a.arunachalam/PycharmProjects/Back_end(Python,SQL)/src\\\\files\\\\records\\\\customer_details.csv.sql'\n"]
2020-10-06 11:22:50,780 - 36772 DEBUG - ['Traceback (most recent call last):\n', '  File "C:/Users/balaji.a.arunachalam/PycharmProjects/Back_end(Python,SQL)/src/main/insertion.py", line 17, in __init__\n    temp = sys.argv[1]\n', 'IndexError: list index out of range\n', '\nDuring handling of the above exception, another exception occurred:\n\n', 'Traceback (most recent call last):\n', '  File "C:/Users/balaji.a.arunachalam/PycharmProjects/Back_end(Python,SQL)/src/main/insertion.py", line 42, in record_insertion\n    with open(file_path, \'r\') as read_file:\n', "FileNotFoundError: [Errno 2] No such file or directory: 'C:/Users/balaji.a.arunachalam/PycharmProjects/Back_end(Python,SQL)/src\\\\files\\\\records\\\\customer_details.csv.sql'\n"]
2020-10-06 11:22:50,781 - 36772 DEBUG - ['Traceback (most recent call last):\n', '  File "C:/Users/balaji.a.arunachalam/PycharmProjects/Back_end(Python,SQL)/src/main/insertion.py", line 17, in __init__\n    temp = sys.argv[1]\n', 'IndexError: list index out of range\n', '\nDuring handling of the above exception, another exception occurred:\n\n', 'Traceback (most recent call last):\n', '  File "C:/Users/balaji.a.arunachalam/PycharmProjects/Back_end(Python,SQL)/src/main/insertion.py", line 42, in record_insertion\n    with open(file_path, \'r\') as read_file:\n', "FileNotFoundError: [Errno 2] No such file or directory: 'C:/Users/balaji.a.arunachalam/PycharmProjects/Back_end(Python,SQL)/src\\\\files\\\\records\\\\order_status_details.csv.sql'\n"]
2020-10-06 11:22:50,781 - 36772 DEBUG - ['Traceback (most recent call last):\n', '  File "C:/Users/balaji.a.arunachalam/PycharmProjects/Back_end(Python,SQL)/src/main/insertion.py", line 17, in __init__\n    temp = sys.argv[1]\n', 'IndexError: list index out of range\n', '\nDuring handling of the above exception, another exception occurred:\n\n', 'Traceback (most recent call last):\n', '  File "C:/Users/balaji.a.arunachalam/PycharmProjects/Back_end(Python,SQL)/src/main/insertion.py", line 42, in record_insertion\n    with open(file_path, \'r\') as read_file:\n', "FileNotFoundError: [Errno 2] No such file or directory: 'C:/Users/balaji.a.arunachalam/PycharmProjects/Back_end(Python,SQL)/src\\\\files\\\\records\\\\order_status_details.csv.sql'\n"]
2020-10-06 11:22:50,781 - 36772 DEBUG - ['Traceback (most recent call last):\n', '  File "C:/Users/balaji.a.arunachalam/PycharmProjects/Back_end(Python,SQL)/src/main/insertion.py", line 17, in __init__\n    temp = sys.argv[1]\n', 'IndexError: list index out of range\n', '\nDuring handling of the above exception, another exception occurred:\n\n', 'Traceback (most recent call last):\n', '  File "C:/Users/balaji.a.arunachalam/PycharmProjects/Back_end(Python,SQL)/src/main/insertion.py", line 42, in record_insertion\n    with open(file_path, \'r\') as read_file:\n', "FileNotFoundError: [Errno 2] No such file or directory: 'C:/Users/balaji.a.arunachalam/PycharmProjects/Back_end(Python,SQL)/src\\\\files\\\\records\\\\order_status_details.csv.sql'\n"]
2020-10-06 11:22:50,782 - 36772 DEBUG - ['Traceback (most recent call last):\n', '  File "C:/Users/balaji.a.arunachalam/PycharmProjects/Back_end(Python,SQL)/src/main/insertion.py", line 17, in __init__\n    temp = sys.argv[1]\n', 'IndexError: list index out of range\n', '\nDuring handling of the above exception, another exception occurred:\n\n', 'Traceback (most recent call last):\n', '  File "C:/Users/balaji.a.arunachalam/PycharmProjects/Back_end(Python,SQL)/src/main/insertion.py", line 42, in record_insertion\n    with open(file_path, \'r\') as read_file:\n', "FileNotFoundError: [Errno 2] No such file or directory: 'C:/Users/balaji.a.arunachalam/PycharmProjects/Back_end(Python,SQL)/src\\\\files\\\\records\\\\seller_details.csv.sql'\n"]
2020-10-06 11:22:50,782 - 36772 DEBUG - ['Traceback (most recent call last):\n', '  File "C:/Users/balaji.a.arunachalam/PycharmProjects/Back_end(Python,SQL)/src/main/insertion.py", line 17, in __init__\n    temp = sys.argv[1]\n', 'IndexError: list index out of range\n', '\nDuring handling of the above exception, another exception occurred:\n\n', 'Traceback (most recent call last):\n', '  File "C:/Users/balaji.a.arunachalam/PycharmProjects/Back_end(Python,SQL)/src/main/insertion.py", line 42, in record_insertion\n    with open(file_path, \'r\') as read_file:\n', "FileNotFoundError: [Errno 2] No such file or directory: 'C:/Users/balaji.a.arunachalam/PycharmProjects/Back_end(Python,SQL)/src\\\\files\\\\records\\\\seller_details.csv.sql'\n"]
2020-10-06 11:22:50,782 - 36772 DEBUG - ['Traceback (most recent call last):\n', '  File "C:/Users/balaji.a.arunachalam/PycharmProjects/Back_end(Python,SQL)/src/main/insertion.py", line 17, in __init__\n    temp = sys.argv[1]\n', 'IndexError: list index out of range\n', '\nDuring handling of the above exception, another exception occurred:\n\n', 'Traceback (most recent call last):\n', '  File "C:/Users/balaji.a.arunachalam/PycharmProjects/Back_end(Python,SQL)/src/main/insertion.py", line 42, in record_insertion\n    with open(file_path, \'r\') as read_file:\n', "FileNotFoundError: [Errno 2] No such file or directory: 'C:/Users/balaji.a.arunachalam/PycharmProjects/Back_end(Python,SQL)/src\\\\files\\\\records\\\\seller_details.csv.sql'\n"]
2020-10-06 11:22:50,782 - 36772 DEBUG - ['Traceback (most recent call last):\n', '  File "C:/Users/balaji.a.arunachalam/PycharmProjects/Back_end(Python,SQL)/src/main/insertion.py", line 17, in __init__\n    temp = sys.argv[1]\n', 'IndexError: list index out of range\n', '\nDuring handling of the above exception, another exception occurred:\n\n', 'Traceback (most recent call last):\n', '  File "C:/Users/balaji.a.arunachalam/PycharmProjects/Back_end(Python,SQL)/src/main/insertion.py", line 42, in record_insertion\n    with open(file_path, \'r\') as read_file:\n', "FileNotFoundError: [Errno 2] No such file or directory: 'C:/Users/balaji.a.arunachalam/PycharmProjects/Back_end(Python,SQL)/src\\\\files\\\\records\\\\cart_details.csv.sql'\n"]
2020-10-06 11:22:50,782 - 36772 DEBUG - ['Traceback (most recent call last):\n', '  File "C:/Users/balaji.a.arunachalam/PycharmProjects/Back_end(Python,SQL)/src/main/insertion.py", line 17, in __init__\n    temp = sys.argv[1]\n', 'IndexError: list index out of range\n', '\nDuring handling of the above exception, another exception occurred:\n\n', 'Traceback (most recent call last):\n', '  File "C:/Users/balaji.a.arunachalam/PycharmProjects/Back_end(Python,SQL)/src/main/insertion.py", line 42, in record_insertion\n    with open(file_path, \'r\') as read_file:\n', "FileNotFoundError: [Errno 2] No such file or directory: 'C:/Users/balaji.a.arunachalam/PycharmProjects/Back_end(Python,SQL)/src\\\\files\\\\records\\\\cart_details.csv.sql'\n"]
2020-10-06 11:22:50,782 - 36772 DEBUG - ['Traceback (most recent call last):\n', '  File "C:/Users/balaji.a.arunachalam/PycharmProjects/Back_end(Python,SQL)/src/main/insertion.py", line 17, in __init__\n    temp = sys.argv[1]\n', 'IndexError: list index out of range\n', '\nDuring handling of the above exception, another exception occurred:\n\n', 'Traceback (most recent call last):\n', '  File "C:/Users/balaji.a.arunachalam/PycharmProjects/Back_end(Python,SQL)/src/main/insertion.py", line 42, in record_insertion\n    with open(file_path, \'r\') as read_file:\n', "FileNotFoundError: [Errno 2] No such file or directory: 'C:/Users/balaji.a.arunachalam/PycharmProjects/Back_end(Python,SQL)/src\\\\files\\\\records\\\\cart_details.csv.sql'\n"]
2020-10-06 11:22:50,783 - 36772 DEBUG - ['Traceback (most recent call last):\n', '  File "C:/Users/balaji.a.arunachalam/PycharmProjects/Back_end(Python,SQL)/src/main/insertion.py", line 17, in __init__\n    temp = sys.argv[1]\n', 'IndexError: list index out of range\n', '\nDuring handling of the above exception, another exception occurred:\n\n', 'Traceback (most recent call last):\n', '  File "C:/Users/balaji.a.arunachalam/PycharmProjects/Back_end(Python,SQL)/src/main/insertion.py", line 42, in record_insertion\n    with open(file_path, \'r\') as read_file:\n', "FileNotFoundError: [Errno 2] No such file or directory: 'C:/Users/balaji.a.arunachalam/PycharmProjects/Back_end(Python,SQL)/src\\\\files\\\\records\\\\customer_address_details.csv.sql'\n"]
2020-10-06 11:22:50,783 - 36772 DEBUG - ['Traceback (most recent call last):\n', '  File "C:/Users/balaji.a.arunachalam/PycharmProjects/Back_end(Python,SQL)/src/main/insertion.py", line 17, in __init__\n    temp = sys.argv[1]\n', 'IndexError: list index out of range\n', '\nDuring handling of the above exception, another exception occurred:\n\n', 'Traceback (most recent call last):\n', '  File "C:/Users/balaji.a.arunachalam/PycharmProjects/Back_end(Python,SQL)/src/main/insertion.py", line 42, in record_insertion\n    with open(file_path, \'r\') as read_file:\n', "FileNotFoundError: [Errno 2] No such file or directory: 'C:/Users/balaji.a.arunachalam/PycharmProjects/Back_end(Python,SQL)/src\\\\files\\\\records\\\\customer_address_details.csv.sql'\n"]
2020-10-06 11:22:50,783 - 36772 DEBUG - ['Traceback (most recent call last):\n', '  File "C:/Users/balaji.a.arunachalam/PycharmProjects/Back_end(Python,SQL)/src/main/insertion.py", line 17, in __init__\n    temp = sys.argv[1]\n', 'IndexError: list index out of range\n', '\nDuring handling of the above exception, another exception occurred:\n\n', 'Traceback (most recent call last):\n', '  File "C:/Users/balaji.a.arunachalam/PycharmProjects/Back_end(Python,SQL)/src/main/insertion.py", line 42, in record_insertion\n    with open(file_path, \'r\') as read_file:\n', "FileNotFoundError: [Errno 2] No such file or directory: 'C:/Users/balaji.a.arunachalam/PycharmProjects/Back_end(Python,SQL)/src\\\\files\\\\records\\\\customer_address_details.csv.sql'\n"]
2020-10-06 11:22:50,784 - 36772 DEBUG - ['Traceback (most recent call last):\n', '  File "C:/Users/balaji.a.arunachalam/PycharmProjects/Back_end(Python,SQL)/src/main/insertion.py", line 17, in __init__\n    temp = sys.argv[1]\n', 'IndexError: list index out of range\n', '\nDuring handling of the above exception, another exception occurred:\n\n', 'Traceback (most recent call last):\n', '  File "C:/Users/balaji.a.arunachalam/PycharmProjects/Back_end(Python,SQL)/src/main/insertion.py", line 42, in record_insertion\n    with open(file_path, \'r\') as read_file:\n', "FileNotFoundError: [Errno 2] No such file or directory: 'C:/Users/balaji.a.arunachalam/PycharmProjects/Back_end(Python,SQL)/src\\\\files\\\\records\\\\order_details.csv.sql'\n"]
2020-10-06 11:22:50,784 - 36772 DEBUG - ['Traceback (most recent call last):\n', '  File "C:/Users/balaji.a.arunachalam/PycharmProjects/Back_end(Python,SQL)/src/main/insertion.py", line 17, in __init__\n    temp = sys.argv[1]\n', 'IndexError: list index out of range\n', '\nDuring handling of the above exception, another exception occurred:\n\n', 'Traceback (most recent call last):\n', '  File "C:/Users/balaji.a.arunachalam/PycharmProjects/Back_end(Python,SQL)/src/main/insertion.py", line 42, in record_insertion\n    with open(file_path, \'r\') as read_file:\n', "FileNotFoundError: [Errno 2] No such file or directory: 'C:/Users/balaji.a.arunachalam/PycharmProjects/Back_end(Python,SQL)/src\\\\files\\\\records\\\\order_details.csv.sql'\n"]
2020-10-06 11:22:50,784 - 36772 DEBUG - ['Traceback (most recent call last):\n', '  File "C:/Users/balaji.a.arunachalam/PycharmProjects/Back_end(Python,SQL)/src/main/insertion.py", line 17, in __init__\n    temp = sys.argv[1]\n', 'IndexError: list index out of range\n', '\nDuring handling of the above exception, another exception occurred:\n\n', 'Traceback (most recent call last):\n', '  File "C:/Users/balaji.a.arunachalam/PycharmProjects/Back_end(Python,SQL)/src/main/insertion.py", line 42, in record_insertion\n    with open(file_path, \'r\') as read_file:\n', "FileNotFoundError: [Errno 2] No such file or directory: 'C:/Users/balaji.a.arunachalam/PycharmProjects/Back_end(Python,SQL)/src\\\\files\\\\records\\\\order_details.csv.sql'\n"]
2020-10-06 11:22:50,785 - 36772 DEBUG - ['Traceback (most recent call last):\n', '  File "C:/Users/balaji.a.arunachalam/PycharmProjects/Back_end(Python,SQL)/src/main/insertion.py", line 17, in __init__\n    temp = sys.argv[1]\n', 'IndexError: list index out of range\n', '\nDuring handling of the above exception, another exception occurred:\n\n', 'Traceback (most recent call last):\n', '  File "C:/Users/balaji.a.arunachalam/PycharmProjects/Back_end(Python,SQL)/src/main/insertion.py", line 42, in record_insertion\n    with open(file_path, \'r\') as read_file:\n', "FileNotFoundError: [Errno 2] No such file or directory: 'C:/Users/balaji.a.arunachalam/PycharmProjects/Back_end(Python,SQL)/src\\\\files\\\\records\\\\product_stock_details.csv.sql'\n"]
2020-10-06 11:22:50,785 - 36772 DEBUG - ['Traceback (most recent call last):\n', '  File "C:/Users/balaji.a.arunachalam/PycharmProjects/Back_end(Python,SQL)/src/main/insertion.py", line 17, in __init__\n    temp = sys.argv[1]\n', 'IndexError: list index out of range\n', '\nDuring handling of the above exception, another exception occurred:\n\n', 'Traceback (most recent call last):\n', '  File "C:/Users/balaji.a.arunachalam/PycharmProjects/Back_end(Python,SQL)/src/main/insertion.py", line 42, in record_insertion\n    with open(file_path, \'r\') as read_file:\n', "FileNotFoundError: [Errno 2] No such file or directory: 'C:/Users/balaji.a.arunachalam/PycharmProjects/Back_end(Python,SQL)/src\\\\files\\\\records\\\\product_stock_details.csv.sql'\n"]
2020-10-06 11:22:50,785 - 36772 DEBUG - ['Traceback (most recent call last):\n', '  File "C:/Users/balaji.a.arunachalam/PycharmProjects/Back_end(Python,SQL)/src/main/insertion.py", line 17, in __init__\n    temp = sys.argv[1]\n', 'IndexError: list index out of range\n', '\nDuring handling of the above exception, another exception occurred:\n\n', 'Traceback (most recent call last):\n', '  File "C:/Users/balaji.a.arunachalam/PycharmProjects/Back_end(Python,SQL)/src/main/insertion.py", line 42, in record_insertion\n    with open(file_path, \'r\') as read_file:\n', "FileNotFoundError: [Errno 2] No such file or directory: 'C:/Users/balaji.a.arunachalam/PycharmProjects/Back_end(Python,SQL)/src\\\\files\\\\records\\\\product_stock_details.csv.sql'\n"]
2020-10-06 11:22:50,786 - 36772 DEBUG - ['Traceback (most recent call last):\n', '  File "C:/Users/balaji.a.arunachalam/PycharmProjects/Back_end(Python,SQL)/src/main/insertion.py", line 17, in __init__\n    temp = sys.argv[1]\n', 'IndexError: list index out of range\n', '\nDuring handling of the above exception, another exception occurred:\n\n', 'Traceback (most recent call last):\n', '  File "C:/Users/balaji.a.arunachalam/PycharmProjects/Back_end(Python,SQL)/src/main/insertion.py", line 42, in record_insertion\n    with open(file_path, \'r\') as read_file:\n', "FileNotFoundError: [Errno 2] No such file or directory: 'C:/Users/balaji.a.arunachalam/PycharmProjects/Back_end(Python,SQL)/src\\\\files\\\\records\\\\product_details.csv.sql'\n"]
2020-10-06 11:22:50,786 - 36772 DEBUG - ['Traceback (most recent call last):\n', '  File "C:/Users/balaji.a.arunachalam/PycharmProjects/Back_end(Python,SQL)/src/main/insertion.py", line 17, in __init__\n    temp = sys.argv[1]\n', 'IndexError: list index out of range\n', '\nDuring handling of the above exception, another exception occurred:\n\n', 'Traceback (most recent call last):\n', '  File "C:/Users/balaji.a.arunachalam/PycharmProjects/Back_end(Python,SQL)/src/main/insertion.py", line 42, in record_insertion\n    with open(file_path, \'r\') as read_file:\n', "FileNotFoundError: [Errno 2] No such file or directory: 'C:/Users/balaji.a.arunachalam/PycharmProjects/Back_end(Python,SQL)/src\\\\files\\\\records\\\\product_details.csv.sql'\n"]
2020-10-06 11:22:50,786 - 36772 DEBUG - ['Traceback (most recent call last):\n', '  File "C:/Users/balaji.a.arunachalam/PycharmProjects/Back_end(Python,SQL)/src/main/insertion.py", line 17, in __init__\n    temp = sys.argv[1]\n', 'IndexError: list index out of range\n', '\nDuring handling of the above exception, another exception occurred:\n\n', 'Traceback (most recent call last):\n', '  File "C:/Users/balaji.a.arunachalam/PycharmProjects/Back_end(Python,SQL)/src/main/insertion.py", line 42, in record_insertion\n    with open(file_path, \'r\') as read_file:\n', "FileNotFoundError: [Errno 2] No such file or directory: 'C:/Users/balaji.a.arunachalam/PycharmProjects/Back_end(Python,SQL)/src\\\\files\\\\records\\\\product_details.csv.sql'\n"]
2020-10-06 11:22:50,786 - 36772 DEBUG - ['Traceback (most recent call last):\n', '  File "C:/Users/balaji.a.arunachalam/PycharmProjects/Back_end(Python,SQL)/src/main/insertion.py", line 17, in __init__\n    temp = sys.argv[1]\n', 'IndexError: list index out of range\n', '\nDuring handling of the above exception, another exception occurred:\n\n', 'Traceback (most recent call last):\n', '  File "C:/Users/balaji.a.arunachalam/PycharmProjects/Back_end(Python,SQL)/src/main/insertion.py", line 42, in record_insertion\n    with open(file_path, \'r\') as read_file:\n', "FileNotFoundError: [Errno 2] No such file or directory: 'C:/Users/balaji.a.arunachalam/PycharmProjects/Back_end(Python,SQL)/src\\\\files\\\\records\\\\cart_product_details.csv.sql'\n"]
2020-10-06 11:22:50,786 - 36772 DEBUG - ['Traceback (most recent call last):\n', '  File "C:/Users/balaji.a.arunachalam/PycharmProjects/Back_end(Python,SQL)/src/main/insertion.py", line 17, in __init__\n    temp = sys.argv[1]\n', 'IndexError: list index out of range\n', '\nDuring handling of the above exception, another exception occurred:\n\n', 'Traceback (most recent call last):\n', '  File "C:/Users/balaji.a.arunachalam/PycharmProjects/Back_end(Python,SQL)/src/main/insertion.py", line 42, in record_insertion\n    with open(file_path, \'r\') as read_file:\n', "FileNotFoundError: [Errno 2] No such file or directory: 'C:/Users/balaji.a.arunachalam/PycharmProjects/Back_end(Python,SQL)/src\\\\files\\\\records\\\\cart_product_details.csv.sql'\n"]
2020-10-06 11:22:50,786 - 36772 DEBUG - ['Traceback (most recent call last):\n', '  File "C:/Users/balaji.a.arunachalam/PycharmProjects/Back_end(Python,SQL)/src/main/insertion.py", line 17, in __init__\n    temp = sys.argv[1]\n', 'IndexError: list index out of range\n', '\nDuring handling of the above exception, another exception occurred:\n\n', 'Traceback (most recent call last):\n', '  File "C:/Users/balaji.a.arunachalam/PycharmProjects/Back_end(Python,SQL)/src/main/insertion.py", line 42, in record_insertion\n    with open(file_path, \'r\') as read_file:\n', "FileNotFoundError: [Errno 2] No such file or directory: 'C:/Users/balaji.a.arunachalam/PycharmProjects/Back_end(Python,SQL)/src\\\\files\\\\records\\\\cart_product_details.csv.sql'\n"]
2020-10-06 11:22:50,787 - 36772 DEBUG - ['Traceback (most recent call last):\n', '  File "C:/Users/balaji.a.arunachalam/PycharmProjects/Back_end(Python,SQL)/src/main/insertion.py", line 17, in __init__\n    temp = sys.argv[1]\n', 'IndexError: list index out of range\n', '\nDuring handling of the above exception, another exception occurred:\n\n', 'Traceback (most recent call last):\n', '  File "C:/Users/balaji.a.arunachalam/PycharmProjects/Back_end(Python,SQL)/src/main/insertion.py", line 42, in record_insertion\n    with open(file_path, \'r\') as read_file:\n', "FileNotFoundError: [Errno 2] No such file or directory: 'C:/Users/balaji.a.arunachalam/PycharmProjects/Back_end(Python,SQL)/src\\\\files\\\\records\\\\category_product_details.csv.sql'\n"]
2020-10-06 11:22:50,787 - 36772 DEBUG - ['Traceback (most recent call last):\n', '  File "C:/Users/balaji.a.arunachalam/PycharmProjects/Back_end(Python,SQL)/src/main/insertion.py", line 17, in __init__\n    temp = sys.argv[1]\n', 'IndexError: list index out of range\n', '\nDuring handling of the above exception, another exception occurred:\n\n', 'Traceback (most recent call last):\n', '  File "C:/Users/balaji.a.arunachalam/PycharmProjects/Back_end(Python,SQL)/src/main/insertion.py", line 42, in record_insertion\n    with open(file_path, \'r\') as read_file:\n', "FileNotFoundError: [Errno 2] No such file or directory: 'C:/Users/balaji.a.arunachalam/PycharmProjects/Back_end(Python,SQL)/src\\\\files\\\\records\\\\category_product_details.csv.sql'\n"]
2020-10-06 11:22:50,787 - 36772 DEBUG - ['Traceback (most recent call last):\n', '  File "C:/Users/balaji.a.arunachalam/PycharmProjects/Back_end(Python,SQL)/src/main/insertion.py", line 17, in __init__\n    temp = sys.argv[1]\n', 'IndexError: list index out of range\n', '\nDuring handling of the above exception, another exception occurred:\n\n', 'Traceback (most recent call last):\n', '  File "C:/Users/balaji.a.arunachalam/PycharmProjects/Back_end(Python,SQL)/src/main/insertion.py", line 42, in record_insertion\n    with open(file_path, \'r\') as read_file:\n', "FileNotFoundError: [Errno 2] No such file or directory: 'C:/Users/balaji.a.arunachalam/PycharmProjects/Back_end(Python,SQL)/src\\\\files\\\\records\\\\category_product_details.csv.sql'\n"]
2020-10-06 11:22:50,788 - 36772 DEBUG - ['Traceback (most recent call last):\n', '  File "C:/Users/balaji.a.arunachalam/PycharmProjects/Back_end(Python,SQL)/src/main/insertion.py", line 17, in __init__\n    temp = sys.argv[1]\n', 'IndexError: list index out of range\n', '\nDuring handling of the above exception, another exception occurred:\n\n', 'Traceback (most recent call last):\n', '  File "C:/Users/balaji.a.arunachalam/PycharmProjects/Back_end(Python,SQL)/src/main/insertion.py", line 42, in record_insertion\n    with open(file_path, \'r\') as read_file:\n', "FileNotFoundError: [Errno 2] No such file or directory: 'C:/Users/balaji.a.arunachalam/PycharmProjects/Back_end(Python,SQL)/src\\\\files\\\\records\\\\customer_rating_details.csv.sql'\n"]
2020-10-06 11:22:50,788 - 36772 DEBUG - ['Traceback (most recent call last):\n', '  File "C:/Users/balaji.a.arunachalam/PycharmProjects/Back_end(Python,SQL)/src/main/insertion.py", line 17, in __init__\n    temp = sys.argv[1]\n', 'IndexError: list index out of range\n', '\nDuring handling of the above exception, another exception occurred:\n\n', 'Traceback (most recent call last):\n', '  File "C:/Users/balaji.a.arunachalam/PycharmProjects/Back_end(Python,SQL)/src/main/insertion.py", line 42, in record_insertion\n    with open(file_path, \'r\') as read_file:\n', "FileNotFoundError: [Errno 2] No such file or directory: 'C:/Users/balaji.a.arunachalam/PycharmProjects/Back_end(Python,SQL)/src\\\\files\\\\records\\\\customer_rating_details.csv.sql'\n"]
2020-10-06 11:22:50,788 - 36772 DEBUG - ['Traceback (most recent call last):\n', '  File "C:/Users/balaji.a.arunachalam/PycharmProjects/Back_end(Python,SQL)/src/main/insertion.py", line 17, in __init__\n    temp = sys.argv[1]\n', 'IndexError: list index out of range\n', '\nDuring handling of the above exception, another exception occurred:\n\n', 'Traceback (most recent call last):\n', '  File "C:/Users/balaji.a.arunachalam/PycharmProjects/Back_end(Python,SQL)/src/main/insertion.py", line 42, in record_insertion\n    with open(file_path, \'r\') as read_file:\n', "FileNotFoundError: [Errno 2] No such file or directory: 'C:/Users/balaji.a.arunachalam/PycharmProjects/Back_end(Python,SQL)/src\\\\files\\\\records\\\\customer_rating_details.csv.sql'\n"]
2020-10-06 11:22:50,789 - 36772 DEBUG - ['Traceback (most recent call last):\n', '  File "C:/Users/balaji.a.arunachalam/PycharmProjects/Back_end(Python,SQL)/src/main/insertion.py", line 17, in __init__\n    temp = sys.argv[1]\n', 'IndexError: list index out of range\n', '\nDuring handling of the above exception, another exception occurred:\n\n', 'Traceback (most recent call last):\n', '  File "C:/Users/balaji.a.arunachalam/PycharmProjects/Back_end(Python,SQL)/src/main/insertion.py", line 42, in record_insertion\n    with open(file_path, \'r\') as read_file:\n', "FileNotFoundError: [Errno 2] No such file or directory: 'C:/Users/balaji.a.arunachalam/PycharmProjects/Back_end(Python,SQL)/src\\\\files\\\\records\\\\invoice_details.csv.sql'\n"]
2020-10-06 11:22:50,789 - 36772 DEBUG - ['Traceback (most recent call last):\n', '  File "C:/Users/balaji.a.arunachalam/PycharmProjects/Back_end(Python,SQL)/src/main/insertion.py", line 17, in __init__\n    temp = sys.argv[1]\n', 'IndexError: list index out of range\n', '\nDuring handling of the above exception, another exception occurred:\n\n', 'Traceback (most recent call last):\n', '  File "C:/Users/balaji.a.arunachalam/PycharmProjects/Back_end(Python,SQL)/src/main/insertion.py", line 42, in record_insertion\n    with open(file_path, \'r\') as read_file:\n', "FileNotFoundError: [Errno 2] No such file or directory: 'C:/Users/balaji.a.arunachalam/PycharmProjects/Back_end(Python,SQL)/src\\\\files\\\\records\\\\invoice_details.csv.sql'\n"]
2020-10-06 11:22:50,789 - 36772 DEBUG - ['Traceback (most recent call last):\n', '  File "C:/Users/balaji.a.arunachalam/PycharmProjects/Back_end(Python,SQL)/src/main/insertion.py", line 17, in __init__\n    temp = sys.argv[1]\n', 'IndexError: list index out of range\n', '\nDuring handling of the above exception, another exception occurred:\n\n', 'Traceback (most recent call last):\n', '  File "C:/Users/balaji.a.arunachalam/PycharmProjects/Back_end(Python,SQL)/src/main/insertion.py", line 42, in record_insertion\n    with open(file_path, \'r\') as read_file:\n', "FileNotFoundError: [Errno 2] No such file or directory: 'C:/Users/balaji.a.arunachalam/PycharmProjects/Back_end(Python,SQL)/src\\\\files\\\\records\\\\invoice_details.csv.sql'\n"]
2020-10-06 11:22:50,789 - 36772 DEBUG - ['Traceback (most recent call last):\n', '  File "C:/Users/balaji.a.arunachalam/PycharmProjects/Back_end(Python,SQL)/src/main/insertion.py", line 17, in __init__\n    temp = sys.argv[1]\n', 'IndexError: list index out of range\n', '\nDuring handling of the above exception, another exception occurred:\n\n', 'Traceback (most recent call last):\n', '  File "C:/Users/balaji.a.arunachalam/PycharmProjects/Back_end(Python,SQL)/src/main/insertion.py", line 42, in record_insertion\n    with open(file_path, \'r\') as read_file:\n', "FileNotFoundError: [Errno 2] No such file or directory: 'C:/Users/balaji.a.arunachalam/PycharmProjects/Back_end(Python,SQL)/src\\\\files\\\\records\\\\payment_details.csv.sql'\n"]
2020-10-06 11:22:50,789 - 36772 DEBUG - ['Traceback (most recent call last):\n', '  File "C:/Users/balaji.a.arunachalam/PycharmProjects/Back_end(Python,SQL)/src/main/insertion.py", line 17, in __init__\n    temp = sys.argv[1]\n', 'IndexError: list index out of range\n', '\nDuring handling of the above exception, another exception occurred:\n\n', 'Traceback (most recent call last):\n', '  File "C:/Users/balaji.a.arunachalam/PycharmProjects/Back_end(Python,SQL)/src/main/insertion.py", line 42, in record_insertion\n    with open(file_path, \'r\') as read_file:\n', "FileNotFoundError: [Errno 2] No such file or directory: 'C:/Users/balaji.a.arunachalam/PycharmProjects/Back_end(Python,SQL)/src\\\\files\\\\records\\\\payment_details.csv.sql'\n"]
2020-10-06 11:22:50,789 - 36772 DEBUG - ['Traceback (most recent call last):\n', '  File "C:/Users/balaji.a.arunachalam/PycharmProjects/Back_end(Python,SQL)/src/main/insertion.py", line 17, in __init__\n    temp = sys.argv[1]\n', 'IndexError: list index out of range\n', '\nDuring handling of the above exception, another exception occurred:\n\n', 'Traceback (most recent call last):\n', '  File "C:/Users/balaji.a.arunachalam/PycharmProjects/Back_end(Python,SQL)/src/main/insertion.py", line 42, in record_insertion\n    with open(file_path, \'r\') as read_file:\n', "FileNotFoundError: [Errno 2] No such file or directory: 'C:/Users/balaji.a.arunachalam/PycharmProjects/Back_end(Python,SQL)/src\\\\files\\\\records\\\\payment_details.csv.sql'\n"]
2020-10-06 11:22:50,790 - 36772 DEBUG - ['Traceback (most recent call last):\n', '  File "C:/Users/balaji.a.arunachalam/PycharmProjects/Back_end(Python,SQL)/src/main/insertion.py", line 17, in __init__\n    temp = sys.argv[1]\n', 'IndexError: list index out of range\n', '\nDuring handling of the above exception, another exception occurred:\n\n', 'Traceback (most recent call last):\n', '  File "C:/Users/balaji.a.arunachalam/PycharmProjects/Back_end(Python,SQL)/src/main/insertion.py", line 42, in record_insertion\n    with open(file_path, \'r\') as read_file:\n', "FileNotFoundError: [Errno 2] No such file or directory: 'C:/Users/balaji.a.arunachalam/PycharmProjects/Back_end(Python,SQL)/src\\\\files\\\\records\\\\product_ordered_details.csv.sql'\n"]
2020-10-06 11:22:50,790 - 36772 DEBUG - ['Traceback (most recent call last):\n', '  File "C:/Users/balaji.a.arunachalam/PycharmProjects/Back_end(Python,SQL)/src/main/insertion.py", line 17, in __init__\n    temp = sys.argv[1]\n', 'IndexError: list index out of range\n', '\nDuring handling of the above exception, another exception occurred:\n\n', 'Traceback (most recent call last):\n', '  File "C:/Users/balaji.a.arunachalam/PycharmProjects/Back_end(Python,SQL)/src/main/insertion.py", line 42, in record_insertion\n    with open(file_path, \'r\') as read_file:\n', "FileNotFoundError: [Errno 2] No such file or directory: 'C:/Users/balaji.a.arunachalam/PycharmProjects/Back_end(Python,SQL)/src\\\\files\\\\records\\\\product_ordered_details.csv.sql'\n"]
2020-10-06 11:22:50,790 - 36772 DEBUG - ['Traceback (most recent call last):\n', '  File "C:/Users/balaji.a.arunachalam/PycharmProjects/Back_end(Python,SQL)/src/main/insertion.py", line 17, in __init__\n    temp = sys.argv[1]\n', 'IndexError: list index out of range\n', '\nDuring handling of the above exception, another exception occurred:\n\n', 'Traceback (most recent call last):\n', '  File "C:/Users/balaji.a.arunachalam/PycharmProjects/Back_end(Python,SQL)/src/main/insertion.py", line 42, in record_insertion\n    with open(file_path, \'r\') as read_file:\n', "FileNotFoundError: [Errno 2] No such file or directory: 'C:/Users/balaji.a.arunachalam/PycharmProjects/Back_end(Python,SQL)/src\\\\files\\\\records\\\\product_ordered_details.csv.sql'\n"]
2020-10-06 11:22:50,791 - 36772 DEBUG - ['Traceback (most recent call last):\n', '  File "C:/Users/balaji.a.arunachalam/PycharmProjects/Back_end(Python,SQL)/src/main/insertion.py", line 17, in __init__\n    temp = sys.argv[1]\n', 'IndexError: list index out of range\n', '\nDuring handling of the above exception, another exception occurred:\n\n', 'Traceback (most recent call last):\n', '  File "C:/Users/balaji.a.arunachalam/PycharmProjects/Back_end(Python,SQL)/src/main/insertion.py", line 42, in record_insertion\n    with open(file_path, \'r\') as read_file:\n', "FileNotFoundError: [Errno 2] No such file or directory: 'C:/Users/balaji.a.arunachalam/PycharmProjects/Back_end(Python,SQL)/src\\\\files\\\\records\\\\shipping_status.csv.sql'\n"]
2020-10-06 11:22:50,791 - 36772 DEBUG - ['Traceback (most recent call last):\n', '  File "C:/Users/balaji.a.arunachalam/PycharmProjects/Back_end(Python,SQL)/src/main/insertion.py", line 17, in __init__\n    temp = sys.argv[1]\n', 'IndexError: list index out of range\n', '\nDuring handling of the above exception, another exception occurred:\n\n', 'Traceback (most recent call last):\n', '  File "C:/Users/balaji.a.arunachalam/PycharmProjects/Back_end(Python,SQL)/src/main/insertion.py", line 42, in record_insertion\n    with open(file_path, \'r\') as read_file:\n', "FileNotFoundError: [Errno 2] No such file or directory: 'C:/Users/balaji.a.arunachalam/PycharmProjects/Back_end(Python,SQL)/src\\\\files\\\\records\\\\shipping_status.csv.sql'\n"]
2020-10-06 11:22:50,791 - 36772 DEBUG - ['Traceback (most recent call last):\n', '  File "C:/Users/balaji.a.arunachalam/PycharmProjects/Back_end(Python,SQL)/src/main/insertion.py", line 17, in __init__\n    temp = sys.argv[1]\n', 'IndexError: list index out of range\n', '\nDuring handling of the above exception, another exception occurred:\n\n', 'Traceback (most recent call last):\n', '  File "C:/Users/balaji.a.arunachalam/PycharmProjects/Back_end(Python,SQL)/src/main/insertion.py", line 42, in record_insertion\n    with open(file_path, \'r\') as read_file:\n', "FileNotFoundError: [Errno 2] No such file or directory: 'C:/Users/balaji.a.arunachalam/PycharmProjects/Back_end(Python,SQL)/src\\\\files\\\\records\\\\shipping_status.csv.sql'\n"]
