2020-10-06 11:25:27,964 - 26784 DEBUG - ['Traceback (most recent call last):\n', '  File "C:/Users/balaji.a.arunachalam/PycharmProjects/Back_end(Python,SQL)/src/main/insertion.py", line 17, in __init__\n    temp = sys.argv[1]\n', 'IndexError: list index out of range\n', '\nDuring handling of the above exception, another exception occurred:\n\n', 'Traceback (most recent call last):\n', '  File "C:/Users/balaji.a.arunachalam/PycharmProjects/Back_end(Python,SQL)/src/main/insertion.py", line 42, in record_insertion\n    with open(file_path, \'r\') as read_file:\n', "FileNotFoundError: [Errno 2] No such file or directory: 'C:/Users/balaji.a.arunachalam/PycharmProjects/Back_end(Python,SQL)/src\\\\files\\\\records\\\\category_details.sql'\n"]
2020-10-06 11:25:27,964 - 26784 DEBUG - ['Traceback (most recent call last):\n', '  File "C:/Users/balaji.a.arunachalam/PycharmProjects/Back_end(Python,SQL)/src/main/insertion.py", line 17, in __init__\n    temp = sys.argv[1]\n', 'IndexError: list index out of range\n', '\nDuring handling of the above exception, another exception occurred:\n\n', 'Traceback (most recent call last):\n', '  File "C:/Users/balaji.a.arunachalam/PycharmProjects/Back_end(Python,SQL)/src/main/insertion.py", line 42, in record_insertion\n    with open(file_path, \'r\') as read_file:\n', "FileNotFoundError: [Errno 2] No such file or directory: 'C:/Users/balaji.a.arunachalam/PycharmProjects/Back_end(Python,SQL)/src\\\\files\\\\records\\\\category_details.sql'\n"]
2020-10-06 11:25:27,964 - 26784 DEBUG - ['Traceback (most recent call last):\n', '  File "C:/Users/balaji.a.arunachalam/PycharmProjects/Back_end(Python,SQL)/src/main/insertion.py", line 17, in __init__\n    temp = sys.argv[1]\n', 'IndexError: list index out of range\n', '\nDuring handling of the above exception, another exception occurred:\n\n', 'Traceback (most recent call last):\n', '  File "C:/Users/balaji.a.arunachalam/PycharmProjects/Back_end(Python,SQL)/src/main/insertion.py", line 42, in record_insertion\n    with open(file_path, \'r\') as read_file:\n', "FileNotFoundError: [Errno 2] No such file or directory: 'C:/Users/balaji.a.arunachalam/PycharmProjects/Back_end(Python,SQL)/src\\\\files\\\\records\\\\category_details.sql'\n"]
2020-10-06 11:25:27,965 - 26784 DEBUG - ['Traceback (most recent call last):\n', '  File "C:/Users/balaji.a.arunachalam/PycharmProjects/Back_end(Python,SQL)/src/main/insertion.py", line 17, in __init__\n    temp = sys.argv[1]\n', 'IndexError: list index out of range\n', '\nDuring handling of the above exception, another exception occurred:\n\n', 'Traceback (most recent call last):\n', '  File "C:/Users/balaji.a.arunachalam/PycharmProjects/Back_end(Python,SQL)/src/main/insertion.py", line 42, in record_insertion\n    with open(file_path, \'r\') as read_file:\n', "FileNotFoundError: [Errno 2] No such file or directory: 'C:/Users/balaji.a.arunachalam/PycharmProjects/Back_end(Python,SQL)/src\\\\files\\\\records\\\\customer_details.sql'\n"]
2020-10-06 11:25:27,965 - 26784 DEBUG - ['Traceback (most recent call last):\n', '  File "C:/Users/balaji.a.arunachalam/PycharmProjects/Back_end(Python,SQL)/src/main/insertion.py", line 17, in __init__\n    temp = sys.argv[1]\n', 'IndexError: list index out of range\n', '\nDuring handling of the above exception, another exception occurred:\n\n', 'Traceback (most recent call last):\n', '  File "C:/Users/balaji.a.arunachalam/PycharmProjects/Back_end(Python,SQL)/src/main/insertion.py", line 42, in record_insertion\n    with open(file_path, \'r\') as read_file:\n', "FileNotFoundError: [Errno 2] No such file or directory: 'C:/Users/balaji.a.arunachalam/PycharmProjects/Back_end(Python,SQL)/src\\\\files\\\\records\\\\customer_details.sql'\n"]
2020-10-06 11:25:27,965 - 26784 DEBUG - ['Traceback (most recent call last):\n', '  File "C:/Users/balaji.a.arunachalam/PycharmProjects/Back_end(Python,SQL)/src/main/insertion.py", line 17, in __init__\n    temp = sys.argv[1]\n', 'IndexError: list index out of range\n', '\nDuring handling of the above exception, another exception occurred:\n\n', 'Traceback (most recent call last):\n', '  File "C:/Users/balaji.a.arunachalam/PycharmProjects/Back_end(Python,SQL)/src/main/insertion.py", line 42, in record_insertion\n    with open(file_path, \'r\') as read_file:\n', "FileNotFoundError: [Errno 2] No such file or directory: 'C:/Users/balaji.a.arunachalam/PycharmProjects/Back_end(Python,SQL)/src\\\\files\\\\records\\\\customer_details.sql'\n"]
2020-10-06 11:25:27,966 - 26784 DEBUG - ['Traceback (most recent call last):\n', '  File "C:/Users/balaji.a.arunachalam/PycharmProjects/Back_end(Python,SQL)/src/main/insertion.py", line 17, in __init__\n    temp = sys.argv[1]\n', 'IndexError: list index out of range\n', '\nDuring handling of the above exception, another exception occurred:\n\n', 'Traceback (most recent call last):\n', '  File "C:/Users/balaji.a.arunachalam/PycharmProjects/Back_end(Python,SQL)/src/main/insertion.py", line 42, in record_insertion\n    with open(file_path, \'r\') as read_file:\n', "FileNotFoundError: [Errno 2] No such file or directory: 'C:/Users/balaji.a.arunachalam/PycharmProjects/Back_end(Python,SQL)/src\\\\files\\\\records\\\\order_status_details.sql'\n"]
2020-10-06 11:25:27,966 - 26784 DEBUG - ['Traceback (most recent call last):\n', '  File "C:/Users/balaji.a.arunachalam/PycharmProjects/Back_end(Python,SQL)/src/main/insertion.py", line 17, in __init__\n    temp = sys.argv[1]\n', 'IndexError: list index out of range\n', '\nDuring handling of the above exception, another exception occurred:\n\n', 'Traceback (most recent call last):\n', '  File "C:/Users/balaji.a.arunachalam/PycharmProjects/Back_end(Python,SQL)/src/main/insertion.py", line 42, in record_insertion\n    with open(file_path, \'r\') as read_file:\n', "FileNotFoundError: [Errno 2] No such file or directory: 'C:/Users/balaji.a.arunachalam/PycharmProjects/Back_end(Python,SQL)/src\\\\files\\\\records\\\\order_status_details.sql'\n"]
2020-10-06 11:25:27,966 - 26784 DEBUG - ['Traceback (most recent call last):\n', '  File "C:/Users/balaji.a.arunachalam/PycharmProjects/Back_end(Python,SQL)/src/main/insertion.py", line 17, in __init__\n    temp = sys.argv[1]\n', 'IndexError: list index out of range\n', '\nDuring handling of the above exception, another exception occurred:\n\n', 'Traceback (most recent call last):\n', '  File "C:/Users/balaji.a.arunachalam/PycharmProjects/Back_end(Python,SQL)/src/main/insertion.py", line 42, in record_insertion\n    with open(file_path, \'r\') as read_file:\n', "FileNotFoundError: [Errno 2] No such file or directory: 'C:/Users/balaji.a.arunachalam/PycharmProjects/Back_end(Python,SQL)/src\\\\files\\\\records\\\\order_status_details.sql'\n"]
2020-10-06 11:25:27,966 - 26784 DEBUG - ['Traceback (most recent call last):\n', '  File "C:/Users/balaji.a.arunachalam/PycharmProjects/Back_end(Python,SQL)/src/main/insertion.py", line 17, in __init__\n    temp = sys.argv[1]\n', 'IndexError: list index out of range\n', '\nDuring handling of the above exception, another exception occurred:\n\n', 'Traceback (most recent call last):\n', '  File "C:/Users/balaji.a.arunachalam/PycharmProjects/Back_end(Python,SQL)/src/main/insertion.py", line 42, in record_insertion\n    with open(file_path, \'r\') as read_file:\n', "FileNotFoundError: [Errno 2] No such file or directory: 'C:/Users/balaji.a.arunachalam/PycharmProjects/Back_end(Python,SQL)/src\\\\files\\\\records\\\\seller_details.sql'\n"]
2020-10-06 11:25:27,966 - 26784 DEBUG - ['Traceback (most recent call last):\n', '  File "C:/Users/balaji.a.arunachalam/PycharmProjects/Back_end(Python,SQL)/src/main/insertion.py", line 17, in __init__\n    temp = sys.argv[1]\n', 'IndexError: list index out of range\n', '\nDuring handling of the above exception, another exception occurred:\n\n', 'Traceback (most recent call last):\n', '  File "C:/Users/balaji.a.arunachalam/PycharmProjects/Back_end(Python,SQL)/src/main/insertion.py", line 42, in record_insertion\n    with open(file_path, \'r\') as read_file:\n', "FileNotFoundError: [Errno 2] No such file or directory: 'C:/Users/balaji.a.arunachalam/PycharmProjects/Back_end(Python,SQL)/src\\\\files\\\\records\\\\seller_details.sql'\n"]
2020-10-06 11:25:27,966 - 26784 DEBUG - ['Traceback (most recent call last):\n', '  File "C:/Users/balaji.a.arunachalam/PycharmProjects/Back_end(Python,SQL)/src/main/insertion.py", line 17, in __init__\n    temp = sys.argv[1]\n', 'IndexError: list index out of range\n', '\nDuring handling of the above exception, another exception occurred:\n\n', 'Traceback (most recent call last):\n', '  File "C:/Users/balaji.a.arunachalam/PycharmProjects/Back_end(Python,SQL)/src/main/insertion.py", line 42, in record_insertion\n    with open(file_path, \'r\') as read_file:\n', "FileNotFoundError: [Errno 2] No such file or directory: 'C:/Users/balaji.a.arunachalam/PycharmProjects/Back_end(Python,SQL)/src\\\\files\\\\records\\\\seller_details.sql'\n"]
2020-10-06 11:25:27,967 - 26784 DEBUG - ['Traceback (most recent call last):\n', '  File "C:/Users/balaji.a.arunachalam/PycharmProjects/Back_end(Python,SQL)/src/main/insertion.py", line 17, in __init__\n    temp = sys.argv[1]\n', 'IndexError: list index out of range\n', '\nDuring handling of the above exception, another exception occurred:\n\n', 'Traceback (most recent call last):\n', '  File "C:/Users/balaji.a.arunachalam/PycharmProjects/Back_end(Python,SQL)/src/main/insertion.py", line 42, in record_insertion\n    with open(file_path, \'r\') as read_file:\n', "FileNotFoundError: [Errno 2] No such file or directory: 'C:/Users/balaji.a.arunachalam/PycharmProjects/Back_end(Python,SQL)/src\\\\files\\\\records\\\\cart_details.sql'\n"]
2020-10-06 11:25:27,967 - 26784 DEBUG - ['Traceback (most recent call last):\n', '  File "C:/Users/balaji.a.arunachalam/PycharmProjects/Back_end(Python,SQL)/src/main/insertion.py", line 17, in __init__\n    temp = sys.argv[1]\n', 'IndexError: list index out of range\n', '\nDuring handling of the above exception, another exception occurred:\n\n', 'Traceback (most recent call last):\n', '  File "C:/Users/balaji.a.arunachalam/PycharmProjects/Back_end(Python,SQL)/src/main/insertion.py", line 42, in record_insertion\n    with open(file_path, \'r\') as read_file:\n', "FileNotFoundError: [Errno 2] No such file or directory: 'C:/Users/balaji.a.arunachalam/PycharmProjects/Back_end(Python,SQL)/src\\\\files\\\\records\\\\cart_details.sql'\n"]
2020-10-06 11:25:27,967 - 26784 DEBUG - ['Traceback (most recent call last):\n', '  File "C:/Users/balaji.a.arunachalam/PycharmProjects/Back_end(Python,SQL)/src/main/insertion.py", line 17, in __init__\n    temp = sys.argv[1]\n', 'IndexError: list index out of range\n', '\nDuring handling of the above exception, another exception occurred:\n\n', 'Traceback (most recent call last):\n', '  File "C:/Users/balaji.a.arunachalam/PycharmProjects/Back_end(Python,SQL)/src/main/insertion.py", line 42, in record_insertion\n    with open(file_path, \'r\') as read_file:\n', "FileNotFoundError: [Errno 2] No such file or directory: 'C:/Users/balaji.a.arunachalam/PycharmProjects/Back_end(Python,SQL)/src\\\\files\\\\records\\\\cart_details.sql'\n"]
2020-10-06 11:25:27,968 - 26784 DEBUG - ['Traceback (most recent call last):\n', '  File "C:/Users/balaji.a.arunachalam/PycharmProjects/Back_end(Python,SQL)/src/main/insertion.py", line 17, in __init__\n    temp = sys.argv[1]\n', 'IndexError: list index out of range\n', '\nDuring handling of the above exception, another exception occurred:\n\n', 'Traceback (most recent call last):\n', '  File "C:/Users/balaji.a.arunachalam/PycharmProjects/Back_end(Python,SQL)/src/main/insertion.py", line 42, in record_insertion\n    with open(file_path, \'r\') as read_file:\n', "FileNotFoundError: [Errno 2] No such file or directory: 'C:/Users/balaji.a.arunachalam/PycharmProjects/Back_end(Python,SQL)/src\\\\files\\\\records\\\\customer_address_details.sql'\n"]
2020-10-06 11:25:27,968 - 26784 DEBUG - ['Traceback (most recent call last):\n', '  File "C:/Users/balaji.a.arunachalam/PycharmProjects/Back_end(Python,SQL)/src/main/insertion.py", line 17, in __init__\n    temp = sys.argv[1]\n', 'IndexError: list index out of range\n', '\nDuring handling of the above exception, another exception occurred:\n\n', 'Traceback (most recent call last):\n', '  File "C:/Users/balaji.a.arunachalam/PycharmProjects/Back_end(Python,SQL)/src/main/insertion.py", line 42, in record_insertion\n    with open(file_path, \'r\') as read_file:\n', "FileNotFoundError: [Errno 2] No such file or directory: 'C:/Users/balaji.a.arunachalam/PycharmProjects/Back_end(Python,SQL)/src\\\\files\\\\records\\\\customer_address_details.sql'\n"]
2020-10-06 11:25:27,968 - 26784 DEBUG - ['Traceback (most recent call last):\n', '  File "C:/Users/balaji.a.arunachalam/PycharmProjects/Back_end(Python,SQL)/src/main/insertion.py", line 17, in __init__\n    temp = sys.argv[1]\n', 'IndexError: list index out of range\n', '\nDuring handling of the above exception, another exception occurred:\n\n', 'Traceback (most recent call last):\n', '  File "C:/Users/balaji.a.arunachalam/PycharmProjects/Back_end(Python,SQL)/src/main/insertion.py", line 42, in record_insertion\n    with open(file_path, \'r\') as read_file:\n', "FileNotFoundError: [Errno 2] No such file or directory: 'C:/Users/balaji.a.arunachalam/PycharmProjects/Back_end(Python,SQL)/src\\\\files\\\\records\\\\customer_address_details.sql'\n"]
2020-10-06 11:25:27,969 - 26784 DEBUG - ['Traceback (most recent call last):\n', '  File "C:/Users/balaji.a.arunachalam/PycharmProjects/Back_end(Python,SQL)/src/main/insertion.py", line 17, in __init__\n    temp = sys.argv[1]\n', 'IndexError: list index out of range\n', '\nDuring handling of the above exception, another exception occurred:\n\n', 'Traceback (most recent call last):\n', '  File "C:/Users/balaji.a.arunachalam/PycharmProjects/Back_end(Python,SQL)/src/main/insertion.py", line 42, in record_insertion\n    with open(file_path, \'r\') as read_file:\n', "FileNotFoundError: [Errno 2] No such file or directory: 'C:/Users/balaji.a.arunachalam/PycharmProjects/Back_end(Python,SQL)/src\\\\files\\\\records\\\\order_details.sql'\n"]
2020-10-06 11:25:27,969 - 26784 DEBUG - ['Traceback (most recent call last):\n', '  File "C:/Users/balaji.a.arunachalam/PycharmProjects/Back_end(Python,SQL)/src/main/insertion.py", line 17, in __init__\n    temp = sys.argv[1]\n', 'IndexError: list index out of range\n', '\nDuring handling of the above exception, another exception occurred:\n\n', 'Traceback (most recent call last):\n', '  File "C:/Users/balaji.a.arunachalam/PycharmProjects/Back_end(Python,SQL)/src/main/insertion.py", line 42, in record_insertion\n    with open(file_path, \'r\') as read_file:\n', "FileNotFoundError: [Errno 2] No such file or directory: 'C:/Users/balaji.a.arunachalam/PycharmProjects/Back_end(Python,SQL)/src\\\\files\\\\records\\\\order_details.sql'\n"]
2020-10-06 11:25:27,969 - 26784 DEBUG - ['Traceback (most recent call last):\n', '  File "C:/Users/balaji.a.arunachalam/PycharmProjects/Back_end(Python,SQL)/src/main/insertion.py", line 17, in __init__\n    temp = sys.argv[1]\n', 'IndexError: list index out of range\n', '\nDuring handling of the above exception, another exception occurred:\n\n', 'Traceback (most recent call last):\n', '  File "C:/Users/balaji.a.arunachalam/PycharmProjects/Back_end(Python,SQL)/src/main/insertion.py", line 42, in record_insertion\n    with open(file_path, \'r\') as read_file:\n', "FileNotFoundError: [Errno 2] No such file or directory: 'C:/Users/balaji.a.arunachalam/PycharmProjects/Back_end(Python,SQL)/src\\\\files\\\\records\\\\order_details.sql'\n"]
2020-10-06 11:25:27,969 - 26784 DEBUG - ['Traceback (most recent call last):\n', '  File "C:/Users/balaji.a.arunachalam/PycharmProjects/Back_end(Python,SQL)/src/main/insertion.py", line 17, in __init__\n    temp = sys.argv[1]\n', 'IndexError: list index out of range\n', '\nDuring handling of the above exception, another exception occurred:\n\n', 'Traceback (most recent call last):\n', '  File "C:/Users/balaji.a.arunachalam/PycharmProjects/Back_end(Python,SQL)/src/main/insertion.py", line 42, in record_insertion\n    with open(file_path, \'r\') as read_file:\n', "FileNotFoundError: [Errno 2] No such file or directory: 'C:/Users/balaji.a.arunachalam/PycharmProjects/Back_end(Python,SQL)/src\\\\files\\\\records\\\\product_stock_details.sql'\n"]
2020-10-06 11:25:27,969 - 26784 DEBUG - ['Traceback (most recent call last):\n', '  File "C:/Users/balaji.a.arunachalam/PycharmProjects/Back_end(Python,SQL)/src/main/insertion.py", line 17, in __init__\n    temp = sys.argv[1]\n', 'IndexError: list index out of range\n', '\nDuring handling of the above exception, another exception occurred:\n\n', 'Traceback (most recent call last):\n', '  File "C:/Users/balaji.a.arunachalam/PycharmProjects/Back_end(Python,SQL)/src/main/insertion.py", line 42, in record_insertion\n    with open(file_path, \'r\') as read_file:\n', "FileNotFoundError: [Errno 2] No such file or directory: 'C:/Users/balaji.a.arunachalam/PycharmProjects/Back_end(Python,SQL)/src\\\\files\\\\records\\\\product_stock_details.sql'\n"]
2020-10-06 11:25:27,969 - 26784 DEBUG - ['Traceback (most recent call last):\n', '  File "C:/Users/balaji.a.arunachalam/PycharmProjects/Back_end(Python,SQL)/src/main/insertion.py", line 17, in __init__\n    temp = sys.argv[1]\n', 'IndexError: list index out of range\n', '\nDuring handling of the above exception, another exception occurred:\n\n', 'Traceback (most recent call last):\n', '  File "C:/Users/balaji.a.arunachalam/PycharmProjects/Back_end(Python,SQL)/src/main/insertion.py", line 42, in record_insertion\n    with open(file_path, \'r\') as read_file:\n', "FileNotFoundError: [Errno 2] No such file or directory: 'C:/Users/balaji.a.arunachalam/PycharmProjects/Back_end(Python,SQL)/src\\\\files\\\\records\\\\product_stock_details.sql'\n"]
2020-10-06 11:25:27,970 - 26784 DEBUG - ['Traceback (most recent call last):\n', '  File "C:/Users/balaji.a.arunachalam/PycharmProjects/Back_end(Python,SQL)/src/main/insertion.py", line 17, in __init__\n    temp = sys.argv[1]\n', 'IndexError: list index out of range\n', '\nDuring handling of the above exception, another exception occurred:\n\n', 'Traceback (most recent call last):\n', '  File "C:/Users/balaji.a.arunachalam/PycharmProjects/Back_end(Python,SQL)/src/main/insertion.py", line 42, in record_insertion\n    with open(file_path, \'r\') as read_file:\n', "FileNotFoundError: [Errno 2] No such file or directory: 'C:/Users/balaji.a.arunachalam/PycharmProjects/Back_end(Python,SQL)/src\\\\files\\\\records\\\\product_details.sql'\n"]
2020-10-06 11:25:27,970 - 26784 DEBUG - ['Traceback (most recent call last):\n', '  File "C:/Users/balaji.a.arunachalam/PycharmProjects/Back_end(Python,SQL)/src/main/insertion.py", line 17, in __init__\n    temp = sys.argv[1]\n', 'IndexError: list index out of range\n', '\nDuring handling of the above exception, another exception occurred:\n\n', 'Traceback (most recent call last):\n', '  File "C:/Users/balaji.a.arunachalam/PycharmProjects/Back_end(Python,SQL)/src/main/insertion.py", line 42, in record_insertion\n    with open(file_path, \'r\') as read_file:\n', "FileNotFoundError: [Errno 2] No such file or directory: 'C:/Users/balaji.a.arunachalam/PycharmProjects/Back_end(Python,SQL)/src\\\\files\\\\records\\\\product_details.sql'\n"]
2020-10-06 11:25:27,970 - 26784 DEBUG - ['Traceback (most recent call last):\n', '  File "C:/Users/balaji.a.arunachalam/PycharmProjects/Back_end(Python,SQL)/src/main/insertion.py", line 17, in __init__\n    temp = sys.argv[1]\n', 'IndexError: list index out of range\n', '\nDuring handling of the above exception, another exception occurred:\n\n', 'Traceback (most recent call last):\n', '  File "C:/Users/balaji.a.arunachalam/PycharmProjects/Back_end(Python,SQL)/src/main/insertion.py", line 42, in record_insertion\n    with open(file_path, \'r\') as read_file:\n', "FileNotFoundError: [Errno 2] No such file or directory: 'C:/Users/balaji.a.arunachalam/PycharmProjects/Back_end(Python,SQL)/src\\\\files\\\\records\\\\product_details.sql'\n"]
2020-10-06 11:25:27,971 - 26784 DEBUG - ['Traceback (most recent call last):\n', '  File "C:/Users/balaji.a.arunachalam/PycharmProjects/Back_end(Python,SQL)/src/main/insertion.py", line 17, in __init__\n    temp = sys.argv[1]\n', 'IndexError: list index out of range\n', '\nDuring handling of the above exception, another exception occurred:\n\n', 'Traceback (most recent call last):\n', '  File "C:/Users/balaji.a.arunachalam/PycharmProjects/Back_end(Python,SQL)/src/main/insertion.py", line 42, in record_insertion\n    with open(file_path, \'r\') as read_file:\n', "FileNotFoundError: [Errno 2] No such file or directory: 'C:/Users/balaji.a.arunachalam/PycharmProjects/Back_end(Python,SQL)/src\\\\files\\\\records\\\\cart_product_details.sql'\n"]
2020-10-06 11:25:27,971 - 26784 DEBUG - ['Traceback (most recent call last):\n', '  File "C:/Users/balaji.a.arunachalam/PycharmProjects/Back_end(Python,SQL)/src/main/insertion.py", line 17, in __init__\n    temp = sys.argv[1]\n', 'IndexError: list index out of range\n', '\nDuring handling of the above exception, another exception occurred:\n\n', 'Traceback (most recent call last):\n', '  File "C:/Users/balaji.a.arunachalam/PycharmProjects/Back_end(Python,SQL)/src/main/insertion.py", line 42, in record_insertion\n    with open(file_path, \'r\') as read_file:\n', "FileNotFoundError: [Errno 2] No such file or directory: 'C:/Users/balaji.a.arunachalam/PycharmProjects/Back_end(Python,SQL)/src\\\\files\\\\records\\\\cart_product_details.sql'\n"]
2020-10-06 11:25:27,971 - 26784 DEBUG - ['Traceback (most recent call last):\n', '  File "C:/Users/balaji.a.arunachalam/PycharmProjects/Back_end(Python,SQL)/src/main/insertion.py", line 17, in __init__\n    temp = sys.argv[1]\n', 'IndexError: list index out of range\n', '\nDuring handling of the above exception, another exception occurred:\n\n', 'Traceback (most recent call last):\n', '  File "C:/Users/balaji.a.arunachalam/PycharmProjects/Back_end(Python,SQL)/src/main/insertion.py", line 42, in record_insertion\n    with open(file_path, \'r\') as read_file:\n', "FileNotFoundError: [Errno 2] No such file or directory: 'C:/Users/balaji.a.arunachalam/PycharmProjects/Back_end(Python,SQL)/src\\\\files\\\\records\\\\cart_product_details.sql'\n"]
2020-10-06 11:25:27,972 - 26784 DEBUG - ['Traceback (most recent call last):\n', '  File "C:/Users/balaji.a.arunachalam/PycharmProjects/Back_end(Python,SQL)/src/main/insertion.py", line 17, in __init__\n    temp = sys.argv[1]\n', 'IndexError: list index out of range\n', '\nDuring handling of the above exception, another exception occurred:\n\n', 'Traceback (most recent call last):\n', '  File "C:/Users/balaji.a.arunachalam/PycharmProjects/Back_end(Python,SQL)/src/main/insertion.py", line 42, in record_insertion\n    with open(file_path, \'r\') as read_file:\n', "FileNotFoundError: [Errno 2] No such file or directory: 'C:/Users/balaji.a.arunachalam/PycharmProjects/Back_end(Python,SQL)/src\\\\files\\\\records\\\\category_product_details.sql'\n"]
2020-10-06 11:25:27,972 - 26784 DEBUG - ['Traceback (most recent call last):\n', '  File "C:/Users/balaji.a.arunachalam/PycharmProjects/Back_end(Python,SQL)/src/main/insertion.py", line 17, in __init__\n    temp = sys.argv[1]\n', 'IndexError: list index out of range\n', '\nDuring handling of the above exception, another exception occurred:\n\n', 'Traceback (most recent call last):\n', '  File "C:/Users/balaji.a.arunachalam/PycharmProjects/Back_end(Python,SQL)/src/main/insertion.py", line 42, in record_insertion\n    with open(file_path, \'r\') as read_file:\n', "FileNotFoundError: [Errno 2] No such file or directory: 'C:/Users/balaji.a.arunachalam/PycharmProjects/Back_end(Python,SQL)/src\\\\files\\\\records\\\\category_product_details.sql'\n"]
2020-10-06 11:25:27,972 - 26784 DEBUG - ['Traceback (most recent call last):\n', '  File "C:/Users/balaji.a.arunachalam/PycharmProjects/Back_end(Python,SQL)/src/main/insertion.py", line 17, in __init__\n    temp = sys.argv[1]\n', 'IndexError: list index out of range\n', '\nDuring handling of the above exception, another exception occurred:\n\n', 'Traceback (most recent call last):\n', '  File "C:/Users/balaji.a.arunachalam/PycharmProjects/Back_end(Python,SQL)/src/main/insertion.py", line 42, in record_insertion\n    with open(file_path, \'r\') as read_file:\n', "FileNotFoundError: [Errno 2] No such file or directory: 'C:/Users/balaji.a.arunachalam/PycharmProjects/Back_end(Python,SQL)/src\\\\files\\\\records\\\\category_product_details.sql'\n"]
2020-10-06 11:25:27,974 - 26784 DEBUG - ['Traceback (most recent call last):\n', '  File "C:/Users/balaji.a.arunachalam/PycharmProjects/Back_end(Python,SQL)/src/main/insertion.py", line 17, in __init__\n    temp = sys.argv[1]\n', 'IndexError: list index out of range\n', '\nDuring handling of the above exception, another exception occurred:\n\n', 'Traceback (most recent call last):\n', '  File "C:/Users/balaji.a.arunachalam/PycharmProjects/Back_end(Python,SQL)/src/main/insertion.py", line 42, in record_insertion\n    with open(file_path, \'r\') as read_file:\n', "FileNotFoundError: [Errno 2] No such file or directory: 'C:/Users/balaji.a.arunachalam/PycharmProjects/Back_end(Python,SQL)/src\\\\files\\\\records\\\\customer_rating_details.sql'\n"]
2020-10-06 11:25:27,974 - 26784 DEBUG - ['Traceback (most recent call last):\n', '  File "C:/Users/balaji.a.arunachalam/PycharmProjects/Back_end(Python,SQL)/src/main/insertion.py", line 17, in __init__\n    temp = sys.argv[1]\n', 'IndexError: list index out of range\n', '\nDuring handling of the above exception, another exception occurred:\n\n', 'Traceback (most recent call last):\n', '  File "C:/Users/balaji.a.arunachalam/PycharmProjects/Back_end(Python,SQL)/src/main/insertion.py", line 42, in record_insertion\n    with open(file_path, \'r\') as read_file:\n', "FileNotFoundError: [Errno 2] No such file or directory: 'C:/Users/balaji.a.arunachalam/PycharmProjects/Back_end(Python,SQL)/src\\\\files\\\\records\\\\customer_rating_details.sql'\n"]
2020-10-06 11:25:27,974 - 26784 DEBUG - ['Traceback (most recent call last):\n', '  File "C:/Users/balaji.a.arunachalam/PycharmProjects/Back_end(Python,SQL)/src/main/insertion.py", line 17, in __init__\n    temp = sys.argv[1]\n', 'IndexError: list index out of range\n', '\nDuring handling of the above exception, another exception occurred:\n\n', 'Traceback (most recent call last):\n', '  File "C:/Users/balaji.a.arunachalam/PycharmProjects/Back_end(Python,SQL)/src/main/insertion.py", line 42, in record_insertion\n    with open(file_path, \'r\') as read_file:\n', "FileNotFoundError: [Errno 2] No such file or directory: 'C:/Users/balaji.a.arunachalam/PycharmProjects/Back_end(Python,SQL)/src\\\\files\\\\records\\\\customer_rating_details.sql'\n"]
2020-10-06 11:25:27,975 - 26784 DEBUG - ['Traceback (most recent call last):\n', '  File "C:/Users/balaji.a.arunachalam/PycharmProjects/Back_end(Python,SQL)/src/main/insertion.py", line 17, in __init__\n    temp = sys.argv[1]\n', 'IndexError: list index out of range\n', '\nDuring handling of the above exception, another exception occurred:\n\n', 'Traceback (most recent call last):\n', '  File "C:/Users/balaji.a.arunachalam/PycharmProjects/Back_end(Python,SQL)/src/main/insertion.py", line 42, in record_insertion\n    with open(file_path, \'r\') as read_file:\n', "FileNotFoundError: [Errno 2] No such file or directory: 'C:/Users/balaji.a.arunachalam/PycharmProjects/Back_end(Python,SQL)/src\\\\files\\\\records\\\\invoice_details.sql'\n"]
2020-10-06 11:25:27,975 - 26784 DEBUG - ['Traceback (most recent call last):\n', '  File "C:/Users/balaji.a.arunachalam/PycharmProjects/Back_end(Python,SQL)/src/main/insertion.py", line 17, in __init__\n    temp = sys.argv[1]\n', 'IndexError: list index out of range\n', '\nDuring handling of the above exception, another exception occurred:\n\n', 'Traceback (most recent call last):\n', '  File "C:/Users/balaji.a.arunachalam/PycharmProjects/Back_end(Python,SQL)/src/main/insertion.py", line 42, in record_insertion\n    with open(file_path, \'r\') as read_file:\n', "FileNotFoundError: [Errno 2] No such file or directory: 'C:/Users/balaji.a.arunachalam/PycharmProjects/Back_end(Python,SQL)/src\\\\files\\\\records\\\\invoice_details.sql'\n"]
2020-10-06 11:25:27,975 - 26784 DEBUG - ['Traceback (most recent call last):\n', '  File "C:/Users/balaji.a.arunachalam/PycharmProjects/Back_end(Python,SQL)/src/main/insertion.py", line 17, in __init__\n    temp = sys.argv[1]\n', 'IndexError: list index out of range\n', '\nDuring handling of the above exception, another exception occurred:\n\n', 'Traceback (most recent call last):\n', '  File "C:/Users/balaji.a.arunachalam/PycharmProjects/Back_end(Python,SQL)/src/main/insertion.py", line 42, in record_insertion\n    with open(file_path, \'r\') as read_file:\n', "FileNotFoundError: [Errno 2] No such file or directory: 'C:/Users/balaji.a.arunachalam/PycharmProjects/Back_end(Python,SQL)/src\\\\files\\\\records\\\\invoice_details.sql'\n"]
2020-10-06 11:25:27,976 - 26784 DEBUG - ['Traceback (most recent call last):\n', '  File "C:/Users/balaji.a.arunachalam/PycharmProjects/Back_end(Python,SQL)/src/main/insertion.py", line 17, in __init__\n    temp = sys.argv[1]\n', 'IndexError: list index out of range\n', '\nDuring handling of the above exception, another exception occurred:\n\n', 'Traceback (most recent call last):\n', '  File "C:/Users/balaji.a.arunachalam/PycharmProjects/Back_end(Python,SQL)/src/main/insertion.py", line 42, in record_insertion\n    with open(file_path, \'r\') as read_file:\n', "FileNotFoundError: [Errno 2] No such file or directory: 'C:/Users/balaji.a.arunachalam/PycharmProjects/Back_end(Python,SQL)/src\\\\files\\\\records\\\\payment_details.sql'\n"]
2020-10-06 11:25:27,976 - 26784 DEBUG - ['Traceback (most recent call last):\n', '  File "C:/Users/balaji.a.arunachalam/PycharmProjects/Back_end(Python,SQL)/src/main/insertion.py", line 17, in __init__\n    temp = sys.argv[1]\n', 'IndexError: list index out of range\n', '\nDuring handling of the above exception, another exception occurred:\n\n', 'Traceback (most recent call last):\n', '  File "C:/Users/balaji.a.arunachalam/PycharmProjects/Back_end(Python,SQL)/src/main/insertion.py", line 42, in record_insertion\n    with open(file_path, \'r\') as read_file:\n', "FileNotFoundError: [Errno 2] No such file or directory: 'C:/Users/balaji.a.arunachalam/PycharmProjects/Back_end(Python,SQL)/src\\\\files\\\\records\\\\payment_details.sql'\n"]
2020-10-06 11:25:27,976 - 26784 DEBUG - ['Traceback (most recent call last):\n', '  File "C:/Users/balaji.a.arunachalam/PycharmProjects/Back_end(Python,SQL)/src/main/insertion.py", line 17, in __init__\n    temp = sys.argv[1]\n', 'IndexError: list index out of range\n', '\nDuring handling of the above exception, another exception occurred:\n\n', 'Traceback (most recent call last):\n', '  File "C:/Users/balaji.a.arunachalam/PycharmProjects/Back_end(Python,SQL)/src/main/insertion.py", line 42, in record_insertion\n    with open(file_path, \'r\') as read_file:\n', "FileNotFoundError: [Errno 2] No such file or directory: 'C:/Users/balaji.a.arunachalam/PycharmProjects/Back_end(Python,SQL)/src\\\\files\\\\records\\\\payment_details.sql'\n"]
2020-10-06 11:25:27,976 - 26784 DEBUG - ['Traceback (most recent call last):\n', '  File "C:/Users/balaji.a.arunachalam/PycharmProjects/Back_end(Python,SQL)/src/main/insertion.py", line 17, in __init__\n    temp = sys.argv[1]\n', 'IndexError: list index out of range\n', '\nDuring handling of the above exception, another exception occurred:\n\n', 'Traceback (most recent call last):\n', '  File "C:/Users/balaji.a.arunachalam/PycharmProjects/Back_end(Python,SQL)/src/main/insertion.py", line 42, in record_insertion\n    with open(file_path, \'r\') as read_file:\n', "FileNotFoundError: [Errno 2] No such file or directory: 'C:/Users/balaji.a.arunachalam/PycharmProjects/Back_end(Python,SQL)/src\\\\files\\\\records\\\\product_ordered_details.sql'\n"]
2020-10-06 11:25:27,976 - 26784 DEBUG - ['Traceback (most recent call last):\n', '  File "C:/Users/balaji.a.arunachalam/PycharmProjects/Back_end(Python,SQL)/src/main/insertion.py", line 17, in __init__\n    temp = sys.argv[1]\n', 'IndexError: list index out of range\n', '\nDuring handling of the above exception, another exception occurred:\n\n', 'Traceback (most recent call last):\n', '  File "C:/Users/balaji.a.arunachalam/PycharmProjects/Back_end(Python,SQL)/src/main/insertion.py", line 42, in record_insertion\n    with open(file_path, \'r\') as read_file:\n', "FileNotFoundError: [Errno 2] No such file or directory: 'C:/Users/balaji.a.arunachalam/PycharmProjects/Back_end(Python,SQL)/src\\\\files\\\\records\\\\product_ordered_details.sql'\n"]
2020-10-06 11:25:27,976 - 26784 DEBUG - ['Traceback (most recent call last):\n', '  File "C:/Users/balaji.a.arunachalam/PycharmProjects/Back_end(Python,SQL)/src/main/insertion.py", line 17, in __init__\n    temp = sys.argv[1]\n', 'IndexError: list index out of range\n', '\nDuring handling of the above exception, another exception occurred:\n\n', 'Traceback (most recent call last):\n', '  File "C:/Users/balaji.a.arunachalam/PycharmProjects/Back_end(Python,SQL)/src/main/insertion.py", line 42, in record_insertion\n    with open(file_path, \'r\') as read_file:\n', "FileNotFoundError: [Errno 2] No such file or directory: 'C:/Users/balaji.a.arunachalam/PycharmProjects/Back_end(Python,SQL)/src\\\\files\\\\records\\\\product_ordered_details.sql'\n"]
2020-10-06 11:25:27,977 - 26784 DEBUG - ['Traceback (most recent call last):\n', '  File "C:/Users/balaji.a.arunachalam/PycharmProjects/Back_end(Python,SQL)/src/main/insertion.py", line 17, in __init__\n    temp = sys.argv[1]\n', 'IndexError: list index out of range\n', '\nDuring handling of the above exception, another exception occurred:\n\n', 'Traceback (most recent call last):\n', '  File "C:/Users/balaji.a.arunachalam/PycharmProjects/Back_end(Python,SQL)/src/main/insertion.py", line 42, in record_insertion\n    with open(file_path, \'r\') as read_file:\n', "FileNotFoundError: [Errno 2] No such file or directory: 'C:/Users/balaji.a.arunachalam/PycharmProjects/Back_end(Python,SQL)/src\\\\files\\\\records\\\\shipping_status.sql'\n"]
2020-10-06 11:25:27,977 - 26784 DEBUG - ['Traceback (most recent call last):\n', '  File "C:/Users/balaji.a.arunachalam/PycharmProjects/Back_end(Python,SQL)/src/main/insertion.py", line 17, in __init__\n    temp = sys.argv[1]\n', 'IndexError: list index out of range\n', '\nDuring handling of the above exception, another exception occurred:\n\n', 'Traceback (most recent call last):\n', '  File "C:/Users/balaji.a.arunachalam/PycharmProjects/Back_end(Python,SQL)/src/main/insertion.py", line 42, in record_insertion\n    with open(file_path, \'r\') as read_file:\n', "FileNotFoundError: [Errno 2] No such file or directory: 'C:/Users/balaji.a.arunachalam/PycharmProjects/Back_end(Python,SQL)/src\\\\files\\\\records\\\\shipping_status.sql'\n"]
2020-10-06 11:25:27,977 - 26784 DEBUG - ['Traceback (most recent call last):\n', '  File "C:/Users/balaji.a.arunachalam/PycharmProjects/Back_end(Python,SQL)/src/main/insertion.py", line 17, in __init__\n    temp = sys.argv[1]\n', 'IndexError: list index out of range\n', '\nDuring handling of the above exception, another exception occurred:\n\n', 'Traceback (most recent call last):\n', '  File "C:/Users/balaji.a.arunachalam/PycharmProjects/Back_end(Python,SQL)/src/main/insertion.py", line 42, in record_insertion\n    with open(file_path, \'r\') as read_file:\n', "FileNotFoundError: [Errno 2] No such file or directory: 'C:/Users/balaji.a.arunachalam/PycharmProjects/Back_end(Python,SQL)/src\\\\files\\\\records\\\\shipping_status.sql'\n"]
