2020-10-06 11:26:01,138 - 35476 DEBUG - ['Traceback (most recent call last):\n', '  File "C:/Users/balaji.a.arunachalam/PycharmProjects/Back_end(Python,SQL)/src/main/insertion.py", line 17, in __init__\n    temp = sys.argv[1]\n', 'IndexError: list index out of range\n', '\nDuring handling of the above exception, another exception occurred:\n\n', 'Traceback (most recent call last):\n', '  File "C:/Users/balaji.a.arunachalam/PycharmProjects/Back_end(Python,SQL)/src/main/insertion.py", line 42, in record_insertion\n    with open(file_path, \'r\') as read_file:\n', "FileNotFoundError: [Errno 2] No such file or directory: 'C:/Users/balaji.a.arunachalam/PycharmProjects/Back_end(Python,SQL)/src\\\\files\\\\records\\\\category_details.sql'\n"]
2020-10-06 11:26:01,138 - 35476 DEBUG - ['Traceback (most recent call last):\n', '  File "C:/Users/balaji.a.arunachalam/PycharmProjects/Back_end(Python,SQL)/src/main/insertion.py", line 17, in __init__\n    temp = sys.argv[1]\n', 'IndexError: list index out of range\n', '\nDuring handling of the above exception, another exception occurred:\n\n', 'Traceback (most recent call last):\n', '  File "C:/Users/balaji.a.arunachalam/PycharmProjects/Back_end(Python,SQL)/src/main/insertion.py", line 42, in record_insertion\n    with open(file_path, \'r\') as read_file:\n', "FileNotFoundError: [Errno 2] No such file or directory: 'C:/Users/balaji.a.arunachalam/PycharmProjects/Back_end(Python,SQL)/src\\\\files\\\\records\\\\category_details.sql'\n"]
2020-10-06 11:26:01,138 - 35476 DEBUG - ['Traceback (most recent call last):\n', '  File "C:/Users/balaji.a.arunachalam/PycharmProjects/Back_end(Python,SQL)/src/main/insertion.py", line 17, in __init__\n    temp = sys.argv[1]\n', 'IndexError: list index out of range\n', '\nDuring handling of the above exception, another exception occurred:\n\n', 'Traceback (most recent call last):\n', '  File "C:/Users/balaji.a.arunachalam/PycharmProjects/Back_end(Python,SQL)/src/main/insertion.py", line 42, in record_insertion\n    with open(file_path, \'r\') as read_file:\n', "FileNotFoundError: [Errno 2] No such file or directory: 'C:/Users/balaji.a.arunachalam/PycharmProjects/Back_end(Python,SQL)/src\\\\files\\\\records\\\\category_details.sql'\n"]
2020-10-06 11:26:01,139 - 35476 DEBUG - ['Traceback (most recent call last):\n', '  File "C:/Users/balaji.a.arunachalam/PycharmProjects/Back_end(Python,SQL)/src/main/insertion.py", line 17, in __init__\n    temp = sys.argv[1]\n', 'IndexError: list index out of range\n', '\nDuring handling of the above exception, another exception occurred:\n\n', 'Traceback (most recent call last):\n', '  File "C:/Users/balaji.a.arunachalam/PycharmProjects/Back_end(Python,SQL)/src/main/insertion.py", line 42, in record_insertion\n    with open(file_path, \'r\') as read_file:\n', "FileNotFoundError: [Errno 2] No such file or directory: 'C:/Users/balaji.a.arunachalam/PycharmProjects/Back_end(Python,SQL)/src\\\\files\\\\records\\\\customer_details.sql'\n"]
2020-10-06 11:26:01,139 - 35476 DEBUG - ['Traceback (most recent call last):\n', '  File "C:/Users/balaji.a.arunachalam/PycharmProjects/Back_end(Python,SQL)/src/main/insertion.py", line 17, in __init__\n    temp = sys.argv[1]\n', 'IndexError: list index out of range\n', '\nDuring handling of the above exception, another exception occurred:\n\n', 'Traceback (most recent call last):\n', '  File "C:/Users/balaji.a.arunachalam/PycharmProjects/Back_end(Python,SQL)/src/main/insertion.py", line 42, in record_insertion\n    with open(file_path, \'r\') as read_file:\n', "FileNotFoundError: [Errno 2] No such file or directory: 'C:/Users/balaji.a.arunachalam/PycharmProjects/Back_end(Python,SQL)/src\\\\files\\\\records\\\\customer_details.sql'\n"]
2020-10-06 11:26:01,139 - 35476 DEBUG - ['Traceback (most recent call last):\n', '  File "C:/Users/balaji.a.arunachalam/PycharmProjects/Back_end(Python,SQL)/src/main/insertion.py", line 17, in __init__\n    temp = sys.argv[1]\n', 'IndexError: list index out of range\n', '\nDuring handling of the above exception, another exception occurred:\n\n', 'Traceback (most recent call last):\n', '  File "C:/Users/balaji.a.arunachalam/PycharmProjects/Back_end(Python,SQL)/src/main/insertion.py", line 42, in record_insertion\n    with open(file_path, \'r\') as read_file:\n', "FileNotFoundError: [Errno 2] No such file or directory: 'C:/Users/balaji.a.arunachalam/PycharmProjects/Back_end(Python,SQL)/src\\\\files\\\\records\\\\customer_details.sql'\n"]
2020-10-06 11:26:01,139 - 35476 DEBUG - ['Traceback (most recent call last):\n', '  File "C:/Users/balaji.a.arunachalam/PycharmProjects/Back_end(Python,SQL)/src/main/insertion.py", line 17, in __init__\n    temp = sys.argv[1]\n', 'IndexError: list index out of range\n', '\nDuring handling of the above exception, another exception occurred:\n\n', 'Traceback (most recent call last):\n', '  File "C:/Users/balaji.a.arunachalam/PycharmProjects/Back_end(Python,SQL)/src/main/insertion.py", line 42, in record_insertion\n    with open(file_path, \'r\') as read_file:\n', "FileNotFoundError: [Errno 2] No such file or directory: 'C:/Users/balaji.a.arunachalam/PycharmProjects/Back_end(Python,SQL)/src\\\\files\\\\records\\\\order_status_details.sql'\n"]
2020-10-06 11:26:01,139 - 35476 DEBUG - ['Traceback (most recent call last):\n', '  File "C:/Users/balaji.a.arunachalam/PycharmProjects/Back_end(Python,SQL)/src/main/insertion.py", line 17, in __init__\n    temp = sys.argv[1]\n', 'IndexError: list index out of range\n', '\nDuring handling of the above exception, another exception occurred:\n\n', 'Traceback (most recent call last):\n', '  File "C:/Users/balaji.a.arunachalam/PycharmProjects/Back_end(Python,SQL)/src/main/insertion.py", line 42, in record_insertion\n    with open(file_path, \'r\') as read_file:\n', "FileNotFoundError: [Errno 2] No such file or directory: 'C:/Users/balaji.a.arunachalam/PycharmProjects/Back_end(Python,SQL)/src\\\\files\\\\records\\\\order_status_details.sql'\n"]
2020-10-06 11:26:01,139 - 35476 DEBUG - ['Traceback (most recent call last):\n', '  File "C:/Users/balaji.a.arunachalam/PycharmProjects/Back_end(Python,SQL)/src/main/insertion.py", line 17, in __init__\n    temp = sys.argv[1]\n', 'IndexError: list index out of range\n', '\nDuring handling of the above exception, another exception occurred:\n\n', 'Traceback (most recent call last):\n', '  File "C:/Users/balaji.a.arunachalam/PycharmProjects/Back_end(Python,SQL)/src/main/insertion.py", line 42, in record_insertion\n    with open(file_path, \'r\') as read_file:\n', "FileNotFoundError: [Errno 2] No such file or directory: 'C:/Users/balaji.a.arunachalam/PycharmProjects/Back_end(Python,SQL)/src\\\\files\\\\records\\\\order_status_details.sql'\n"]
2020-10-06 11:26:01,140 - 35476 DEBUG - ['Traceback (most recent call last):\n', '  File "C:/Users/balaji.a.arunachalam/PycharmProjects/Back_end(Python,SQL)/src/main/insertion.py", line 17, in __init__\n    temp = sys.argv[1]\n', 'IndexError: list index out of range\n', '\nDuring handling of the above exception, another exception occurred:\n\n', 'Traceback (most recent call last):\n', '  File "C:/Users/balaji.a.arunachalam/PycharmProjects/Back_end(Python,SQL)/src/main/insertion.py", line 42, in record_insertion\n    with open(file_path, \'r\') as read_file:\n', "FileNotFoundError: [Errno 2] No such file or directory: 'C:/Users/balaji.a.arunachalam/PycharmProjects/Back_end(Python,SQL)/src\\\\files\\\\records\\\\seller_details.sql'\n"]
2020-10-06 11:26:01,140 - 35476 DEBUG - ['Traceback (most recent call last):\n', '  File "C:/Users/balaji.a.arunachalam/PycharmProjects/Back_end(Python,SQL)/src/main/insertion.py", line 17, in __init__\n    temp = sys.argv[1]\n', 'IndexError: list index out of range\n', '\nDuring handling of the above exception, another exception occurred:\n\n', 'Traceback (most recent call last):\n', '  File "C:/Users/balaji.a.arunachalam/PycharmProjects/Back_end(Python,SQL)/src/main/insertion.py", line 42, in record_insertion\n    with open(file_path, \'r\') as read_file:\n', "FileNotFoundError: [Errno 2] No such file or directory: 'C:/Users/balaji.a.arunachalam/PycharmProjects/Back_end(Python,SQL)/src\\\\files\\\\records\\\\seller_details.sql'\n"]
2020-10-06 11:26:01,140 - 35476 DEBUG - ['Traceback (most recent call last):\n', '  File "C:/Users/balaji.a.arunachalam/PycharmProjects/Back_end(Python,SQL)/src/main/insertion.py", line 17, in __init__\n    temp = sys.argv[1]\n', 'IndexError: list index out of range\n', '\nDuring handling of the above exception, another exception occurred:\n\n', 'Traceback (most recent call last):\n', '  File "C:/Users/balaji.a.arunachalam/PycharmProjects/Back_end(Python,SQL)/src/main/insertion.py", line 42, in record_insertion\n    with open(file_path, \'r\') as read_file:\n', "FileNotFoundError: [Errno 2] No such file or directory: 'C:/Users/balaji.a.arunachalam/PycharmProjects/Back_end(Python,SQL)/src\\\\files\\\\records\\\\seller_details.sql'\n"]
2020-10-06 11:26:01,141 - 35476 DEBUG - ['Traceback (most recent call last):\n', '  File "C:/Users/balaji.a.arunachalam/PycharmProjects/Back_end(Python,SQL)/src/main/insertion.py", line 17, in __init__\n    temp = sys.argv[1]\n', 'IndexError: list index out of range\n', '\nDuring handling of the above exception, another exception occurred:\n\n', 'Traceback (most recent call last):\n', '  File "C:/Users/balaji.a.arunachalam/PycharmProjects/Back_end(Python,SQL)/src/main/insertion.py", line 42, in record_insertion\n    with open(file_path, \'r\') as read_file:\n', "FileNotFoundError: [Errno 2] No such file or directory: 'C:/Users/balaji.a.arunachalam/PycharmProjects/Back_end(Python,SQL)/src\\\\files\\\\records\\\\cart_details.sql'\n"]
2020-10-06 11:26:01,141 - 35476 DEBUG - ['Traceback (most recent call last):\n', '  File "C:/Users/balaji.a.arunachalam/PycharmProjects/Back_end(Python,SQL)/src/main/insertion.py", line 17, in __init__\n    temp = sys.argv[1]\n', 'IndexError: list index out of range\n', '\nDuring handling of the above exception, another exception occurred:\n\n', 'Traceback (most recent call last):\n', '  File "C:/Users/balaji.a.arunachalam/PycharmProjects/Back_end(Python,SQL)/src/main/insertion.py", line 42, in record_insertion\n    with open(file_path, \'r\') as read_file:\n', "FileNotFoundError: [Errno 2] No such file or directory: 'C:/Users/balaji.a.arunachalam/PycharmProjects/Back_end(Python,SQL)/src\\\\files\\\\records\\\\cart_details.sql'\n"]
2020-10-06 11:26:01,141 - 35476 DEBUG - ['Traceback (most recent call last):\n', '  File "C:/Users/balaji.a.arunachalam/PycharmProjects/Back_end(Python,SQL)/src/main/insertion.py", line 17, in __init__\n    temp = sys.argv[1]\n', 'IndexError: list index out of range\n', '\nDuring handling of the above exception, another exception occurred:\n\n', 'Traceback (most recent call last):\n', '  File "C:/Users/balaji.a.arunachalam/PycharmProjects/Back_end(Python,SQL)/src/main/insertion.py", line 42, in record_insertion\n    with open(file_path, \'r\') as read_file:\n', "FileNotFoundError: [Errno 2] No such file or directory: 'C:/Users/balaji.a.arunachalam/PycharmProjects/Back_end(Python,SQL)/src\\\\files\\\\records\\\\cart_details.sql'\n"]
2020-10-06 11:26:01,141 - 35476 DEBUG - ['Traceback (most recent call last):\n', '  File "C:/Users/balaji.a.arunachalam/PycharmProjects/Back_end(Python,SQL)/src/main/insertion.py", line 17, in __init__\n    temp = sys.argv[1]\n', 'IndexError: list index out of range\n', '\nDuring handling of the above exception, another exception occurred:\n\n', 'Traceback (most recent call last):\n', '  File "C:/Users/balaji.a.arunachalam/PycharmProjects/Back_end(Python,SQL)/src/main/insertion.py", line 42, in record_insertion\n    with open(file_path, \'r\') as read_file:\n', "FileNotFoundError: [Errno 2] No such file or directory: 'C:/Users/balaji.a.arunachalam/PycharmProjects/Back_end(Python,SQL)/src\\\\files\\\\records\\\\customer_address_details.sql'\n"]
2020-10-06 11:26:01,141 - 35476 DEBUG - ['Traceback (most recent call last):\n', '  File "C:/Users/balaji.a.arunachalam/PycharmProjects/Back_end(Python,SQL)/src/main/insertion.py", line 17, in __init__\n    temp = sys.argv[1]\n', 'IndexError: list index out of range\n', '\nDuring handling of the above exception, another exception occurred:\n\n', 'Traceback (most recent call last):\n', '  File "C:/Users/balaji.a.arunachalam/PycharmProjects/Back_end(Python,SQL)/src/main/insertion.py", line 42, in record_insertion\n    with open(file_path, \'r\') as read_file:\n', "FileNotFoundError: [Errno 2] No such file or directory: 'C:/Users/balaji.a.arunachalam/PycharmProjects/Back_end(Python,SQL)/src\\\\files\\\\records\\\\customer_address_details.sql'\n"]
2020-10-06 11:26:01,141 - 35476 DEBUG - ['Traceback (most recent call last):\n', '  File "C:/Users/balaji.a.arunachalam/PycharmProjects/Back_end(Python,SQL)/src/main/insertion.py", line 17, in __init__\n    temp = sys.argv[1]\n', 'IndexError: list index out of range\n', '\nDuring handling of the above exception, another exception occurred:\n\n', 'Traceback (most recent call last):\n', '  File "C:/Users/balaji.a.arunachalam/PycharmProjects/Back_end(Python,SQL)/src/main/insertion.py", line 42, in record_insertion\n    with open(file_path, \'r\') as read_file:\n', "FileNotFoundError: [Errno 2] No such file or directory: 'C:/Users/balaji.a.arunachalam/PycharmProjects/Back_end(Python,SQL)/src\\\\files\\\\records\\\\customer_address_details.sql'\n"]
2020-10-06 11:26:01,142 - 35476 DEBUG - ['Traceback (most recent call last):\n', '  File "C:/Users/balaji.a.arunachalam/PycharmProjects/Back_end(Python,SQL)/src/main/insertion.py", line 17, in __init__\n    temp = sys.argv[1]\n', 'IndexError: list index out of range\n', '\nDuring handling of the above exception, another exception occurred:\n\n', 'Traceback (most recent call last):\n', '  File "C:/Users/balaji.a.arunachalam/PycharmProjects/Back_end(Python,SQL)/src/main/insertion.py", line 42, in record_insertion\n    with open(file_path, \'r\') as read_file:\n', "FileNotFoundError: [Errno 2] No such file or directory: 'C:/Users/balaji.a.arunachalam/PycharmProjects/Back_end(Python,SQL)/src\\\\files\\\\records\\\\order_details.sql'\n"]
2020-10-06 11:26:01,142 - 35476 DEBUG - ['Traceback (most recent call last):\n', '  File "C:/Users/balaji.a.arunachalam/PycharmProjects/Back_end(Python,SQL)/src/main/insertion.py", line 17, in __init__\n    temp = sys.argv[1]\n', 'IndexError: list index out of range\n', '\nDuring handling of the above exception, another exception occurred:\n\n', 'Traceback (most recent call last):\n', '  File "C:/Users/balaji.a.arunachalam/PycharmProjects/Back_end(Python,SQL)/src/main/insertion.py", line 42, in record_insertion\n    with open(file_path, \'r\') as read_file:\n', "FileNotFoundError: [Errno 2] No such file or directory: 'C:/Users/balaji.a.arunachalam/PycharmProjects/Back_end(Python,SQL)/src\\\\files\\\\records\\\\order_details.sql'\n"]
2020-10-06 11:26:01,142 - 35476 DEBUG - ['Traceback (most recent call last):\n', '  File "C:/Users/balaji.a.arunachalam/PycharmProjects/Back_end(Python,SQL)/src/main/insertion.py", line 17, in __init__\n    temp = sys.argv[1]\n', 'IndexError: list index out of range\n', '\nDuring handling of the above exception, another exception occurred:\n\n', 'Traceback (most recent call last):\n', '  File "C:/Users/balaji.a.arunachalam/PycharmProjects/Back_end(Python,SQL)/src/main/insertion.py", line 42, in record_insertion\n    with open(file_path, \'r\') as read_file:\n', "FileNotFoundError: [Errno 2] No such file or directory: 'C:/Users/balaji.a.arunachalam/PycharmProjects/Back_end(Python,SQL)/src\\\\files\\\\records\\\\order_details.sql'\n"]
2020-10-06 11:26:01,143 - 35476 DEBUG - ['Traceback (most recent call last):\n', '  File "C:/Users/balaji.a.arunachalam/PycharmProjects/Back_end(Python,SQL)/src/main/insertion.py", line 17, in __init__\n    temp = sys.argv[1]\n', 'IndexError: list index out of range\n', '\nDuring handling of the above exception, another exception occurred:\n\n', 'Traceback (most recent call last):\n', '  File "C:/Users/balaji.a.arunachalam/PycharmProjects/Back_end(Python,SQL)/src/main/insertion.py", line 42, in record_insertion\n    with open(file_path, \'r\') as read_file:\n', "FileNotFoundError: [Errno 2] No such file or directory: 'C:/Users/balaji.a.arunachalam/PycharmProjects/Back_end(Python,SQL)/src\\\\files\\\\records\\\\product_stock_details.sql'\n"]
2020-10-06 11:26:01,143 - 35476 DEBUG - ['Traceback (most recent call last):\n', '  File "C:/Users/balaji.a.arunachalam/PycharmProjects/Back_end(Python,SQL)/src/main/insertion.py", line 17, in __init__\n    temp = sys.argv[1]\n', 'IndexError: list index out of range\n', '\nDuring handling of the above exception, another exception occurred:\n\n', 'Traceback (most recent call last):\n', '  File "C:/Users/balaji.a.arunachalam/PycharmProjects/Back_end(Python,SQL)/src/main/insertion.py", line 42, in record_insertion\n    with open(file_path, \'r\') as read_file:\n', "FileNotFoundError: [Errno 2] No such file or directory: 'C:/Users/balaji.a.arunachalam/PycharmProjects/Back_end(Python,SQL)/src\\\\files\\\\records\\\\product_stock_details.sql'\n"]
2020-10-06 11:26:01,143 - 35476 DEBUG - ['Traceback (most recent call last):\n', '  File "C:/Users/balaji.a.arunachalam/PycharmProjects/Back_end(Python,SQL)/src/main/insertion.py", line 17, in __init__\n    temp = sys.argv[1]\n', 'IndexError: list index out of range\n', '\nDuring handling of the above exception, another exception occurred:\n\n', 'Traceback (most recent call last):\n', '  File "C:/Users/balaji.a.arunachalam/PycharmProjects/Back_end(Python,SQL)/src/main/insertion.py", line 42, in record_insertion\n    with open(file_path, \'r\') as read_file:\n', "FileNotFoundError: [Errno 2] No such file or directory: 'C:/Users/balaji.a.arunachalam/PycharmProjects/Back_end(Python,SQL)/src\\\\files\\\\records\\\\product_stock_details.sql'\n"]
2020-10-06 11:26:01,144 - 35476 DEBUG - ['Traceback (most recent call last):\n', '  File "C:/Users/balaji.a.arunachalam/PycharmProjects/Back_end(Python,SQL)/src/main/insertion.py", line 17, in __init__\n    temp = sys.argv[1]\n', 'IndexError: list index out of range\n', '\nDuring handling of the above exception, another exception occurred:\n\n', 'Traceback (most recent call last):\n', '  File "C:/Users/balaji.a.arunachalam/PycharmProjects/Back_end(Python,SQL)/src/main/insertion.py", line 42, in record_insertion\n    with open(file_path, \'r\') as read_file:\n', "FileNotFoundError: [Errno 2] No such file or directory: 'C:/Users/balaji.a.arunachalam/PycharmProjects/Back_end(Python,SQL)/src\\\\files\\\\records\\\\product_details.sql'\n"]
2020-10-06 11:26:01,144 - 35476 DEBUG - ['Traceback (most recent call last):\n', '  File "C:/Users/balaji.a.arunachalam/PycharmProjects/Back_end(Python,SQL)/src/main/insertion.py", line 17, in __init__\n    temp = sys.argv[1]\n', 'IndexError: list index out of range\n', '\nDuring handling of the above exception, another exception occurred:\n\n', 'Traceback (most recent call last):\n', '  File "C:/Users/balaji.a.arunachalam/PycharmProjects/Back_end(Python,SQL)/src/main/insertion.py", line 42, in record_insertion\n    with open(file_path, \'r\') as read_file:\n', "FileNotFoundError: [Errno 2] No such file or directory: 'C:/Users/balaji.a.arunachalam/PycharmProjects/Back_end(Python,SQL)/src\\\\files\\\\records\\\\product_details.sql'\n"]
2020-10-06 11:26:01,144 - 35476 DEBUG - ['Traceback (most recent call last):\n', '  File "C:/Users/balaji.a.arunachalam/PycharmProjects/Back_end(Python,SQL)/src/main/insertion.py", line 17, in __init__\n    temp = sys.argv[1]\n', 'IndexError: list index out of range\n', '\nDuring handling of the above exception, another exception occurred:\n\n', 'Traceback (most recent call last):\n', '  File "C:/Users/balaji.a.arunachalam/PycharmProjects/Back_end(Python,SQL)/src/main/insertion.py", line 42, in record_insertion\n    with open(file_path, \'r\') as read_file:\n', "FileNotFoundError: [Errno 2] No such file or directory: 'C:/Users/balaji.a.arunachalam/PycharmProjects/Back_end(Python,SQL)/src\\\\files\\\\records\\\\product_details.sql'\n"]
2020-10-06 11:26:01,145 - 35476 DEBUG - ['Traceback (most recent call last):\n', '  File "C:/Users/balaji.a.arunachalam/PycharmProjects/Back_end(Python,SQL)/src/main/insertion.py", line 17, in __init__\n    temp = sys.argv[1]\n', 'IndexError: list index out of range\n', '\nDuring handling of the above exception, another exception occurred:\n\n', 'Traceback (most recent call last):\n', '  File "C:/Users/balaji.a.arunachalam/PycharmProjects/Back_end(Python,SQL)/src/main/insertion.py", line 42, in record_insertion\n    with open(file_path, \'r\') as read_file:\n', "FileNotFoundError: [Errno 2] No such file or directory: 'C:/Users/balaji.a.arunachalam/PycharmProjects/Back_end(Python,SQL)/src\\\\files\\\\records\\\\cart_product_details.sql'\n"]
2020-10-06 11:26:01,145 - 35476 DEBUG - ['Traceback (most recent call last):\n', '  File "C:/Users/balaji.a.arunachalam/PycharmProjects/Back_end(Python,SQL)/src/main/insertion.py", line 17, in __init__\n    temp = sys.argv[1]\n', 'IndexError: list index out of range\n', '\nDuring handling of the above exception, another exception occurred:\n\n', 'Traceback (most recent call last):\n', '  File "C:/Users/balaji.a.arunachalam/PycharmProjects/Back_end(Python,SQL)/src/main/insertion.py", line 42, in record_insertion\n    with open(file_path, \'r\') as read_file:\n', "FileNotFoundError: [Errno 2] No such file or directory: 'C:/Users/balaji.a.arunachalam/PycharmProjects/Back_end(Python,SQL)/src\\\\files\\\\records\\\\cart_product_details.sql'\n"]
2020-10-06 11:26:01,145 - 35476 DEBUG - ['Traceback (most recent call last):\n', '  File "C:/Users/balaji.a.arunachalam/PycharmProjects/Back_end(Python,SQL)/src/main/insertion.py", line 17, in __init__\n    temp = sys.argv[1]\n', 'IndexError: list index out of range\n', '\nDuring handling of the above exception, another exception occurred:\n\n', 'Traceback (most recent call last):\n', '  File "C:/Users/balaji.a.arunachalam/PycharmProjects/Back_end(Python,SQL)/src/main/insertion.py", line 42, in record_insertion\n    with open(file_path, \'r\') as read_file:\n', "FileNotFoundError: [Errno 2] No such file or directory: 'C:/Users/balaji.a.arunachalam/PycharmProjects/Back_end(Python,SQL)/src\\\\files\\\\records\\\\cart_product_details.sql'\n"]
2020-10-06 11:26:01,146 - 35476 DEBUG - ['Traceback (most recent call last):\n', '  File "C:/Users/balaji.a.arunachalam/PycharmProjects/Back_end(Python,SQL)/src/main/insertion.py", line 17, in __init__\n    temp = sys.argv[1]\n', 'IndexError: list index out of range\n', '\nDuring handling of the above exception, another exception occurred:\n\n', 'Traceback (most recent call last):\n', '  File "C:/Users/balaji.a.arunachalam/PycharmProjects/Back_end(Python,SQL)/src/main/insertion.py", line 42, in record_insertion\n    with open(file_path, \'r\') as read_file:\n', "FileNotFoundError: [Errno 2] No such file or directory: 'C:/Users/balaji.a.arunachalam/PycharmProjects/Back_end(Python,SQL)/src\\\\files\\\\records\\\\category_product_details.sql'\n"]
2020-10-06 11:26:01,146 - 35476 DEBUG - ['Traceback (most recent call last):\n', '  File "C:/Users/balaji.a.arunachalam/PycharmProjects/Back_end(Python,SQL)/src/main/insertion.py", line 17, in __init__\n    temp = sys.argv[1]\n', 'IndexError: list index out of range\n', '\nDuring handling of the above exception, another exception occurred:\n\n', 'Traceback (most recent call last):\n', '  File "C:/Users/balaji.a.arunachalam/PycharmProjects/Back_end(Python,SQL)/src/main/insertion.py", line 42, in record_insertion\n    with open(file_path, \'r\') as read_file:\n', "FileNotFoundError: [Errno 2] No such file or directory: 'C:/Users/balaji.a.arunachalam/PycharmProjects/Back_end(Python,SQL)/src\\\\files\\\\records\\\\category_product_details.sql'\n"]
2020-10-06 11:26:01,146 - 35476 DEBUG - ['Traceback (most recent call last):\n', '  File "C:/Users/balaji.a.arunachalam/PycharmProjects/Back_end(Python,SQL)/src/main/insertion.py", line 17, in __init__\n    temp = sys.argv[1]\n', 'IndexError: list index out of range\n', '\nDuring handling of the above exception, another exception occurred:\n\n', 'Traceback (most recent call last):\n', '  File "C:/Users/balaji.a.arunachalam/PycharmProjects/Back_end(Python,SQL)/src/main/insertion.py", line 42, in record_insertion\n    with open(file_path, \'r\') as read_file:\n', "FileNotFoundError: [Errno 2] No such file or directory: 'C:/Users/balaji.a.arunachalam/PycharmProjects/Back_end(Python,SQL)/src\\\\files\\\\records\\\\category_product_details.sql'\n"]
2020-10-06 11:26:01,147 - 35476 DEBUG - ['Traceback (most recent call last):\n', '  File "C:/Users/balaji.a.arunachalam/PycharmProjects/Back_end(Python,SQL)/src/main/insertion.py", line 17, in __init__\n    temp = sys.argv[1]\n', 'IndexError: list index out of range\n', '\nDuring handling of the above exception, another exception occurred:\n\n', 'Traceback (most recent call last):\n', '  File "C:/Users/balaji.a.arunachalam/PycharmProjects/Back_end(Python,SQL)/src/main/insertion.py", line 42, in record_insertion\n    with open(file_path, \'r\') as read_file:\n', "FileNotFoundError: [Errno 2] No such file or directory: 'C:/Users/balaji.a.arunachalam/PycharmProjects/Back_end(Python,SQL)/src\\\\files\\\\records\\\\customer_rating_details.sql'\n"]
2020-10-06 11:26:01,147 - 35476 DEBUG - ['Traceback (most recent call last):\n', '  File "C:/Users/balaji.a.arunachalam/PycharmProjects/Back_end(Python,SQL)/src/main/insertion.py", line 17, in __init__\n    temp = sys.argv[1]\n', 'IndexError: list index out of range\n', '\nDuring handling of the above exception, another exception occurred:\n\n', 'Traceback (most recent call last):\n', '  File "C:/Users/balaji.a.arunachalam/PycharmProjects/Back_end(Python,SQL)/src/main/insertion.py", line 42, in record_insertion\n    with open(file_path, \'r\') as read_file:\n', "FileNotFoundError: [Errno 2] No such file or directory: 'C:/Users/balaji.a.arunachalam/PycharmProjects/Back_end(Python,SQL)/src\\\\files\\\\records\\\\customer_rating_details.sql'\n"]
2020-10-06 11:26:01,147 - 35476 DEBUG - ['Traceback (most recent call last):\n', '  File "C:/Users/balaji.a.arunachalam/PycharmProjects/Back_end(Python,SQL)/src/main/insertion.py", line 17, in __init__\n    temp = sys.argv[1]\n', 'IndexError: list index out of range\n', '\nDuring handling of the above exception, another exception occurred:\n\n', 'Traceback (most recent call last):\n', '  File "C:/Users/balaji.a.arunachalam/PycharmProjects/Back_end(Python,SQL)/src/main/insertion.py", line 42, in record_insertion\n    with open(file_path, \'r\') as read_file:\n', "FileNotFoundError: [Errno 2] No such file or directory: 'C:/Users/balaji.a.arunachalam/PycharmProjects/Back_end(Python,SQL)/src\\\\files\\\\records\\\\customer_rating_details.sql'\n"]
2020-10-06 11:26:01,147 - 35476 DEBUG - ['Traceback (most recent call last):\n', '  File "C:/Users/balaji.a.arunachalam/PycharmProjects/Back_end(Python,SQL)/src/main/insertion.py", line 17, in __init__\n    temp = sys.argv[1]\n', 'IndexError: list index out of range\n', '\nDuring handling of the above exception, another exception occurred:\n\n', 'Traceback (most recent call last):\n', '  File "C:/Users/balaji.a.arunachalam/PycharmProjects/Back_end(Python,SQL)/src/main/insertion.py", line 42, in record_insertion\n    with open(file_path, \'r\') as read_file:\n', "FileNotFoundError: [Errno 2] No such file or directory: 'C:/Users/balaji.a.arunachalam/PycharmProjects/Back_end(Python,SQL)/src\\\\files\\\\records\\\\invoice_details.sql'\n"]
2020-10-06 11:26:01,147 - 35476 DEBUG - ['Traceback (most recent call last):\n', '  File "C:/Users/balaji.a.arunachalam/PycharmProjects/Back_end(Python,SQL)/src/main/insertion.py", line 17, in __init__\n    temp = sys.argv[1]\n', 'IndexError: list index out of range\n', '\nDuring handling of the above exception, another exception occurred:\n\n', 'Traceback (most recent call last):\n', '  File "C:/Users/balaji.a.arunachalam/PycharmProjects/Back_end(Python,SQL)/src/main/insertion.py", line 42, in record_insertion\n    with open(file_path, \'r\') as read_file:\n', "FileNotFoundError: [Errno 2] No such file or directory: 'C:/Users/balaji.a.arunachalam/PycharmProjects/Back_end(Python,SQL)/src\\\\files\\\\records\\\\invoice_details.sql'\n"]
2020-10-06 11:26:01,147 - 35476 DEBUG - ['Traceback (most recent call last):\n', '  File "C:/Users/balaji.a.arunachalam/PycharmProjects/Back_end(Python,SQL)/src/main/insertion.py", line 17, in __init__\n    temp = sys.argv[1]\n', 'IndexError: list index out of range\n', '\nDuring handling of the above exception, another exception occurred:\n\n', 'Traceback (most recent call last):\n', '  File "C:/Users/balaji.a.arunachalam/PycharmProjects/Back_end(Python,SQL)/src/main/insertion.py", line 42, in record_insertion\n    with open(file_path, \'r\') as read_file:\n', "FileNotFoundError: [Errno 2] No such file or directory: 'C:/Users/balaji.a.arunachalam/PycharmProjects/Back_end(Python,SQL)/src\\\\files\\\\records\\\\invoice_details.sql'\n"]
2020-10-06 11:26:01,148 - 35476 DEBUG - ['Traceback (most recent call last):\n', '  File "C:/Users/balaji.a.arunachalam/PycharmProjects/Back_end(Python,SQL)/src/main/insertion.py", line 17, in __init__\n    temp = sys.argv[1]\n', 'IndexError: list index out of range\n', '\nDuring handling of the above exception, another exception occurred:\n\n', 'Traceback (most recent call last):\n', '  File "C:/Users/balaji.a.arunachalam/PycharmProjects/Back_end(Python,SQL)/src/main/insertion.py", line 42, in record_insertion\n    with open(file_path, \'r\') as read_file:\n', "FileNotFoundError: [Errno 2] No such file or directory: 'C:/Users/balaji.a.arunachalam/PycharmProjects/Back_end(Python,SQL)/src\\\\files\\\\records\\\\payment_details.sql'\n"]
2020-10-06 11:26:01,148 - 35476 DEBUG - ['Traceback (most recent call last):\n', '  File "C:/Users/balaji.a.arunachalam/PycharmProjects/Back_end(Python,SQL)/src/main/insertion.py", line 17, in __init__\n    temp = sys.argv[1]\n', 'IndexError: list index out of range\n', '\nDuring handling of the above exception, another exception occurred:\n\n', 'Traceback (most recent call last):\n', '  File "C:/Users/balaji.a.arunachalam/PycharmProjects/Back_end(Python,SQL)/src/main/insertion.py", line 42, in record_insertion\n    with open(file_path, \'r\') as read_file:\n', "FileNotFoundError: [Errno 2] No such file or directory: 'C:/Users/balaji.a.arunachalam/PycharmProjects/Back_end(Python,SQL)/src\\\\files\\\\records\\\\payment_details.sql'\n"]
2020-10-06 11:26:01,148 - 35476 DEBUG - ['Traceback (most recent call last):\n', '  File "C:/Users/balaji.a.arunachalam/PycharmProjects/Back_end(Python,SQL)/src/main/insertion.py", line 17, in __init__\n    temp = sys.argv[1]\n', 'IndexError: list index out of range\n', '\nDuring handling of the above exception, another exception occurred:\n\n', 'Traceback (most recent call last):\n', '  File "C:/Users/balaji.a.arunachalam/PycharmProjects/Back_end(Python,SQL)/src/main/insertion.py", line 42, in record_insertion\n    with open(file_path, \'r\') as read_file:\n', "FileNotFoundError: [Errno 2] No such file or directory: 'C:/Users/balaji.a.arunachalam/PycharmProjects/Back_end(Python,SQL)/src\\\\files\\\\records\\\\payment_details.sql'\n"]
2020-10-06 11:26:01,149 - 35476 DEBUG - ['Traceback (most recent call last):\n', '  File "C:/Users/balaji.a.arunachalam/PycharmProjects/Back_end(Python,SQL)/src/main/insertion.py", line 17, in __init__\n    temp = sys.argv[1]\n', 'IndexError: list index out of range\n', '\nDuring handling of the above exception, another exception occurred:\n\n', 'Traceback (most recent call last):\n', '  File "C:/Users/balaji.a.arunachalam/PycharmProjects/Back_end(Python,SQL)/src/main/insertion.py", line 42, in record_insertion\n    with open(file_path, \'r\') as read_file:\n', "FileNotFoundError: [Errno 2] No such file or directory: 'C:/Users/balaji.a.arunachalam/PycharmProjects/Back_end(Python,SQL)/src\\\\files\\\\records\\\\product_ordered_details.sql'\n"]
2020-10-06 11:26:01,149 - 35476 DEBUG - ['Traceback (most recent call last):\n', '  File "C:/Users/balaji.a.arunachalam/PycharmProjects/Back_end(Python,SQL)/src/main/insertion.py", line 17, in __init__\n    temp = sys.argv[1]\n', 'IndexError: list index out of range\n', '\nDuring handling of the above exception, another exception occurred:\n\n', 'Traceback (most recent call last):\n', '  File "C:/Users/balaji.a.arunachalam/PycharmProjects/Back_end(Python,SQL)/src/main/insertion.py", line 42, in record_insertion\n    with open(file_path, \'r\') as read_file:\n', "FileNotFoundError: [Errno 2] No such file or directory: 'C:/Users/balaji.a.arunachalam/PycharmProjects/Back_end(Python,SQL)/src\\\\files\\\\records\\\\product_ordered_details.sql'\n"]
2020-10-06 11:26:01,149 - 35476 DEBUG - ['Traceback (most recent call last):\n', '  File "C:/Users/balaji.a.arunachalam/PycharmProjects/Back_end(Python,SQL)/src/main/insertion.py", line 17, in __init__\n    temp = sys.argv[1]\n', 'IndexError: list index out of range\n', '\nDuring handling of the above exception, another exception occurred:\n\n', 'Traceback (most recent call last):\n', '  File "C:/Users/balaji.a.arunachalam/PycharmProjects/Back_end(Python,SQL)/src/main/insertion.py", line 42, in record_insertion\n    with open(file_path, \'r\') as read_file:\n', "FileNotFoundError: [Errno 2] No such file or directory: 'C:/Users/balaji.a.arunachalam/PycharmProjects/Back_end(Python,SQL)/src\\\\files\\\\records\\\\product_ordered_details.sql'\n"]
2020-10-06 11:26:01,149 - 35476 DEBUG - ['Traceback (most recent call last):\n', '  File "C:/Users/balaji.a.arunachalam/PycharmProjects/Back_end(Python,SQL)/src/main/insertion.py", line 17, in __init__\n    temp = sys.argv[1]\n', 'IndexError: list index out of range\n', '\nDuring handling of the above exception, another exception occurred:\n\n', 'Traceback (most recent call last):\n', '  File "C:/Users/balaji.a.arunachalam/PycharmProjects/Back_end(Python,SQL)/src/main/insertion.py", line 42, in record_insertion\n    with open(file_path, \'r\') as read_file:\n', "FileNotFoundError: [Errno 2] No such file or directory: 'C:/Users/balaji.a.arunachalam/PycharmProjects/Back_end(Python,SQL)/src\\\\files\\\\records\\\\shipping_status.sql'\n"]
2020-10-06 11:26:01,149 - 35476 DEBUG - ['Traceback (most recent call last):\n', '  File "C:/Users/balaji.a.arunachalam/PycharmProjects/Back_end(Python,SQL)/src/main/insertion.py", line 17, in __init__\n    temp = sys.argv[1]\n', 'IndexError: list index out of range\n', '\nDuring handling of the above exception, another exception occurred:\n\n', 'Traceback (most recent call last):\n', '  File "C:/Users/balaji.a.arunachalam/PycharmProjects/Back_end(Python,SQL)/src/main/insertion.py", line 42, in record_insertion\n    with open(file_path, \'r\') as read_file:\n', "FileNotFoundError: [Errno 2] No such file or directory: 'C:/Users/balaji.a.arunachalam/PycharmProjects/Back_end(Python,SQL)/src\\\\files\\\\records\\\\shipping_status.sql'\n"]
2020-10-06 11:26:01,149 - 35476 DEBUG - ['Traceback (most recent call last):\n', '  File "C:/Users/balaji.a.arunachalam/PycharmProjects/Back_end(Python,SQL)/src/main/insertion.py", line 17, in __init__\n    temp = sys.argv[1]\n', 'IndexError: list index out of range\n', '\nDuring handling of the above exception, another exception occurred:\n\n', 'Traceback (most recent call last):\n', '  File "C:/Users/balaji.a.arunachalam/PycharmProjects/Back_end(Python,SQL)/src/main/insertion.py", line 42, in record_insertion\n    with open(file_path, \'r\') as read_file:\n', "FileNotFoundError: [Errno 2] No such file or directory: 'C:/Users/balaji.a.arunachalam/PycharmProjects/Back_end(Python,SQL)/src\\\\files\\\\records\\\\shipping_status.sql'\n"]
2020-10-06 11:26:59,399 - 34096 DEBUG - ['Traceback (most recent call last):\n', '  File "C:/Users/balaji.a.arunachalam/PycharmProjects/Back_end(Python,SQL)/src/main/insertion.py", line 17, in __init__\n    temp = sys.argv[1]\n', 'IndexError: list index out of range\n', '\nDuring handling of the above exception, another exception occurred:\n\n', 'Traceback (most recent call last):\n', '  File "C:/Users/balaji.a.arunachalam/PycharmProjects/Back_end(Python,SQL)/src/main/insertion.py", line 42, in record_insertion\n    with open(file_path, \'r\') as read_file:\n', "FileNotFoundError: [Errno 2] No such file or directory: 'C:/Users/balaji.a.arunachalam/PycharmProjects/Back_end(Python,SQL)/src\\\\files\\\\records\\\\category_details'\n"]
2020-10-06 11:26:59,399 - 34096 DEBUG - ['Traceback (most recent call last):\n', '  File "C:/Users/balaji.a.arunachalam/PycharmProjects/Back_end(Python,SQL)/src/main/insertion.py", line 17, in __init__\n    temp = sys.argv[1]\n', 'IndexError: list index out of range\n', '\nDuring handling of the above exception, another exception occurred:\n\n', 'Traceback (most recent call last):\n', '  File "C:/Users/balaji.a.arunachalam/PycharmProjects/Back_end(Python,SQL)/src/main/insertion.py", line 42, in record_insertion\n    with open(file_path, \'r\') as read_file:\n', "FileNotFoundError: [Errno 2] No such file or directory: 'C:/Users/balaji.a.arunachalam/PycharmProjects/Back_end(Python,SQL)/src\\\\files\\\\records\\\\category_details'\n"]
2020-10-06 11:26:59,399 - 34096 DEBUG - ['Traceback (most recent call last):\n', '  File "C:/Users/balaji.a.arunachalam/PycharmProjects/Back_end(Python,SQL)/src/main/insertion.py", line 17, in __init__\n    temp = sys.argv[1]\n', 'IndexError: list index out of range\n', '\nDuring handling of the above exception, another exception occurred:\n\n', 'Traceback (most recent call last):\n', '  File "C:/Users/balaji.a.arunachalam/PycharmProjects/Back_end(Python,SQL)/src/main/insertion.py", line 42, in record_insertion\n    with open(file_path, \'r\') as read_file:\n', "FileNotFoundError: [Errno 2] No such file or directory: 'C:/Users/balaji.a.arunachalam/PycharmProjects/Back_end(Python,SQL)/src\\\\files\\\\records\\\\category_details'\n"]
2020-10-06 11:26:59,400 - 34096 DEBUG - ['Traceback (most recent call last):\n', '  File "C:/Users/balaji.a.arunachalam/PycharmProjects/Back_end(Python,SQL)/src/main/insertion.py", line 17, in __init__\n    temp = sys.argv[1]\n', 'IndexError: list index out of range\n', '\nDuring handling of the above exception, another exception occurred:\n\n', 'Traceback (most recent call last):\n', '  File "C:/Users/balaji.a.arunachalam/PycharmProjects/Back_end(Python,SQL)/src/main/insertion.py", line 42, in record_insertion\n    with open(file_path, \'r\') as read_file:\n', "FileNotFoundError: [Errno 2] No such file or directory: 'C:/Users/balaji.a.arunachalam/PycharmProjects/Back_end(Python,SQL)/src\\\\files\\\\records\\\\customer_details'\n"]
2020-10-06 11:26:59,400 - 34096 DEBUG - ['Traceback (most recent call last):\n', '  File "C:/Users/balaji.a.arunachalam/PycharmProjects/Back_end(Python,SQL)/src/main/insertion.py", line 17, in __init__\n    temp = sys.argv[1]\n', 'IndexError: list index out of range\n', '\nDuring handling of the above exception, another exception occurred:\n\n', 'Traceback (most recent call last):\n', '  File "C:/Users/balaji.a.arunachalam/PycharmProjects/Back_end(Python,SQL)/src/main/insertion.py", line 42, in record_insertion\n    with open(file_path, \'r\') as read_file:\n', "FileNotFoundError: [Errno 2] No such file or directory: 'C:/Users/balaji.a.arunachalam/PycharmProjects/Back_end(Python,SQL)/src\\\\files\\\\records\\\\customer_details'\n"]
2020-10-06 11:26:59,400 - 34096 DEBUG - ['Traceback (most recent call last):\n', '  File "C:/Users/balaji.a.arunachalam/PycharmProjects/Back_end(Python,SQL)/src/main/insertion.py", line 17, in __init__\n    temp = sys.argv[1]\n', 'IndexError: list index out of range\n', '\nDuring handling of the above exception, another exception occurred:\n\n', 'Traceback (most recent call last):\n', '  File "C:/Users/balaji.a.arunachalam/PycharmProjects/Back_end(Python,SQL)/src/main/insertion.py", line 42, in record_insertion\n    with open(file_path, \'r\') as read_file:\n', "FileNotFoundError: [Errno 2] No such file or directory: 'C:/Users/balaji.a.arunachalam/PycharmProjects/Back_end(Python,SQL)/src\\\\files\\\\records\\\\customer_details'\n"]
2020-10-06 11:26:59,401 - 34096 DEBUG - ['Traceback (most recent call last):\n', '  File "C:/Users/balaji.a.arunachalam/PycharmProjects/Back_end(Python,SQL)/src/main/insertion.py", line 17, in __init__\n    temp = sys.argv[1]\n', 'IndexError: list index out of range\n', '\nDuring handling of the above exception, another exception occurred:\n\n', 'Traceback (most recent call last):\n', '  File "C:/Users/balaji.a.arunachalam/PycharmProjects/Back_end(Python,SQL)/src/main/insertion.py", line 42, in record_insertion\n    with open(file_path, \'r\') as read_file:\n', "FileNotFoundError: [Errno 2] No such file or directory: 'C:/Users/balaji.a.arunachalam/PycharmProjects/Back_end(Python,SQL)/src\\\\files\\\\records\\\\order_status_details'\n"]
2020-10-06 11:26:59,401 - 34096 DEBUG - ['Traceback (most recent call last):\n', '  File "C:/Users/balaji.a.arunachalam/PycharmProjects/Back_end(Python,SQL)/src/main/insertion.py", line 17, in __init__\n    temp = sys.argv[1]\n', 'IndexError: list index out of range\n', '\nDuring handling of the above exception, another exception occurred:\n\n', 'Traceback (most recent call last):\n', '  File "C:/Users/balaji.a.arunachalam/PycharmProjects/Back_end(Python,SQL)/src/main/insertion.py", line 42, in record_insertion\n    with open(file_path, \'r\') as read_file:\n', "FileNotFoundError: [Errno 2] No such file or directory: 'C:/Users/balaji.a.arunachalam/PycharmProjects/Back_end(Python,SQL)/src\\\\files\\\\records\\\\order_status_details'\n"]
2020-10-06 11:26:59,401 - 34096 DEBUG - ['Traceback (most recent call last):\n', '  File "C:/Users/balaji.a.arunachalam/PycharmProjects/Back_end(Python,SQL)/src/main/insertion.py", line 17, in __init__\n    temp = sys.argv[1]\n', 'IndexError: list index out of range\n', '\nDuring handling of the above exception, another exception occurred:\n\n', 'Traceback (most recent call last):\n', '  File "C:/Users/balaji.a.arunachalam/PycharmProjects/Back_end(Python,SQL)/src/main/insertion.py", line 42, in record_insertion\n    with open(file_path, \'r\') as read_file:\n', "FileNotFoundError: [Errno 2] No such file or directory: 'C:/Users/balaji.a.arunachalam/PycharmProjects/Back_end(Python,SQL)/src\\\\files\\\\records\\\\order_status_details'\n"]
2020-10-06 11:26:59,402 - 34096 DEBUG - ['Traceback (most recent call last):\n', '  File "C:/Users/balaji.a.arunachalam/PycharmProjects/Back_end(Python,SQL)/src/main/insertion.py", line 17, in __init__\n    temp = sys.argv[1]\n', 'IndexError: list index out of range\n', '\nDuring handling of the above exception, another exception occurred:\n\n', 'Traceback (most recent call last):\n', '  File "C:/Users/balaji.a.arunachalam/PycharmProjects/Back_end(Python,SQL)/src/main/insertion.py", line 42, in record_insertion\n    with open(file_path, \'r\') as read_file:\n', "FileNotFoundError: [Errno 2] No such file or directory: 'C:/Users/balaji.a.arunachalam/PycharmProjects/Back_end(Python,SQL)/src\\\\files\\\\records\\\\seller_details'\n"]
2020-10-06 11:26:59,402 - 34096 DEBUG - ['Traceback (most recent call last):\n', '  File "C:/Users/balaji.a.arunachalam/PycharmProjects/Back_end(Python,SQL)/src/main/insertion.py", line 17, in __init__\n    temp = sys.argv[1]\n', 'IndexError: list index out of range\n', '\nDuring handling of the above exception, another exception occurred:\n\n', 'Traceback (most recent call last):\n', '  File "C:/Users/balaji.a.arunachalam/PycharmProjects/Back_end(Python,SQL)/src/main/insertion.py", line 42, in record_insertion\n    with open(file_path, \'r\') as read_file:\n', "FileNotFoundError: [Errno 2] No such file or directory: 'C:/Users/balaji.a.arunachalam/PycharmProjects/Back_end(Python,SQL)/src\\\\files\\\\records\\\\seller_details'\n"]
2020-10-06 11:26:59,402 - 34096 DEBUG - ['Traceback (most recent call last):\n', '  File "C:/Users/balaji.a.arunachalam/PycharmProjects/Back_end(Python,SQL)/src/main/insertion.py", line 17, in __init__\n    temp = sys.argv[1]\n', 'IndexError: list index out of range\n', '\nDuring handling of the above exception, another exception occurred:\n\n', 'Traceback (most recent call last):\n', '  File "C:/Users/balaji.a.arunachalam/PycharmProjects/Back_end(Python,SQL)/src/main/insertion.py", line 42, in record_insertion\n    with open(file_path, \'r\') as read_file:\n', "FileNotFoundError: [Errno 2] No such file or directory: 'C:/Users/balaji.a.arunachalam/PycharmProjects/Back_end(Python,SQL)/src\\\\files\\\\records\\\\seller_details'\n"]
2020-10-06 11:26:59,402 - 34096 DEBUG - ['Traceback (most recent call last):\n', '  File "C:/Users/balaji.a.arunachalam/PycharmProjects/Back_end(Python,SQL)/src/main/insertion.py", line 17, in __init__\n    temp = sys.argv[1]\n', 'IndexError: list index out of range\n', '\nDuring handling of the above exception, another exception occurred:\n\n', 'Traceback (most recent call last):\n', '  File "C:/Users/balaji.a.arunachalam/PycharmProjects/Back_end(Python,SQL)/src/main/insertion.py", line 42, in record_insertion\n    with open(file_path, \'r\') as read_file:\n', "FileNotFoundError: [Errno 2] No such file or directory: 'C:/Users/balaji.a.arunachalam/PycharmProjects/Back_end(Python,SQL)/src\\\\files\\\\records\\\\cart_details'\n"]
2020-10-06 11:26:59,402 - 34096 DEBUG - ['Traceback (most recent call last):\n', '  File "C:/Users/balaji.a.arunachalam/PycharmProjects/Back_end(Python,SQL)/src/main/insertion.py", line 17, in __init__\n    temp = sys.argv[1]\n', 'IndexError: list index out of range\n', '\nDuring handling of the above exception, another exception occurred:\n\n', 'Traceback (most recent call last):\n', '  File "C:/Users/balaji.a.arunachalam/PycharmProjects/Back_end(Python,SQL)/src/main/insertion.py", line 42, in record_insertion\n    with open(file_path, \'r\') as read_file:\n', "FileNotFoundError: [Errno 2] No such file or directory: 'C:/Users/balaji.a.arunachalam/PycharmProjects/Back_end(Python,SQL)/src\\\\files\\\\records\\\\cart_details'\n"]
2020-10-06 11:26:59,402 - 34096 DEBUG - ['Traceback (most recent call last):\n', '  File "C:/Users/balaji.a.arunachalam/PycharmProjects/Back_end(Python,SQL)/src/main/insertion.py", line 17, in __init__\n    temp = sys.argv[1]\n', 'IndexError: list index out of range\n', '\nDuring handling of the above exception, another exception occurred:\n\n', 'Traceback (most recent call last):\n', '  File "C:/Users/balaji.a.arunachalam/PycharmProjects/Back_end(Python,SQL)/src/main/insertion.py", line 42, in record_insertion\n    with open(file_path, \'r\') as read_file:\n', "FileNotFoundError: [Errno 2] No such file or directory: 'C:/Users/balaji.a.arunachalam/PycharmProjects/Back_end(Python,SQL)/src\\\\files\\\\records\\\\cart_details'\n"]
2020-10-06 11:26:59,403 - 34096 DEBUG - ['Traceback (most recent call last):\n', '  File "C:/Users/balaji.a.arunachalam/PycharmProjects/Back_end(Python,SQL)/src/main/insertion.py", line 17, in __init__\n    temp = sys.argv[1]\n', 'IndexError: list index out of range\n', '\nDuring handling of the above exception, another exception occurred:\n\n', 'Traceback (most recent call last):\n', '  File "C:/Users/balaji.a.arunachalam/PycharmProjects/Back_end(Python,SQL)/src/main/insertion.py", line 42, in record_insertion\n    with open(file_path, \'r\') as read_file:\n', "FileNotFoundError: [Errno 2] No such file or directory: 'C:/Users/balaji.a.arunachalam/PycharmProjects/Back_end(Python,SQL)/src\\\\files\\\\records\\\\customer_address_details'\n"]
2020-10-06 11:26:59,403 - 34096 DEBUG - ['Traceback (most recent call last):\n', '  File "C:/Users/balaji.a.arunachalam/PycharmProjects/Back_end(Python,SQL)/src/main/insertion.py", line 17, in __init__\n    temp = sys.argv[1]\n', 'IndexError: list index out of range\n', '\nDuring handling of the above exception, another exception occurred:\n\n', 'Traceback (most recent call last):\n', '  File "C:/Users/balaji.a.arunachalam/PycharmProjects/Back_end(Python,SQL)/src/main/insertion.py", line 42, in record_insertion\n    with open(file_path, \'r\') as read_file:\n', "FileNotFoundError: [Errno 2] No such file or directory: 'C:/Users/balaji.a.arunachalam/PycharmProjects/Back_end(Python,SQL)/src\\\\files\\\\records\\\\customer_address_details'\n"]
2020-10-06 11:26:59,403 - 34096 DEBUG - ['Traceback (most recent call last):\n', '  File "C:/Users/balaji.a.arunachalam/PycharmProjects/Back_end(Python,SQL)/src/main/insertion.py", line 17, in __init__\n    temp = sys.argv[1]\n', 'IndexError: list index out of range\n', '\nDuring handling of the above exception, another exception occurred:\n\n', 'Traceback (most recent call last):\n', '  File "C:/Users/balaji.a.arunachalam/PycharmProjects/Back_end(Python,SQL)/src/main/insertion.py", line 42, in record_insertion\n    with open(file_path, \'r\') as read_file:\n', "FileNotFoundError: [Errno 2] No such file or directory: 'C:/Users/balaji.a.arunachalam/PycharmProjects/Back_end(Python,SQL)/src\\\\files\\\\records\\\\customer_address_details'\n"]
2020-10-06 11:26:59,404 - 34096 DEBUG - ['Traceback (most recent call last):\n', '  File "C:/Users/balaji.a.arunachalam/PycharmProjects/Back_end(Python,SQL)/src/main/insertion.py", line 17, in __init__\n    temp = sys.argv[1]\n', 'IndexError: list index out of range\n', '\nDuring handling of the above exception, another exception occurred:\n\n', 'Traceback (most recent call last):\n', '  File "C:/Users/balaji.a.arunachalam/PycharmProjects/Back_end(Python,SQL)/src/main/insertion.py", line 42, in record_insertion\n    with open(file_path, \'r\') as read_file:\n', "FileNotFoundError: [Errno 2] No such file or directory: 'C:/Users/balaji.a.arunachalam/PycharmProjects/Back_end(Python,SQL)/src\\\\files\\\\records\\\\order_details'\n"]
2020-10-06 11:26:59,404 - 34096 DEBUG - ['Traceback (most recent call last):\n', '  File "C:/Users/balaji.a.arunachalam/PycharmProjects/Back_end(Python,SQL)/src/main/insertion.py", line 17, in __init__\n    temp = sys.argv[1]\n', 'IndexError: list index out of range\n', '\nDuring handling of the above exception, another exception occurred:\n\n', 'Traceback (most recent call last):\n', '  File "C:/Users/balaji.a.arunachalam/PycharmProjects/Back_end(Python,SQL)/src/main/insertion.py", line 42, in record_insertion\n    with open(file_path, \'r\') as read_file:\n', "FileNotFoundError: [Errno 2] No such file or directory: 'C:/Users/balaji.a.arunachalam/PycharmProjects/Back_end(Python,SQL)/src\\\\files\\\\records\\\\order_details'\n"]
2020-10-06 11:26:59,404 - 34096 DEBUG - ['Traceback (most recent call last):\n', '  File "C:/Users/balaji.a.arunachalam/PycharmProjects/Back_end(Python,SQL)/src/main/insertion.py", line 17, in __init__\n    temp = sys.argv[1]\n', 'IndexError: list index out of range\n', '\nDuring handling of the above exception, another exception occurred:\n\n', 'Traceback (most recent call last):\n', '  File "C:/Users/balaji.a.arunachalam/PycharmProjects/Back_end(Python,SQL)/src/main/insertion.py", line 42, in record_insertion\n    with open(file_path, \'r\') as read_file:\n', "FileNotFoundError: [Errno 2] No such file or directory: 'C:/Users/balaji.a.arunachalam/PycharmProjects/Back_end(Python,SQL)/src\\\\files\\\\records\\\\order_details'\n"]
2020-10-06 11:26:59,405 - 34096 DEBUG - ['Traceback (most recent call last):\n', '  File "C:/Users/balaji.a.arunachalam/PycharmProjects/Back_end(Python,SQL)/src/main/insertion.py", line 17, in __init__\n    temp = sys.argv[1]\n', 'IndexError: list index out of range\n', '\nDuring handling of the above exception, another exception occurred:\n\n', 'Traceback (most recent call last):\n', '  File "C:/Users/balaji.a.arunachalam/PycharmProjects/Back_end(Python,SQL)/src/main/insertion.py", line 42, in record_insertion\n    with open(file_path, \'r\') as read_file:\n', "FileNotFoundError: [Errno 2] No such file or directory: 'C:/Users/balaji.a.arunachalam/PycharmProjects/Back_end(Python,SQL)/src\\\\files\\\\records\\\\product_stock_details'\n"]
2020-10-06 11:26:59,405 - 34096 DEBUG - ['Traceback (most recent call last):\n', '  File "C:/Users/balaji.a.arunachalam/PycharmProjects/Back_end(Python,SQL)/src/main/insertion.py", line 17, in __init__\n    temp = sys.argv[1]\n', 'IndexError: list index out of range\n', '\nDuring handling of the above exception, another exception occurred:\n\n', 'Traceback (most recent call last):\n', '  File "C:/Users/balaji.a.arunachalam/PycharmProjects/Back_end(Python,SQL)/src/main/insertion.py", line 42, in record_insertion\n    with open(file_path, \'r\') as read_file:\n', "FileNotFoundError: [Errno 2] No such file or directory: 'C:/Users/balaji.a.arunachalam/PycharmProjects/Back_end(Python,SQL)/src\\\\files\\\\records\\\\product_stock_details'\n"]
2020-10-06 11:26:59,405 - 34096 DEBUG - ['Traceback (most recent call last):\n', '  File "C:/Users/balaji.a.arunachalam/PycharmProjects/Back_end(Python,SQL)/src/main/insertion.py", line 17, in __init__\n    temp = sys.argv[1]\n', 'IndexError: list index out of range\n', '\nDuring handling of the above exception, another exception occurred:\n\n', 'Traceback (most recent call last):\n', '  File "C:/Users/balaji.a.arunachalam/PycharmProjects/Back_end(Python,SQL)/src/main/insertion.py", line 42, in record_insertion\n    with open(file_path, \'r\') as read_file:\n', "FileNotFoundError: [Errno 2] No such file or directory: 'C:/Users/balaji.a.arunachalam/PycharmProjects/Back_end(Python,SQL)/src\\\\files\\\\records\\\\product_stock_details'\n"]
2020-10-06 11:26:59,405 - 34096 DEBUG - ['Traceback (most recent call last):\n', '  File "C:/Users/balaji.a.arunachalam/PycharmProjects/Back_end(Python,SQL)/src/main/insertion.py", line 17, in __init__\n    temp = sys.argv[1]\n', 'IndexError: list index out of range\n', '\nDuring handling of the above exception, another exception occurred:\n\n', 'Traceback (most recent call last):\n', '  File "C:/Users/balaji.a.arunachalam/PycharmProjects/Back_end(Python,SQL)/src/main/insertion.py", line 42, in record_insertion\n    with open(file_path, \'r\') as read_file:\n', "FileNotFoundError: [Errno 2] No such file or directory: 'C:/Users/balaji.a.arunachalam/PycharmProjects/Back_end(Python,SQL)/src\\\\files\\\\records\\\\product_details'\n"]
2020-10-06 11:26:59,405 - 34096 DEBUG - ['Traceback (most recent call last):\n', '  File "C:/Users/balaji.a.arunachalam/PycharmProjects/Back_end(Python,SQL)/src/main/insertion.py", line 17, in __init__\n    temp = sys.argv[1]\n', 'IndexError: list index out of range\n', '\nDuring handling of the above exception, another exception occurred:\n\n', 'Traceback (most recent call last):\n', '  File "C:/Users/balaji.a.arunachalam/PycharmProjects/Back_end(Python,SQL)/src/main/insertion.py", line 42, in record_insertion\n    with open(file_path, \'r\') as read_file:\n', "FileNotFoundError: [Errno 2] No such file or directory: 'C:/Users/balaji.a.arunachalam/PycharmProjects/Back_end(Python,SQL)/src\\\\files\\\\records\\\\product_details'\n"]
2020-10-06 11:26:59,405 - 34096 DEBUG - ['Traceback (most recent call last):\n', '  File "C:/Users/balaji.a.arunachalam/PycharmProjects/Back_end(Python,SQL)/src/main/insertion.py", line 17, in __init__\n    temp = sys.argv[1]\n', 'IndexError: list index out of range\n', '\nDuring handling of the above exception, another exception occurred:\n\n', 'Traceback (most recent call last):\n', '  File "C:/Users/balaji.a.arunachalam/PycharmProjects/Back_end(Python,SQL)/src/main/insertion.py", line 42, in record_insertion\n    with open(file_path, \'r\') as read_file:\n', "FileNotFoundError: [Errno 2] No such file or directory: 'C:/Users/balaji.a.arunachalam/PycharmProjects/Back_end(Python,SQL)/src\\\\files\\\\records\\\\product_details'\n"]
2020-10-06 11:26:59,406 - 34096 DEBUG - ['Traceback (most recent call last):\n', '  File "C:/Users/balaji.a.arunachalam/PycharmProjects/Back_end(Python,SQL)/src/main/insertion.py", line 17, in __init__\n    temp = sys.argv[1]\n', 'IndexError: list index out of range\n', '\nDuring handling of the above exception, another exception occurred:\n\n', 'Traceback (most recent call last):\n', '  File "C:/Users/balaji.a.arunachalam/PycharmProjects/Back_end(Python,SQL)/src/main/insertion.py", line 42, in record_insertion\n    with open(file_path, \'r\') as read_file:\n', "FileNotFoundError: [Errno 2] No such file or directory: 'C:/Users/balaji.a.arunachalam/PycharmProjects/Back_end(Python,SQL)/src\\\\files\\\\records\\\\cart_product_details'\n"]
2020-10-06 11:26:59,406 - 34096 DEBUG - ['Traceback (most recent call last):\n', '  File "C:/Users/balaji.a.arunachalam/PycharmProjects/Back_end(Python,SQL)/src/main/insertion.py", line 17, in __init__\n    temp = sys.argv[1]\n', 'IndexError: list index out of range\n', '\nDuring handling of the above exception, another exception occurred:\n\n', 'Traceback (most recent call last):\n', '  File "C:/Users/balaji.a.arunachalam/PycharmProjects/Back_end(Python,SQL)/src/main/insertion.py", line 42, in record_insertion\n    with open(file_path, \'r\') as read_file:\n', "FileNotFoundError: [Errno 2] No such file or directory: 'C:/Users/balaji.a.arunachalam/PycharmProjects/Back_end(Python,SQL)/src\\\\files\\\\records\\\\cart_product_details'\n"]
2020-10-06 11:26:59,406 - 34096 DEBUG - ['Traceback (most recent call last):\n', '  File "C:/Users/balaji.a.arunachalam/PycharmProjects/Back_end(Python,SQL)/src/main/insertion.py", line 17, in __init__\n    temp = sys.argv[1]\n', 'IndexError: list index out of range\n', '\nDuring handling of the above exception, another exception occurred:\n\n', 'Traceback (most recent call last):\n', '  File "C:/Users/balaji.a.arunachalam/PycharmProjects/Back_end(Python,SQL)/src/main/insertion.py", line 42, in record_insertion\n    with open(file_path, \'r\') as read_file:\n', "FileNotFoundError: [Errno 2] No such file or directory: 'C:/Users/balaji.a.arunachalam/PycharmProjects/Back_end(Python,SQL)/src\\\\files\\\\records\\\\cart_product_details'\n"]
2020-10-06 11:26:59,407 - 34096 DEBUG - ['Traceback (most recent call last):\n', '  File "C:/Users/balaji.a.arunachalam/PycharmProjects/Back_end(Python,SQL)/src/main/insertion.py", line 17, in __init__\n    temp = sys.argv[1]\n', 'IndexError: list index out of range\n', '\nDuring handling of the above exception, another exception occurred:\n\n', 'Traceback (most recent call last):\n', '  File "C:/Users/balaji.a.arunachalam/PycharmProjects/Back_end(Python,SQL)/src/main/insertion.py", line 42, in record_insertion\n    with open(file_path, \'r\') as read_file:\n', "FileNotFoundError: [Errno 2] No such file or directory: 'C:/Users/balaji.a.arunachalam/PycharmProjects/Back_end(Python,SQL)/src\\\\files\\\\records\\\\category_product_details'\n"]
2020-10-06 11:26:59,407 - 34096 DEBUG - ['Traceback (most recent call last):\n', '  File "C:/Users/balaji.a.arunachalam/PycharmProjects/Back_end(Python,SQL)/src/main/insertion.py", line 17, in __init__\n    temp = sys.argv[1]\n', 'IndexError: list index out of range\n', '\nDuring handling of the above exception, another exception occurred:\n\n', 'Traceback (most recent call last):\n', '  File "C:/Users/balaji.a.arunachalam/PycharmProjects/Back_end(Python,SQL)/src/main/insertion.py", line 42, in record_insertion\n    with open(file_path, \'r\') as read_file:\n', "FileNotFoundError: [Errno 2] No such file or directory: 'C:/Users/balaji.a.arunachalam/PycharmProjects/Back_end(Python,SQL)/src\\\\files\\\\records\\\\category_product_details'\n"]
2020-10-06 11:26:59,407 - 34096 DEBUG - ['Traceback (most recent call last):\n', '  File "C:/Users/balaji.a.arunachalam/PycharmProjects/Back_end(Python,SQL)/src/main/insertion.py", line 17, in __init__\n    temp = sys.argv[1]\n', 'IndexError: list index out of range\n', '\nDuring handling of the above exception, another exception occurred:\n\n', 'Traceback (most recent call last):\n', '  File "C:/Users/balaji.a.arunachalam/PycharmProjects/Back_end(Python,SQL)/src/main/insertion.py", line 42, in record_insertion\n    with open(file_path, \'r\') as read_file:\n', "FileNotFoundError: [Errno 2] No such file or directory: 'C:/Users/balaji.a.arunachalam/PycharmProjects/Back_end(Python,SQL)/src\\\\files\\\\records\\\\category_product_details'\n"]
2020-10-06 11:26:59,408 - 34096 DEBUG - ['Traceback (most recent call last):\n', '  File "C:/Users/balaji.a.arunachalam/PycharmProjects/Back_end(Python,SQL)/src/main/insertion.py", line 17, in __init__\n    temp = sys.argv[1]\n', 'IndexError: list index out of range\n', '\nDuring handling of the above exception, another exception occurred:\n\n', 'Traceback (most recent call last):\n', '  File "C:/Users/balaji.a.arunachalam/PycharmProjects/Back_end(Python,SQL)/src/main/insertion.py", line 42, in record_insertion\n    with open(file_path, \'r\') as read_file:\n', "FileNotFoundError: [Errno 2] No such file or directory: 'C:/Users/balaji.a.arunachalam/PycharmProjects/Back_end(Python,SQL)/src\\\\files\\\\records\\\\customer_rating_details'\n"]
2020-10-06 11:26:59,408 - 34096 DEBUG - ['Traceback (most recent call last):\n', '  File "C:/Users/balaji.a.arunachalam/PycharmProjects/Back_end(Python,SQL)/src/main/insertion.py", line 17, in __init__\n    temp = sys.argv[1]\n', 'IndexError: list index out of range\n', '\nDuring handling of the above exception, another exception occurred:\n\n', 'Traceback (most recent call last):\n', '  File "C:/Users/balaji.a.arunachalam/PycharmProjects/Back_end(Python,SQL)/src/main/insertion.py", line 42, in record_insertion\n    with open(file_path, \'r\') as read_file:\n', "FileNotFoundError: [Errno 2] No such file or directory: 'C:/Users/balaji.a.arunachalam/PycharmProjects/Back_end(Python,SQL)/src\\\\files\\\\records\\\\customer_rating_details'\n"]
2020-10-06 11:26:59,408 - 34096 DEBUG - ['Traceback (most recent call last):\n', '  File "C:/Users/balaji.a.arunachalam/PycharmProjects/Back_end(Python,SQL)/src/main/insertion.py", line 17, in __init__\n    temp = sys.argv[1]\n', 'IndexError: list index out of range\n', '\nDuring handling of the above exception, another exception occurred:\n\n', 'Traceback (most recent call last):\n', '  File "C:/Users/balaji.a.arunachalam/PycharmProjects/Back_end(Python,SQL)/src/main/insertion.py", line 42, in record_insertion\n    with open(file_path, \'r\') as read_file:\n', "FileNotFoundError: [Errno 2] No such file or directory: 'C:/Users/balaji.a.arunachalam/PycharmProjects/Back_end(Python,SQL)/src\\\\files\\\\records\\\\customer_rating_details'\n"]
2020-10-06 11:26:59,409 - 34096 DEBUG - ['Traceback (most recent call last):\n', '  File "C:/Users/balaji.a.arunachalam/PycharmProjects/Back_end(Python,SQL)/src/main/insertion.py", line 17, in __init__\n    temp = sys.argv[1]\n', 'IndexError: list index out of range\n', '\nDuring handling of the above exception, another exception occurred:\n\n', 'Traceback (most recent call last):\n', '  File "C:/Users/balaji.a.arunachalam/PycharmProjects/Back_end(Python,SQL)/src/main/insertion.py", line 42, in record_insertion\n    with open(file_path, \'r\') as read_file:\n', "FileNotFoundError: [Errno 2] No such file or directory: 'C:/Users/balaji.a.arunachalam/PycharmProjects/Back_end(Python,SQL)/src\\\\files\\\\records\\\\invoice_details'\n"]
2020-10-06 11:26:59,409 - 34096 DEBUG - ['Traceback (most recent call last):\n', '  File "C:/Users/balaji.a.arunachalam/PycharmProjects/Back_end(Python,SQL)/src/main/insertion.py", line 17, in __init__\n    temp = sys.argv[1]\n', 'IndexError: list index out of range\n', '\nDuring handling of the above exception, another exception occurred:\n\n', 'Traceback (most recent call last):\n', '  File "C:/Users/balaji.a.arunachalam/PycharmProjects/Back_end(Python,SQL)/src/main/insertion.py", line 42, in record_insertion\n    with open(file_path, \'r\') as read_file:\n', "FileNotFoundError: [Errno 2] No such file or directory: 'C:/Users/balaji.a.arunachalam/PycharmProjects/Back_end(Python,SQL)/src\\\\files\\\\records\\\\invoice_details'\n"]
2020-10-06 11:26:59,409 - 34096 DEBUG - ['Traceback (most recent call last):\n', '  File "C:/Users/balaji.a.arunachalam/PycharmProjects/Back_end(Python,SQL)/src/main/insertion.py", line 17, in __init__\n    temp = sys.argv[1]\n', 'IndexError: list index out of range\n', '\nDuring handling of the above exception, another exception occurred:\n\n', 'Traceback (most recent call last):\n', '  File "C:/Users/balaji.a.arunachalam/PycharmProjects/Back_end(Python,SQL)/src/main/insertion.py", line 42, in record_insertion\n    with open(file_path, \'r\') as read_file:\n', "FileNotFoundError: [Errno 2] No such file or directory: 'C:/Users/balaji.a.arunachalam/PycharmProjects/Back_end(Python,SQL)/src\\\\files\\\\records\\\\invoice_details'\n"]
2020-10-06 11:26:59,410 - 34096 DEBUG - ['Traceback (most recent call last):\n', '  File "C:/Users/balaji.a.arunachalam/PycharmProjects/Back_end(Python,SQL)/src/main/insertion.py", line 17, in __init__\n    temp = sys.argv[1]\n', 'IndexError: list index out of range\n', '\nDuring handling of the above exception, another exception occurred:\n\n', 'Traceback (most recent call last):\n', '  File "C:/Users/balaji.a.arunachalam/PycharmProjects/Back_end(Python,SQL)/src/main/insertion.py", line 42, in record_insertion\n    with open(file_path, \'r\') as read_file:\n', "FileNotFoundError: [Errno 2] No such file or directory: 'C:/Users/balaji.a.arunachalam/PycharmProjects/Back_end(Python,SQL)/src\\\\files\\\\records\\\\payment_details'\n"]
2020-10-06 11:26:59,410 - 34096 DEBUG - ['Traceback (most recent call last):\n', '  File "C:/Users/balaji.a.arunachalam/PycharmProjects/Back_end(Python,SQL)/src/main/insertion.py", line 17, in __init__\n    temp = sys.argv[1]\n', 'IndexError: list index out of range\n', '\nDuring handling of the above exception, another exception occurred:\n\n', 'Traceback (most recent call last):\n', '  File "C:/Users/balaji.a.arunachalam/PycharmProjects/Back_end(Python,SQL)/src/main/insertion.py", line 42, in record_insertion\n    with open(file_path, \'r\') as read_file:\n', "FileNotFoundError: [Errno 2] No such file or directory: 'C:/Users/balaji.a.arunachalam/PycharmProjects/Back_end(Python,SQL)/src\\\\files\\\\records\\\\payment_details'\n"]
2020-10-06 11:26:59,410 - 34096 DEBUG - ['Traceback (most recent call last):\n', '  File "C:/Users/balaji.a.arunachalam/PycharmProjects/Back_end(Python,SQL)/src/main/insertion.py", line 17, in __init__\n    temp = sys.argv[1]\n', 'IndexError: list index out of range\n', '\nDuring handling of the above exception, another exception occurred:\n\n', 'Traceback (most recent call last):\n', '  File "C:/Users/balaji.a.arunachalam/PycharmProjects/Back_end(Python,SQL)/src/main/insertion.py", line 42, in record_insertion\n    with open(file_path, \'r\') as read_file:\n', "FileNotFoundError: [Errno 2] No such file or directory: 'C:/Users/balaji.a.arunachalam/PycharmProjects/Back_end(Python,SQL)/src\\\\files\\\\records\\\\payment_details'\n"]
2020-10-06 11:26:59,410 - 34096 DEBUG - ['Traceback (most recent call last):\n', '  File "C:/Users/balaji.a.arunachalam/PycharmProjects/Back_end(Python,SQL)/src/main/insertion.py", line 17, in __init__\n    temp = sys.argv[1]\n', 'IndexError: list index out of range\n', '\nDuring handling of the above exception, another exception occurred:\n\n', 'Traceback (most recent call last):\n', '  File "C:/Users/balaji.a.arunachalam/PycharmProjects/Back_end(Python,SQL)/src/main/insertion.py", line 42, in record_insertion\n    with open(file_path, \'r\') as read_file:\n', "FileNotFoundError: [Errno 2] No such file or directory: 'C:/Users/balaji.a.arunachalam/PycharmProjects/Back_end(Python,SQL)/src\\\\files\\\\records\\\\product_ordered_details'\n"]
2020-10-06 11:26:59,410 - 34096 DEBUG - ['Traceback (most recent call last):\n', '  File "C:/Users/balaji.a.arunachalam/PycharmProjects/Back_end(Python,SQL)/src/main/insertion.py", line 17, in __init__\n    temp = sys.argv[1]\n', 'IndexError: list index out of range\n', '\nDuring handling of the above exception, another exception occurred:\n\n', 'Traceback (most recent call last):\n', '  File "C:/Users/balaji.a.arunachalam/PycharmProjects/Back_end(Python,SQL)/src/main/insertion.py", line 42, in record_insertion\n    with open(file_path, \'r\') as read_file:\n', "FileNotFoundError: [Errno 2] No such file or directory: 'C:/Users/balaji.a.arunachalam/PycharmProjects/Back_end(Python,SQL)/src\\\\files\\\\records\\\\product_ordered_details'\n"]
2020-10-06 11:26:59,410 - 34096 DEBUG - ['Traceback (most recent call last):\n', '  File "C:/Users/balaji.a.arunachalam/PycharmProjects/Back_end(Python,SQL)/src/main/insertion.py", line 17, in __init__\n    temp = sys.argv[1]\n', 'IndexError: list index out of range\n', '\nDuring handling of the above exception, another exception occurred:\n\n', 'Traceback (most recent call last):\n', '  File "C:/Users/balaji.a.arunachalam/PycharmProjects/Back_end(Python,SQL)/src/main/insertion.py", line 42, in record_insertion\n    with open(file_path, \'r\') as read_file:\n', "FileNotFoundError: [Errno 2] No such file or directory: 'C:/Users/balaji.a.arunachalam/PycharmProjects/Back_end(Python,SQL)/src\\\\files\\\\records\\\\product_ordered_details'\n"]
2020-10-06 11:26:59,411 - 34096 DEBUG - ['Traceback (most recent call last):\n', '  File "C:/Users/balaji.a.arunachalam/PycharmProjects/Back_end(Python,SQL)/src/main/insertion.py", line 17, in __init__\n    temp = sys.argv[1]\n', 'IndexError: list index out of range\n', '\nDuring handling of the above exception, another exception occurred:\n\n', 'Traceback (most recent call last):\n', '  File "C:/Users/balaji.a.arunachalam/PycharmProjects/Back_end(Python,SQL)/src/main/insertion.py", line 42, in record_insertion\n    with open(file_path, \'r\') as read_file:\n', "FileNotFoundError: [Errno 2] No such file or directory: 'C:/Users/balaji.a.arunachalam/PycharmProjects/Back_end(Python,SQL)/src\\\\files\\\\records\\\\shipping_status'\n"]
2020-10-06 11:26:59,411 - 34096 DEBUG - ['Traceback (most recent call last):\n', '  File "C:/Users/balaji.a.arunachalam/PycharmProjects/Back_end(Python,SQL)/src/main/insertion.py", line 17, in __init__\n    temp = sys.argv[1]\n', 'IndexError: list index out of range\n', '\nDuring handling of the above exception, another exception occurred:\n\n', 'Traceback (most recent call last):\n', '  File "C:/Users/balaji.a.arunachalam/PycharmProjects/Back_end(Python,SQL)/src/main/insertion.py", line 42, in record_insertion\n    with open(file_path, \'r\') as read_file:\n', "FileNotFoundError: [Errno 2] No such file or directory: 'C:/Users/balaji.a.arunachalam/PycharmProjects/Back_end(Python,SQL)/src\\\\files\\\\records\\\\shipping_status'\n"]
2020-10-06 11:26:59,411 - 34096 DEBUG - ['Traceback (most recent call last):\n', '  File "C:/Users/balaji.a.arunachalam/PycharmProjects/Back_end(Python,SQL)/src/main/insertion.py", line 17, in __init__\n    temp = sys.argv[1]\n', 'IndexError: list index out of range\n', '\nDuring handling of the above exception, another exception occurred:\n\n', 'Traceback (most recent call last):\n', '  File "C:/Users/balaji.a.arunachalam/PycharmProjects/Back_end(Python,SQL)/src/main/insertion.py", line 42, in record_insertion\n    with open(file_path, \'r\') as read_file:\n', "FileNotFoundError: [Errno 2] No such file or directory: 'C:/Users/balaji.a.arunachalam/PycharmProjects/Back_end(Python,SQL)/src\\\\files\\\\records\\\\shipping_status'\n"]
