2020-10-06 11:19:06,865 - 28552 DEBUG - ['Traceback (most recent call last):\n', '  File "C:/Users/balaji.a.arunachalam/PycharmProjects/Back_end(Python,SQL)/src/main/insertion.py", line 17, in __init__\n    temp = sys.argv[1]\n', 'IndexError: list index out of range\n', '\nDuring handling of the above exception, another exception occurred:\n\n', 'Traceback (most recent call last):\n', '  File "C:/Users/balaji.a.arunachalam/PycharmProjects/Back_end(Python,SQL)/src/main/insertion.py", line 39, in record_insertion\n    with open(file_path, \'r\') as read_file:\n', "FileNotFoundError: [Errno 2] No such file or directory: 'C:/Users/balaji.a.arunachalam/PycharmProjects/Back_end(Python,SQL)/src\\\\files\\\\records\\\\ref_category_details.sql'\n"]
2020-10-06 11:19:06,865 - 28552 DEBUG - ['Traceback (most recent call last):\n', '  File "C:/Users/balaji.a.arunachalam/PycharmProjects/Back_end(Python,SQL)/src/main/insertion.py", line 17, in __init__\n    temp = sys.argv[1]\n', 'IndexError: list index out of range\n', '\nDuring handling of the above exception, another exception occurred:\n\n', 'Traceback (most recent call last):\n', '  File "C:/Users/balaji.a.arunachalam/PycharmProjects/Back_end(Python,SQL)/src/main/insertion.py", line 39, in record_insertion\n    with open(file_path, \'r\') as read_file:\n', "FileNotFoundError: [Errno 2] No such file or directory: 'C:/Users/balaji.a.arunachalam/PycharmProjects/Back_end(Python,SQL)/src\\\\files\\\\records\\\\ref_category_details.sql'\n"]
2020-10-06 11:19:06,865 - 28552 DEBUG - ['Traceback (most recent call last):\n', '  File "C:/Users/balaji.a.arunachalam/PycharmProjects/Back_end(Python,SQL)/src/main/insertion.py", line 17, in __init__\n    temp = sys.argv[1]\n', 'IndexError: list index out of range\n', '\nDuring handling of the above exception, another exception occurred:\n\n', 'Traceback (most recent call last):\n', '  File "C:/Users/balaji.a.arunachalam/PycharmProjects/Back_end(Python,SQL)/src/main/insertion.py", line 39, in record_insertion\n    with open(file_path, \'r\') as read_file:\n', "FileNotFoundError: [Errno 2] No such file or directory: 'C:/Users/balaji.a.arunachalam/PycharmProjects/Back_end(Python,SQL)/src\\\\files\\\\records\\\\ref_category_details.sql'\n"]
2020-10-06 11:19:06,912 - 28552 DEBUG - ['Traceback (most recent call last):\n', '  File "C:/Users/balaji.a.arunachalam/PycharmProjects/Back_end(Python,SQL)/src/main/insertion.py", line 17, in __init__\n    temp = sys.argv[1]\n', 'IndexError: list index out of range\n', '\nDuring handling of the above exception, another exception occurred:\n\n', 'Traceback (most recent call last):\n', '  File "C:/Users/balaji.a.arunachalam/PycharmProjects/Back_end(Python,SQL)/src/main/insertion.py", line 39, in record_insertion\n    with open(file_path, \'r\') as read_file:\n', "FileNotFoundError: [Errno 2] No such file or directory: 'C:/Users/balaji.a.arunachalam/PycharmProjects/Back_end(Python,SQL)/src\\\\files\\\\records\\\\ref_customer_details.sql'\n"]
2020-10-06 11:19:06,912 - 28552 DEBUG - ['Traceback (most recent call last):\n', '  File "C:/Users/balaji.a.arunachalam/PycharmProjects/Back_end(Python,SQL)/src/main/insertion.py", line 17, in __init__\n    temp = sys.argv[1]\n', 'IndexError: list index out of range\n', '\nDuring handling of the above exception, another exception occurred:\n\n', 'Traceback (most recent call last):\n', '  File "C:/Users/balaji.a.arunachalam/PycharmProjects/Back_end(Python,SQL)/src/main/insertion.py", line 39, in record_insertion\n    with open(file_path, \'r\') as read_file:\n', "FileNotFoundError: [Errno 2] No such file or directory: 'C:/Users/balaji.a.arunachalam/PycharmProjects/Back_end(Python,SQL)/src\\\\files\\\\records\\\\ref_customer_details.sql'\n"]
2020-10-06 11:19:06,912 - 28552 DEBUG - ['Traceback (most recent call last):\n', '  File "C:/Users/balaji.a.arunachalam/PycharmProjects/Back_end(Python,SQL)/src/main/insertion.py", line 17, in __init__\n    temp = sys.argv[1]\n', 'IndexError: list index out of range\n', '\nDuring handling of the above exception, another exception occurred:\n\n', 'Traceback (most recent call last):\n', '  File "C:/Users/balaji.a.arunachalam/PycharmProjects/Back_end(Python,SQL)/src/main/insertion.py", line 39, in record_insertion\n    with open(file_path, \'r\') as read_file:\n', "FileNotFoundError: [Errno 2] No such file or directory: 'C:/Users/balaji.a.arunachalam/PycharmProjects/Back_end(Python,SQL)/src\\\\files\\\\records\\\\ref_customer_details.sql'\n"]
2020-10-06 11:19:06,913 - 28552 DEBUG - ['Traceback (most recent call last):\n', '  File "C:/Users/balaji.a.arunachalam/PycharmProjects/Back_end(Python,SQL)/src/main/insertion.py", line 17, in __init__\n    temp = sys.argv[1]\n', 'IndexError: list index out of range\n', '\nDuring handling of the above exception, another exception occurred:\n\n', 'Traceback (most recent call last):\n', '  File "C:/Users/balaji.a.arunachalam/PycharmProjects/Back_end(Python,SQL)/src/main/insertion.py", line 39, in record_insertion\n    with open(file_path, \'r\') as read_file:\n', "FileNotFoundError: [Errno 2] No such file or directory: 'C:/Users/balaji.a.arunachalam/PycharmProjects/Back_end(Python,SQL)/src\\\\files\\\\records\\\\ref_order_status_details.sql'\n"]
2020-10-06 11:19:06,913 - 28552 DEBUG - ['Traceback (most recent call last):\n', '  File "C:/Users/balaji.a.arunachalam/PycharmProjects/Back_end(Python,SQL)/src/main/insertion.py", line 17, in __init__\n    temp = sys.argv[1]\n', 'IndexError: list index out of range\n', '\nDuring handling of the above exception, another exception occurred:\n\n', 'Traceback (most recent call last):\n', '  File "C:/Users/balaji.a.arunachalam/PycharmProjects/Back_end(Python,SQL)/src/main/insertion.py", line 39, in record_insertion\n    with open(file_path, \'r\') as read_file:\n', "FileNotFoundError: [Errno 2] No such file or directory: 'C:/Users/balaji.a.arunachalam/PycharmProjects/Back_end(Python,SQL)/src\\\\files\\\\records\\\\ref_order_status_details.sql'\n"]
2020-10-06 11:19:06,913 - 28552 DEBUG - ['Traceback (most recent call last):\n', '  File "C:/Users/balaji.a.arunachalam/PycharmProjects/Back_end(Python,SQL)/src/main/insertion.py", line 17, in __init__\n    temp = sys.argv[1]\n', 'IndexError: list index out of range\n', '\nDuring handling of the above exception, another exception occurred:\n\n', 'Traceback (most recent call last):\n', '  File "C:/Users/balaji.a.arunachalam/PycharmProjects/Back_end(Python,SQL)/src/main/insertion.py", line 39, in record_insertion\n    with open(file_path, \'r\') as read_file:\n', "FileNotFoundError: [Errno 2] No such file or directory: 'C:/Users/balaji.a.arunachalam/PycharmProjects/Back_end(Python,SQL)/src\\\\files\\\\records\\\\ref_order_status_details.sql'\n"]
2020-10-06 11:19:06,914 - 28552 DEBUG - ['Traceback (most recent call last):\n', '  File "C:/Users/balaji.a.arunachalam/PycharmProjects/Back_end(Python,SQL)/src/main/insertion.py", line 17, in __init__\n    temp = sys.argv[1]\n', 'IndexError: list index out of range\n', '\nDuring handling of the above exception, another exception occurred:\n\n', 'Traceback (most recent call last):\n', '  File "C:/Users/balaji.a.arunachalam/PycharmProjects/Back_end(Python,SQL)/src/main/insertion.py", line 39, in record_insertion\n    with open(file_path, \'r\') as read_file:\n', "FileNotFoundError: [Errno 2] No such file or directory: 'C:/Users/balaji.a.arunachalam/PycharmProjects/Back_end(Python,SQL)/src\\\\files\\\\records\\\\ref_seller_details.sql'\n"]
2020-10-06 11:19:06,914 - 28552 DEBUG - ['Traceback (most recent call last):\n', '  File "C:/Users/balaji.a.arunachalam/PycharmProjects/Back_end(Python,SQL)/src/main/insertion.py", line 17, in __init__\n    temp = sys.argv[1]\n', 'IndexError: list index out of range\n', '\nDuring handling of the above exception, another exception occurred:\n\n', 'Traceback (most recent call last):\n', '  File "C:/Users/balaji.a.arunachalam/PycharmProjects/Back_end(Python,SQL)/src/main/insertion.py", line 39, in record_insertion\n    with open(file_path, \'r\') as read_file:\n', "FileNotFoundError: [Errno 2] No such file or directory: 'C:/Users/balaji.a.arunachalam/PycharmProjects/Back_end(Python,SQL)/src\\\\files\\\\records\\\\ref_seller_details.sql'\n"]
2020-10-06 11:19:06,914 - 28552 DEBUG - ['Traceback (most recent call last):\n', '  File "C:/Users/balaji.a.arunachalam/PycharmProjects/Back_end(Python,SQL)/src/main/insertion.py", line 17, in __init__\n    temp = sys.argv[1]\n', 'IndexError: list index out of range\n', '\nDuring handling of the above exception, another exception occurred:\n\n', 'Traceback (most recent call last):\n', '  File "C:/Users/balaji.a.arunachalam/PycharmProjects/Back_end(Python,SQL)/src/main/insertion.py", line 39, in record_insertion\n    with open(file_path, \'r\') as read_file:\n', "FileNotFoundError: [Errno 2] No such file or directory: 'C:/Users/balaji.a.arunachalam/PycharmProjects/Back_end(Python,SQL)/src\\\\files\\\\records\\\\ref_seller_details.sql'\n"]
2020-10-06 11:19:06,915 - 28552 DEBUG - ['Traceback (most recent call last):\n', '  File "C:/Users/balaji.a.arunachalam/PycharmProjects/Back_end(Python,SQL)/src/main/insertion.py", line 17, in __init__\n    temp = sys.argv[1]\n', 'IndexError: list index out of range\n', '\nDuring handling of the above exception, another exception occurred:\n\n', 'Traceback (most recent call last):\n', '  File "C:/Users/balaji.a.arunachalam/PycharmProjects/Back_end(Python,SQL)/src/main/insertion.py", line 39, in record_insertion\n    with open(file_path, \'r\') as read_file:\n', "FileNotFoundError: [Errno 2] No such file or directory: 'C:/Users/balaji.a.arunachalam/PycharmProjects/Back_end(Python,SQL)/src\\\\files\\\\records\\\\ref_cart_details.sql'\n"]
2020-10-06 11:19:06,915 - 28552 DEBUG - ['Traceback (most recent call last):\n', '  File "C:/Users/balaji.a.arunachalam/PycharmProjects/Back_end(Python,SQL)/src/main/insertion.py", line 17, in __init__\n    temp = sys.argv[1]\n', 'IndexError: list index out of range\n', '\nDuring handling of the above exception, another exception occurred:\n\n', 'Traceback (most recent call last):\n', '  File "C:/Users/balaji.a.arunachalam/PycharmProjects/Back_end(Python,SQL)/src/main/insertion.py", line 39, in record_insertion\n    with open(file_path, \'r\') as read_file:\n', "FileNotFoundError: [Errno 2] No such file or directory: 'C:/Users/balaji.a.arunachalam/PycharmProjects/Back_end(Python,SQL)/src\\\\files\\\\records\\\\ref_cart_details.sql'\n"]
2020-10-06 11:19:06,915 - 28552 DEBUG - ['Traceback (most recent call last):\n', '  File "C:/Users/balaji.a.arunachalam/PycharmProjects/Back_end(Python,SQL)/src/main/insertion.py", line 17, in __init__\n    temp = sys.argv[1]\n', 'IndexError: list index out of range\n', '\nDuring handling of the above exception, another exception occurred:\n\n', 'Traceback (most recent call last):\n', '  File "C:/Users/balaji.a.arunachalam/PycharmProjects/Back_end(Python,SQL)/src/main/insertion.py", line 39, in record_insertion\n    with open(file_path, \'r\') as read_file:\n', "FileNotFoundError: [Errno 2] No such file or directory: 'C:/Users/balaji.a.arunachalam/PycharmProjects/Back_end(Python,SQL)/src\\\\files\\\\records\\\\ref_cart_details.sql'\n"]
2020-10-06 11:19:06,916 - 28552 DEBUG - ['Traceback (most recent call last):\n', '  File "C:/Users/balaji.a.arunachalam/PycharmProjects/Back_end(Python,SQL)/src/main/insertion.py", line 17, in __init__\n    temp = sys.argv[1]\n', 'IndexError: list index out of range\n', '\nDuring handling of the above exception, another exception occurred:\n\n', 'Traceback (most recent call last):\n', '  File "C:/Users/balaji.a.arunachalam/PycharmProjects/Back_end(Python,SQL)/src/main/insertion.py", line 39, in record_insertion\n    with open(file_path, \'r\') as read_file:\n', "FileNotFoundError: [Errno 2] No such file or directory: 'C:/Users/balaji.a.arunachalam/PycharmProjects/Back_end(Python,SQL)/src\\\\files\\\\records\\\\ref_customer_address_details.sql'\n"]
2020-10-06 11:19:06,916 - 28552 DEBUG - ['Traceback (most recent call last):\n', '  File "C:/Users/balaji.a.arunachalam/PycharmProjects/Back_end(Python,SQL)/src/main/insertion.py", line 17, in __init__\n    temp = sys.argv[1]\n', 'IndexError: list index out of range\n', '\nDuring handling of the above exception, another exception occurred:\n\n', 'Traceback (most recent call last):\n', '  File "C:/Users/balaji.a.arunachalam/PycharmProjects/Back_end(Python,SQL)/src/main/insertion.py", line 39, in record_insertion\n    with open(file_path, \'r\') as read_file:\n', "FileNotFoundError: [Errno 2] No such file or directory: 'C:/Users/balaji.a.arunachalam/PycharmProjects/Back_end(Python,SQL)/src\\\\files\\\\records\\\\ref_customer_address_details.sql'\n"]
2020-10-06 11:19:06,916 - 28552 DEBUG - ['Traceback (most recent call last):\n', '  File "C:/Users/balaji.a.arunachalam/PycharmProjects/Back_end(Python,SQL)/src/main/insertion.py", line 17, in __init__\n    temp = sys.argv[1]\n', 'IndexError: list index out of range\n', '\nDuring handling of the above exception, another exception occurred:\n\n', 'Traceback (most recent call last):\n', '  File "C:/Users/balaji.a.arunachalam/PycharmProjects/Back_end(Python,SQL)/src/main/insertion.py", line 39, in record_insertion\n    with open(file_path, \'r\') as read_file:\n', "FileNotFoundError: [Errno 2] No such file or directory: 'C:/Users/balaji.a.arunachalam/PycharmProjects/Back_end(Python,SQL)/src\\\\files\\\\records\\\\ref_customer_address_details.sql'\n"]
2020-10-06 11:19:06,917 - 28552 DEBUG - ['Traceback (most recent call last):\n', '  File "C:/Users/balaji.a.arunachalam/PycharmProjects/Back_end(Python,SQL)/src/main/insertion.py", line 17, in __init__\n    temp = sys.argv[1]\n', 'IndexError: list index out of range\n', '\nDuring handling of the above exception, another exception occurred:\n\n', 'Traceback (most recent call last):\n', '  File "C:/Users/balaji.a.arunachalam/PycharmProjects/Back_end(Python,SQL)/src/main/insertion.py", line 39, in record_insertion\n    with open(file_path, \'r\') as read_file:\n', "FileNotFoundError: [Errno 2] No such file or directory: 'C:/Users/balaji.a.arunachalam/PycharmProjects/Back_end(Python,SQL)/src\\\\files\\\\records\\\\ref_order_details.sql'\n"]
2020-10-06 11:19:06,917 - 28552 DEBUG - ['Traceback (most recent call last):\n', '  File "C:/Users/balaji.a.arunachalam/PycharmProjects/Back_end(Python,SQL)/src/main/insertion.py", line 17, in __init__\n    temp = sys.argv[1]\n', 'IndexError: list index out of range\n', '\nDuring handling of the above exception, another exception occurred:\n\n', 'Traceback (most recent call last):\n', '  File "C:/Users/balaji.a.arunachalam/PycharmProjects/Back_end(Python,SQL)/src/main/insertion.py", line 39, in record_insertion\n    with open(file_path, \'r\') as read_file:\n', "FileNotFoundError: [Errno 2] No such file or directory: 'C:/Users/balaji.a.arunachalam/PycharmProjects/Back_end(Python,SQL)/src\\\\files\\\\records\\\\ref_order_details.sql'\n"]
2020-10-06 11:19:06,917 - 28552 DEBUG - ['Traceback (most recent call last):\n', '  File "C:/Users/balaji.a.arunachalam/PycharmProjects/Back_end(Python,SQL)/src/main/insertion.py", line 17, in __init__\n    temp = sys.argv[1]\n', 'IndexError: list index out of range\n', '\nDuring handling of the above exception, another exception occurred:\n\n', 'Traceback (most recent call last):\n', '  File "C:/Users/balaji.a.arunachalam/PycharmProjects/Back_end(Python,SQL)/src/main/insertion.py", line 39, in record_insertion\n    with open(file_path, \'r\') as read_file:\n', "FileNotFoundError: [Errno 2] No such file or directory: 'C:/Users/balaji.a.arunachalam/PycharmProjects/Back_end(Python,SQL)/src\\\\files\\\\records\\\\ref_order_details.sql'\n"]
2020-10-06 11:19:06,918 - 28552 DEBUG - ['Traceback (most recent call last):\n', '  File "C:/Users/balaji.a.arunachalam/PycharmProjects/Back_end(Python,SQL)/src/main/insertion.py", line 17, in __init__\n    temp = sys.argv[1]\n', 'IndexError: list index out of range\n', '\nDuring handling of the above exception, another exception occurred:\n\n', 'Traceback (most recent call last):\n', '  File "C:/Users/balaji.a.arunachalam/PycharmProjects/Back_end(Python,SQL)/src/main/insertion.py", line 39, in record_insertion\n    with open(file_path, \'r\') as read_file:\n', "FileNotFoundError: [Errno 2] No such file or directory: 'C:/Users/balaji.a.arunachalam/PycharmProjects/Back_end(Python,SQL)/src\\\\files\\\\records\\\\ref_product_stock_details.sql'\n"]
2020-10-06 11:19:06,918 - 28552 DEBUG - ['Traceback (most recent call last):\n', '  File "C:/Users/balaji.a.arunachalam/PycharmProjects/Back_end(Python,SQL)/src/main/insertion.py", line 17, in __init__\n    temp = sys.argv[1]\n', 'IndexError: list index out of range\n', '\nDuring handling of the above exception, another exception occurred:\n\n', 'Traceback (most recent call last):\n', '  File "C:/Users/balaji.a.arunachalam/PycharmProjects/Back_end(Python,SQL)/src/main/insertion.py", line 39, in record_insertion\n    with open(file_path, \'r\') as read_file:\n', "FileNotFoundError: [Errno 2] No such file or directory: 'C:/Users/balaji.a.arunachalam/PycharmProjects/Back_end(Python,SQL)/src\\\\files\\\\records\\\\ref_product_stock_details.sql'\n"]
2020-10-06 11:19:06,918 - 28552 DEBUG - ['Traceback (most recent call last):\n', '  File "C:/Users/balaji.a.arunachalam/PycharmProjects/Back_end(Python,SQL)/src/main/insertion.py", line 17, in __init__\n    temp = sys.argv[1]\n', 'IndexError: list index out of range\n', '\nDuring handling of the above exception, another exception occurred:\n\n', 'Traceback (most recent call last):\n', '  File "C:/Users/balaji.a.arunachalam/PycharmProjects/Back_end(Python,SQL)/src/main/insertion.py", line 39, in record_insertion\n    with open(file_path, \'r\') as read_file:\n', "FileNotFoundError: [Errno 2] No such file or directory: 'C:/Users/balaji.a.arunachalam/PycharmProjects/Back_end(Python,SQL)/src\\\\files\\\\records\\\\ref_product_stock_details.sql'\n"]
2020-10-06 11:19:06,918 - 28552 DEBUG - ['Traceback (most recent call last):\n', '  File "C:/Users/balaji.a.arunachalam/PycharmProjects/Back_end(Python,SQL)/src/main/insertion.py", line 17, in __init__\n    temp = sys.argv[1]\n', 'IndexError: list index out of range\n', '\nDuring handling of the above exception, another exception occurred:\n\n', 'Traceback (most recent call last):\n', '  File "C:/Users/balaji.a.arunachalam/PycharmProjects/Back_end(Python,SQL)/src/main/insertion.py", line 39, in record_insertion\n    with open(file_path, \'r\') as read_file:\n', "FileNotFoundError: [Errno 2] No such file or directory: 'C:/Users/balaji.a.arunachalam/PycharmProjects/Back_end(Python,SQL)/src\\\\files\\\\records\\\\ref_product_details.sql'\n"]
2020-10-06 11:19:06,918 - 28552 DEBUG - ['Traceback (most recent call last):\n', '  File "C:/Users/balaji.a.arunachalam/PycharmProjects/Back_end(Python,SQL)/src/main/insertion.py", line 17, in __init__\n    temp = sys.argv[1]\n', 'IndexError: list index out of range\n', '\nDuring handling of the above exception, another exception occurred:\n\n', 'Traceback (most recent call last):\n', '  File "C:/Users/balaji.a.arunachalam/PycharmProjects/Back_end(Python,SQL)/src/main/insertion.py", line 39, in record_insertion\n    with open(file_path, \'r\') as read_file:\n', "FileNotFoundError: [Errno 2] No such file or directory: 'C:/Users/balaji.a.arunachalam/PycharmProjects/Back_end(Python,SQL)/src\\\\files\\\\records\\\\ref_product_details.sql'\n"]
2020-10-06 11:19:06,918 - 28552 DEBUG - ['Traceback (most recent call last):\n', '  File "C:/Users/balaji.a.arunachalam/PycharmProjects/Back_end(Python,SQL)/src/main/insertion.py", line 17, in __init__\n    temp = sys.argv[1]\n', 'IndexError: list index out of range\n', '\nDuring handling of the above exception, another exception occurred:\n\n', 'Traceback (most recent call last):\n', '  File "C:/Users/balaji.a.arunachalam/PycharmProjects/Back_end(Python,SQL)/src/main/insertion.py", line 39, in record_insertion\n    with open(file_path, \'r\') as read_file:\n', "FileNotFoundError: [Errno 2] No such file or directory: 'C:/Users/balaji.a.arunachalam/PycharmProjects/Back_end(Python,SQL)/src\\\\files\\\\records\\\\ref_product_details.sql'\n"]
2020-10-06 11:19:06,919 - 28552 DEBUG - ['Traceback (most recent call last):\n', '  File "C:/Users/balaji.a.arunachalam/PycharmProjects/Back_end(Python,SQL)/src/main/insertion.py", line 17, in __init__\n    temp = sys.argv[1]\n', 'IndexError: list index out of range\n', '\nDuring handling of the above exception, another exception occurred:\n\n', 'Traceback (most recent call last):\n', '  File "C:/Users/balaji.a.arunachalam/PycharmProjects/Back_end(Python,SQL)/src/main/insertion.py", line 39, in record_insertion\n    with open(file_path, \'r\') as read_file:\n', "FileNotFoundError: [Errno 2] No such file or directory: 'C:/Users/balaji.a.arunachalam/PycharmProjects/Back_end(Python,SQL)/src\\\\files\\\\records\\\\ref_cart_product_details.sql'\n"]
2020-10-06 11:19:06,919 - 28552 DEBUG - ['Traceback (most recent call last):\n', '  File "C:/Users/balaji.a.arunachalam/PycharmProjects/Back_end(Python,SQL)/src/main/insertion.py", line 17, in __init__\n    temp = sys.argv[1]\n', 'IndexError: list index out of range\n', '\nDuring handling of the above exception, another exception occurred:\n\n', 'Traceback (most recent call last):\n', '  File "C:/Users/balaji.a.arunachalam/PycharmProjects/Back_end(Python,SQL)/src/main/insertion.py", line 39, in record_insertion\n    with open(file_path, \'r\') as read_file:\n', "FileNotFoundError: [Errno 2] No such file or directory: 'C:/Users/balaji.a.arunachalam/PycharmProjects/Back_end(Python,SQL)/src\\\\files\\\\records\\\\ref_cart_product_details.sql'\n"]
2020-10-06 11:19:06,919 - 28552 DEBUG - ['Traceback (most recent call last):\n', '  File "C:/Users/balaji.a.arunachalam/PycharmProjects/Back_end(Python,SQL)/src/main/insertion.py", line 17, in __init__\n    temp = sys.argv[1]\n', 'IndexError: list index out of range\n', '\nDuring handling of the above exception, another exception occurred:\n\n', 'Traceback (most recent call last):\n', '  File "C:/Users/balaji.a.arunachalam/PycharmProjects/Back_end(Python,SQL)/src/main/insertion.py", line 39, in record_insertion\n    with open(file_path, \'r\') as read_file:\n', "FileNotFoundError: [Errno 2] No such file or directory: 'C:/Users/balaji.a.arunachalam/PycharmProjects/Back_end(Python,SQL)/src\\\\files\\\\records\\\\ref_cart_product_details.sql'\n"]
2020-10-06 11:19:06,920 - 28552 DEBUG - ['Traceback (most recent call last):\n', '  File "C:/Users/balaji.a.arunachalam/PycharmProjects/Back_end(Python,SQL)/src/main/insertion.py", line 17, in __init__\n    temp = sys.argv[1]\n', 'IndexError: list index out of range\n', '\nDuring handling of the above exception, another exception occurred:\n\n', 'Traceback (most recent call last):\n', '  File "C:/Users/balaji.a.arunachalam/PycharmProjects/Back_end(Python,SQL)/src/main/insertion.py", line 39, in record_insertion\n    with open(file_path, \'r\') as read_file:\n', "FileNotFoundError: [Errno 2] No such file or directory: 'C:/Users/balaji.a.arunachalam/PycharmProjects/Back_end(Python,SQL)/src\\\\files\\\\records\\\\ref_category_product_details.sql'\n"]
2020-10-06 11:19:06,920 - 28552 DEBUG - ['Traceback (most recent call last):\n', '  File "C:/Users/balaji.a.arunachalam/PycharmProjects/Back_end(Python,SQL)/src/main/insertion.py", line 17, in __init__\n    temp = sys.argv[1]\n', 'IndexError: list index out of range\n', '\nDuring handling of the above exception, another exception occurred:\n\n', 'Traceback (most recent call last):\n', '  File "C:/Users/balaji.a.arunachalam/PycharmProjects/Back_end(Python,SQL)/src/main/insertion.py", line 39, in record_insertion\n    with open(file_path, \'r\') as read_file:\n', "FileNotFoundError: [Errno 2] No such file or directory: 'C:/Users/balaji.a.arunachalam/PycharmProjects/Back_end(Python,SQL)/src\\\\files\\\\records\\\\ref_category_product_details.sql'\n"]
2020-10-06 11:19:06,920 - 28552 DEBUG - ['Traceback (most recent call last):\n', '  File "C:/Users/balaji.a.arunachalam/PycharmProjects/Back_end(Python,SQL)/src/main/insertion.py", line 17, in __init__\n    temp = sys.argv[1]\n', 'IndexError: list index out of range\n', '\nDuring handling of the above exception, another exception occurred:\n\n', 'Traceback (most recent call last):\n', '  File "C:/Users/balaji.a.arunachalam/PycharmProjects/Back_end(Python,SQL)/src/main/insertion.py", line 39, in record_insertion\n    with open(file_path, \'r\') as read_file:\n', "FileNotFoundError: [Errno 2] No such file or directory: 'C:/Users/balaji.a.arunachalam/PycharmProjects/Back_end(Python,SQL)/src\\\\files\\\\records\\\\ref_category_product_details.sql'\n"]
2020-10-06 11:19:06,921 - 28552 DEBUG - ['Traceback (most recent call last):\n', '  File "C:/Users/balaji.a.arunachalam/PycharmProjects/Back_end(Python,SQL)/src/main/insertion.py", line 17, in __init__\n    temp = sys.argv[1]\n', 'IndexError: list index out of range\n', '\nDuring handling of the above exception, another exception occurred:\n\n', 'Traceback (most recent call last):\n', '  File "C:/Users/balaji.a.arunachalam/PycharmProjects/Back_end(Python,SQL)/src/main/insertion.py", line 39, in record_insertion\n    with open(file_path, \'r\') as read_file:\n', "FileNotFoundError: [Errno 2] No such file or directory: 'C:/Users/balaji.a.arunachalam/PycharmProjects/Back_end(Python,SQL)/src\\\\files\\\\records\\\\ref_customer_rating_details.sql'\n"]
2020-10-06 11:19:06,921 - 28552 DEBUG - ['Traceback (most recent call last):\n', '  File "C:/Users/balaji.a.arunachalam/PycharmProjects/Back_end(Python,SQL)/src/main/insertion.py", line 17, in __init__\n    temp = sys.argv[1]\n', 'IndexError: list index out of range\n', '\nDuring handling of the above exception, another exception occurred:\n\n', 'Traceback (most recent call last):\n', '  File "C:/Users/balaji.a.arunachalam/PycharmProjects/Back_end(Python,SQL)/src/main/insertion.py", line 39, in record_insertion\n    with open(file_path, \'r\') as read_file:\n', "FileNotFoundError: [Errno 2] No such file or directory: 'C:/Users/balaji.a.arunachalam/PycharmProjects/Back_end(Python,SQL)/src\\\\files\\\\records\\\\ref_customer_rating_details.sql'\n"]
2020-10-06 11:19:06,921 - 28552 DEBUG - ['Traceback (most recent call last):\n', '  File "C:/Users/balaji.a.arunachalam/PycharmProjects/Back_end(Python,SQL)/src/main/insertion.py", line 17, in __init__\n    temp = sys.argv[1]\n', 'IndexError: list index out of range\n', '\nDuring handling of the above exception, another exception occurred:\n\n', 'Traceback (most recent call last):\n', '  File "C:/Users/balaji.a.arunachalam/PycharmProjects/Back_end(Python,SQL)/src/main/insertion.py", line 39, in record_insertion\n    with open(file_path, \'r\') as read_file:\n', "FileNotFoundError: [Errno 2] No such file or directory: 'C:/Users/balaji.a.arunachalam/PycharmProjects/Back_end(Python,SQL)/src\\\\files\\\\records\\\\ref_customer_rating_details.sql'\n"]
2020-10-06 11:19:06,922 - 28552 DEBUG - ['Traceback (most recent call last):\n', '  File "C:/Users/balaji.a.arunachalam/PycharmProjects/Back_end(Python,SQL)/src/main/insertion.py", line 17, in __init__\n    temp = sys.argv[1]\n', 'IndexError: list index out of range\n', '\nDuring handling of the above exception, another exception occurred:\n\n', 'Traceback (most recent call last):\n', '  File "C:/Users/balaji.a.arunachalam/PycharmProjects/Back_end(Python,SQL)/src/main/insertion.py", line 39, in record_insertion\n    with open(file_path, \'r\') as read_file:\n', "FileNotFoundError: [Errno 2] No such file or directory: 'C:/Users/balaji.a.arunachalam/PycharmProjects/Back_end(Python,SQL)/src\\\\files\\\\records\\\\ref_invoice_details.sql'\n"]
2020-10-06 11:19:06,922 - 28552 DEBUG - ['Traceback (most recent call last):\n', '  File "C:/Users/balaji.a.arunachalam/PycharmProjects/Back_end(Python,SQL)/src/main/insertion.py", line 17, in __init__\n    temp = sys.argv[1]\n', 'IndexError: list index out of range\n', '\nDuring handling of the above exception, another exception occurred:\n\n', 'Traceback (most recent call last):\n', '  File "C:/Users/balaji.a.arunachalam/PycharmProjects/Back_end(Python,SQL)/src/main/insertion.py", line 39, in record_insertion\n    with open(file_path, \'r\') as read_file:\n', "FileNotFoundError: [Errno 2] No such file or directory: 'C:/Users/balaji.a.arunachalam/PycharmProjects/Back_end(Python,SQL)/src\\\\files\\\\records\\\\ref_invoice_details.sql'\n"]
2020-10-06 11:19:06,922 - 28552 DEBUG - ['Traceback (most recent call last):\n', '  File "C:/Users/balaji.a.arunachalam/PycharmProjects/Back_end(Python,SQL)/src/main/insertion.py", line 17, in __init__\n    temp = sys.argv[1]\n', 'IndexError: list index out of range\n', '\nDuring handling of the above exception, another exception occurred:\n\n', 'Traceback (most recent call last):\n', '  File "C:/Users/balaji.a.arunachalam/PycharmProjects/Back_end(Python,SQL)/src/main/insertion.py", line 39, in record_insertion\n    with open(file_path, \'r\') as read_file:\n', "FileNotFoundError: [Errno 2] No such file or directory: 'C:/Users/balaji.a.arunachalam/PycharmProjects/Back_end(Python,SQL)/src\\\\files\\\\records\\\\ref_invoice_details.sql'\n"]
2020-10-06 11:19:06,922 - 28552 DEBUG - ['Traceback (most recent call last):\n', '  File "C:/Users/balaji.a.arunachalam/PycharmProjects/Back_end(Python,SQL)/src/main/insertion.py", line 17, in __init__\n    temp = sys.argv[1]\n', 'IndexError: list index out of range\n', '\nDuring handling of the above exception, another exception occurred:\n\n', 'Traceback (most recent call last):\n', '  File "C:/Users/balaji.a.arunachalam/PycharmProjects/Back_end(Python,SQL)/src/main/insertion.py", line 39, in record_insertion\n    with open(file_path, \'r\') as read_file:\n', "FileNotFoundError: [Errno 2] No such file or directory: 'C:/Users/balaji.a.arunachalam/PycharmProjects/Back_end(Python,SQL)/src\\\\files\\\\records\\\\ref_payment_details.sql'\n"]
2020-10-06 11:19:06,922 - 28552 DEBUG - ['Traceback (most recent call last):\n', '  File "C:/Users/balaji.a.arunachalam/PycharmProjects/Back_end(Python,SQL)/src/main/insertion.py", line 17, in __init__\n    temp = sys.argv[1]\n', 'IndexError: list index out of range\n', '\nDuring handling of the above exception, another exception occurred:\n\n', 'Traceback (most recent call last):\n', '  File "C:/Users/balaji.a.arunachalam/PycharmProjects/Back_end(Python,SQL)/src/main/insertion.py", line 39, in record_insertion\n    with open(file_path, \'r\') as read_file:\n', "FileNotFoundError: [Errno 2] No such file or directory: 'C:/Users/balaji.a.arunachalam/PycharmProjects/Back_end(Python,SQL)/src\\\\files\\\\records\\\\ref_payment_details.sql'\n"]
2020-10-06 11:19:06,922 - 28552 DEBUG - ['Traceback (most recent call last):\n', '  File "C:/Users/balaji.a.arunachalam/PycharmProjects/Back_end(Python,SQL)/src/main/insertion.py", line 17, in __init__\n    temp = sys.argv[1]\n', 'IndexError: list index out of range\n', '\nDuring handling of the above exception, another exception occurred:\n\n', 'Traceback (most recent call last):\n', '  File "C:/Users/balaji.a.arunachalam/PycharmProjects/Back_end(Python,SQL)/src/main/insertion.py", line 39, in record_insertion\n    with open(file_path, \'r\') as read_file:\n', "FileNotFoundError: [Errno 2] No such file or directory: 'C:/Users/balaji.a.arunachalam/PycharmProjects/Back_end(Python,SQL)/src\\\\files\\\\records\\\\ref_payment_details.sql'\n"]
2020-10-06 11:19:06,923 - 28552 DEBUG - ['Traceback (most recent call last):\n', '  File "C:/Users/balaji.a.arunachalam/PycharmProjects/Back_end(Python,SQL)/src/main/insertion.py", line 17, in __init__\n    temp = sys.argv[1]\n', 'IndexError: list index out of range\n', '\nDuring handling of the above exception, another exception occurred:\n\n', 'Traceback (most recent call last):\n', '  File "C:/Users/balaji.a.arunachalam/PycharmProjects/Back_end(Python,SQL)/src/main/insertion.py", line 39, in record_insertion\n    with open(file_path, \'r\') as read_file:\n', "FileNotFoundError: [Errno 2] No such file or directory: 'C:/Users/balaji.a.arunachalam/PycharmProjects/Back_end(Python,SQL)/src\\\\files\\\\records\\\\ref_product_ordered_details.sql'\n"]
2020-10-06 11:19:06,923 - 28552 DEBUG - ['Traceback (most recent call last):\n', '  File "C:/Users/balaji.a.arunachalam/PycharmProjects/Back_end(Python,SQL)/src/main/insertion.py", line 17, in __init__\n    temp = sys.argv[1]\n', 'IndexError: list index out of range\n', '\nDuring handling of the above exception, another exception occurred:\n\n', 'Traceback (most recent call last):\n', '  File "C:/Users/balaji.a.arunachalam/PycharmProjects/Back_end(Python,SQL)/src/main/insertion.py", line 39, in record_insertion\n    with open(file_path, \'r\') as read_file:\n', "FileNotFoundError: [Errno 2] No such file or directory: 'C:/Users/balaji.a.arunachalam/PycharmProjects/Back_end(Python,SQL)/src\\\\files\\\\records\\\\ref_product_ordered_details.sql'\n"]
2020-10-06 11:19:06,923 - 28552 DEBUG - ['Traceback (most recent call last):\n', '  File "C:/Users/balaji.a.arunachalam/PycharmProjects/Back_end(Python,SQL)/src/main/insertion.py", line 17, in __init__\n    temp = sys.argv[1]\n', 'IndexError: list index out of range\n', '\nDuring handling of the above exception, another exception occurred:\n\n', 'Traceback (most recent call last):\n', '  File "C:/Users/balaji.a.arunachalam/PycharmProjects/Back_end(Python,SQL)/src/main/insertion.py", line 39, in record_insertion\n    with open(file_path, \'r\') as read_file:\n', "FileNotFoundError: [Errno 2] No such file or directory: 'C:/Users/balaji.a.arunachalam/PycharmProjects/Back_end(Python,SQL)/src\\\\files\\\\records\\\\ref_product_ordered_details.sql'\n"]
2020-10-06 11:19:06,924 - 28552 DEBUG - ['Traceback (most recent call last):\n', '  File "C:/Users/balaji.a.arunachalam/PycharmProjects/Back_end(Python,SQL)/src/main/insertion.py", line 17, in __init__\n    temp = sys.argv[1]\n', 'IndexError: list index out of range\n', '\nDuring handling of the above exception, another exception occurred:\n\n', 'Traceback (most recent call last):\n', '  File "C:/Users/balaji.a.arunachalam/PycharmProjects/Back_end(Python,SQL)/src/main/insertion.py", line 39, in record_insertion\n    with open(file_path, \'r\') as read_file:\n', "FileNotFoundError: [Errno 2] No such file or directory: 'C:/Users/balaji.a.arunachalam/PycharmProjects/Back_end(Python,SQL)/src\\\\files\\\\records\\\\ref_shipping_status.sql'\n"]
2020-10-06 11:19:06,924 - 28552 DEBUG - ['Traceback (most recent call last):\n', '  File "C:/Users/balaji.a.arunachalam/PycharmProjects/Back_end(Python,SQL)/src/main/insertion.py", line 17, in __init__\n    temp = sys.argv[1]\n', 'IndexError: list index out of range\n', '\nDuring handling of the above exception, another exception occurred:\n\n', 'Traceback (most recent call last):\n', '  File "C:/Users/balaji.a.arunachalam/PycharmProjects/Back_end(Python,SQL)/src/main/insertion.py", line 39, in record_insertion\n    with open(file_path, \'r\') as read_file:\n', "FileNotFoundError: [Errno 2] No such file or directory: 'C:/Users/balaji.a.arunachalam/PycharmProjects/Back_end(Python,SQL)/src\\\\files\\\\records\\\\ref_shipping_status.sql'\n"]
2020-10-06 11:19:06,924 - 28552 DEBUG - ['Traceback (most recent call last):\n', '  File "C:/Users/balaji.a.arunachalam/PycharmProjects/Back_end(Python,SQL)/src/main/insertion.py", line 17, in __init__\n    temp = sys.argv[1]\n', 'IndexError: list index out of range\n', '\nDuring handling of the above exception, another exception occurred:\n\n', 'Traceback (most recent call last):\n', '  File "C:/Users/balaji.a.arunachalam/PycharmProjects/Back_end(Python,SQL)/src/main/insertion.py", line 39, in record_insertion\n    with open(file_path, \'r\') as read_file:\n', "FileNotFoundError: [Errno 2] No such file or directory: 'C:/Users/balaji.a.arunachalam/PycharmProjects/Back_end(Python,SQL)/src\\\\files\\\\records\\\\ref_shipping_status.sql'\n"]
2020-10-06 11:19:36,617 - 30340 DEBUG - ['Traceback (most recent call last):\n', '  File "C:/Users/balaji.a.arunachalam/PycharmProjects/Back_end(Python,SQL)/src/main/insertion.py", line 17, in __init__\n    temp = sys.argv[1]\n', 'IndexError: list index out of range\n', '\nDuring handling of the above exception, another exception occurred:\n\n', 'Traceback (most recent call last):\n', '  File "C:/Users/balaji.a.arunachalam/PycharmProjects/Back_end(Python,SQL)/src/main/insertion.py", line 39, in record_insertion\n    with open(file_path, \'r\') as read_file:\n', "FileNotFoundError: [Errno 2] No such file or directory: 'C:/Users/balaji.a.arunachalam/PycharmProjects/Back_end(Python,SQL)/src\\\\files\\\\records\\\\ref_category_details.sql'\n"]
2020-10-06 11:19:36,617 - 30340 DEBUG - ['Traceback (most recent call last):\n', '  File "C:/Users/balaji.a.arunachalam/PycharmProjects/Back_end(Python,SQL)/src/main/insertion.py", line 17, in __init__\n    temp = sys.argv[1]\n', 'IndexError: list index out of range\n', '\nDuring handling of the above exception, another exception occurred:\n\n', 'Traceback (most recent call last):\n', '  File "C:/Users/balaji.a.arunachalam/PycharmProjects/Back_end(Python,SQL)/src/main/insertion.py", line 39, in record_insertion\n    with open(file_path, \'r\') as read_file:\n', "FileNotFoundError: [Errno 2] No such file or directory: 'C:/Users/balaji.a.arunachalam/PycharmProjects/Back_end(Python,SQL)/src\\\\files\\\\records\\\\ref_category_details.sql'\n"]
2020-10-06 11:19:36,617 - 30340 DEBUG - ['Traceback (most recent call last):\n', '  File "C:/Users/balaji.a.arunachalam/PycharmProjects/Back_end(Python,SQL)/src/main/insertion.py", line 17, in __init__\n    temp = sys.argv[1]\n', 'IndexError: list index out of range\n', '\nDuring handling of the above exception, another exception occurred:\n\n', 'Traceback (most recent call last):\n', '  File "C:/Users/balaji.a.arunachalam/PycharmProjects/Back_end(Python,SQL)/src/main/insertion.py", line 39, in record_insertion\n    with open(file_path, \'r\') as read_file:\n', "FileNotFoundError: [Errno 2] No such file or directory: 'C:/Users/balaji.a.arunachalam/PycharmProjects/Back_end(Python,SQL)/src\\\\files\\\\records\\\\ref_category_details.sql'\n"]
2020-10-06 11:19:36,619 - 30340 DEBUG - ['Traceback (most recent call last):\n', '  File "C:/Users/balaji.a.arunachalam/PycharmProjects/Back_end(Python,SQL)/src/main/insertion.py", line 17, in __init__\n    temp = sys.argv[1]\n', 'IndexError: list index out of range\n', '\nDuring handling of the above exception, another exception occurred:\n\n', 'Traceback (most recent call last):\n', '  File "C:/Users/balaji.a.arunachalam/PycharmProjects/Back_end(Python,SQL)/src/main/insertion.py", line 39, in record_insertion\n    with open(file_path, \'r\') as read_file:\n', "FileNotFoundError: [Errno 2] No such file or directory: 'C:/Users/balaji.a.arunachalam/PycharmProjects/Back_end(Python,SQL)/src\\\\files\\\\records\\\\ref_customer_details.sql'\n"]
2020-10-06 11:19:36,619 - 30340 DEBUG - ['Traceback (most recent call last):\n', '  File "C:/Users/balaji.a.arunachalam/PycharmProjects/Back_end(Python,SQL)/src/main/insertion.py", line 17, in __init__\n    temp = sys.argv[1]\n', 'IndexError: list index out of range\n', '\nDuring handling of the above exception, another exception occurred:\n\n', 'Traceback (most recent call last):\n', '  File "C:/Users/balaji.a.arunachalam/PycharmProjects/Back_end(Python,SQL)/src/main/insertion.py", line 39, in record_insertion\n    with open(file_path, \'r\') as read_file:\n', "FileNotFoundError: [Errno 2] No such file or directory: 'C:/Users/balaji.a.arunachalam/PycharmProjects/Back_end(Python,SQL)/src\\\\files\\\\records\\\\ref_customer_details.sql'\n"]
2020-10-06 11:19:36,619 - 30340 DEBUG - ['Traceback (most recent call last):\n', '  File "C:/Users/balaji.a.arunachalam/PycharmProjects/Back_end(Python,SQL)/src/main/insertion.py", line 17, in __init__\n    temp = sys.argv[1]\n', 'IndexError: list index out of range\n', '\nDuring handling of the above exception, another exception occurred:\n\n', 'Traceback (most recent call last):\n', '  File "C:/Users/balaji.a.arunachalam/PycharmProjects/Back_end(Python,SQL)/src/main/insertion.py", line 39, in record_insertion\n    with open(file_path, \'r\') as read_file:\n', "FileNotFoundError: [Errno 2] No such file or directory: 'C:/Users/balaji.a.arunachalam/PycharmProjects/Back_end(Python,SQL)/src\\\\files\\\\records\\\\ref_customer_details.sql'\n"]
2020-10-06 11:19:36,619 - 30340 DEBUG - ['Traceback (most recent call last):\n', '  File "C:/Users/balaji.a.arunachalam/PycharmProjects/Back_end(Python,SQL)/src/main/insertion.py", line 17, in __init__\n    temp = sys.argv[1]\n', 'IndexError: list index out of range\n', '\nDuring handling of the above exception, another exception occurred:\n\n', 'Traceback (most recent call last):\n', '  File "C:/Users/balaji.a.arunachalam/PycharmProjects/Back_end(Python,SQL)/src/main/insertion.py", line 39, in record_insertion\n    with open(file_path, \'r\') as read_file:\n', "FileNotFoundError: [Errno 2] No such file or directory: 'C:/Users/balaji.a.arunachalam/PycharmProjects/Back_end(Python,SQL)/src\\\\files\\\\records\\\\ref_order_status_details.sql'\n"]
2020-10-06 11:19:36,619 - 30340 DEBUG - ['Traceback (most recent call last):\n', '  File "C:/Users/balaji.a.arunachalam/PycharmProjects/Back_end(Python,SQL)/src/main/insertion.py", line 17, in __init__\n    temp = sys.argv[1]\n', 'IndexError: list index out of range\n', '\nDuring handling of the above exception, another exception occurred:\n\n', 'Traceback (most recent call last):\n', '  File "C:/Users/balaji.a.arunachalam/PycharmProjects/Back_end(Python,SQL)/src/main/insertion.py", line 39, in record_insertion\n    with open(file_path, \'r\') as read_file:\n', "FileNotFoundError: [Errno 2] No such file or directory: 'C:/Users/balaji.a.arunachalam/PycharmProjects/Back_end(Python,SQL)/src\\\\files\\\\records\\\\ref_order_status_details.sql'\n"]
2020-10-06 11:19:36,619 - 30340 DEBUG - ['Traceback (most recent call last):\n', '  File "C:/Users/balaji.a.arunachalam/PycharmProjects/Back_end(Python,SQL)/src/main/insertion.py", line 17, in __init__\n    temp = sys.argv[1]\n', 'IndexError: list index out of range\n', '\nDuring handling of the above exception, another exception occurred:\n\n', 'Traceback (most recent call last):\n', '  File "C:/Users/balaji.a.arunachalam/PycharmProjects/Back_end(Python,SQL)/src/main/insertion.py", line 39, in record_insertion\n    with open(file_path, \'r\') as read_file:\n', "FileNotFoundError: [Errno 2] No such file or directory: 'C:/Users/balaji.a.arunachalam/PycharmProjects/Back_end(Python,SQL)/src\\\\files\\\\records\\\\ref_order_status_details.sql'\n"]
2020-10-06 11:19:36,621 - 30340 DEBUG - ['Traceback (most recent call last):\n', '  File "C:/Users/balaji.a.arunachalam/PycharmProjects/Back_end(Python,SQL)/src/main/insertion.py", line 17, in __init__\n    temp = sys.argv[1]\n', 'IndexError: list index out of range\n', '\nDuring handling of the above exception, another exception occurred:\n\n', 'Traceback (most recent call last):\n', '  File "C:/Users/balaji.a.arunachalam/PycharmProjects/Back_end(Python,SQL)/src/main/insertion.py", line 39, in record_insertion\n    with open(file_path, \'r\') as read_file:\n', "FileNotFoundError: [Errno 2] No such file or directory: 'C:/Users/balaji.a.arunachalam/PycharmProjects/Back_end(Python,SQL)/src\\\\files\\\\records\\\\ref_seller_details.sql'\n"]
2020-10-06 11:19:36,621 - 30340 DEBUG - ['Traceback (most recent call last):\n', '  File "C:/Users/balaji.a.arunachalam/PycharmProjects/Back_end(Python,SQL)/src/main/insertion.py", line 17, in __init__\n    temp = sys.argv[1]\n', 'IndexError: list index out of range\n', '\nDuring handling of the above exception, another exception occurred:\n\n', 'Traceback (most recent call last):\n', '  File "C:/Users/balaji.a.arunachalam/PycharmProjects/Back_end(Python,SQL)/src/main/insertion.py", line 39, in record_insertion\n    with open(file_path, \'r\') as read_file:\n', "FileNotFoundError: [Errno 2] No such file or directory: 'C:/Users/balaji.a.arunachalam/PycharmProjects/Back_end(Python,SQL)/src\\\\files\\\\records\\\\ref_seller_details.sql'\n"]
2020-10-06 11:19:36,621 - 30340 DEBUG - ['Traceback (most recent call last):\n', '  File "C:/Users/balaji.a.arunachalam/PycharmProjects/Back_end(Python,SQL)/src/main/insertion.py", line 17, in __init__\n    temp = sys.argv[1]\n', 'IndexError: list index out of range\n', '\nDuring handling of the above exception, another exception occurred:\n\n', 'Traceback (most recent call last):\n', '  File "C:/Users/balaji.a.arunachalam/PycharmProjects/Back_end(Python,SQL)/src/main/insertion.py", line 39, in record_insertion\n    with open(file_path, \'r\') as read_file:\n', "FileNotFoundError: [Errno 2] No such file or directory: 'C:/Users/balaji.a.arunachalam/PycharmProjects/Back_end(Python,SQL)/src\\\\files\\\\records\\\\ref_seller_details.sql'\n"]
2020-10-06 11:19:36,622 - 30340 DEBUG - ['Traceback (most recent call last):\n', '  File "C:/Users/balaji.a.arunachalam/PycharmProjects/Back_end(Python,SQL)/src/main/insertion.py", line 17, in __init__\n    temp = sys.argv[1]\n', 'IndexError: list index out of range\n', '\nDuring handling of the above exception, another exception occurred:\n\n', 'Traceback (most recent call last):\n', '  File "C:/Users/balaji.a.arunachalam/PycharmProjects/Back_end(Python,SQL)/src/main/insertion.py", line 39, in record_insertion\n    with open(file_path, \'r\') as read_file:\n', "FileNotFoundError: [Errno 2] No such file or directory: 'C:/Users/balaji.a.arunachalam/PycharmProjects/Back_end(Python,SQL)/src\\\\files\\\\records\\\\ref_cart_details.sql'\n"]
2020-10-06 11:19:36,622 - 30340 DEBUG - ['Traceback (most recent call last):\n', '  File "C:/Users/balaji.a.arunachalam/PycharmProjects/Back_end(Python,SQL)/src/main/insertion.py", line 17, in __init__\n    temp = sys.argv[1]\n', 'IndexError: list index out of range\n', '\nDuring handling of the above exception, another exception occurred:\n\n', 'Traceback (most recent call last):\n', '  File "C:/Users/balaji.a.arunachalam/PycharmProjects/Back_end(Python,SQL)/src/main/insertion.py", line 39, in record_insertion\n    with open(file_path, \'r\') as read_file:\n', "FileNotFoundError: [Errno 2] No such file or directory: 'C:/Users/balaji.a.arunachalam/PycharmProjects/Back_end(Python,SQL)/src\\\\files\\\\records\\\\ref_cart_details.sql'\n"]
2020-10-06 11:19:36,622 - 30340 DEBUG - ['Traceback (most recent call last):\n', '  File "C:/Users/balaji.a.arunachalam/PycharmProjects/Back_end(Python,SQL)/src/main/insertion.py", line 17, in __init__\n    temp = sys.argv[1]\n', 'IndexError: list index out of range\n', '\nDuring handling of the above exception, another exception occurred:\n\n', 'Traceback (most recent call last):\n', '  File "C:/Users/balaji.a.arunachalam/PycharmProjects/Back_end(Python,SQL)/src/main/insertion.py", line 39, in record_insertion\n    with open(file_path, \'r\') as read_file:\n', "FileNotFoundError: [Errno 2] No such file or directory: 'C:/Users/balaji.a.arunachalam/PycharmProjects/Back_end(Python,SQL)/src\\\\files\\\\records\\\\ref_cart_details.sql'\n"]
2020-10-06 11:19:36,623 - 30340 DEBUG - ['Traceback (most recent call last):\n', '  File "C:/Users/balaji.a.arunachalam/PycharmProjects/Back_end(Python,SQL)/src/main/insertion.py", line 17, in __init__\n    temp = sys.argv[1]\n', 'IndexError: list index out of range\n', '\nDuring handling of the above exception, another exception occurred:\n\n', 'Traceback (most recent call last):\n', '  File "C:/Users/balaji.a.arunachalam/PycharmProjects/Back_end(Python,SQL)/src/main/insertion.py", line 39, in record_insertion\n    with open(file_path, \'r\') as read_file:\n', "FileNotFoundError: [Errno 2] No such file or directory: 'C:/Users/balaji.a.arunachalam/PycharmProjects/Back_end(Python,SQL)/src\\\\files\\\\records\\\\ref_customer_address_details.sql'\n"]
2020-10-06 11:19:36,623 - 30340 DEBUG - ['Traceback (most recent call last):\n', '  File "C:/Users/balaji.a.arunachalam/PycharmProjects/Back_end(Python,SQL)/src/main/insertion.py", line 17, in __init__\n    temp = sys.argv[1]\n', 'IndexError: list index out of range\n', '\nDuring handling of the above exception, another exception occurred:\n\n', 'Traceback (most recent call last):\n', '  File "C:/Users/balaji.a.arunachalam/PycharmProjects/Back_end(Python,SQL)/src/main/insertion.py", line 39, in record_insertion\n    with open(file_path, \'r\') as read_file:\n', "FileNotFoundError: [Errno 2] No such file or directory: 'C:/Users/balaji.a.arunachalam/PycharmProjects/Back_end(Python,SQL)/src\\\\files\\\\records\\\\ref_customer_address_details.sql'\n"]
2020-10-06 11:19:36,623 - 30340 DEBUG - ['Traceback (most recent call last):\n', '  File "C:/Users/balaji.a.arunachalam/PycharmProjects/Back_end(Python,SQL)/src/main/insertion.py", line 17, in __init__\n    temp = sys.argv[1]\n', 'IndexError: list index out of range\n', '\nDuring handling of the above exception, another exception occurred:\n\n', 'Traceback (most recent call last):\n', '  File "C:/Users/balaji.a.arunachalam/PycharmProjects/Back_end(Python,SQL)/src/main/insertion.py", line 39, in record_insertion\n    with open(file_path, \'r\') as read_file:\n', "FileNotFoundError: [Errno 2] No such file or directory: 'C:/Users/balaji.a.arunachalam/PycharmProjects/Back_end(Python,SQL)/src\\\\files\\\\records\\\\ref_customer_address_details.sql'\n"]
2020-10-06 11:19:36,625 - 30340 DEBUG - ['Traceback (most recent call last):\n', '  File "C:/Users/balaji.a.arunachalam/PycharmProjects/Back_end(Python,SQL)/src/main/insertion.py", line 17, in __init__\n    temp = sys.argv[1]\n', 'IndexError: list index out of range\n', '\nDuring handling of the above exception, another exception occurred:\n\n', 'Traceback (most recent call last):\n', '  File "C:/Users/balaji.a.arunachalam/PycharmProjects/Back_end(Python,SQL)/src/main/insertion.py", line 39, in record_insertion\n    with open(file_path, \'r\') as read_file:\n', "FileNotFoundError: [Errno 2] No such file or directory: 'C:/Users/balaji.a.arunachalam/PycharmProjects/Back_end(Python,SQL)/src\\\\files\\\\records\\\\ref_order_details.sql'\n"]
2020-10-06 11:19:36,625 - 30340 DEBUG - ['Traceback (most recent call last):\n', '  File "C:/Users/balaji.a.arunachalam/PycharmProjects/Back_end(Python,SQL)/src/main/insertion.py", line 17, in __init__\n    temp = sys.argv[1]\n', 'IndexError: list index out of range\n', '\nDuring handling of the above exception, another exception occurred:\n\n', 'Traceback (most recent call last):\n', '  File "C:/Users/balaji.a.arunachalam/PycharmProjects/Back_end(Python,SQL)/src/main/insertion.py", line 39, in record_insertion\n    with open(file_path, \'r\') as read_file:\n', "FileNotFoundError: [Errno 2] No such file or directory: 'C:/Users/balaji.a.arunachalam/PycharmProjects/Back_end(Python,SQL)/src\\\\files\\\\records\\\\ref_order_details.sql'\n"]
2020-10-06 11:19:36,625 - 30340 DEBUG - ['Traceback (most recent call last):\n', '  File "C:/Users/balaji.a.arunachalam/PycharmProjects/Back_end(Python,SQL)/src/main/insertion.py", line 17, in __init__\n    temp = sys.argv[1]\n', 'IndexError: list index out of range\n', '\nDuring handling of the above exception, another exception occurred:\n\n', 'Traceback (most recent call last):\n', '  File "C:/Users/balaji.a.arunachalam/PycharmProjects/Back_end(Python,SQL)/src/main/insertion.py", line 39, in record_insertion\n    with open(file_path, \'r\') as read_file:\n', "FileNotFoundError: [Errno 2] No such file or directory: 'C:/Users/balaji.a.arunachalam/PycharmProjects/Back_end(Python,SQL)/src\\\\files\\\\records\\\\ref_order_details.sql'\n"]
2020-10-06 11:19:36,626 - 30340 DEBUG - ['Traceback (most recent call last):\n', '  File "C:/Users/balaji.a.arunachalam/PycharmProjects/Back_end(Python,SQL)/src/main/insertion.py", line 17, in __init__\n    temp = sys.argv[1]\n', 'IndexError: list index out of range\n', '\nDuring handling of the above exception, another exception occurred:\n\n', 'Traceback (most recent call last):\n', '  File "C:/Users/balaji.a.arunachalam/PycharmProjects/Back_end(Python,SQL)/src/main/insertion.py", line 39, in record_insertion\n    with open(file_path, \'r\') as read_file:\n', "FileNotFoundError: [Errno 2] No such file or directory: 'C:/Users/balaji.a.arunachalam/PycharmProjects/Back_end(Python,SQL)/src\\\\files\\\\records\\\\ref_product_stock_details.sql'\n"]
2020-10-06 11:19:36,626 - 30340 DEBUG - ['Traceback (most recent call last):\n', '  File "C:/Users/balaji.a.arunachalam/PycharmProjects/Back_end(Python,SQL)/src/main/insertion.py", line 17, in __init__\n    temp = sys.argv[1]\n', 'IndexError: list index out of range\n', '\nDuring handling of the above exception, another exception occurred:\n\n', 'Traceback (most recent call last):\n', '  File "C:/Users/balaji.a.arunachalam/PycharmProjects/Back_end(Python,SQL)/src/main/insertion.py", line 39, in record_insertion\n    with open(file_path, \'r\') as read_file:\n', "FileNotFoundError: [Errno 2] No such file or directory: 'C:/Users/balaji.a.arunachalam/PycharmProjects/Back_end(Python,SQL)/src\\\\files\\\\records\\\\ref_product_stock_details.sql'\n"]
2020-10-06 11:19:36,626 - 30340 DEBUG - ['Traceback (most recent call last):\n', '  File "C:/Users/balaji.a.arunachalam/PycharmProjects/Back_end(Python,SQL)/src/main/insertion.py", line 17, in __init__\n    temp = sys.argv[1]\n', 'IndexError: list index out of range\n', '\nDuring handling of the above exception, another exception occurred:\n\n', 'Traceback (most recent call last):\n', '  File "C:/Users/balaji.a.arunachalam/PycharmProjects/Back_end(Python,SQL)/src/main/insertion.py", line 39, in record_insertion\n    with open(file_path, \'r\') as read_file:\n', "FileNotFoundError: [Errno 2] No such file or directory: 'C:/Users/balaji.a.arunachalam/PycharmProjects/Back_end(Python,SQL)/src\\\\files\\\\records\\\\ref_product_stock_details.sql'\n"]
2020-10-06 11:19:36,627 - 30340 DEBUG - ['Traceback (most recent call last):\n', '  File "C:/Users/balaji.a.arunachalam/PycharmProjects/Back_end(Python,SQL)/src/main/insertion.py", line 17, in __init__\n    temp = sys.argv[1]\n', 'IndexError: list index out of range\n', '\nDuring handling of the above exception, another exception occurred:\n\n', 'Traceback (most recent call last):\n', '  File "C:/Users/balaji.a.arunachalam/PycharmProjects/Back_end(Python,SQL)/src/main/insertion.py", line 39, in record_insertion\n    with open(file_path, \'r\') as read_file:\n', "FileNotFoundError: [Errno 2] No such file or directory: 'C:/Users/balaji.a.arunachalam/PycharmProjects/Back_end(Python,SQL)/src\\\\files\\\\records\\\\ref_product_details.sql'\n"]
2020-10-06 11:19:36,627 - 30340 DEBUG - ['Traceback (most recent call last):\n', '  File "C:/Users/balaji.a.arunachalam/PycharmProjects/Back_end(Python,SQL)/src/main/insertion.py", line 17, in __init__\n    temp = sys.argv[1]\n', 'IndexError: list index out of range\n', '\nDuring handling of the above exception, another exception occurred:\n\n', 'Traceback (most recent call last):\n', '  File "C:/Users/balaji.a.arunachalam/PycharmProjects/Back_end(Python,SQL)/src/main/insertion.py", line 39, in record_insertion\n    with open(file_path, \'r\') as read_file:\n', "FileNotFoundError: [Errno 2] No such file or directory: 'C:/Users/balaji.a.arunachalam/PycharmProjects/Back_end(Python,SQL)/src\\\\files\\\\records\\\\ref_product_details.sql'\n"]
2020-10-06 11:19:36,627 - 30340 DEBUG - ['Traceback (most recent call last):\n', '  File "C:/Users/balaji.a.arunachalam/PycharmProjects/Back_end(Python,SQL)/src/main/insertion.py", line 17, in __init__\n    temp = sys.argv[1]\n', 'IndexError: list index out of range\n', '\nDuring handling of the above exception, another exception occurred:\n\n', 'Traceback (most recent call last):\n', '  File "C:/Users/balaji.a.arunachalam/PycharmProjects/Back_end(Python,SQL)/src/main/insertion.py", line 39, in record_insertion\n    with open(file_path, \'r\') as read_file:\n', "FileNotFoundError: [Errno 2] No such file or directory: 'C:/Users/balaji.a.arunachalam/PycharmProjects/Back_end(Python,SQL)/src\\\\files\\\\records\\\\ref_product_details.sql'\n"]
2020-10-06 11:19:36,628 - 30340 DEBUG - ['Traceback (most recent call last):\n', '  File "C:/Users/balaji.a.arunachalam/PycharmProjects/Back_end(Python,SQL)/src/main/insertion.py", line 17, in __init__\n    temp = sys.argv[1]\n', 'IndexError: list index out of range\n', '\nDuring handling of the above exception, another exception occurred:\n\n', 'Traceback (most recent call last):\n', '  File "C:/Users/balaji.a.arunachalam/PycharmProjects/Back_end(Python,SQL)/src/main/insertion.py", line 39, in record_insertion\n    with open(file_path, \'r\') as read_file:\n', "FileNotFoundError: [Errno 2] No such file or directory: 'C:/Users/balaji.a.arunachalam/PycharmProjects/Back_end(Python,SQL)/src\\\\files\\\\records\\\\ref_cart_product_details.sql'\n"]
2020-10-06 11:19:36,628 - 30340 DEBUG - ['Traceback (most recent call last):\n', '  File "C:/Users/balaji.a.arunachalam/PycharmProjects/Back_end(Python,SQL)/src/main/insertion.py", line 17, in __init__\n    temp = sys.argv[1]\n', 'IndexError: list index out of range\n', '\nDuring handling of the above exception, another exception occurred:\n\n', 'Traceback (most recent call last):\n', '  File "C:/Users/balaji.a.arunachalam/PycharmProjects/Back_end(Python,SQL)/src/main/insertion.py", line 39, in record_insertion\n    with open(file_path, \'r\') as read_file:\n', "FileNotFoundError: [Errno 2] No such file or directory: 'C:/Users/balaji.a.arunachalam/PycharmProjects/Back_end(Python,SQL)/src\\\\files\\\\records\\\\ref_cart_product_details.sql'\n"]
2020-10-06 11:19:36,628 - 30340 DEBUG - ['Traceback (most recent call last):\n', '  File "C:/Users/balaji.a.arunachalam/PycharmProjects/Back_end(Python,SQL)/src/main/insertion.py", line 17, in __init__\n    temp = sys.argv[1]\n', 'IndexError: list index out of range\n', '\nDuring handling of the above exception, another exception occurred:\n\n', 'Traceback (most recent call last):\n', '  File "C:/Users/balaji.a.arunachalam/PycharmProjects/Back_end(Python,SQL)/src/main/insertion.py", line 39, in record_insertion\n    with open(file_path, \'r\') as read_file:\n', "FileNotFoundError: [Errno 2] No such file or directory: 'C:/Users/balaji.a.arunachalam/PycharmProjects/Back_end(Python,SQL)/src\\\\files\\\\records\\\\ref_cart_product_details.sql'\n"]
2020-10-06 11:19:36,630 - 30340 DEBUG - ['Traceback (most recent call last):\n', '  File "C:/Users/balaji.a.arunachalam/PycharmProjects/Back_end(Python,SQL)/src/main/insertion.py", line 17, in __init__\n    temp = sys.argv[1]\n', 'IndexError: list index out of range\n', '\nDuring handling of the above exception, another exception occurred:\n\n', 'Traceback (most recent call last):\n', '  File "C:/Users/balaji.a.arunachalam/PycharmProjects/Back_end(Python,SQL)/src/main/insertion.py", line 39, in record_insertion\n    with open(file_path, \'r\') as read_file:\n', "FileNotFoundError: [Errno 2] No such file or directory: 'C:/Users/balaji.a.arunachalam/PycharmProjects/Back_end(Python,SQL)/src\\\\files\\\\records\\\\ref_category_product_details.sql'\n"]
2020-10-06 11:19:36,630 - 30340 DEBUG - ['Traceback (most recent call last):\n', '  File "C:/Users/balaji.a.arunachalam/PycharmProjects/Back_end(Python,SQL)/src/main/insertion.py", line 17, in __init__\n    temp = sys.argv[1]\n', 'IndexError: list index out of range\n', '\nDuring handling of the above exception, another exception occurred:\n\n', 'Traceback (most recent call last):\n', '  File "C:/Users/balaji.a.arunachalam/PycharmProjects/Back_end(Python,SQL)/src/main/insertion.py", line 39, in record_insertion\n    with open(file_path, \'r\') as read_file:\n', "FileNotFoundError: [Errno 2] No such file or directory: 'C:/Users/balaji.a.arunachalam/PycharmProjects/Back_end(Python,SQL)/src\\\\files\\\\records\\\\ref_category_product_details.sql'\n"]
2020-10-06 11:19:36,630 - 30340 DEBUG - ['Traceback (most recent call last):\n', '  File "C:/Users/balaji.a.arunachalam/PycharmProjects/Back_end(Python,SQL)/src/main/insertion.py", line 17, in __init__\n    temp = sys.argv[1]\n', 'IndexError: list index out of range\n', '\nDuring handling of the above exception, another exception occurred:\n\n', 'Traceback (most recent call last):\n', '  File "C:/Users/balaji.a.arunachalam/PycharmProjects/Back_end(Python,SQL)/src/main/insertion.py", line 39, in record_insertion\n    with open(file_path, \'r\') as read_file:\n', "FileNotFoundError: [Errno 2] No such file or directory: 'C:/Users/balaji.a.arunachalam/PycharmProjects/Back_end(Python,SQL)/src\\\\files\\\\records\\\\ref_category_product_details.sql'\n"]
2020-10-06 11:19:36,631 - 30340 DEBUG - ['Traceback (most recent call last):\n', '  File "C:/Users/balaji.a.arunachalam/PycharmProjects/Back_end(Python,SQL)/src/main/insertion.py", line 17, in __init__\n    temp = sys.argv[1]\n', 'IndexError: list index out of range\n', '\nDuring handling of the above exception, another exception occurred:\n\n', 'Traceback (most recent call last):\n', '  File "C:/Users/balaji.a.arunachalam/PycharmProjects/Back_end(Python,SQL)/src/main/insertion.py", line 39, in record_insertion\n    with open(file_path, \'r\') as read_file:\n', "FileNotFoundError: [Errno 2] No such file or directory: 'C:/Users/balaji.a.arunachalam/PycharmProjects/Back_end(Python,SQL)/src\\\\files\\\\records\\\\ref_customer_rating_details.sql'\n"]
2020-10-06 11:19:36,631 - 30340 DEBUG - ['Traceback (most recent call last):\n', '  File "C:/Users/balaji.a.arunachalam/PycharmProjects/Back_end(Python,SQL)/src/main/insertion.py", line 17, in __init__\n    temp = sys.argv[1]\n', 'IndexError: list index out of range\n', '\nDuring handling of the above exception, another exception occurred:\n\n', 'Traceback (most recent call last):\n', '  File "C:/Users/balaji.a.arunachalam/PycharmProjects/Back_end(Python,SQL)/src/main/insertion.py", line 39, in record_insertion\n    with open(file_path, \'r\') as read_file:\n', "FileNotFoundError: [Errno 2] No such file or directory: 'C:/Users/balaji.a.arunachalam/PycharmProjects/Back_end(Python,SQL)/src\\\\files\\\\records\\\\ref_customer_rating_details.sql'\n"]
2020-10-06 11:19:36,631 - 30340 DEBUG - ['Traceback (most recent call last):\n', '  File "C:/Users/balaji.a.arunachalam/PycharmProjects/Back_end(Python,SQL)/src/main/insertion.py", line 17, in __init__\n    temp = sys.argv[1]\n', 'IndexError: list index out of range\n', '\nDuring handling of the above exception, another exception occurred:\n\n', 'Traceback (most recent call last):\n', '  File "C:/Users/balaji.a.arunachalam/PycharmProjects/Back_end(Python,SQL)/src/main/insertion.py", line 39, in record_insertion\n    with open(file_path, \'r\') as read_file:\n', "FileNotFoundError: [Errno 2] No such file or directory: 'C:/Users/balaji.a.arunachalam/PycharmProjects/Back_end(Python,SQL)/src\\\\files\\\\records\\\\ref_customer_rating_details.sql'\n"]
2020-10-06 11:19:36,632 - 30340 DEBUG - ['Traceback (most recent call last):\n', '  File "C:/Users/balaji.a.arunachalam/PycharmProjects/Back_end(Python,SQL)/src/main/insertion.py", line 17, in __init__\n    temp = sys.argv[1]\n', 'IndexError: list index out of range\n', '\nDuring handling of the above exception, another exception occurred:\n\n', 'Traceback (most recent call last):\n', '  File "C:/Users/balaji.a.arunachalam/PycharmProjects/Back_end(Python,SQL)/src/main/insertion.py", line 39, in record_insertion\n    with open(file_path, \'r\') as read_file:\n', "FileNotFoundError: [Errno 2] No such file or directory: 'C:/Users/balaji.a.arunachalam/PycharmProjects/Back_end(Python,SQL)/src\\\\files\\\\records\\\\ref_invoice_details.sql'\n"]
2020-10-06 11:19:36,632 - 30340 DEBUG - ['Traceback (most recent call last):\n', '  File "C:/Users/balaji.a.arunachalam/PycharmProjects/Back_end(Python,SQL)/src/main/insertion.py", line 17, in __init__\n    temp = sys.argv[1]\n', 'IndexError: list index out of range\n', '\nDuring handling of the above exception, another exception occurred:\n\n', 'Traceback (most recent call last):\n', '  File "C:/Users/balaji.a.arunachalam/PycharmProjects/Back_end(Python,SQL)/src/main/insertion.py", line 39, in record_insertion\n    with open(file_path, \'r\') as read_file:\n', "FileNotFoundError: [Errno 2] No such file or directory: 'C:/Users/balaji.a.arunachalam/PycharmProjects/Back_end(Python,SQL)/src\\\\files\\\\records\\\\ref_invoice_details.sql'\n"]
2020-10-06 11:19:36,632 - 30340 DEBUG - ['Traceback (most recent call last):\n', '  File "C:/Users/balaji.a.arunachalam/PycharmProjects/Back_end(Python,SQL)/src/main/insertion.py", line 17, in __init__\n    temp = sys.argv[1]\n', 'IndexError: list index out of range\n', '\nDuring handling of the above exception, another exception occurred:\n\n', 'Traceback (most recent call last):\n', '  File "C:/Users/balaji.a.arunachalam/PycharmProjects/Back_end(Python,SQL)/src/main/insertion.py", line 39, in record_insertion\n    with open(file_path, \'r\') as read_file:\n', "FileNotFoundError: [Errno 2] No such file or directory: 'C:/Users/balaji.a.arunachalam/PycharmProjects/Back_end(Python,SQL)/src\\\\files\\\\records\\\\ref_invoice_details.sql'\n"]
2020-10-06 11:19:36,633 - 30340 DEBUG - ['Traceback (most recent call last):\n', '  File "C:/Users/balaji.a.arunachalam/PycharmProjects/Back_end(Python,SQL)/src/main/insertion.py", line 17, in __init__\n    temp = sys.argv[1]\n', 'IndexError: list index out of range\n', '\nDuring handling of the above exception, another exception occurred:\n\n', 'Traceback (most recent call last):\n', '  File "C:/Users/balaji.a.arunachalam/PycharmProjects/Back_end(Python,SQL)/src/main/insertion.py", line 39, in record_insertion\n    with open(file_path, \'r\') as read_file:\n', "FileNotFoundError: [Errno 2] No such file or directory: 'C:/Users/balaji.a.arunachalam/PycharmProjects/Back_end(Python,SQL)/src\\\\files\\\\records\\\\ref_payment_details.sql'\n"]
2020-10-06 11:19:36,633 - 30340 DEBUG - ['Traceback (most recent call last):\n', '  File "C:/Users/balaji.a.arunachalam/PycharmProjects/Back_end(Python,SQL)/src/main/insertion.py", line 17, in __init__\n    temp = sys.argv[1]\n', 'IndexError: list index out of range\n', '\nDuring handling of the above exception, another exception occurred:\n\n', 'Traceback (most recent call last):\n', '  File "C:/Users/balaji.a.arunachalam/PycharmProjects/Back_end(Python,SQL)/src/main/insertion.py", line 39, in record_insertion\n    with open(file_path, \'r\') as read_file:\n', "FileNotFoundError: [Errno 2] No such file or directory: 'C:/Users/balaji.a.arunachalam/PycharmProjects/Back_end(Python,SQL)/src\\\\files\\\\records\\\\ref_payment_details.sql'\n"]
2020-10-06 11:19:36,633 - 30340 DEBUG - ['Traceback (most recent call last):\n', '  File "C:/Users/balaji.a.arunachalam/PycharmProjects/Back_end(Python,SQL)/src/main/insertion.py", line 17, in __init__\n    temp = sys.argv[1]\n', 'IndexError: list index out of range\n', '\nDuring handling of the above exception, another exception occurred:\n\n', 'Traceback (most recent call last):\n', '  File "C:/Users/balaji.a.arunachalam/PycharmProjects/Back_end(Python,SQL)/src/main/insertion.py", line 39, in record_insertion\n    with open(file_path, \'r\') as read_file:\n', "FileNotFoundError: [Errno 2] No such file or directory: 'C:/Users/balaji.a.arunachalam/PycharmProjects/Back_end(Python,SQL)/src\\\\files\\\\records\\\\ref_payment_details.sql'\n"]
2020-10-06 11:19:36,634 - 30340 DEBUG - ['Traceback (most recent call last):\n', '  File "C:/Users/balaji.a.arunachalam/PycharmProjects/Back_end(Python,SQL)/src/main/insertion.py", line 17, in __init__\n    temp = sys.argv[1]\n', 'IndexError: list index out of range\n', '\nDuring handling of the above exception, another exception occurred:\n\n', 'Traceback (most recent call last):\n', '  File "C:/Users/balaji.a.arunachalam/PycharmProjects/Back_end(Python,SQL)/src/main/insertion.py", line 39, in record_insertion\n    with open(file_path, \'r\') as read_file:\n', "FileNotFoundError: [Errno 2] No such file or directory: 'C:/Users/balaji.a.arunachalam/PycharmProjects/Back_end(Python,SQL)/src\\\\files\\\\records\\\\ref_product_ordered_details.sql'\n"]
2020-10-06 11:19:36,634 - 30340 DEBUG - ['Traceback (most recent call last):\n', '  File "C:/Users/balaji.a.arunachalam/PycharmProjects/Back_end(Python,SQL)/src/main/insertion.py", line 17, in __init__\n    temp = sys.argv[1]\n', 'IndexError: list index out of range\n', '\nDuring handling of the above exception, another exception occurred:\n\n', 'Traceback (most recent call last):\n', '  File "C:/Users/balaji.a.arunachalam/PycharmProjects/Back_end(Python,SQL)/src/main/insertion.py", line 39, in record_insertion\n    with open(file_path, \'r\') as read_file:\n', "FileNotFoundError: [Errno 2] No such file or directory: 'C:/Users/balaji.a.arunachalam/PycharmProjects/Back_end(Python,SQL)/src\\\\files\\\\records\\\\ref_product_ordered_details.sql'\n"]
2020-10-06 11:19:36,634 - 30340 DEBUG - ['Traceback (most recent call last):\n', '  File "C:/Users/balaji.a.arunachalam/PycharmProjects/Back_end(Python,SQL)/src/main/insertion.py", line 17, in __init__\n    temp = sys.argv[1]\n', 'IndexError: list index out of range\n', '\nDuring handling of the above exception, another exception occurred:\n\n', 'Traceback (most recent call last):\n', '  File "C:/Users/balaji.a.arunachalam/PycharmProjects/Back_end(Python,SQL)/src/main/insertion.py", line 39, in record_insertion\n    with open(file_path, \'r\') as read_file:\n', "FileNotFoundError: [Errno 2] No such file or directory: 'C:/Users/balaji.a.arunachalam/PycharmProjects/Back_end(Python,SQL)/src\\\\files\\\\records\\\\ref_product_ordered_details.sql'\n"]
2020-10-06 11:19:36,635 - 30340 DEBUG - ['Traceback (most recent call last):\n', '  File "C:/Users/balaji.a.arunachalam/PycharmProjects/Back_end(Python,SQL)/src/main/insertion.py", line 17, in __init__\n    temp = sys.argv[1]\n', 'IndexError: list index out of range\n', '\nDuring handling of the above exception, another exception occurred:\n\n', 'Traceback (most recent call last):\n', '  File "C:/Users/balaji.a.arunachalam/PycharmProjects/Back_end(Python,SQL)/src/main/insertion.py", line 39, in record_insertion\n    with open(file_path, \'r\') as read_file:\n', "FileNotFoundError: [Errno 2] No such file or directory: 'C:/Users/balaji.a.arunachalam/PycharmProjects/Back_end(Python,SQL)/src\\\\files\\\\records\\\\ref_shipping_status.sql'\n"]
2020-10-06 11:19:36,635 - 30340 DEBUG - ['Traceback (most recent call last):\n', '  File "C:/Users/balaji.a.arunachalam/PycharmProjects/Back_end(Python,SQL)/src/main/insertion.py", line 17, in __init__\n    temp = sys.argv[1]\n', 'IndexError: list index out of range\n', '\nDuring handling of the above exception, another exception occurred:\n\n', 'Traceback (most recent call last):\n', '  File "C:/Users/balaji.a.arunachalam/PycharmProjects/Back_end(Python,SQL)/src/main/insertion.py", line 39, in record_insertion\n    with open(file_path, \'r\') as read_file:\n', "FileNotFoundError: [Errno 2] No such file or directory: 'C:/Users/balaji.a.arunachalam/PycharmProjects/Back_end(Python,SQL)/src\\\\files\\\\records\\\\ref_shipping_status.sql'\n"]
2020-10-06 11:19:36,635 - 30340 DEBUG - ['Traceback (most recent call last):\n', '  File "C:/Users/balaji.a.arunachalam/PycharmProjects/Back_end(Python,SQL)/src/main/insertion.py", line 17, in __init__\n    temp = sys.argv[1]\n', 'IndexError: list index out of range\n', '\nDuring handling of the above exception, another exception occurred:\n\n', 'Traceback (most recent call last):\n', '  File "C:/Users/balaji.a.arunachalam/PycharmProjects/Back_end(Python,SQL)/src/main/insertion.py", line 39, in record_insertion\n    with open(file_path, \'r\') as read_file:\n', "FileNotFoundError: [Errno 2] No such file or directory: 'C:/Users/balaji.a.arunachalam/PycharmProjects/Back_end(Python,SQL)/src\\\\files\\\\records\\\\ref_shipping_status.sql'\n"]
